[2020-10-20T19:55:03-0700] [MainThread] [C] [toil.jobStores.abstractJobStore] Repairing job: kind-run_phlat/instance-wyy831pe
[2020-10-20T19:55:03-0700] [MainThread] [I] [toil] Running Toil version 4.2.0-3aa1da130141039cb357efe36d7df9b9f6ae9b5b on host drkthomp-virtualbox.
[2020-10-20T19:55:03-0700] [MainThread] [I] [toil.leader] Issued job 'run_phlat' kind-run_phlat/instance-wyy831pe with job batch system ID: 0 and cores: 4, disk: 7.8 G, and memory: 2.0 G
[2020-10-20T19:55:03-0700] [MainThread] [I] [toil.leader] Issued job 'run_phlat' kind-run_phlat/instance-j5t5f3ax with job batch system ID: 1 and cores: 4, disk: 7.7 G, and memory: 2.0 G
[2020-10-20T19:55:03-0700] [MainThread] [I] [toil.leader] Issued job 'run_mutect_perchrom' kind-run_mutect_perchrom/instance-8gyqgqyx with job batch system ID: 2 and cores: 1, disk: 23.0 G, and memory: 6.0 G
[2020-10-20T19:55:03-0700] [MainThread] [I] [toil.leader] Issued job 'run_mutect_perchrom' kind-run_mutect_perchrom/instance-55hd3p6y with job batch system ID: 3 and cores: 1, disk: 23.0 G, and memory: 6.0 G
[2020-10-20T19:55:03-0700] [MainThread] [I] [toil.leader] Issued job 'run_mutect_perchrom' kind-run_mutect_perchrom/instance-cije5tr0 with job batch system ID: 4 and cores: 1, disk: 23.0 G, and memory: 6.0 G
[2020-10-20T19:55:03-0700] [MainThread] [I] [toil.leader] Issued job 'run_mutect_perchrom' kind-run_mutect_perchrom/instance-cp3zlhzq with job batch system ID: 5 and cores: 1, disk: 23.0 G, and memory: 6.0 G
[2020-10-20T19:55:03-0700] [MainThread] [I] [toil.leader] Issued job 'run_mutect_perchrom' kind-run_mutect_perchrom/instance-h18ep_9e with job batch system ID: 6 and cores: 1, disk: 23.0 G, and memory: 6.0 G
[2020-10-20T19:55:03-0700] [MainThread] [I] [toil.leader] Issued job 'run_mutect_perchrom' kind-run_mutect_perchrom/instance-vodde7jc with job batch system ID: 7 and cores: 1, disk: 23.0 G, and memory: 6.0 G
[2020-10-20T19:55:03-0700] [MainThread] [I] [toil.leader] Issued job 'run_mutect_perchrom' kind-run_mutect_perchrom/instance-40bfs1db with job batch system ID: 8 and cores: 1, disk: 23.0 G, and memory: 6.0 G
[2020-10-20T19:55:03-0700] [MainThread] [I] [toil.leader] Issued job 'run_mutect_perchrom' kind-run_mutect_perchrom/instance-92gnpm9m with job batch system ID: 9 and cores: 1, disk: 23.0 G, and memory: 6.0 G
[2020-10-20T19:55:03-0700] [MainThread] [I] [toil.leader] Issued job 'run_mutect_perchrom' kind-run_mutect_perchrom/instance-gl_w17lv with job batch system ID: 10 and cores: 1, disk: 23.0 G, and memory: 6.0 G
[2020-10-20T19:55:03-0700] [MainThread] [I] [toil.leader] Issued job 'run_mutect_perchrom' kind-run_mutect_perchrom/instance-6clikwgf with job batch system ID: 11 and cores: 1, disk: 23.0 G, and memory: 6.0 G
[2020-10-20T19:55:03-0700] [MainThread] [I] [toil.leader] Issued job 'run_mutect_perchrom' kind-run_mutect_perchrom/instance-0p9602y6 with job batch system ID: 12 and cores: 1, disk: 23.0 G, and memory: 6.0 G
[2020-10-20T19:55:03-0700] [MainThread] [I] [toil.leader] Issued job 'run_mutect_perchrom' kind-run_mutect_perchrom/instance-tjkov9ea with job batch system ID: 13 and cores: 1, disk: 23.0 G, and memory: 6.0 G
[2020-10-20T19:55:03-0700] [MainThread] [I] [toil.leader] Issued job 'run_mutect_perchrom' kind-run_mutect_perchrom/instance-9hdk8gj3 with job batch system ID: 14 and cores: 1, disk: 23.0 G, and memory: 6.0 G
[2020-10-20T19:55:03-0700] [MainThread] [I] [toil.leader] Issued job 'run_mutect_perchrom' kind-run_mutect_perchrom/instance-cev_msom with job batch system ID: 15 and cores: 1, disk: 23.0 G, and memory: 6.0 G
[2020-10-20T19:55:03-0700] [MainThread] [I] [toil.leader] Issued job 'run_mutect_perchrom' kind-run_mutect_perchrom/instance-fu63ea_u with job batch system ID: 16 and cores: 1, disk: 23.0 G, and memory: 6.0 G
[2020-10-20T19:55:03-0700] [MainThread] [I] [toil.leader] Issued job 'run_mutect_perchrom' kind-run_mutect_perchrom/instance-0oyi7ie_ with job batch system ID: 17 and cores: 1, disk: 23.0 G, and memory: 6.0 G
[2020-10-20T19:55:03-0700] [MainThread] [I] [toil.leader] Issued job 'run_mutect_perchrom' kind-run_mutect_perchrom/instance-ourgk6vm with job batch system ID: 18 and cores: 1, disk: 23.0 G, and memory: 6.0 G
[2020-10-20T19:55:03-0700] [MainThread] [I] [toil.leader] Issued job 'run_mutect_perchrom' kind-run_mutect_perchrom/instance-3a6rn9f9 with job batch system ID: 19 and cores: 1, disk: 23.0 G, and memory: 6.0 G
[2020-10-20T19:55:03-0700] [MainThread] [I] [toil.leader] Issued job 'run_mutect_perchrom' kind-run_mutect_perchrom/instance-sfhpnee3 with job batch system ID: 20 and cores: 1, disk: 23.0 G, and memory: 6.0 G
[2020-10-20T19:55:03-0700] [MainThread] [I] [toil.leader] Issued job 'run_mutect_perchrom' kind-run_mutect_perchrom/instance-bm4dpfik with job batch system ID: 21 and cores: 1, disk: 23.0 G, and memory: 6.0 G
[2020-10-20T19:55:03-0700] [MainThread] [I] [toil.leader] Issued job 'run_mutect_perchrom' kind-run_mutect_perchrom/instance-0t3dxg78 with job batch system ID: 22 and cores: 1, disk: 23.0 G, and memory: 6.0 G
[2020-10-20T19:55:03-0700] [MainThread] [I] [toil.leader] Issued job 'run_mutect_perchrom' kind-run_mutect_perchrom/instance-daisoolw with job batch system ID: 23 and cores: 1, disk: 23.0 G, and memory: 6.0 G
[2020-10-20T19:55:03-0700] [MainThread] [I] [toil.leader] Issued job 'run_mutect_perchrom' kind-run_mutect_perchrom/instance-c65720sq with job batch system ID: 24 and cores: 1, disk: 23.0 G, and memory: 6.0 G
[2020-10-20T19:55:03-0700] [MainThread] [I] [toil.leader] Issued job 'run_mutect_perchrom' kind-run_mutect_perchrom/instance-wflniclq with job batch system ID: 25 and cores: 1, disk: 23.0 G, and memory: 6.0 G
[2020-10-20T19:55:03-0700] [MainThread] [I] [toil.leader] Issued job 'run_mutect_perchrom' kind-run_mutect_perchrom/instance-yrvj0gxx with job batch system ID: 26 and cores: 1, disk: 23.0 G, and memory: 6.0 G
[2020-10-20T19:55:03-0700] [MainThread] [I] [toil.leader] Issued job 'run_phlat' kind-run_phlat/instance-dyn6bo3z with job batch system ID: 27 and cores: 4, disk: 7.7 G, and memory: 2.0 G
[2020-10-20T19:55:03-0700] [MainThread] [I] [toil.leader] Issued job 'run_star' kind-run_star/instance-5q77j6ix with job batch system ID: 28 and cores: 4, disk: 52.8 G, and memory: 48.6 G
[2020-10-20T19:55:04-0700] [MainThread] [I] [toil.worker] Redirecting logging to /home/drkthomp/workDir/node-72996abd-6cf4-462a-aea1-4d483640105b-1e53f69f16d74e0b881e7db602b2d2c3/tmpzq2p34mq/worker_log.txt
[2020-10-20T19:55:05-0700] [MainThread] [I] [toil.leader] 1 jobs are running, 28 jobs are issued and waiting to run
[2020-10-20T19:59:53-0700] [Thread-1  ] [E] [toil.batchSystems.singleMachine] Got exit code 1 (indicating failure) from job _toil_worker run_phlat file:/home/drkthomp/protect3/jobStore kind-run_phlat/instance-wyy831pe.
[2020-10-20T19:59:53-0700] [MainThread] [W] [toil.leader] Job failed with exit value 1: 'run_phlat' kind-run_phlat/instance-wyy831pe
[2020-10-20T19:59:53-0700] [MainThread] [W] [toil.leader] The job seems to have left a log file, indicating failure: 'run_phlat' kind-run_phlat/instance-wyy831pe
[2020-10-20T19:59:53-0700] [MainThread] [W] [toil.leader] Log from job kind-run_phlat/instance-wyy831pe follows:
=========>
	[2020-10-20T19:55:04-0700] [MainThread] [I] [toil.worker] ---TOIL WORKER OUTPUT LOG---
	[2020-10-20T19:55:04-0700] [MainThread] [I] [toil] Running Toil version 4.2.0-3aa1da130141039cb357efe36d7df9b9f6ae9b5b on host drkthomp-virtualbox.
	567573 reads; of these:
	  567573 (100.00%) were paired; of these:
	    3570 (0.63%) aligned concordantly 0 times
	    514680 (90.68%) aligned concordantly exactly 1 time
	    49323 (8.69%) aligned concordantly >1 times
	99.37% overall alignment rate
	.....Process Bowtie 2 mapping on tumor_dna.......
	
	.....Prepare files of tumor_dna for PHLAT.......
	
	Traceback (most recent call last):
	  File "/home/phlat-1.0/dist/PHLAT.py", line 64, in <module>
	..... Running PHLAT .......
	    go(tag,outdir,phlatdir)
	  File "/home/yubai/programs/phlat-1.0/dist/utilities.py", line 79, in go
	  File "/home/yubai/programs/phlat-1.0/dist/extensions.py", line 617, in __init__
	  File "/home/yubai/programs/phlat-1.0/dist/extensions.py", line 645, in setMaster
	IndexError: list index out of range
	Traceback (most recent call last):
	  File "/home/drkthomp/protect3/src/protect/common.py", line 136, in docker_call
	    subprocess.check_call(call, stdout=outfile)
	  File "/usr/lib/python3.8/subprocess.py", line 364, in check_call
	    raise CalledProcessError(retcode, cmd)
	subprocess.CalledProcessError: Command '['docker', 'run', '--rm=true', '-v', '/home/drkthomp/workDir/node-72996abd-6cf4-462a-aea1-4d483640105b-1e53f69f16d74e0b881e7db602b2d2c3/tmpzq2p34mq/dc8ad8e1-8a53-4203-a6be-af90156e5ece:/data', '--log-driver=none', 'aarjunrao/phlat:1.0', '-1', '/data/input_1.fastq', '-2', '/data/input_2.fastq', '-index', '/data/index4phlat', '-b2url', '/usr/local/bin/bowtie2', '-tag', 'tumor_dna', '-e', '/home/phlat-1.0', '-o', '/data', '-p', '4']' returned non-zero exit status 1.
	
	During handling of the above exception, another exception occurred:
	
	Traceback (most recent call last):
	  File "/home/drkthomp/protect3/venv/lib/python3.8/site-packages/toil/worker.py", line 368, in workerScript
	    job._runner(jobGraph=jobGraph, jobStore=jobStore, fileStore=fileStore, defer=defer)
	  File "/home/drkthomp/protect3/venv/lib/python3.8/site-packages/toil/job.py", line 1424, in _runner
	    returnValues = self._run(jobGraph, fileStore)
	  File "/home/drkthomp/protect3/venv/lib/python3.8/site-packages/toil/job.py", line 1361, in _run
	    return self.run(fileStore)
	  File "/home/drkthomp/protect3/venv/lib/python3.8/site-packages/toil/job.py", line 1565, in run
	    rValue = userFunction(*((self,) + tuple(self._args)), **self._kwargs)
	  File "/home/drkthomp/protect3/src/protect/haplotyping/phlat.py", line 73, in run_phlat
	    docker_call(tool='phlat', tool_parameters=parameters, work_dir=work_dir,
	  File "/home/drkthomp/protect3/src/protect/common.py", line 138, in docker_call
	    raise RuntimeError('docker command returned a non-zero exit status (%s)' % err.returncode +
	RuntimeError: docker command returned a non-zero exit status (1)for command "docker run --rm=true -v /home/drkthomp/workDir/node-72996abd-6cf4-462a-aea1-4d483640105b-1e53f69f16d74e0b881e7db602b2d2c3/tmpzq2p34mq/dc8ad8e1-8a53-4203-a6be-af90156e5ece:/data --log-driver=none aarjunrao/phlat:1.0 -1 /data/input_1.fastq -2 /data/input_2.fastq -index /data/index4phlat -b2url /usr/local/bin/bowtie2 -tag tumor_dna -e /home/phlat-1.0 -o /data -p 4"
	[2020-10-20T19:59:53-0700] [MainThread] [E] [toil.worker] Exiting the worker because of a failed job on host drkthomp-virtualbox
	{'input_1.fastq': '/home/drkthomp/workDir/node-72996abd-6cf4-462a-aea1-4d483640105b-1e53f69f16d74e0b881e7db602b2d2c3/tmpzq2p34mq/dc8ad8e1-8a53-4203-a6be-af90156e5ece/input_1.fastq', 'input_2.fastq': '/home/drkthomp/workDir/node-72996abd-6cf4-462a-aea1-4d483640105b-1e53f69f16d74e0b881e7db602b2d2c3/tmpzq2p34mq/dc8ad8e1-8a53-4203-a6be-af90156e5ece/input_2.fastq', 'phlat_index.tar.gz': '/home/drkthomp/workDir/node-72996abd-6cf4-462a-aea1-4d483640105b-1e53f69f16d74e0b881e7db602b2d2c3/tmpzq2p34mq/dc8ad8e1-8a53-4203-a6be-af90156e5ece/phlat_index.tar.gz'}
<=========
[2020-10-20T19:59:53-0700] [MainThread] [W] [toil.jobGraph] Due to failure we are reducing the remaining retry count of job 'run_phlat' kind-run_phlat/instance-wyy831pe with ID kind-run_phlat/instance-wyy831pe to 1
[2020-10-20T19:59:53-0700] [MainThread] [I] [toil.leader] Issued job 'run_phlat' kind-run_phlat/instance-wyy831pe with job batch system ID: 29 and cores: 4, disk: 7.8 G, and memory: 2.0 G
[2020-10-20T19:59:55-0700] [MainThread] [I] [toil.worker] Redirecting logging to /home/drkthomp/workDir/node-72996abd-6cf4-462a-aea1-4d483640105b-1e53f69f16d74e0b881e7db602b2d2c3/tmph6pezca5/worker_log.txt
[2020-10-20T19:59:55-0700] [MainThread] [I] [toil.worker] Redirecting logging to /home/drkthomp/workDir/node-72996abd-6cf4-462a-aea1-4d483640105b-1e53f69f16d74e0b881e7db602b2d2c3/tmpo_180tf9/worker_log.txt
[2020-10-20T19:59:55-0700] [Thread-1  ] [E] [toil.batchSystems.singleMachine] Got exit code 1 (indicating failure) from job _toil_worker run_mutect_perchrom file:/home/drkthomp/protect3/jobStore kind-run_mutect_perchrom/instance-fu63ea_u.
[2020-10-20T19:59:55-0700] [MainThread] [W] [toil.leader] Job failed with exit value 1: 'run_mutect_perchrom' kind-run_mutect_perchrom/instance-fu63ea_u
[2020-10-20T19:59:55-0700] [MainThread] [W] [toil.leader] The job seems to have left a log file, indicating failure: 'run_mutect_perchrom' kind-run_mutect_perchrom/instance-fu63ea_u
[2020-10-20T19:59:55-0700] [MainThread] [W] [toil.leader] Log from job kind-run_mutect_perchrom/instance-fu63ea_u follows:
=========>
	[2020-10-20T19:59:55-0700] [MainThread] [I] [toil.worker] ---TOIL WORKER OUTPUT LOG---
	[2020-10-20T19:59:55-0700] [MainThread] [I] [toil] Running Toil version 4.2.0-3aa1da130141039cb357efe36d7df9b9f6ae9b5b on host drkthomp-virtualbox.
	Traceback (most recent call last):
	  File "/home/drkthomp/protect3/venv/lib/python3.8/site-packages/toil/worker.py", line 368, in workerScript
	    job._runner(jobGraph=jobGraph, jobStore=jobStore, fileStore=fileStore, defer=defer)
	  File "/home/drkthomp/protect3/venv/lib/python3.8/site-packages/toil/job.py", line 1424, in _runner
	    returnValues = self._run(jobGraph, fileStore)
	  File "/home/drkthomp/protect3/venv/lib/python3.8/site-packages/toil/job.py", line 1361, in _run
	    return self.run(fileStore)
	  File "/home/drkthomp/protect3/venv/lib/python3.8/site-packages/toil/job.py", line 1565, in run
	    rValue = userFunction(*((self,) + tuple(self._args)), **self._kwargs)
	  File "/home/drkthomp/protect3/src/protect/mutation_calling/mutect.py", line 123, in run_mutect_perchrom
	    input_files['dbsnp.vcf'] = gunzip(input_files['dbsnp.vcf.gz'])
	  File "/home/drkthomp/protect3/src/protect/common.py", line 172, in gunzip
	    assert is_gzipfile(input_gzip_file)
	AssertionError
	[2020-10-20T19:59:55-0700] [MainThread] [E] [toil.worker] Exiting the worker because of a failed job on host drkthomp-virtualbox
<=========
[2020-10-20T19:59:55-0700] [MainThread] [W] [toil.jobGraph] Due to failure we are reducing the remaining retry count of job 'run_mutect_perchrom' kind-run_mutect_perchrom/instance-fu63ea_u with ID kind-run_mutect_perchrom/instance-fu63ea_u to 1
[2020-10-20T19:59:55-0700] [MainThread] [I] [toil.leader] Issued job 'run_mutect_perchrom' kind-run_mutect_perchrom/instance-fu63ea_u with job batch system ID: 30 and cores: 1, disk: 23.0 G, and memory: 6.0 G
[2020-10-20T19:59:55-0700] [Thread-1  ] [E] [toil.batchSystems.singleMachine] Got exit code 1 (indicating failure) from job _toil_worker run_mutect_perchrom file:/home/drkthomp/protect3/jobStore kind-run_mutect_perchrom/instance-0oyi7ie_.
[2020-10-20T19:59:55-0700] [MainThread] [W] [toil.leader] Job failed with exit value 1: 'run_mutect_perchrom' kind-run_mutect_perchrom/instance-0oyi7ie_
[2020-10-20T19:59:55-0700] [MainThread] [W] [toil.leader] The job seems to have left a log file, indicating failure: 'run_mutect_perchrom' kind-run_mutect_perchrom/instance-0oyi7ie_
[2020-10-20T19:59:55-0700] [MainThread] [W] [toil.leader] Log from job kind-run_mutect_perchrom/instance-0oyi7ie_ follows:
=========>
	[2020-10-20T19:59:55-0700] [MainThread] [I] [toil.worker] ---TOIL WORKER OUTPUT LOG---
	[2020-10-20T19:59:55-0700] [MainThread] [I] [toil] Running Toil version 4.2.0-3aa1da130141039cb357efe36d7df9b9f6ae9b5b on host drkthomp-virtualbox.
	Traceback (most recent call last):
	  File "/home/drkthomp/protect3/venv/lib/python3.8/site-packages/toil/worker.py", line 368, in workerScript
	    job._runner(jobGraph=jobGraph, jobStore=jobStore, fileStore=fileStore, defer=defer)
	  File "/home/drkthomp/protect3/venv/lib/python3.8/site-packages/toil/job.py", line 1424, in _runner
	    returnValues = self._run(jobGraph, fileStore)
	  File "/home/drkthomp/protect3/venv/lib/python3.8/site-packages/toil/job.py", line 1361, in _run
	    return self.run(fileStore)
	  File "/home/drkthomp/protect3/venv/lib/python3.8/site-packages/toil/job.py", line 1565, in run
	    rValue = userFunction(*((self,) + tuple(self._args)), **self._kwargs)
	  File "/home/drkthomp/protect3/src/protect/mutation_calling/mutect.py", line 123, in run_mutect_perchrom
	    input_files['dbsnp.vcf'] = gunzip(input_files['dbsnp.vcf.gz'])
	  File "/home/drkthomp/protect3/src/protect/common.py", line 172, in gunzip
	    assert is_gzipfile(input_gzip_file)
	AssertionError
	[2020-10-20T19:59:55-0700] [MainThread] [E] [toil.worker] Exiting the worker because of a failed job on host drkthomp-virtualbox
<=========
[2020-10-20T19:59:55-0700] [MainThread] [W] [toil.jobGraph] Due to failure we are reducing the remaining retry count of job 'run_mutect_perchrom' kind-run_mutect_perchrom/instance-0oyi7ie_ with ID kind-run_mutect_perchrom/instance-0oyi7ie_ to 1
[2020-10-20T19:59:55-0700] [MainThread] [I] [toil.leader] Issued job 'run_mutect_perchrom' kind-run_mutect_perchrom/instance-0oyi7ie_ with job batch system ID: 31 and cores: 1, disk: 23.0 G, and memory: 6.0 G
[2020-10-20T19:59:56-0700] [MainThread] [I] [toil.worker] Redirecting logging to /home/drkthomp/workDir/node-72996abd-6cf4-462a-aea1-4d483640105b-1e53f69f16d74e0b881e7db602b2d2c3/tmpp3s46i2h/worker_log.txt
[2020-10-20T19:59:56-0700] [MainThread] [I] [toil.worker] Redirecting logging to /home/drkthomp/workDir/node-72996abd-6cf4-462a-aea1-4d483640105b-1e53f69f16d74e0b881e7db602b2d2c3/tmpl_mg14pv/worker_log.txt
[2020-10-20T19:59:56-0700] [Thread-1  ] [E] [toil.batchSystems.singleMachine] Got exit code 1 (indicating failure) from job _toil_worker run_mutect_perchrom file:/home/drkthomp/protect3/jobStore kind-run_mutect_perchrom/instance-sfhpnee3.
[2020-10-20T19:59:56-0700] [MainThread] [W] [toil.leader] Job failed with exit value 1: 'run_mutect_perchrom' kind-run_mutect_perchrom/instance-sfhpnee3
[2020-10-20T19:59:56-0700] [MainThread] [W] [toil.leader] The job seems to have left a log file, indicating failure: 'run_mutect_perchrom' kind-run_mutect_perchrom/instance-sfhpnee3
[2020-10-20T19:59:56-0700] [MainThread] [W] [toil.leader] Log from job kind-run_mutect_perchrom/instance-sfhpnee3 follows:
=========>
	[2020-10-20T19:59:56-0700] [MainThread] [I] [toil.worker] ---TOIL WORKER OUTPUT LOG---
	[2020-10-20T19:59:56-0700] [MainThread] [I] [toil] Running Toil version 4.2.0-3aa1da130141039cb357efe36d7df9b9f6ae9b5b on host drkthomp-virtualbox.
	Traceback (most recent call last):
	  File "/home/drkthomp/protect3/venv/lib/python3.8/site-packages/toil/worker.py", line 368, in workerScript
	    job._runner(jobGraph=jobGraph, jobStore=jobStore, fileStore=fileStore, defer=defer)
	  File "/home/drkthomp/protect3/venv/lib/python3.8/site-packages/toil/job.py", line 1424, in _runner
	    returnValues = self._run(jobGraph, fileStore)
	  File "/home/drkthomp/protect3/venv/lib/python3.8/site-packages/toil/job.py", line 1361, in _run
	    return self.run(fileStore)
	  File "/home/drkthomp/protect3/venv/lib/python3.8/site-packages/toil/job.py", line 1565, in run
	    rValue = userFunction(*((self,) + tuple(self._args)), **self._kwargs)
	  File "/home/drkthomp/protect3/src/protect/mutation_calling/mutect.py", line 123, in run_mutect_perchrom
	    input_files['dbsnp.vcf'] = gunzip(input_files['dbsnp.vcf.gz'])
	  File "/home/drkthomp/protect3/src/protect/common.py", line 172, in gunzip
	    assert is_gzipfile(input_gzip_file)
	AssertionError
	[2020-10-20T19:59:56-0700] [MainThread] [E] [toil.worker] Exiting the worker because of a failed job on host drkthomp-virtualbox
<=========
[2020-10-20T19:59:56-0700] [MainThread] [W] [toil.jobGraph] Due to failure we are reducing the remaining retry count of job 'run_mutect_perchrom' kind-run_mutect_perchrom/instance-sfhpnee3 with ID kind-run_mutect_perchrom/instance-sfhpnee3 to 1
[2020-10-20T19:59:56-0700] [MainThread] [I] [toil.leader] Issued job 'run_mutect_perchrom' kind-run_mutect_perchrom/instance-sfhpnee3 with job batch system ID: 32 and cores: 1, disk: 23.0 G, and memory: 6.0 G
[2020-10-20T19:59:56-0700] [Thread-1  ] [E] [toil.batchSystems.singleMachine] Got exit code 1 (indicating failure) from job _toil_worker run_mutect_perchrom file:/home/drkthomp/protect3/jobStore kind-run_mutect_perchrom/instance-daisoolw.
[2020-10-20T19:59:56-0700] [MainThread] [W] [toil.leader] Job failed with exit value 1: 'run_mutect_perchrom' kind-run_mutect_perchrom/instance-daisoolw
[2020-10-20T19:59:56-0700] [MainThread] [W] [toil.leader] The job seems to have left a log file, indicating failure: 'run_mutect_perchrom' kind-run_mutect_perchrom/instance-daisoolw
[2020-10-20T19:59:56-0700] [MainThread] [W] [toil.leader] Log from job kind-run_mutect_perchrom/instance-daisoolw follows:
=========>
	[2020-10-20T19:59:56-0700] [MainThread] [I] [toil.worker] ---TOIL WORKER OUTPUT LOG---
	[2020-10-20T19:59:56-0700] [MainThread] [I] [toil] Running Toil version 4.2.0-3aa1da130141039cb357efe36d7df9b9f6ae9b5b on host drkthomp-virtualbox.
	Traceback (most recent call last):
	  File "/home/drkthomp/protect3/venv/lib/python3.8/site-packages/toil/worker.py", line 368, in workerScript
	    job._runner(jobGraph=jobGraph, jobStore=jobStore, fileStore=fileStore, defer=defer)
	  File "/home/drkthomp/protect3/venv/lib/python3.8/site-packages/toil/job.py", line 1424, in _runner
	    returnValues = self._run(jobGraph, fileStore)
	  File "/home/drkthomp/protect3/venv/lib/python3.8/site-packages/toil/job.py", line 1361, in _run
	    return self.run(fileStore)
	  File "/home/drkthomp/protect3/venv/lib/python3.8/site-packages/toil/job.py", line 1565, in run
	    rValue = userFunction(*((self,) + tuple(self._args)), **self._kwargs)
	  File "/home/drkthomp/protect3/src/protect/mutation_calling/mutect.py", line 123, in run_mutect_perchrom
	    input_files['dbsnp.vcf'] = gunzip(input_files['dbsnp.vcf.gz'])
	  File "/home/drkthomp/protect3/src/protect/common.py", line 172, in gunzip
	    assert is_gzipfile(input_gzip_file)
	AssertionError
	[2020-10-20T19:59:56-0700] [MainThread] [E] [toil.worker] Exiting the worker because of a failed job on host drkthomp-virtualbox
<=========
[2020-10-20T19:59:56-0700] [MainThread] [W] [toil.jobGraph] Due to failure we are reducing the remaining retry count of job 'run_mutect_perchrom' kind-run_mutect_perchrom/instance-daisoolw with ID kind-run_mutect_perchrom/instance-daisoolw to 1
[2020-10-20T19:59:56-0700] [MainThread] [I] [toil.leader] Issued job 'run_mutect_perchrom' kind-run_mutect_perchrom/instance-daisoolw with job batch system ID: 33 and cores: 1, disk: 23.0 G, and memory: 6.0 G
[2020-10-20T19:59:56-0700] [MainThread] [I] [toil.worker] Redirecting logging to /home/drkthomp/workDir/node-72996abd-6cf4-462a-aea1-4d483640105b-1e53f69f16d74e0b881e7db602b2d2c3/tmpzczpuoh0/worker_log.txt
[2020-10-20T19:59:56-0700] [MainThread] [I] [toil.worker] Redirecting logging to /home/drkthomp/workDir/node-72996abd-6cf4-462a-aea1-4d483640105b-1e53f69f16d74e0b881e7db602b2d2c3/tmpzcuw8cy_/worker_log.txt
[2020-10-20T19:59:56-0700] [Thread-1  ] [E] [toil.batchSystems.singleMachine] Got exit code 1 (indicating failure) from job _toil_worker run_mutect_perchrom file:/home/drkthomp/protect3/jobStore kind-run_mutect_perchrom/instance-8gyqgqyx.
[2020-10-20T19:59:56-0700] [MainThread] [W] [toil.leader] Job failed with exit value 1: 'run_mutect_perchrom' kind-run_mutect_perchrom/instance-8gyqgqyx
[2020-10-20T19:59:56-0700] [MainThread] [W] [toil.leader] The job seems to have left a log file, indicating failure: 'run_mutect_perchrom' kind-run_mutect_perchrom/instance-8gyqgqyx
[2020-10-20T19:59:56-0700] [MainThread] [W] [toil.leader] Log from job kind-run_mutect_perchrom/instance-8gyqgqyx follows:
=========>
	[2020-10-20T19:59:56-0700] [MainThread] [I] [toil.worker] ---TOIL WORKER OUTPUT LOG---
	[2020-10-20T19:59:56-0700] [MainThread] [I] [toil] Running Toil version 4.2.0-3aa1da130141039cb357efe36d7df9b9f6ae9b5b on host drkthomp-virtualbox.
	Traceback (most recent call last):
	  File "/home/drkthomp/protect3/venv/lib/python3.8/site-packages/toil/worker.py", line 368, in workerScript
	    job._runner(jobGraph=jobGraph, jobStore=jobStore, fileStore=fileStore, defer=defer)
	  File "/home/drkthomp/protect3/venv/lib/python3.8/site-packages/toil/job.py", line 1424, in _runner
	    returnValues = self._run(jobGraph, fileStore)
	  File "/home/drkthomp/protect3/venv/lib/python3.8/site-packages/toil/job.py", line 1361, in _run
	    return self.run(fileStore)
	  File "/home/drkthomp/protect3/venv/lib/python3.8/site-packages/toil/job.py", line 1565, in run
	    rValue = userFunction(*((self,) + tuple(self._args)), **self._kwargs)
	  File "/home/drkthomp/protect3/src/protect/mutation_calling/mutect.py", line 123, in run_mutect_perchrom
	    input_files['dbsnp.vcf'] = gunzip(input_files['dbsnp.vcf.gz'])
	  File "/home/drkthomp/protect3/src/protect/common.py", line 172, in gunzip
	    assert is_gzipfile(input_gzip_file)
	AssertionError
	[2020-10-20T19:59:56-0700] [MainThread] [E] [toil.worker] Exiting the worker because of a failed job on host drkthomp-virtualbox
<=========
[2020-10-20T19:59:56-0700] [MainThread] [W] [toil.jobGraph] Due to failure we are reducing the remaining retry count of job 'run_mutect_perchrom' kind-run_mutect_perchrom/instance-8gyqgqyx with ID kind-run_mutect_perchrom/instance-8gyqgqyx to 1
[2020-10-20T19:59:56-0700] [MainThread] [I] [toil.leader] Issued job 'run_mutect_perchrom' kind-run_mutect_perchrom/instance-8gyqgqyx with job batch system ID: 34 and cores: 1, disk: 23.0 G, and memory: 6.0 G
[2020-10-20T19:59:56-0700] [Thread-1  ] [E] [toil.batchSystems.singleMachine] Got exit code 1 (indicating failure) from job _toil_worker run_mutect_perchrom file:/home/drkthomp/protect3/jobStore kind-run_mutect_perchrom/instance-cp3zlhzq.
[2020-10-20T19:59:56-0700] [MainThread] [W] [toil.leader] Job failed with exit value 1: 'run_mutect_perchrom' kind-run_mutect_perchrom/instance-cp3zlhzq
[2020-10-20T19:59:56-0700] [MainThread] [W] [toil.leader] The job seems to have left a log file, indicating failure: 'run_mutect_perchrom' kind-run_mutect_perchrom/instance-cp3zlhzq
[2020-10-20T19:59:56-0700] [MainThread] [W] [toil.leader] Log from job kind-run_mutect_perchrom/instance-cp3zlhzq follows:
=========>
	[2020-10-20T19:59:56-0700] [MainThread] [I] [toil.worker] ---TOIL WORKER OUTPUT LOG---
	[2020-10-20T19:59:56-0700] [MainThread] [I] [toil] Running Toil version 4.2.0-3aa1da130141039cb357efe36d7df9b9f6ae9b5b on host drkthomp-virtualbox.
	Traceback (most recent call last):
	  File "/home/drkthomp/protect3/venv/lib/python3.8/site-packages/toil/worker.py", line 368, in workerScript
	    job._runner(jobGraph=jobGraph, jobStore=jobStore, fileStore=fileStore, defer=defer)
	  File "/home/drkthomp/protect3/venv/lib/python3.8/site-packages/toil/job.py", line 1424, in _runner
	    returnValues = self._run(jobGraph, fileStore)
	  File "/home/drkthomp/protect3/venv/lib/python3.8/site-packages/toil/job.py", line 1361, in _run
	    return self.run(fileStore)
	  File "/home/drkthomp/protect3/venv/lib/python3.8/site-packages/toil/job.py", line 1565, in run
	    rValue = userFunction(*((self,) + tuple(self._args)), **self._kwargs)
	  File "/home/drkthomp/protect3/src/protect/mutation_calling/mutect.py", line 123, in run_mutect_perchrom
	    input_files['dbsnp.vcf'] = gunzip(input_files['dbsnp.vcf.gz'])
	  File "/home/drkthomp/protect3/src/protect/common.py", line 172, in gunzip
	    assert is_gzipfile(input_gzip_file)
	AssertionError
	[2020-10-20T19:59:56-0700] [MainThread] [E] [toil.worker] Exiting the worker because of a failed job on host drkthomp-virtualbox
<=========
[2020-10-20T19:59:56-0700] [MainThread] [W] [toil.jobGraph] Due to failure we are reducing the remaining retry count of job 'run_mutect_perchrom' kind-run_mutect_perchrom/instance-cp3zlhzq with ID kind-run_mutect_perchrom/instance-cp3zlhzq to 1
[2020-10-20T19:59:56-0700] [MainThread] [I] [toil.leader] Issued job 'run_mutect_perchrom' kind-run_mutect_perchrom/instance-cp3zlhzq with job batch system ID: 35 and cores: 1, disk: 23.0 G, and memory: 6.0 G
[2020-10-20T19:59:56-0700] [MainThread] [I] [toil.worker] Redirecting logging to /home/drkthomp/workDir/node-72996abd-6cf4-462a-aea1-4d483640105b-1e53f69f16d74e0b881e7db602b2d2c3/tmpug3kd1d1/worker_log.txt
[2020-10-20T19:59:56-0700] [MainThread] [I] [toil.worker] Redirecting logging to /home/drkthomp/workDir/node-72996abd-6cf4-462a-aea1-4d483640105b-1e53f69f16d74e0b881e7db602b2d2c3/tmpuhdsryhg/worker_log.txt
[2020-10-20T19:59:56-0700] [Thread-1  ] [E] [toil.batchSystems.singleMachine] Got exit code 1 (indicating failure) from job _toil_worker run_mutect_perchrom file:/home/drkthomp/protect3/jobStore kind-run_mutect_perchrom/instance-0p9602y6.
[2020-10-20T19:59:56-0700] [MainThread] [W] [toil.leader] Job failed with exit value 1: 'run_mutect_perchrom' kind-run_mutect_perchrom/instance-0p9602y6
[2020-10-20T19:59:56-0700] [MainThread] [W] [toil.leader] The job seems to have left a log file, indicating failure: 'run_mutect_perchrom' kind-run_mutect_perchrom/instance-0p9602y6
[2020-10-20T19:59:56-0700] [MainThread] [W] [toil.leader] Log from job kind-run_mutect_perchrom/instance-0p9602y6 follows:
=========>
	[2020-10-20T19:59:56-0700] [MainThread] [I] [toil.worker] ---TOIL WORKER OUTPUT LOG---
	[2020-10-20T19:59:56-0700] [MainThread] [I] [toil] Running Toil version 4.2.0-3aa1da130141039cb357efe36d7df9b9f6ae9b5b on host drkthomp-virtualbox.
	Traceback (most recent call last):
	  File "/home/drkthomp/protect3/venv/lib/python3.8/site-packages/toil/worker.py", line 368, in workerScript
	    job._runner(jobGraph=jobGraph, jobStore=jobStore, fileStore=fileStore, defer=defer)
	  File "/home/drkthomp/protect3/venv/lib/python3.8/site-packages/toil/job.py", line 1424, in _runner
	    returnValues = self._run(jobGraph, fileStore)
	  File "/home/drkthomp/protect3/venv/lib/python3.8/site-packages/toil/job.py", line 1361, in _run
	    return self.run(fileStore)
	  File "/home/drkthomp/protect3/venv/lib/python3.8/site-packages/toil/job.py", line 1565, in run
	    rValue = userFunction(*((self,) + tuple(self._args)), **self._kwargs)
	  File "/home/drkthomp/protect3/src/protect/mutation_calling/mutect.py", line 123, in run_mutect_perchrom
	    input_files['dbsnp.vcf'] = gunzip(input_files['dbsnp.vcf.gz'])
	  File "/home/drkthomp/protect3/src/protect/common.py", line 172, in gunzip
	    assert is_gzipfile(input_gzip_file)
	AssertionError
	[2020-10-20T19:59:56-0700] [MainThread] [E] [toil.worker] Exiting the worker because of a failed job on host drkthomp-virtualbox
<=========
[2020-10-20T19:59:56-0700] [MainThread] [W] [toil.jobGraph] Due to failure we are reducing the remaining retry count of job 'run_mutect_perchrom' kind-run_mutect_perchrom/instance-0p9602y6 with ID kind-run_mutect_perchrom/instance-0p9602y6 to 1
[2020-10-20T19:59:56-0700] [MainThread] [I] [toil.leader] Issued job 'run_mutect_perchrom' kind-run_mutect_perchrom/instance-0p9602y6 with job batch system ID: 36 and cores: 1, disk: 23.0 G, and memory: 6.0 G
[2020-10-20T19:59:56-0700] [Thread-1  ] [E] [toil.batchSystems.singleMachine] Got exit code 1 (indicating failure) from job _toil_worker run_mutect_perchrom file:/home/drkthomp/protect3/jobStore kind-run_mutect_perchrom/instance-9hdk8gj3.
[2020-10-20T19:59:56-0700] [MainThread] [W] [toil.leader] Job failed with exit value 1: 'run_mutect_perchrom' kind-run_mutect_perchrom/instance-9hdk8gj3
[2020-10-20T19:59:56-0700] [MainThread] [W] [toil.leader] The job seems to have left a log file, indicating failure: 'run_mutect_perchrom' kind-run_mutect_perchrom/instance-9hdk8gj3
[2020-10-20T19:59:56-0700] [MainThread] [W] [toil.leader] Log from job kind-run_mutect_perchrom/instance-9hdk8gj3 follows:
=========>
	[2020-10-20T19:59:56-0700] [MainThread] [I] [toil.worker] ---TOIL WORKER OUTPUT LOG---
	[2020-10-20T19:59:56-0700] [MainThread] [I] [toil] Running Toil version 4.2.0-3aa1da130141039cb357efe36d7df9b9f6ae9b5b on host drkthomp-virtualbox.
	Traceback (most recent call last):
	  File "/home/drkthomp/protect3/venv/lib/python3.8/site-packages/toil/worker.py", line 368, in workerScript
	    job._runner(jobGraph=jobGraph, jobStore=jobStore, fileStore=fileStore, defer=defer)
	  File "/home/drkthomp/protect3/venv/lib/python3.8/site-packages/toil/job.py", line 1424, in _runner
	    returnValues = self._run(jobGraph, fileStore)
	  File "/home/drkthomp/protect3/venv/lib/python3.8/site-packages/toil/job.py", line 1361, in _run
	    return self.run(fileStore)
	  File "/home/drkthomp/protect3/venv/lib/python3.8/site-packages/toil/job.py", line 1565, in run
	    rValue = userFunction(*((self,) + tuple(self._args)), **self._kwargs)
	  File "/home/drkthomp/protect3/src/protect/mutation_calling/mutect.py", line 123, in run_mutect_perchrom
	    input_files['dbsnp.vcf'] = gunzip(input_files['dbsnp.vcf.gz'])
	  File "/home/drkthomp/protect3/src/protect/common.py", line 172, in gunzip
	    assert is_gzipfile(input_gzip_file)
	AssertionError
	[2020-10-20T19:59:56-0700] [MainThread] [E] [toil.worker] Exiting the worker because of a failed job on host drkthomp-virtualbox
<=========
[2020-10-20T19:59:56-0700] [MainThread] [W] [toil.jobGraph] Due to failure we are reducing the remaining retry count of job 'run_mutect_perchrom' kind-run_mutect_perchrom/instance-9hdk8gj3 with ID kind-run_mutect_perchrom/instance-9hdk8gj3 to 1
[2020-10-20T19:59:56-0700] [MainThread] [I] [toil.leader] Issued job 'run_mutect_perchrom' kind-run_mutect_perchrom/instance-9hdk8gj3 with job batch system ID: 37 and cores: 1, disk: 23.0 G, and memory: 6.0 G
[2020-10-20T19:59:57-0700] [MainThread] [I] [toil.worker] Redirecting logging to /home/drkthomp/workDir/node-72996abd-6cf4-462a-aea1-4d483640105b-1e53f69f16d74e0b881e7db602b2d2c3/tmpw5juq_26/worker_log.txt
[2020-10-20T19:59:57-0700] [MainThread] [I] [toil.worker] Redirecting logging to /home/drkthomp/workDir/node-72996abd-6cf4-462a-aea1-4d483640105b-1e53f69f16d74e0b881e7db602b2d2c3/tmpqq4z20t9/worker_log.txt
[2020-10-20T19:59:57-0700] [Thread-1  ] [E] [toil.batchSystems.singleMachine] Got exit code 1 (indicating failure) from job _toil_worker run_mutect_perchrom file:/home/drkthomp/protect3/jobStore kind-run_mutect_perchrom/instance-ourgk6vm.
[2020-10-20T19:59:57-0700] [MainThread] [W] [toil.leader] Job failed with exit value 1: 'run_mutect_perchrom' kind-run_mutect_perchrom/instance-ourgk6vm
[2020-10-20T19:59:57-0700] [MainThread] [W] [toil.leader] The job seems to have left a log file, indicating failure: 'run_mutect_perchrom' kind-run_mutect_perchrom/instance-ourgk6vm
[2020-10-20T19:59:57-0700] [MainThread] [W] [toil.leader] Log from job kind-run_mutect_perchrom/instance-ourgk6vm follows:
=========>
	[2020-10-20T19:59:57-0700] [MainThread] [I] [toil.worker] ---TOIL WORKER OUTPUT LOG---
	[2020-10-20T19:59:57-0700] [MainThread] [I] [toil] Running Toil version 4.2.0-3aa1da130141039cb357efe36d7df9b9f6ae9b5b on host drkthomp-virtualbox.
	Traceback (most recent call last):
	  File "/home/drkthomp/protect3/venv/lib/python3.8/site-packages/toil/worker.py", line 368, in workerScript
	    job._runner(jobGraph=jobGraph, jobStore=jobStore, fileStore=fileStore, defer=defer)
	  File "/home/drkthomp/protect3/venv/lib/python3.8/site-packages/toil/job.py", line 1424, in _runner
	    returnValues = self._run(jobGraph, fileStore)
	  File "/home/drkthomp/protect3/venv/lib/python3.8/site-packages/toil/job.py", line 1361, in _run
	    return self.run(fileStore)
	  File "/home/drkthomp/protect3/venv/lib/python3.8/site-packages/toil/job.py", line 1565, in run
	    rValue = userFunction(*((self,) + tuple(self._args)), **self._kwargs)
	  File "/home/drkthomp/protect3/src/protect/mutation_calling/mutect.py", line 123, in run_mutect_perchrom
	    input_files['dbsnp.vcf'] = gunzip(input_files['dbsnp.vcf.gz'])
	  File "/home/drkthomp/protect3/src/protect/common.py", line 172, in gunzip
	    assert is_gzipfile(input_gzip_file)
	AssertionError
	[2020-10-20T19:59:57-0700] [MainThread] [E] [toil.worker] Exiting the worker because of a failed job on host drkthomp-virtualbox
<=========
[2020-10-20T19:59:57-0700] [MainThread] [W] [toil.jobGraph] Due to failure we are reducing the remaining retry count of job 'run_mutect_perchrom' kind-run_mutect_perchrom/instance-ourgk6vm with ID kind-run_mutect_perchrom/instance-ourgk6vm to 1
[2020-10-20T19:59:57-0700] [MainThread] [I] [toil.leader] Issued job 'run_mutect_perchrom' kind-run_mutect_perchrom/instance-ourgk6vm with job batch system ID: 38 and cores: 1, disk: 23.0 G, and memory: 6.0 G
[2020-10-20T19:59:57-0700] [Thread-1  ] [E] [toil.batchSystems.singleMachine] Got exit code 1 (indicating failure) from job _toil_worker run_mutect_perchrom file:/home/drkthomp/protect3/jobStore kind-run_mutect_perchrom/instance-0t3dxg78.
[2020-10-20T19:59:57-0700] [MainThread] [W] [toil.leader] Job failed with exit value 1: 'run_mutect_perchrom' kind-run_mutect_perchrom/instance-0t3dxg78
[2020-10-20T19:59:57-0700] [MainThread] [W] [toil.leader] The job seems to have left a log file, indicating failure: 'run_mutect_perchrom' kind-run_mutect_perchrom/instance-0t3dxg78
[2020-10-20T19:59:57-0700] [MainThread] [W] [toil.leader] Log from job kind-run_mutect_perchrom/instance-0t3dxg78 follows:
=========>
	[2020-10-20T19:59:57-0700] [MainThread] [I] [toil.worker] ---TOIL WORKER OUTPUT LOG---
	[2020-10-20T19:59:57-0700] [MainThread] [I] [toil] Running Toil version 4.2.0-3aa1da130141039cb357efe36d7df9b9f6ae9b5b on host drkthomp-virtualbox.
	Traceback (most recent call last):
	  File "/home/drkthomp/protect3/venv/lib/python3.8/site-packages/toil/worker.py", line 368, in workerScript
	    job._runner(jobGraph=jobGraph, jobStore=jobStore, fileStore=fileStore, defer=defer)
	  File "/home/drkthomp/protect3/venv/lib/python3.8/site-packages/toil/job.py", line 1424, in _runner
	    returnValues = self._run(jobGraph, fileStore)
	  File "/home/drkthomp/protect3/venv/lib/python3.8/site-packages/toil/job.py", line 1361, in _run
	    return self.run(fileStore)
	  File "/home/drkthomp/protect3/venv/lib/python3.8/site-packages/toil/job.py", line 1565, in run
	    rValue = userFunction(*((self,) + tuple(self._args)), **self._kwargs)
	  File "/home/drkthomp/protect3/src/protect/mutation_calling/mutect.py", line 123, in run_mutect_perchrom
	    input_files['dbsnp.vcf'] = gunzip(input_files['dbsnp.vcf.gz'])
	  File "/home/drkthomp/protect3/src/protect/common.py", line 172, in gunzip
	    assert is_gzipfile(input_gzip_file)
	AssertionError
	[2020-10-20T19:59:57-0700] [MainThread] [E] [toil.worker] Exiting the worker because of a failed job on host drkthomp-virtualbox
<=========
[2020-10-20T19:59:57-0700] [MainThread] [W] [toil.jobGraph] Due to failure we are reducing the remaining retry count of job 'run_mutect_perchrom' kind-run_mutect_perchrom/instance-0t3dxg78 with ID kind-run_mutect_perchrom/instance-0t3dxg78 to 1
[2020-10-20T19:59:57-0700] [MainThread] [I] [toil.leader] Issued job 'run_mutect_perchrom' kind-run_mutect_perchrom/instance-0t3dxg78 with job batch system ID: 39 and cores: 1, disk: 23.0 G, and memory: 6.0 G
[2020-10-20T19:59:57-0700] [MainThread] [I] [toil.worker] Redirecting logging to /home/drkthomp/workDir/node-72996abd-6cf4-462a-aea1-4d483640105b-1e53f69f16d74e0b881e7db602b2d2c3/tmpjgnmciut/worker_log.txt
[2020-10-20T19:59:57-0700] [Thread-1  ] [E] [toil.batchSystems.singleMachine] Got exit code 1 (indicating failure) from job _toil_worker run_mutect_perchrom file:/home/drkthomp/protect3/jobStore kind-run_mutect_perchrom/instance-c65720sq.
[2020-10-20T19:59:57-0700] [MainThread] [W] [toil.leader] Job failed with exit value 1: 'run_mutect_perchrom' kind-run_mutect_perchrom/instance-c65720sq
[2020-10-20T19:59:57-0700] [MainThread] [W] [toil.leader] The job seems to have left a log file, indicating failure: 'run_mutect_perchrom' kind-run_mutect_perchrom/instance-c65720sq
[2020-10-20T19:59:57-0700] [MainThread] [W] [toil.leader] Log from job kind-run_mutect_perchrom/instance-c65720sq follows:
=========>
	[2020-10-20T19:59:57-0700] [MainThread] [I] [toil.worker] ---TOIL WORKER OUTPUT LOG---
	[2020-10-20T19:59:57-0700] [MainThread] [I] [toil] Running Toil version 4.2.0-3aa1da130141039cb357efe36d7df9b9f6ae9b5b on host drkthomp-virtualbox.
	Traceback (most recent call last):
	  File "/home/drkthomp/protect3/venv/lib/python3.8/site-packages/toil/worker.py", line 368, in workerScript
	    job._runner(jobGraph=jobGraph, jobStore=jobStore, fileStore=fileStore, defer=defer)
	  File "/home/drkthomp/protect3/venv/lib/python3.8/site-packages/toil/job.py", line 1424, in _runner
	    returnValues = self._run(jobGraph, fileStore)
	  File "/home/drkthomp/protect3/venv/lib/python3.8/site-packages/toil/job.py", line 1361, in _run
	    return self.run(fileStore)
	  File "/home/drkthomp/protect3/venv/lib/python3.8/site-packages/toil/job.py", line 1565, in run
	    rValue = userFunction(*((self,) + tuple(self._args)), **self._kwargs)
	  File "/home/drkthomp/protect3/src/protect/mutation_calling/mutect.py", line 123, in run_mutect_perchrom
	    input_files['dbsnp.vcf'] = gunzip(input_files['dbsnp.vcf.gz'])
	  File "/home/drkthomp/protect3/src/protect/common.py", line 172, in gunzip
	    assert is_gzipfile(input_gzip_file)
	AssertionError
	[2020-10-20T19:59:57-0700] [MainThread] [E] [toil.worker] Exiting the worker because of a failed job on host drkthomp-virtualbox
<=========
[2020-10-20T19:59:57-0700] [MainThread] [W] [toil.jobGraph] Due to failure we are reducing the remaining retry count of job 'run_mutect_perchrom' kind-run_mutect_perchrom/instance-c65720sq with ID kind-run_mutect_perchrom/instance-c65720sq to 1
[2020-10-20T19:59:57-0700] [MainThread] [I] [toil.leader] Issued job 'run_mutect_perchrom' kind-run_mutect_perchrom/instance-c65720sq with job batch system ID: 40 and cores: 1, disk: 23.0 G, and memory: 6.0 G
[2020-10-20T19:59:57-0700] [MainThread] [I] [toil.worker] Redirecting logging to /home/drkthomp/workDir/node-72996abd-6cf4-462a-aea1-4d483640105b-1e53f69f16d74e0b881e7db602b2d2c3/tmpri6pgo4b/worker_log.txt
[2020-10-20T19:59:57-0700] [Thread-1  ] [E] [toil.batchSystems.singleMachine] Got exit code 1 (indicating failure) from job _toil_worker run_mutect_perchrom file:/home/drkthomp/protect3/jobStore kind-run_mutect_perchrom/instance-55hd3p6y.
[2020-10-20T19:59:57-0700] [MainThread] [W] [toil.leader] Job failed with exit value 1: 'run_mutect_perchrom' kind-run_mutect_perchrom/instance-55hd3p6y
[2020-10-20T19:59:57-0700] [MainThread] [W] [toil.leader] The job seems to have left a log file, indicating failure: 'run_mutect_perchrom' kind-run_mutect_perchrom/instance-55hd3p6y
[2020-10-20T19:59:57-0700] [MainThread] [W] [toil.leader] Log from job kind-run_mutect_perchrom/instance-55hd3p6y follows:
=========>
	[2020-10-20T19:59:57-0700] [MainThread] [I] [toil.worker] ---TOIL WORKER OUTPUT LOG---
	[2020-10-20T19:59:57-0700] [MainThread] [I] [toil] Running Toil version 4.2.0-3aa1da130141039cb357efe36d7df9b9f6ae9b5b on host drkthomp-virtualbox.
	Traceback (most recent call last):
	  File "/home/drkthomp/protect3/venv/lib/python3.8/site-packages/toil/worker.py", line 368, in workerScript
	    job._runner(jobGraph=jobGraph, jobStore=jobStore, fileStore=fileStore, defer=defer)
	  File "/home/drkthomp/protect3/venv/lib/python3.8/site-packages/toil/job.py", line 1424, in _runner
	    returnValues = self._run(jobGraph, fileStore)
	  File "/home/drkthomp/protect3/venv/lib/python3.8/site-packages/toil/job.py", line 1361, in _run
	    return self.run(fileStore)
	  File "/home/drkthomp/protect3/venv/lib/python3.8/site-packages/toil/job.py", line 1565, in run
	    rValue = userFunction(*((self,) + tuple(self._args)), **self._kwargs)
	  File "/home/drkthomp/protect3/src/protect/mutation_calling/mutect.py", line 123, in run_mutect_perchrom
	    input_files['dbsnp.vcf'] = gunzip(input_files['dbsnp.vcf.gz'])
	  File "/home/drkthomp/protect3/src/protect/common.py", line 172, in gunzip
	    assert is_gzipfile(input_gzip_file)
	AssertionError
	[2020-10-20T19:59:57-0700] [MainThread] [E] [toil.worker] Exiting the worker because of a failed job on host drkthomp-virtualbox
<=========
[2020-10-20T19:59:57-0700] [MainThread] [W] [toil.jobGraph] Due to failure we are reducing the remaining retry count of job 'run_mutect_perchrom' kind-run_mutect_perchrom/instance-55hd3p6y with ID kind-run_mutect_perchrom/instance-55hd3p6y to 1
[2020-10-20T19:59:57-0700] [MainThread] [I] [toil.leader] Issued job 'run_mutect_perchrom' kind-run_mutect_perchrom/instance-55hd3p6y with job batch system ID: 41 and cores: 1, disk: 23.0 G, and memory: 6.0 G
[2020-10-20T19:59:57-0700] [MainThread] [I] [toil.worker] Redirecting logging to /home/drkthomp/workDir/node-72996abd-6cf4-462a-aea1-4d483640105b-1e53f69f16d74e0b881e7db602b2d2c3/tmp_akv79mp/worker_log.txt
[2020-10-20T19:59:57-0700] [MainThread] [I] [toil.worker] Redirecting logging to /home/drkthomp/workDir/node-72996abd-6cf4-462a-aea1-4d483640105b-1e53f69f16d74e0b881e7db602b2d2c3/tmpoctwff98/worker_log.txt
[2020-10-20T19:59:57-0700] [Thread-1  ] [E] [toil.batchSystems.singleMachine] Got exit code 1 (indicating failure) from job _toil_worker run_mutect_perchrom file:/home/drkthomp/protect3/jobStore kind-run_mutect_perchrom/instance-sfhpnee3.
[2020-10-20T19:59:57-0700] [MainThread] [W] [toil.leader] Job failed with exit value 1: 'run_mutect_perchrom' kind-run_mutect_perchrom/instance-sfhpnee3
[2020-10-20T19:59:57-0700] [MainThread] [W] [toil.leader] The job seems to have left a log file, indicating failure: 'run_mutect_perchrom' kind-run_mutect_perchrom/instance-sfhpnee3
[2020-10-20T19:59:57-0700] [MainThread] [W] [toil.leader] Log from job kind-run_mutect_perchrom/instance-sfhpnee3 follows:
=========>
	[2020-10-20T19:59:57-0700] [MainThread] [I] [toil.worker] ---TOIL WORKER OUTPUT LOG---
	[2020-10-20T19:59:57-0700] [MainThread] [I] [toil] Running Toil version 4.2.0-3aa1da130141039cb357efe36d7df9b9f6ae9b5b on host drkthomp-virtualbox.
	Traceback (most recent call last):
	  File "/home/drkthomp/protect3/venv/lib/python3.8/site-packages/toil/worker.py", line 368, in workerScript
	    job._runner(jobGraph=jobGraph, jobStore=jobStore, fileStore=fileStore, defer=defer)
	  File "/home/drkthomp/protect3/venv/lib/python3.8/site-packages/toil/job.py", line 1424, in _runner
	    returnValues = self._run(jobGraph, fileStore)
	  File "/home/drkthomp/protect3/venv/lib/python3.8/site-packages/toil/job.py", line 1361, in _run
	    return self.run(fileStore)
	  File "/home/drkthomp/protect3/venv/lib/python3.8/site-packages/toil/job.py", line 1565, in run
	    rValue = userFunction(*((self,) + tuple(self._args)), **self._kwargs)
	  File "/home/drkthomp/protect3/src/protect/mutation_calling/mutect.py", line 123, in run_mutect_perchrom
	    input_files['dbsnp.vcf'] = gunzip(input_files['dbsnp.vcf.gz'])
	  File "/home/drkthomp/protect3/src/protect/common.py", line 172, in gunzip
	    assert is_gzipfile(input_gzip_file)
	AssertionError
	[2020-10-20T19:59:57-0700] [MainThread] [E] [toil.worker] Exiting the worker because of a failed job on host drkthomp-virtualbox
<=========
[2020-10-20T19:59:57-0700] [MainThread] [W] [toil.jobGraph] Due to failure we are reducing the remaining retry count of job 'run_mutect_perchrom' kind-run_mutect_perchrom/instance-sfhpnee3 with ID kind-run_mutect_perchrom/instance-sfhpnee3 to 0
[2020-10-20T19:59:57-0700] [MainThread] [W] [toil.leader] Job 'run_mutect_perchrom' kind-run_mutect_perchrom/instance-sfhpnee3 with ID kind-run_mutect_perchrom/instance-sfhpnee3 is completely failed
[2020-10-20T19:59:58-0700] [Thread-1  ] [E] [toil.batchSystems.singleMachine] Got exit code 1 (indicating failure) from job _toil_worker run_mutect_perchrom file:/home/drkthomp/protect3/jobStore kind-run_mutect_perchrom/instance-vodde7jc.
[2020-10-20T19:59:58-0700] [MainThread] [W] [toil.leader] Job failed with exit value 1: 'run_mutect_perchrom' kind-run_mutect_perchrom/instance-vodde7jc
[2020-10-20T19:59:58-0700] [MainThread] [W] [toil.leader] The job seems to have left a log file, indicating failure: 'run_mutect_perchrom' kind-run_mutect_perchrom/instance-vodde7jc
[2020-10-20T19:59:58-0700] [MainThread] [W] [toil.leader] Log from job kind-run_mutect_perchrom/instance-vodde7jc follows:
=========>
	[2020-10-20T19:59:57-0700] [MainThread] [I] [toil.worker] ---TOIL WORKER OUTPUT LOG---
	[2020-10-20T19:59:57-0700] [MainThread] [I] [toil] Running Toil version 4.2.0-3aa1da130141039cb357efe36d7df9b9f6ae9b5b on host drkthomp-virtualbox.
	Traceback (most recent call last):
	  File "/home/drkthomp/protect3/venv/lib/python3.8/site-packages/toil/worker.py", line 368, in workerScript
	    job._runner(jobGraph=jobGraph, jobStore=jobStore, fileStore=fileStore, defer=defer)
	  File "/home/drkthomp/protect3/venv/lib/python3.8/site-packages/toil/job.py", line 1424, in _runner
	    returnValues = self._run(jobGraph, fileStore)
	  File "/home/drkthomp/protect3/venv/lib/python3.8/site-packages/toil/job.py", line 1361, in _run
	    return self.run(fileStore)
	  File "/home/drkthomp/protect3/venv/lib/python3.8/site-packages/toil/job.py", line 1565, in run
	    rValue = userFunction(*((self,) + tuple(self._args)), **self._kwargs)
	  File "/home/drkthomp/protect3/src/protect/mutation_calling/mutect.py", line 123, in run_mutect_perchrom
	    input_files['dbsnp.vcf'] = gunzip(input_files['dbsnp.vcf.gz'])
	  File "/home/drkthomp/protect3/src/protect/common.py", line 172, in gunzip
	    assert is_gzipfile(input_gzip_file)
	AssertionError
	[2020-10-20T19:59:57-0700] [MainThread] [E] [toil.worker] Exiting the worker because of a failed job on host drkthomp-virtualbox
<=========
[2020-10-20T19:59:58-0700] [MainThread] [W] [toil.jobGraph] Due to failure we are reducing the remaining retry count of job 'run_mutect_perchrom' kind-run_mutect_perchrom/instance-vodde7jc with ID kind-run_mutect_perchrom/instance-vodde7jc to 1
[2020-10-20T19:59:58-0700] [MainThread] [I] [toil.leader] Issued job 'run_mutect_perchrom' kind-run_mutect_perchrom/instance-vodde7jc with job batch system ID: 42 and cores: 1, disk: 23.0 G, and memory: 6.0 G
[2020-10-20T19:59:58-0700] [MainThread] [I] [toil.worker] Redirecting logging to /home/drkthomp/workDir/node-72996abd-6cf4-462a-aea1-4d483640105b-1e53f69f16d74e0b881e7db602b2d2c3/tmp2haaw2c4/worker_log.txt
[2020-10-20T19:59:58-0700] [MainThread] [I] [toil.worker] Redirecting logging to /home/drkthomp/workDir/node-72996abd-6cf4-462a-aea1-4d483640105b-1e53f69f16d74e0b881e7db602b2d2c3/tmph2rur90m/worker_log.txt
[2020-10-20T19:59:58-0700] [Thread-1  ] [E] [toil.batchSystems.singleMachine] Got exit code 1 (indicating failure) from job _toil_worker run_mutect_perchrom file:/home/drkthomp/protect3/jobStore kind-run_mutect_perchrom/instance-55hd3p6y.
[2020-10-20T19:59:58-0700] [MainThread] [W] [toil.leader] Job failed with exit value 1: 'run_mutect_perchrom' kind-run_mutect_perchrom/instance-55hd3p6y
[2020-10-20T19:59:58-0700] [MainThread] [W] [toil.leader] The job seems to have left a log file, indicating failure: 'run_mutect_perchrom' kind-run_mutect_perchrom/instance-55hd3p6y
[2020-10-20T19:59:58-0700] [MainThread] [W] [toil.leader] Log from job kind-run_mutect_perchrom/instance-55hd3p6y follows:
=========>
	[2020-10-20T19:59:58-0700] [MainThread] [I] [toil.worker] ---TOIL WORKER OUTPUT LOG---
	[2020-10-20T19:59:58-0700] [MainThread] [I] [toil] Running Toil version 4.2.0-3aa1da130141039cb357efe36d7df9b9f6ae9b5b on host drkthomp-virtualbox.
	Traceback (most recent call last):
	  File "/home/drkthomp/protect3/venv/lib/python3.8/site-packages/toil/worker.py", line 368, in workerScript
	    job._runner(jobGraph=jobGraph, jobStore=jobStore, fileStore=fileStore, defer=defer)
	  File "/home/drkthomp/protect3/venv/lib/python3.8/site-packages/toil/job.py", line 1424, in _runner
	    returnValues = self._run(jobGraph, fileStore)
	  File "/home/drkthomp/protect3/venv/lib/python3.8/site-packages/toil/job.py", line 1361, in _run
	    return self.run(fileStore)
	  File "/home/drkthomp/protect3/venv/lib/python3.8/site-packages/toil/job.py", line 1565, in run
	    rValue = userFunction(*((self,) + tuple(self._args)), **self._kwargs)
	  File "/home/drkthomp/protect3/src/protect/mutation_calling/mutect.py", line 123, in run_mutect_perchrom
	    input_files['dbsnp.vcf'] = gunzip(input_files['dbsnp.vcf.gz'])
	  File "/home/drkthomp/protect3/src/protect/common.py", line 172, in gunzip
	    assert is_gzipfile(input_gzip_file)
	AssertionError
	[2020-10-20T19:59:58-0700] [MainThread] [E] [toil.worker] Exiting the worker because of a failed job on host drkthomp-virtualbox
<=========
[2020-10-20T19:59:58-0700] [MainThread] [W] [toil.jobGraph] Due to failure we are reducing the remaining retry count of job 'run_mutect_perchrom' kind-run_mutect_perchrom/instance-55hd3p6y with ID kind-run_mutect_perchrom/instance-55hd3p6y to 0
[2020-10-20T19:59:58-0700] [MainThread] [W] [toil.leader] Job 'run_mutect_perchrom' kind-run_mutect_perchrom/instance-55hd3p6y with ID kind-run_mutect_perchrom/instance-55hd3p6y is completely failed
[2020-10-20T19:59:58-0700] [Thread-1  ] [E] [toil.batchSystems.singleMachine] Got exit code 1 (indicating failure) from job _toil_worker run_mutect_perchrom file:/home/drkthomp/protect3/jobStore kind-run_mutect_perchrom/instance-gl_w17lv.
[2020-10-20T19:59:58-0700] [MainThread] [W] [toil.leader] Job failed with exit value 1: 'run_mutect_perchrom' kind-run_mutect_perchrom/instance-gl_w17lv
[2020-10-20T19:59:58-0700] [MainThread] [W] [toil.leader] The job seems to have left a log file, indicating failure: 'run_mutect_perchrom' kind-run_mutect_perchrom/instance-gl_w17lv
[2020-10-20T19:59:58-0700] [MainThread] [W] [toil.leader] Log from job kind-run_mutect_perchrom/instance-gl_w17lv follows:
=========>
	[2020-10-20T19:59:58-0700] [MainThread] [I] [toil.worker] ---TOIL WORKER OUTPUT LOG---
	[2020-10-20T19:59:58-0700] [MainThread] [I] [toil] Running Toil version 4.2.0-3aa1da130141039cb357efe36d7df9b9f6ae9b5b on host drkthomp-virtualbox.
	Traceback (most recent call last):
	  File "/home/drkthomp/protect3/venv/lib/python3.8/site-packages/toil/worker.py", line 368, in workerScript
	    job._runner(jobGraph=jobGraph, jobStore=jobStore, fileStore=fileStore, defer=defer)
	  File "/home/drkthomp/protect3/venv/lib/python3.8/site-packages/toil/job.py", line 1424, in _runner
	    returnValues = self._run(jobGraph, fileStore)
	  File "/home/drkthomp/protect3/venv/lib/python3.8/site-packages/toil/job.py", line 1361, in _run
	    return self.run(fileStore)
	  File "/home/drkthomp/protect3/venv/lib/python3.8/site-packages/toil/job.py", line 1565, in run
	    rValue = userFunction(*((self,) + tuple(self._args)), **self._kwargs)
	  File "/home/drkthomp/protect3/src/protect/mutation_calling/mutect.py", line 123, in run_mutect_perchrom
	    input_files['dbsnp.vcf'] = gunzip(input_files['dbsnp.vcf.gz'])
	  File "/home/drkthomp/protect3/src/protect/common.py", line 172, in gunzip
	    assert is_gzipfile(input_gzip_file)
	AssertionError
	[2020-10-20T19:59:58-0700] [MainThread] [E] [toil.worker] Exiting the worker because of a failed job on host drkthomp-virtualbox
<=========
[2020-10-20T19:59:58-0700] [MainThread] [W] [toil.jobGraph] Due to failure we are reducing the remaining retry count of job 'run_mutect_perchrom' kind-run_mutect_perchrom/instance-gl_w17lv with ID kind-run_mutect_perchrom/instance-gl_w17lv to 1
[2020-10-20T19:59:58-0700] [MainThread] [I] [toil.leader] Issued job 'run_mutect_perchrom' kind-run_mutect_perchrom/instance-gl_w17lv with job batch system ID: 43 and cores: 1, disk: 23.0 G, and memory: 6.0 G
[2020-10-20T19:59:58-0700] [MainThread] [I] [toil.worker] Redirecting logging to /home/drkthomp/workDir/node-72996abd-6cf4-462a-aea1-4d483640105b-1e53f69f16d74e0b881e7db602b2d2c3/tmpqcjs5siu/worker_log.txt
[2020-10-20T19:59:58-0700] [MainThread] [I] [toil.worker] Redirecting logging to /home/drkthomp/workDir/node-72996abd-6cf4-462a-aea1-4d483640105b-1e53f69f16d74e0b881e7db602b2d2c3/tmpolf2dxb6/worker_log.txt
[2020-10-20T19:59:58-0700] [Thread-1  ] [E] [toil.batchSystems.singleMachine] Got exit code 1 (indicating failure) from job _toil_worker run_mutect_perchrom file:/home/drkthomp/protect3/jobStore kind-run_mutect_perchrom/instance-92gnpm9m.
[2020-10-20T19:59:58-0700] [MainThread] [W] [toil.leader] Job failed with exit value 1: 'run_mutect_perchrom' kind-run_mutect_perchrom/instance-92gnpm9m
[2020-10-20T19:59:58-0700] [MainThread] [W] [toil.leader] The job seems to have left a log file, indicating failure: 'run_mutect_perchrom' kind-run_mutect_perchrom/instance-92gnpm9m
[2020-10-20T19:59:58-0700] [MainThread] [W] [toil.leader] Log from job kind-run_mutect_perchrom/instance-92gnpm9m follows:
=========>
	[2020-10-20T19:59:58-0700] [MainThread] [I] [toil.worker] ---TOIL WORKER OUTPUT LOG---
	[2020-10-20T19:59:58-0700] [MainThread] [I] [toil] Running Toil version 4.2.0-3aa1da130141039cb357efe36d7df9b9f6ae9b5b on host drkthomp-virtualbox.
	Traceback (most recent call last):
	  File "/home/drkthomp/protect3/venv/lib/python3.8/site-packages/toil/worker.py", line 368, in workerScript
	    job._runner(jobGraph=jobGraph, jobStore=jobStore, fileStore=fileStore, defer=defer)
	  File "/home/drkthomp/protect3/venv/lib/python3.8/site-packages/toil/job.py", line 1424, in _runner
	    returnValues = self._run(jobGraph, fileStore)
	  File "/home/drkthomp/protect3/venv/lib/python3.8/site-packages/toil/job.py", line 1361, in _run
	    return self.run(fileStore)
	  File "/home/drkthomp/protect3/venv/lib/python3.8/site-packages/toil/job.py", line 1565, in run
	    rValue = userFunction(*((self,) + tuple(self._args)), **self._kwargs)
	  File "/home/drkthomp/protect3/src/protect/mutation_calling/mutect.py", line 123, in run_mutect_perchrom
	    input_files['dbsnp.vcf'] = gunzip(input_files['dbsnp.vcf.gz'])
	  File "/home/drkthomp/protect3/src/protect/common.py", line 172, in gunzip
	    assert is_gzipfile(input_gzip_file)
	AssertionError
	[2020-10-20T19:59:58-0700] [MainThread] [E] [toil.worker] Exiting the worker because of a failed job on host drkthomp-virtualbox
<=========
[2020-10-20T19:59:58-0700] [MainThread] [W] [toil.jobGraph] Due to failure we are reducing the remaining retry count of job 'run_mutect_perchrom' kind-run_mutect_perchrom/instance-92gnpm9m with ID kind-run_mutect_perchrom/instance-92gnpm9m to 1
[2020-10-20T19:59:58-0700] [MainThread] [I] [toil.leader] Issued job 'run_mutect_perchrom' kind-run_mutect_perchrom/instance-92gnpm9m with job batch system ID: 44 and cores: 1, disk: 23.0 G, and memory: 6.0 G
[2020-10-20T19:59:58-0700] [Thread-1  ] [E] [toil.batchSystems.singleMachine] Got exit code 1 (indicating failure) from job _toil_worker run_mutect_perchrom file:/home/drkthomp/protect3/jobStore kind-run_mutect_perchrom/instance-cev_msom.
[2020-10-20T19:59:58-0700] [MainThread] [W] [toil.leader] Job failed with exit value 1: 'run_mutect_perchrom' kind-run_mutect_perchrom/instance-cev_msom
[2020-10-20T19:59:58-0700] [MainThread] [W] [toil.leader] The job seems to have left a log file, indicating failure: 'run_mutect_perchrom' kind-run_mutect_perchrom/instance-cev_msom
[2020-10-20T19:59:58-0700] [MainThread] [W] [toil.leader] Log from job kind-run_mutect_perchrom/instance-cev_msom follows:
=========>
	[2020-10-20T19:59:58-0700] [MainThread] [I] [toil.worker] ---TOIL WORKER OUTPUT LOG---
	[2020-10-20T19:59:58-0700] [MainThread] [I] [toil] Running Toil version 4.2.0-3aa1da130141039cb357efe36d7df9b9f6ae9b5b on host drkthomp-virtualbox.
	Traceback (most recent call last):
	  File "/home/drkthomp/protect3/venv/lib/python3.8/site-packages/toil/worker.py", line 368, in workerScript
	    job._runner(jobGraph=jobGraph, jobStore=jobStore, fileStore=fileStore, defer=defer)
	  File "/home/drkthomp/protect3/venv/lib/python3.8/site-packages/toil/job.py", line 1424, in _runner
	    returnValues = self._run(jobGraph, fileStore)
	  File "/home/drkthomp/protect3/venv/lib/python3.8/site-packages/toil/job.py", line 1361, in _run
	    return self.run(fileStore)
	  File "/home/drkthomp/protect3/venv/lib/python3.8/site-packages/toil/job.py", line 1565, in run
	    rValue = userFunction(*((self,) + tuple(self._args)), **self._kwargs)
	  File "/home/drkthomp/protect3/src/protect/mutation_calling/mutect.py", line 123, in run_mutect_perchrom
	    input_files['dbsnp.vcf'] = gunzip(input_files['dbsnp.vcf.gz'])
	  File "/home/drkthomp/protect3/src/protect/common.py", line 172, in gunzip
	    assert is_gzipfile(input_gzip_file)
	AssertionError
	[2020-10-20T19:59:58-0700] [MainThread] [E] [toil.worker] Exiting the worker because of a failed job on host drkthomp-virtualbox
<=========
[2020-10-20T19:59:58-0700] [MainThread] [W] [toil.jobGraph] Due to failure we are reducing the remaining retry count of job 'run_mutect_perchrom' kind-run_mutect_perchrom/instance-cev_msom with ID kind-run_mutect_perchrom/instance-cev_msom to 1
[2020-10-20T19:59:58-0700] [MainThread] [I] [toil.leader] Issued job 'run_mutect_perchrom' kind-run_mutect_perchrom/instance-cev_msom with job batch system ID: 45 and cores: 1, disk: 23.0 G, and memory: 6.0 G
[2020-10-20T19:59:58-0700] [MainThread] [I] [toil.worker] Redirecting logging to /home/drkthomp/workDir/node-72996abd-6cf4-462a-aea1-4d483640105b-1e53f69f16d74e0b881e7db602b2d2c3/tmpab6zbvec/worker_log.txt
[2020-10-20T19:59:58-0700] [MainThread] [I] [toil.worker] Redirecting logging to /home/drkthomp/workDir/node-72996abd-6cf4-462a-aea1-4d483640105b-1e53f69f16d74e0b881e7db602b2d2c3/tmpojcdezzk/worker_log.txt
[2020-10-20T19:59:59-0700] [Thread-1  ] [E] [toil.batchSystems.singleMachine] Got exit code 1 (indicating failure) from job _toil_worker run_mutect_perchrom file:/home/drkthomp/protect3/jobStore kind-run_mutect_perchrom/instance-gl_w17lv.
[2020-10-20T19:59:59-0700] [MainThread] [W] [toil.leader] Job failed with exit value 1: 'run_mutect_perchrom' kind-run_mutect_perchrom/instance-gl_w17lv
[2020-10-20T19:59:59-0700] [MainThread] [W] [toil.leader] The job seems to have left a log file, indicating failure: 'run_mutect_perchrom' kind-run_mutect_perchrom/instance-gl_w17lv
[2020-10-20T19:59:59-0700] [MainThread] [W] [toil.leader] Log from job kind-run_mutect_perchrom/instance-gl_w17lv follows:
=========>
	[2020-10-20T19:59:58-0700] [MainThread] [I] [toil.worker] ---TOIL WORKER OUTPUT LOG---
	[2020-10-20T19:59:58-0700] [MainThread] [I] [toil] Running Toil version 4.2.0-3aa1da130141039cb357efe36d7df9b9f6ae9b5b on host drkthomp-virtualbox.
	Traceback (most recent call last):
	  File "/home/drkthomp/protect3/venv/lib/python3.8/site-packages/toil/worker.py", line 368, in workerScript
	    job._runner(jobGraph=jobGraph, jobStore=jobStore, fileStore=fileStore, defer=defer)
	  File "/home/drkthomp/protect3/venv/lib/python3.8/site-packages/toil/job.py", line 1424, in _runner
	    returnValues = self._run(jobGraph, fileStore)
	  File "/home/drkthomp/protect3/venv/lib/python3.8/site-packages/toil/job.py", line 1361, in _run
	    return self.run(fileStore)
	  File "/home/drkthomp/protect3/venv/lib/python3.8/site-packages/toil/job.py", line 1565, in run
	    rValue = userFunction(*((self,) + tuple(self._args)), **self._kwargs)
	  File "/home/drkthomp/protect3/src/protect/mutation_calling/mutect.py", line 123, in run_mutect_perchrom
	    input_files['dbsnp.vcf'] = gunzip(input_files['dbsnp.vcf.gz'])
	  File "/home/drkthomp/protect3/src/protect/common.py", line 172, in gunzip
	    assert is_gzipfile(input_gzip_file)
	AssertionError
	[2020-10-20T19:59:58-0700] [MainThread] [E] [toil.worker] Exiting the worker because of a failed job on host drkthomp-virtualbox
<=========
[2020-10-20T19:59:59-0700] [MainThread] [W] [toil.jobGraph] Due to failure we are reducing the remaining retry count of job 'run_mutect_perchrom' kind-run_mutect_perchrom/instance-gl_w17lv with ID kind-run_mutect_perchrom/instance-gl_w17lv to 0
[2020-10-20T19:59:59-0700] [MainThread] [W] [toil.leader] Job 'run_mutect_perchrom' kind-run_mutect_perchrom/instance-gl_w17lv with ID kind-run_mutect_perchrom/instance-gl_w17lv is completely failed
[2020-10-20T19:59:59-0700] [Thread-1  ] [E] [toil.batchSystems.singleMachine] Got exit code 1 (indicating failure) from job _toil_worker run_mutect_perchrom file:/home/drkthomp/protect3/jobStore kind-run_mutect_perchrom/instance-bm4dpfik.
[2020-10-20T19:59:59-0700] [MainThread] [W] [toil.leader] Job failed with exit value 1: 'run_mutect_perchrom' kind-run_mutect_perchrom/instance-bm4dpfik
[2020-10-20T19:59:59-0700] [MainThread] [W] [toil.leader] The job seems to have left a log file, indicating failure: 'run_mutect_perchrom' kind-run_mutect_perchrom/instance-bm4dpfik
[2020-10-20T19:59:59-0700] [MainThread] [W] [toil.leader] Log from job kind-run_mutect_perchrom/instance-bm4dpfik follows:
=========>
	[2020-10-20T19:59:58-0700] [MainThread] [I] [toil.worker] ---TOIL WORKER OUTPUT LOG---
	[2020-10-20T19:59:58-0700] [MainThread] [I] [toil] Running Toil version 4.2.0-3aa1da130141039cb357efe36d7df9b9f6ae9b5b on host drkthomp-virtualbox.
	Traceback (most recent call last):
	  File "/home/drkthomp/protect3/venv/lib/python3.8/site-packages/toil/worker.py", line 368, in workerScript
	    job._runner(jobGraph=jobGraph, jobStore=jobStore, fileStore=fileStore, defer=defer)
	  File "/home/drkthomp/protect3/venv/lib/python3.8/site-packages/toil/job.py", line 1424, in _runner
	    returnValues = self._run(jobGraph, fileStore)
	  File "/home/drkthomp/protect3/venv/lib/python3.8/site-packages/toil/job.py", line 1361, in _run
	    return self.run(fileStore)
	  File "/home/drkthomp/protect3/venv/lib/python3.8/site-packages/toil/job.py", line 1565, in run
	    rValue = userFunction(*((self,) + tuple(self._args)), **self._kwargs)
	  File "/home/drkthomp/protect3/src/protect/mutation_calling/mutect.py", line 123, in run_mutect_perchrom
	    input_files['dbsnp.vcf'] = gunzip(input_files['dbsnp.vcf.gz'])
	  File "/home/drkthomp/protect3/src/protect/common.py", line 172, in gunzip
	    assert is_gzipfile(input_gzip_file)
	AssertionError
	[2020-10-20T19:59:58-0700] [MainThread] [E] [toil.worker] Exiting the worker because of a failed job on host drkthomp-virtualbox
<=========
[2020-10-20T19:59:59-0700] [MainThread] [W] [toil.jobGraph] Due to failure we are reducing the remaining retry count of job 'run_mutect_perchrom' kind-run_mutect_perchrom/instance-bm4dpfik with ID kind-run_mutect_perchrom/instance-bm4dpfik to 1
[2020-10-20T19:59:59-0700] [MainThread] [I] [toil.leader] Issued job 'run_mutect_perchrom' kind-run_mutect_perchrom/instance-bm4dpfik with job batch system ID: 46 and cores: 1, disk: 23.0 G, and memory: 6.0 G
[2020-10-20T19:59:59-0700] [MainThread] [I] [toil.worker] Redirecting logging to /home/drkthomp/workDir/node-72996abd-6cf4-462a-aea1-4d483640105b-1e53f69f16d74e0b881e7db602b2d2c3/tmpy02q8oxb/worker_log.txt
[2020-10-20T19:59:59-0700] [MainThread] [I] [toil.worker] Redirecting logging to /home/drkthomp/workDir/node-72996abd-6cf4-462a-aea1-4d483640105b-1e53f69f16d74e0b881e7db602b2d2c3/tmpktcox5ss/worker_log.txt
[2020-10-20T19:59:59-0700] [Thread-1  ] [E] [toil.batchSystems.singleMachine] Got exit code 1 (indicating failure) from job _toil_worker run_mutect_perchrom file:/home/drkthomp/protect3/jobStore kind-run_mutect_perchrom/instance-cije5tr0.
[2020-10-20T19:59:59-0700] [MainThread] [W] [toil.leader] Job failed with exit value 1: 'run_mutect_perchrom' kind-run_mutect_perchrom/instance-cije5tr0
[2020-10-20T19:59:59-0700] [MainThread] [W] [toil.leader] The job seems to have left a log file, indicating failure: 'run_mutect_perchrom' kind-run_mutect_perchrom/instance-cije5tr0
[2020-10-20T19:59:59-0700] [MainThread] [W] [toil.leader] Log from job kind-run_mutect_perchrom/instance-cije5tr0 follows:
=========>
	[2020-10-20T19:59:59-0700] [MainThread] [I] [toil.worker] ---TOIL WORKER OUTPUT LOG---
	[2020-10-20T19:59:59-0700] [MainThread] [I] [toil] Running Toil version 4.2.0-3aa1da130141039cb357efe36d7df9b9f6ae9b5b on host drkthomp-virtualbox.
	Traceback (most recent call last):
	  File "/home/drkthomp/protect3/venv/lib/python3.8/site-packages/toil/worker.py", line 368, in workerScript
	    job._runner(jobGraph=jobGraph, jobStore=jobStore, fileStore=fileStore, defer=defer)
	  File "/home/drkthomp/protect3/venv/lib/python3.8/site-packages/toil/job.py", line 1424, in _runner
	    returnValues = self._run(jobGraph, fileStore)
	  File "/home/drkthomp/protect3/venv/lib/python3.8/site-packages/toil/job.py", line 1361, in _run
	    return self.run(fileStore)
	  File "/home/drkthomp/protect3/venv/lib/python3.8/site-packages/toil/job.py", line 1565, in run
	    rValue = userFunction(*((self,) + tuple(self._args)), **self._kwargs)
	  File "/home/drkthomp/protect3/src/protect/mutation_calling/mutect.py", line 123, in run_mutect_perchrom
	    input_files['dbsnp.vcf'] = gunzip(input_files['dbsnp.vcf.gz'])
	  File "/home/drkthomp/protect3/src/protect/common.py", line 172, in gunzip
	    assert is_gzipfile(input_gzip_file)
	AssertionError
	[2020-10-20T19:59:59-0700] [MainThread] [E] [toil.worker] Exiting the worker because of a failed job on host drkthomp-virtualbox
<=========
[2020-10-20T19:59:59-0700] [MainThread] [W] [toil.jobGraph] Due to failure we are reducing the remaining retry count of job 'run_mutect_perchrom' kind-run_mutect_perchrom/instance-cije5tr0 with ID kind-run_mutect_perchrom/instance-cije5tr0 to 1
[2020-10-20T19:59:59-0700] [MainThread] [I] [toil.leader] Issued job 'run_mutect_perchrom' kind-run_mutect_perchrom/instance-cije5tr0 with job batch system ID: 47 and cores: 1, disk: 23.0 G, and memory: 6.0 G
[2020-10-20T19:59:59-0700] [Thread-1  ] [E] [toil.batchSystems.singleMachine] Got exit code 1 (indicating failure) from job _toil_worker run_mutect_perchrom file:/home/drkthomp/protect3/jobStore kind-run_mutect_perchrom/instance-40bfs1db.
[2020-10-20T19:59:59-0700] [MainThread] [W] [toil.leader] Job failed with exit value 1: 'run_mutect_perchrom' kind-run_mutect_perchrom/instance-40bfs1db
[2020-10-20T19:59:59-0700] [MainThread] [W] [toil.leader] The job seems to have left a log file, indicating failure: 'run_mutect_perchrom' kind-run_mutect_perchrom/instance-40bfs1db
[2020-10-20T19:59:59-0700] [MainThread] [W] [toil.leader] Log from job kind-run_mutect_perchrom/instance-40bfs1db follows:
=========>
	[2020-10-20T19:59:59-0700] [MainThread] [I] [toil.worker] ---TOIL WORKER OUTPUT LOG---
	[2020-10-20T19:59:59-0700] [MainThread] [I] [toil] Running Toil version 4.2.0-3aa1da130141039cb357efe36d7df9b9f6ae9b5b on host drkthomp-virtualbox.
	Traceback (most recent call last):
	  File "/home/drkthomp/protect3/venv/lib/python3.8/site-packages/toil/worker.py", line 368, in workerScript
	    job._runner(jobGraph=jobGraph, jobStore=jobStore, fileStore=fileStore, defer=defer)
	  File "/home/drkthomp/protect3/venv/lib/python3.8/site-packages/toil/job.py", line 1424, in _runner
	    returnValues = self._run(jobGraph, fileStore)
	  File "/home/drkthomp/protect3/venv/lib/python3.8/site-packages/toil/job.py", line 1361, in _run
	    return self.run(fileStore)
	  File "/home/drkthomp/protect3/venv/lib/python3.8/site-packages/toil/job.py", line 1565, in run
	    rValue = userFunction(*((self,) + tuple(self._args)), **self._kwargs)
	  File "/home/drkthomp/protect3/src/protect/mutation_calling/mutect.py", line 123, in run_mutect_perchrom
	    input_files['dbsnp.vcf'] = gunzip(input_files['dbsnp.vcf.gz'])
	  File "/home/drkthomp/protect3/src/protect/common.py", line 172, in gunzip
	    assert is_gzipfile(input_gzip_file)
	AssertionError
	[2020-10-20T19:59:59-0700] [MainThread] [E] [toil.worker] Exiting the worker because of a failed job on host drkthomp-virtualbox
<=========
[2020-10-20T19:59:59-0700] [MainThread] [W] [toil.jobGraph] Due to failure we are reducing the remaining retry count of job 'run_mutect_perchrom' kind-run_mutect_perchrom/instance-40bfs1db with ID kind-run_mutect_perchrom/instance-40bfs1db to 1
[2020-10-20T19:59:59-0700] [MainThread] [I] [toil.leader] Issued job 'run_mutect_perchrom' kind-run_mutect_perchrom/instance-40bfs1db with job batch system ID: 48 and cores: 1, disk: 23.0 G, and memory: 6.0 G
[2020-10-20T19:59:59-0700] [MainThread] [I] [toil.worker] Redirecting logging to /home/drkthomp/workDir/node-72996abd-6cf4-462a-aea1-4d483640105b-1e53f69f16d74e0b881e7db602b2d2c3/tmppgbecg02/worker_log.txt
[2020-10-20T19:59:59-0700] [MainThread] [I] [toil.worker] Redirecting logging to /home/drkthomp/workDir/node-72996abd-6cf4-462a-aea1-4d483640105b-1e53f69f16d74e0b881e7db602b2d2c3/tmp7zbjx70s/worker_log.txt
[2020-10-20T19:59:59-0700] [Thread-1  ] [E] [toil.batchSystems.singleMachine] Got exit code 1 (indicating failure) from job _toil_worker run_mutect_perchrom file:/home/drkthomp/protect3/jobStore kind-run_mutect_perchrom/instance-cev_msom.
[2020-10-20T19:59:59-0700] [MainThread] [W] [toil.leader] Job failed with exit value 1: 'run_mutect_perchrom' kind-run_mutect_perchrom/instance-cev_msom
[2020-10-20T19:59:59-0700] [MainThread] [W] [toil.leader] The job seems to have left a log file, indicating failure: 'run_mutect_perchrom' kind-run_mutect_perchrom/instance-cev_msom
[2020-10-20T19:59:59-0700] [MainThread] [W] [toil.leader] Log from job kind-run_mutect_perchrom/instance-cev_msom follows:
=========>
	[2020-10-20T19:59:59-0700] [MainThread] [I] [toil.worker] ---TOIL WORKER OUTPUT LOG---
	[2020-10-20T19:59:59-0700] [MainThread] [I] [toil] Running Toil version 4.2.0-3aa1da130141039cb357efe36d7df9b9f6ae9b5b on host drkthomp-virtualbox.
	Traceback (most recent call last):
	  File "/home/drkthomp/protect3/venv/lib/python3.8/site-packages/toil/worker.py", line 368, in workerScript
	    job._runner(jobGraph=jobGraph, jobStore=jobStore, fileStore=fileStore, defer=defer)
	  File "/home/drkthomp/protect3/venv/lib/python3.8/site-packages/toil/job.py", line 1424, in _runner
	    returnValues = self._run(jobGraph, fileStore)
	  File "/home/drkthomp/protect3/venv/lib/python3.8/site-packages/toil/job.py", line 1361, in _run
	    return self.run(fileStore)
	  File "/home/drkthomp/protect3/venv/lib/python3.8/site-packages/toil/job.py", line 1565, in run
	    rValue = userFunction(*((self,) + tuple(self._args)), **self._kwargs)
	  File "/home/drkthomp/protect3/src/protect/mutation_calling/mutect.py", line 123, in run_mutect_perchrom
	    input_files['dbsnp.vcf'] = gunzip(input_files['dbsnp.vcf.gz'])
	  File "/home/drkthomp/protect3/src/protect/common.py", line 172, in gunzip
	    assert is_gzipfile(input_gzip_file)
	AssertionError
	[2020-10-20T19:59:59-0700] [MainThread] [E] [toil.worker] Exiting the worker because of a failed job on host drkthomp-virtualbox
<=========
[2020-10-20T19:59:59-0700] [MainThread] [W] [toil.jobGraph] Due to failure we are reducing the remaining retry count of job 'run_mutect_perchrom' kind-run_mutect_perchrom/instance-cev_msom with ID kind-run_mutect_perchrom/instance-cev_msom to 0
[2020-10-20T19:59:59-0700] [MainThread] [W] [toil.leader] Job 'run_mutect_perchrom' kind-run_mutect_perchrom/instance-cev_msom with ID kind-run_mutect_perchrom/instance-cev_msom is completely failed
[2020-10-20T19:59:59-0700] [Thread-1  ] [E] [toil.batchSystems.singleMachine] Got exit code 1 (indicating failure) from job _toil_worker run_mutect_perchrom file:/home/drkthomp/protect3/jobStore kind-run_mutect_perchrom/instance-0oyi7ie_.
[2020-10-20T19:59:59-0700] [MainThread] [W] [toil.leader] Job failed with exit value 1: 'run_mutect_perchrom' kind-run_mutect_perchrom/instance-0oyi7ie_
[2020-10-20T19:59:59-0700] [MainThread] [W] [toil.leader] The job seems to have left a log file, indicating failure: 'run_mutect_perchrom' kind-run_mutect_perchrom/instance-0oyi7ie_
[2020-10-20T19:59:59-0700] [MainThread] [W] [toil.leader] Log from job kind-run_mutect_perchrom/instance-0oyi7ie_ follows:
=========>
	[2020-10-20T19:59:59-0700] [MainThread] [I] [toil.worker] ---TOIL WORKER OUTPUT LOG---
	[2020-10-20T19:59:59-0700] [MainThread] [I] [toil] Running Toil version 4.2.0-3aa1da130141039cb357efe36d7df9b9f6ae9b5b on host drkthomp-virtualbox.
	Traceback (most recent call last):
	  File "/home/drkthomp/protect3/venv/lib/python3.8/site-packages/toil/worker.py", line 368, in workerScript
	    job._runner(jobGraph=jobGraph, jobStore=jobStore, fileStore=fileStore, defer=defer)
	  File "/home/drkthomp/protect3/venv/lib/python3.8/site-packages/toil/job.py", line 1424, in _runner
	    returnValues = self._run(jobGraph, fileStore)
	  File "/home/drkthomp/protect3/venv/lib/python3.8/site-packages/toil/job.py", line 1361, in _run
	    return self.run(fileStore)
	  File "/home/drkthomp/protect3/venv/lib/python3.8/site-packages/toil/job.py", line 1565, in run
	    rValue = userFunction(*((self,) + tuple(self._args)), **self._kwargs)
	  File "/home/drkthomp/protect3/src/protect/mutation_calling/mutect.py", line 123, in run_mutect_perchrom
	    input_files['dbsnp.vcf'] = gunzip(input_files['dbsnp.vcf.gz'])
	  File "/home/drkthomp/protect3/src/protect/common.py", line 172, in gunzip
	    assert is_gzipfile(input_gzip_file)
	AssertionError
	[2020-10-20T19:59:59-0700] [MainThread] [E] [toil.worker] Exiting the worker because of a failed job on host drkthomp-virtualbox
<=========
[2020-10-20T19:59:59-0700] [MainThread] [W] [toil.jobGraph] Due to failure we are reducing the remaining retry count of job 'run_mutect_perchrom' kind-run_mutect_perchrom/instance-0oyi7ie_ with ID kind-run_mutect_perchrom/instance-0oyi7ie_ to 0
[2020-10-20T19:59:59-0700] [MainThread] [W] [toil.leader] Job 'run_mutect_perchrom' kind-run_mutect_perchrom/instance-0oyi7ie_ with ID kind-run_mutect_perchrom/instance-0oyi7ie_ is completely failed
[2020-10-20T20:00:00-0700] [MainThread] [I] [toil.worker] Redirecting logging to /home/drkthomp/workDir/node-72996abd-6cf4-462a-aea1-4d483640105b-1e53f69f16d74e0b881e7db602b2d2c3/tmp22lvx68s/worker_log.txt
[2020-10-20T20:00:00-0700] [MainThread] [I] [toil.worker] Redirecting logging to /home/drkthomp/workDir/node-72996abd-6cf4-462a-aea1-4d483640105b-1e53f69f16d74e0b881e7db602b2d2c3/tmpeg94j_5q/worker_log.txt
[2020-10-20T20:00:00-0700] [Thread-1  ] [E] [toil.batchSystems.singleMachine] Got exit code 1 (indicating failure) from job _toil_worker run_mutect_perchrom file:/home/drkthomp/protect3/jobStore kind-run_mutect_perchrom/instance-0t3dxg78.
[2020-10-20T20:00:00-0700] [MainThread] [W] [toil.leader] Job failed with exit value 1: 'run_mutect_perchrom' kind-run_mutect_perchrom/instance-0t3dxg78
[2020-10-20T20:00:00-0700] [MainThread] [W] [toil.leader] The job seems to have left a log file, indicating failure: 'run_mutect_perchrom' kind-run_mutect_perchrom/instance-0t3dxg78
[2020-10-20T20:00:00-0700] [MainThread] [W] [toil.leader] Log from job kind-run_mutect_perchrom/instance-0t3dxg78 follows:
=========>
	[2020-10-20T20:00:00-0700] [MainThread] [I] [toil.worker] ---TOIL WORKER OUTPUT LOG---
	[2020-10-20T20:00:00-0700] [MainThread] [I] [toil] Running Toil version 4.2.0-3aa1da130141039cb357efe36d7df9b9f6ae9b5b on host drkthomp-virtualbox.
	Traceback (most recent call last):
	  File "/home/drkthomp/protect3/venv/lib/python3.8/site-packages/toil/worker.py", line 368, in workerScript
	    job._runner(jobGraph=jobGraph, jobStore=jobStore, fileStore=fileStore, defer=defer)
	  File "/home/drkthomp/protect3/venv/lib/python3.8/site-packages/toil/job.py", line 1424, in _runner
	    returnValues = self._run(jobGraph, fileStore)
	  File "/home/drkthomp/protect3/venv/lib/python3.8/site-packages/toil/job.py", line 1361, in _run
	    return self.run(fileStore)
	  File "/home/drkthomp/protect3/venv/lib/python3.8/site-packages/toil/job.py", line 1565, in run
	    rValue = userFunction(*((self,) + tuple(self._args)), **self._kwargs)
	  File "/home/drkthomp/protect3/src/protect/mutation_calling/mutect.py", line 123, in run_mutect_perchrom
	    input_files['dbsnp.vcf'] = gunzip(input_files['dbsnp.vcf.gz'])
	  File "/home/drkthomp/protect3/src/protect/common.py", line 172, in gunzip
	    assert is_gzipfile(input_gzip_file)
	AssertionError
	[2020-10-20T20:00:00-0700] [MainThread] [E] [toil.worker] Exiting the worker because of a failed job on host drkthomp-virtualbox
<=========
[2020-10-20T20:00:00-0700] [MainThread] [W] [toil.jobGraph] Due to failure we are reducing the remaining retry count of job 'run_mutect_perchrom' kind-run_mutect_perchrom/instance-0t3dxg78 with ID kind-run_mutect_perchrom/instance-0t3dxg78 to 0
[2020-10-20T20:00:00-0700] [MainThread] [W] [toil.leader] Job 'run_mutect_perchrom' kind-run_mutect_perchrom/instance-0t3dxg78 with ID kind-run_mutect_perchrom/instance-0t3dxg78 is completely failed
[2020-10-20T20:00:00-0700] [Thread-1  ] [E] [toil.batchSystems.singleMachine] Got exit code 1 (indicating failure) from job _toil_worker run_mutect_perchrom file:/home/drkthomp/protect3/jobStore kind-run_mutect_perchrom/instance-6clikwgf.
[2020-10-20T20:00:00-0700] [MainThread] [W] [toil.leader] Job failed with exit value 1: 'run_mutect_perchrom' kind-run_mutect_perchrom/instance-6clikwgf
[2020-10-20T20:00:00-0700] [MainThread] [W] [toil.leader] The job seems to have left a log file, indicating failure: 'run_mutect_perchrom' kind-run_mutect_perchrom/instance-6clikwgf
[2020-10-20T20:00:00-0700] [MainThread] [W] [toil.leader] Log from job kind-run_mutect_perchrom/instance-6clikwgf follows:
=========>
	[2020-10-20T20:00:00-0700] [MainThread] [I] [toil.worker] ---TOIL WORKER OUTPUT LOG---
	[2020-10-20T20:00:00-0700] [MainThread] [I] [toil] Running Toil version 4.2.0-3aa1da130141039cb357efe36d7df9b9f6ae9b5b on host drkthomp-virtualbox.
	Traceback (most recent call last):
	  File "/home/drkthomp/protect3/venv/lib/python3.8/site-packages/toil/worker.py", line 368, in workerScript
	    job._runner(jobGraph=jobGraph, jobStore=jobStore, fileStore=fileStore, defer=defer)
	  File "/home/drkthomp/protect3/venv/lib/python3.8/site-packages/toil/job.py", line 1424, in _runner
	    returnValues = self._run(jobGraph, fileStore)
	  File "/home/drkthomp/protect3/venv/lib/python3.8/site-packages/toil/job.py", line 1361, in _run
	    return self.run(fileStore)
	  File "/home/drkthomp/protect3/venv/lib/python3.8/site-packages/toil/job.py", line 1565, in run
	    rValue = userFunction(*((self,) + tuple(self._args)), **self._kwargs)
	  File "/home/drkthomp/protect3/src/protect/mutation_calling/mutect.py", line 123, in run_mutect_perchrom
	    input_files['dbsnp.vcf'] = gunzip(input_files['dbsnp.vcf.gz'])
	  File "/home/drkthomp/protect3/src/protect/common.py", line 172, in gunzip
	    assert is_gzipfile(input_gzip_file)
	AssertionError
	[2020-10-20T20:00:00-0700] [MainThread] [E] [toil.worker] Exiting the worker because of a failed job on host drkthomp-virtualbox
<=========
[2020-10-20T20:00:00-0700] [MainThread] [W] [toil.jobGraph] Due to failure we are reducing the remaining retry count of job 'run_mutect_perchrom' kind-run_mutect_perchrom/instance-6clikwgf with ID kind-run_mutect_perchrom/instance-6clikwgf to 1
[2020-10-20T20:00:00-0700] [MainThread] [I] [toil.leader] Issued job 'run_mutect_perchrom' kind-run_mutect_perchrom/instance-6clikwgf with job batch system ID: 49 and cores: 1, disk: 23.0 G, and memory: 6.0 G
[2020-10-20T20:00:00-0700] [MainThread] [I] [toil.worker] Redirecting logging to /home/drkthomp/workDir/node-72996abd-6cf4-462a-aea1-4d483640105b-1e53f69f16d74e0b881e7db602b2d2c3/tmpigmwmx3j/worker_log.txt
[2020-10-20T20:00:00-0700] [MainThread] [I] [toil.worker] Redirecting logging to /home/drkthomp/workDir/node-72996abd-6cf4-462a-aea1-4d483640105b-1e53f69f16d74e0b881e7db602b2d2c3/tmp9t5utgiw/worker_log.txt
[2020-10-20T20:00:00-0700] [Thread-1  ] [E] [toil.batchSystems.singleMachine] Got exit code 1 (indicating failure) from job _toil_worker run_mutect_perchrom file:/home/drkthomp/protect3/jobStore kind-run_mutect_perchrom/instance-0p9602y6.
[2020-10-20T20:00:00-0700] [MainThread] [W] [toil.leader] Job failed with exit value 1: 'run_mutect_perchrom' kind-run_mutect_perchrom/instance-0p9602y6
[2020-10-20T20:00:00-0700] [MainThread] [W] [toil.leader] The job seems to have left a log file, indicating failure: 'run_mutect_perchrom' kind-run_mutect_perchrom/instance-0p9602y6
[2020-10-20T20:00:00-0700] [MainThread] [W] [toil.leader] Log from job kind-run_mutect_perchrom/instance-0p9602y6 follows:
=========>
	[2020-10-20T20:00:00-0700] [MainThread] [I] [toil.worker] ---TOIL WORKER OUTPUT LOG---
	[2020-10-20T20:00:00-0700] [MainThread] [I] [toil] Running Toil version 4.2.0-3aa1da130141039cb357efe36d7df9b9f6ae9b5b on host drkthomp-virtualbox.
	Traceback (most recent call last):
	  File "/home/drkthomp/protect3/venv/lib/python3.8/site-packages/toil/worker.py", line 368, in workerScript
	    job._runner(jobGraph=jobGraph, jobStore=jobStore, fileStore=fileStore, defer=defer)
	  File "/home/drkthomp/protect3/venv/lib/python3.8/site-packages/toil/job.py", line 1424, in _runner
	    returnValues = self._run(jobGraph, fileStore)
	  File "/home/drkthomp/protect3/venv/lib/python3.8/site-packages/toil/job.py", line 1361, in _run
	    return self.run(fileStore)
	  File "/home/drkthomp/protect3/venv/lib/python3.8/site-packages/toil/job.py", line 1565, in run
	    rValue = userFunction(*((self,) + tuple(self._args)), **self._kwargs)
	  File "/home/drkthomp/protect3/src/protect/mutation_calling/mutect.py", line 123, in run_mutect_perchrom
	    input_files['dbsnp.vcf'] = gunzip(input_files['dbsnp.vcf.gz'])
	  File "/home/drkthomp/protect3/src/protect/common.py", line 172, in gunzip
	    assert is_gzipfile(input_gzip_file)
	AssertionError
	[2020-10-20T20:00:00-0700] [MainThread] [E] [toil.worker] Exiting the worker because of a failed job on host drkthomp-virtualbox
<=========
[2020-10-20T20:00:00-0700] [MainThread] [W] [toil.jobGraph] Due to failure we are reducing the remaining retry count of job 'run_mutect_perchrom' kind-run_mutect_perchrom/instance-0p9602y6 with ID kind-run_mutect_perchrom/instance-0p9602y6 to 0
[2020-10-20T20:00:00-0700] [MainThread] [W] [toil.leader] Job 'run_mutect_perchrom' kind-run_mutect_perchrom/instance-0p9602y6 with ID kind-run_mutect_perchrom/instance-0p9602y6 is completely failed
[2020-10-20T20:00:00-0700] [Thread-1  ] [E] [toil.batchSystems.singleMachine] Got exit code 1 (indicating failure) from job _toil_worker run_mutect_perchrom file:/home/drkthomp/protect3/jobStore kind-run_mutect_perchrom/instance-ourgk6vm.
[2020-10-20T20:00:00-0700] [MainThread] [W] [toil.leader] Job failed with exit value 1: 'run_mutect_perchrom' kind-run_mutect_perchrom/instance-ourgk6vm
[2020-10-20T20:00:00-0700] [MainThread] [W] [toil.leader] The job seems to have left a log file, indicating failure: 'run_mutect_perchrom' kind-run_mutect_perchrom/instance-ourgk6vm
[2020-10-20T20:00:00-0700] [MainThread] [W] [toil.leader] Log from job kind-run_mutect_perchrom/instance-ourgk6vm follows:
=========>
	[2020-10-20T20:00:00-0700] [MainThread] [I] [toil.worker] ---TOIL WORKER OUTPUT LOG---
	[2020-10-20T20:00:00-0700] [MainThread] [I] [toil] Running Toil version 4.2.0-3aa1da130141039cb357efe36d7df9b9f6ae9b5b on host drkthomp-virtualbox.
	Traceback (most recent call last):
	  File "/home/drkthomp/protect3/venv/lib/python3.8/site-packages/toil/worker.py", line 368, in workerScript
	    job._runner(jobGraph=jobGraph, jobStore=jobStore, fileStore=fileStore, defer=defer)
	  File "/home/drkthomp/protect3/venv/lib/python3.8/site-packages/toil/job.py", line 1424, in _runner
	    returnValues = self._run(jobGraph, fileStore)
	  File "/home/drkthomp/protect3/venv/lib/python3.8/site-packages/toil/job.py", line 1361, in _run
	    return self.run(fileStore)
	  File "/home/drkthomp/protect3/venv/lib/python3.8/site-packages/toil/job.py", line 1565, in run
	    rValue = userFunction(*((self,) + tuple(self._args)), **self._kwargs)
	  File "/home/drkthomp/protect3/src/protect/mutation_calling/mutect.py", line 123, in run_mutect_perchrom
	    input_files['dbsnp.vcf'] = gunzip(input_files['dbsnp.vcf.gz'])
	  File "/home/drkthomp/protect3/src/protect/common.py", line 172, in gunzip
	    assert is_gzipfile(input_gzip_file)
	AssertionError
	[2020-10-20T20:00:00-0700] [MainThread] [E] [toil.worker] Exiting the worker because of a failed job on host drkthomp-virtualbox
<=========
[2020-10-20T20:00:00-0700] [MainThread] [W] [toil.jobGraph] Due to failure we are reducing the remaining retry count of job 'run_mutect_perchrom' kind-run_mutect_perchrom/instance-ourgk6vm with ID kind-run_mutect_perchrom/instance-ourgk6vm to 0
[2020-10-20T20:00:00-0700] [MainThread] [W] [toil.leader] Job 'run_mutect_perchrom' kind-run_mutect_perchrom/instance-ourgk6vm with ID kind-run_mutect_perchrom/instance-ourgk6vm is completely failed
[2020-10-20T20:00:00-0700] [MainThread] [I] [toil.worker] Redirecting logging to /home/drkthomp/workDir/node-72996abd-6cf4-462a-aea1-4d483640105b-1e53f69f16d74e0b881e7db602b2d2c3/tmptcmuqes8/worker_log.txt
[2020-10-20T20:00:00-0700] [MainThread] [I] [toil.worker] Redirecting logging to /home/drkthomp/workDir/node-72996abd-6cf4-462a-aea1-4d483640105b-1e53f69f16d74e0b881e7db602b2d2c3/tmp9vj_szc8/worker_log.txt
[2020-10-20T20:00:00-0700] [Thread-1  ] [E] [toil.batchSystems.singleMachine] Got exit code 1 (indicating failure) from job _toil_worker run_mutect_perchrom file:/home/drkthomp/protect3/jobStore kind-run_mutect_perchrom/instance-8gyqgqyx.
[2020-10-20T20:00:00-0700] [MainThread] [W] [toil.leader] Job failed with exit value 1: 'run_mutect_perchrom' kind-run_mutect_perchrom/instance-8gyqgqyx
[2020-10-20T20:00:00-0700] [MainThread] [W] [toil.leader] The job seems to have left a log file, indicating failure: 'run_mutect_perchrom' kind-run_mutect_perchrom/instance-8gyqgqyx
[2020-10-20T20:00:00-0700] [MainThread] [W] [toil.leader] Log from job kind-run_mutect_perchrom/instance-8gyqgqyx follows:
=========>
	[2020-10-20T20:00:00-0700] [MainThread] [I] [toil.worker] ---TOIL WORKER OUTPUT LOG---
	[2020-10-20T20:00:00-0700] [MainThread] [I] [toil] Running Toil version 4.2.0-3aa1da130141039cb357efe36d7df9b9f6ae9b5b on host drkthomp-virtualbox.
	Traceback (most recent call last):
	  File "/home/drkthomp/protect3/venv/lib/python3.8/site-packages/toil/worker.py", line 368, in workerScript
	    job._runner(jobGraph=jobGraph, jobStore=jobStore, fileStore=fileStore, defer=defer)
	  File "/home/drkthomp/protect3/venv/lib/python3.8/site-packages/toil/job.py", line 1424, in _runner
	    returnValues = self._run(jobGraph, fileStore)
	  File "/home/drkthomp/protect3/venv/lib/python3.8/site-packages/toil/job.py", line 1361, in _run
	    return self.run(fileStore)
	  File "/home/drkthomp/protect3/venv/lib/python3.8/site-packages/toil/job.py", line 1565, in run
	    rValue = userFunction(*((self,) + tuple(self._args)), **self._kwargs)
	  File "/home/drkthomp/protect3/src/protect/mutation_calling/mutect.py", line 123, in run_mutect_perchrom
	    input_files['dbsnp.vcf'] = gunzip(input_files['dbsnp.vcf.gz'])
	  File "/home/drkthomp/protect3/src/protect/common.py", line 172, in gunzip
	    assert is_gzipfile(input_gzip_file)
	AssertionError
	[2020-10-20T20:00:00-0700] [MainThread] [E] [toil.worker] Exiting the worker because of a failed job on host drkthomp-virtualbox
<=========
[2020-10-20T20:00:00-0700] [MainThread] [W] [toil.jobGraph] Due to failure we are reducing the remaining retry count of job 'run_mutect_perchrom' kind-run_mutect_perchrom/instance-8gyqgqyx with ID kind-run_mutect_perchrom/instance-8gyqgqyx to 0
[2020-10-20T20:00:00-0700] [Thread-1  ] [E] [toil.batchSystems.singleMachine] Got exit code 1 (indicating failure) from job _toil_worker run_mutect_perchrom file:/home/drkthomp/protect3/jobStore kind-run_mutect_perchrom/instance-cp3zlhzq.
[2020-10-20T20:00:00-0700] [MainThread] [W] [toil.leader] Job 'run_mutect_perchrom' kind-run_mutect_perchrom/instance-8gyqgqyx with ID kind-run_mutect_perchrom/instance-8gyqgqyx is completely failed
[2020-10-20T20:00:00-0700] [MainThread] [W] [toil.leader] Job failed with exit value 1: 'run_mutect_perchrom' kind-run_mutect_perchrom/instance-cp3zlhzq
[2020-10-20T20:00:00-0700] [MainThread] [W] [toil.leader] The job seems to have left a log file, indicating failure: 'run_mutect_perchrom' kind-run_mutect_perchrom/instance-cp3zlhzq
[2020-10-20T20:00:00-0700] [MainThread] [W] [toil.leader] Log from job kind-run_mutect_perchrom/instance-cp3zlhzq follows:
=========>
	[2020-10-20T20:00:00-0700] [MainThread] [I] [toil.worker] ---TOIL WORKER OUTPUT LOG---
	[2020-10-20T20:00:00-0700] [MainThread] [I] [toil] Running Toil version 4.2.0-3aa1da130141039cb357efe36d7df9b9f6ae9b5b on host drkthomp-virtualbox.
	Traceback (most recent call last):
	  File "/home/drkthomp/protect3/venv/lib/python3.8/site-packages/toil/worker.py", line 368, in workerScript
	    job._runner(jobGraph=jobGraph, jobStore=jobStore, fileStore=fileStore, defer=defer)
	  File "/home/drkthomp/protect3/venv/lib/python3.8/site-packages/toil/job.py", line 1424, in _runner
	    returnValues = self._run(jobGraph, fileStore)
	  File "/home/drkthomp/protect3/venv/lib/python3.8/site-packages/toil/job.py", line 1361, in _run
	    return self.run(fileStore)
	  File "/home/drkthomp/protect3/venv/lib/python3.8/site-packages/toil/job.py", line 1565, in run
	    rValue = userFunction(*((self,) + tuple(self._args)), **self._kwargs)
	  File "/home/drkthomp/protect3/src/protect/mutation_calling/mutect.py", line 123, in run_mutect_perchrom
	    input_files['dbsnp.vcf'] = gunzip(input_files['dbsnp.vcf.gz'])
	  File "/home/drkthomp/protect3/src/protect/common.py", line 172, in gunzip
	    assert is_gzipfile(input_gzip_file)
	AssertionError
	[2020-10-20T20:00:00-0700] [MainThread] [E] [toil.worker] Exiting the worker because of a failed job on host drkthomp-virtualbox
<=========
[2020-10-20T20:00:00-0700] [MainThread] [W] [toil.jobGraph] Due to failure we are reducing the remaining retry count of job 'run_mutect_perchrom' kind-run_mutect_perchrom/instance-cp3zlhzq with ID kind-run_mutect_perchrom/instance-cp3zlhzq to 0
[2020-10-20T20:00:00-0700] [MainThread] [W] [toil.leader] Job 'run_mutect_perchrom' kind-run_mutect_perchrom/instance-cp3zlhzq with ID kind-run_mutect_perchrom/instance-cp3zlhzq is completely failed
[2020-10-20T20:00:01-0700] [MainThread] [I] [toil.worker] Redirecting logging to /home/drkthomp/workDir/node-72996abd-6cf4-462a-aea1-4d483640105b-1e53f69f16d74e0b881e7db602b2d2c3/tmph5nse9nj/worker_log.txt
[2020-10-20T20:00:01-0700] [MainThread] [I] [toil.worker] Redirecting logging to /home/drkthomp/workDir/node-72996abd-6cf4-462a-aea1-4d483640105b-1e53f69f16d74e0b881e7db602b2d2c3/tmpmr5dn890/worker_log.txt
[2020-10-20T20:00:01-0700] [Thread-1  ] [E] [toil.batchSystems.singleMachine] Got exit code 1 (indicating failure) from job _toil_worker run_mutect_perchrom file:/home/drkthomp/protect3/jobStore kind-run_mutect_perchrom/instance-vodde7jc.
[2020-10-20T20:00:01-0700] [MainThread] [W] [toil.leader] Job failed with exit value 1: 'run_mutect_perchrom' kind-run_mutect_perchrom/instance-vodde7jc
[2020-10-20T20:00:01-0700] [MainThread] [W] [toil.leader] The job seems to have left a log file, indicating failure: 'run_mutect_perchrom' kind-run_mutect_perchrom/instance-vodde7jc
[2020-10-20T20:00:01-0700] [MainThread] [W] [toil.leader] Log from job kind-run_mutect_perchrom/instance-vodde7jc follows:
=========>
	[2020-10-20T20:00:01-0700] [MainThread] [I] [toil.worker] ---TOIL WORKER OUTPUT LOG---
	[2020-10-20T20:00:01-0700] [MainThread] [I] [toil] Running Toil version 4.2.0-3aa1da130141039cb357efe36d7df9b9f6ae9b5b on host drkthomp-virtualbox.
	Traceback (most recent call last):
	  File "/home/drkthomp/protect3/venv/lib/python3.8/site-packages/toil/worker.py", line 368, in workerScript
	    job._runner(jobGraph=jobGraph, jobStore=jobStore, fileStore=fileStore, defer=defer)
	  File "/home/drkthomp/protect3/venv/lib/python3.8/site-packages/toil/job.py", line 1424, in _runner
	    returnValues = self._run(jobGraph, fileStore)
	  File "/home/drkthomp/protect3/venv/lib/python3.8/site-packages/toil/job.py", line 1361, in _run
	    return self.run(fileStore)
	  File "/home/drkthomp/protect3/venv/lib/python3.8/site-packages/toil/job.py", line 1565, in run
	    rValue = userFunction(*((self,) + tuple(self._args)), **self._kwargs)
	  File "/home/drkthomp/protect3/src/protect/mutation_calling/mutect.py", line 123, in run_mutect_perchrom
	    input_files['dbsnp.vcf'] = gunzip(input_files['dbsnp.vcf.gz'])
	  File "/home/drkthomp/protect3/src/protect/common.py", line 172, in gunzip
	    assert is_gzipfile(input_gzip_file)
	AssertionError
	[2020-10-20T20:00:01-0700] [MainThread] [E] [toil.worker] Exiting the worker because of a failed job on host drkthomp-virtualbox
<=========
[2020-10-20T20:00:01-0700] [MainThread] [W] [toil.jobGraph] Due to failure we are reducing the remaining retry count of job 'run_mutect_perchrom' kind-run_mutect_perchrom/instance-vodde7jc with ID kind-run_mutect_perchrom/instance-vodde7jc to 0
[2020-10-20T20:00:01-0700] [MainThread] [W] [toil.leader] Job 'run_mutect_perchrom' kind-run_mutect_perchrom/instance-vodde7jc with ID kind-run_mutect_perchrom/instance-vodde7jc is completely failed
[2020-10-20T20:00:01-0700] [Thread-1  ] [E] [toil.batchSystems.singleMachine] Got exit code 1 (indicating failure) from job _toil_worker run_mutect_perchrom file:/home/drkthomp/protect3/jobStore kind-run_mutect_perchrom/instance-h18ep_9e.
[2020-10-20T20:00:01-0700] [MainThread] [W] [toil.leader] Job failed with exit value 1: 'run_mutect_perchrom' kind-run_mutect_perchrom/instance-h18ep_9e
[2020-10-20T20:00:01-0700] [MainThread] [W] [toil.leader] The job seems to have left a log file, indicating failure: 'run_mutect_perchrom' kind-run_mutect_perchrom/instance-h18ep_9e
[2020-10-20T20:00:01-0700] [MainThread] [W] [toil.leader] Log from job kind-run_mutect_perchrom/instance-h18ep_9e follows:
=========>
	[2020-10-20T20:00:01-0700] [MainThread] [I] [toil.worker] ---TOIL WORKER OUTPUT LOG---
	[2020-10-20T20:00:01-0700] [MainThread] [I] [toil] Running Toil version 4.2.0-3aa1da130141039cb357efe36d7df9b9f6ae9b5b on host drkthomp-virtualbox.
	Traceback (most recent call last):
	  File "/home/drkthomp/protect3/venv/lib/python3.8/site-packages/toil/worker.py", line 368, in workerScript
	    job._runner(jobGraph=jobGraph, jobStore=jobStore, fileStore=fileStore, defer=defer)
	  File "/home/drkthomp/protect3/venv/lib/python3.8/site-packages/toil/job.py", line 1424, in _runner
	    returnValues = self._run(jobGraph, fileStore)
	  File "/home/drkthomp/protect3/venv/lib/python3.8/site-packages/toil/job.py", line 1361, in _run
	    return self.run(fileStore)
	  File "/home/drkthomp/protect3/venv/lib/python3.8/site-packages/toil/job.py", line 1565, in run
	    rValue = userFunction(*((self,) + tuple(self._args)), **self._kwargs)
	  File "/home/drkthomp/protect3/src/protect/mutation_calling/mutect.py", line 123, in run_mutect_perchrom
	    input_files['dbsnp.vcf'] = gunzip(input_files['dbsnp.vcf.gz'])
	  File "/home/drkthomp/protect3/src/protect/common.py", line 172, in gunzip
	    assert is_gzipfile(input_gzip_file)
	AssertionError
	[2020-10-20T20:00:01-0700] [MainThread] [E] [toil.worker] Exiting the worker because of a failed job on host drkthomp-virtualbox
<=========
[2020-10-20T20:00:01-0700] [MainThread] [W] [toil.jobGraph] Due to failure we are reducing the remaining retry count of job 'run_mutect_perchrom' kind-run_mutect_perchrom/instance-h18ep_9e with ID kind-run_mutect_perchrom/instance-h18ep_9e to 1
[2020-10-20T20:00:01-0700] [MainThread] [I] [toil.leader] Issued job 'run_mutect_perchrom' kind-run_mutect_perchrom/instance-h18ep_9e with job batch system ID: 50 and cores: 1, disk: 23.0 G, and memory: 6.0 G
[2020-10-20T20:00:01-0700] [MainThread] [I] [toil.worker] Redirecting logging to /home/drkthomp/workDir/node-72996abd-6cf4-462a-aea1-4d483640105b-1e53f69f16d74e0b881e7db602b2d2c3/tmphprc8weq/worker_log.txt
[2020-10-20T20:00:01-0700] [Thread-1  ] [E] [toil.batchSystems.singleMachine] Got exit code 1 (indicating failure) from job _toil_worker run_mutect_perchrom file:/home/drkthomp/protect3/jobStore kind-run_mutect_perchrom/instance-tjkov9ea.
[2020-10-20T20:00:01-0700] [MainThread] [W] [toil.leader] Job failed with exit value 1: 'run_mutect_perchrom' kind-run_mutect_perchrom/instance-tjkov9ea
[2020-10-20T20:00:01-0700] [MainThread] [W] [toil.leader] The job seems to have left a log file, indicating failure: 'run_mutect_perchrom' kind-run_mutect_perchrom/instance-tjkov9ea
[2020-10-20T20:00:01-0700] [MainThread] [W] [toil.leader] Log from job kind-run_mutect_perchrom/instance-tjkov9ea follows:
=========>
	[2020-10-20T20:00:01-0700] [MainThread] [I] [toil.worker] ---TOIL WORKER OUTPUT LOG---
	[2020-10-20T20:00:01-0700] [MainThread] [I] [toil] Running Toil version 4.2.0-3aa1da130141039cb357efe36d7df9b9f6ae9b5b on host drkthomp-virtualbox.
	Traceback (most recent call last):
	  File "/home/drkthomp/protect3/venv/lib/python3.8/site-packages/toil/worker.py", line 368, in workerScript
	    job._runner(jobGraph=jobGraph, jobStore=jobStore, fileStore=fileStore, defer=defer)
	  File "/home/drkthomp/protect3/venv/lib/python3.8/site-packages/toil/job.py", line 1424, in _runner
	    returnValues = self._run(jobGraph, fileStore)
	  File "/home/drkthomp/protect3/venv/lib/python3.8/site-packages/toil/job.py", line 1361, in _run
	    return self.run(fileStore)
	  File "/home/drkthomp/protect3/venv/lib/python3.8/site-packages/toil/job.py", line 1565, in run
	    rValue = userFunction(*((self,) + tuple(self._args)), **self._kwargs)
	  File "/home/drkthomp/protect3/src/protect/mutation_calling/mutect.py", line 123, in run_mutect_perchrom
	    input_files['dbsnp.vcf'] = gunzip(input_files['dbsnp.vcf.gz'])
	  File "/home/drkthomp/protect3/src/protect/common.py", line 172, in gunzip
	    assert is_gzipfile(input_gzip_file)
	AssertionError
	[2020-10-20T20:00:01-0700] [MainThread] [E] [toil.worker] Exiting the worker because of a failed job on host drkthomp-virtualbox
<=========
[2020-10-20T20:00:01-0700] [MainThread] [W] [toil.jobGraph] Due to failure we are reducing the remaining retry count of job 'run_mutect_perchrom' kind-run_mutect_perchrom/instance-tjkov9ea with ID kind-run_mutect_perchrom/instance-tjkov9ea to 1
[2020-10-20T20:00:01-0700] [MainThread] [I] [toil.leader] Issued job 'run_mutect_perchrom' kind-run_mutect_perchrom/instance-tjkov9ea with job batch system ID: 51 and cores: 1, disk: 23.0 G, and memory: 6.0 G
[2020-10-20T20:00:01-0700] [MainThread] [I] [toil.worker] Redirecting logging to /home/drkthomp/workDir/node-72996abd-6cf4-462a-aea1-4d483640105b-1e53f69f16d74e0b881e7db602b2d2c3/tmpbj0gnit_/worker_log.txt
[2020-10-20T20:00:01-0700] [Thread-1  ] [E] [toil.batchSystems.singleMachine] Got exit code 1 (indicating failure) from job _toil_worker run_mutect_perchrom file:/home/drkthomp/protect3/jobStore kind-run_mutect_perchrom/instance-wflniclq.
[2020-10-20T20:00:01-0700] [MainThread] [W] [toil.leader] Job failed with exit value 1: 'run_mutect_perchrom' kind-run_mutect_perchrom/instance-wflniclq
[2020-10-20T20:00:01-0700] [MainThread] [W] [toil.leader] The job seems to have left a log file, indicating failure: 'run_mutect_perchrom' kind-run_mutect_perchrom/instance-wflniclq
[2020-10-20T20:00:01-0700] [MainThread] [W] [toil.leader] Log from job kind-run_mutect_perchrom/instance-wflniclq follows:
=========>
	[2020-10-20T20:00:01-0700] [MainThread] [I] [toil.worker] ---TOIL WORKER OUTPUT LOG---
	[2020-10-20T20:00:01-0700] [MainThread] [I] [toil] Running Toil version 4.2.0-3aa1da130141039cb357efe36d7df9b9f6ae9b5b on host drkthomp-virtualbox.
	Traceback (most recent call last):
	  File "/home/drkthomp/protect3/venv/lib/python3.8/site-packages/toil/worker.py", line 368, in workerScript
	    job._runner(jobGraph=jobGraph, jobStore=jobStore, fileStore=fileStore, defer=defer)
	  File "/home/drkthomp/protect3/venv/lib/python3.8/site-packages/toil/job.py", line 1424, in _runner
	    returnValues = self._run(jobGraph, fileStore)
	  File "/home/drkthomp/protect3/venv/lib/python3.8/site-packages/toil/job.py", line 1361, in _run
	    return self.run(fileStore)
	  File "/home/drkthomp/protect3/venv/lib/python3.8/site-packages/toil/job.py", line 1565, in run
	    rValue = userFunction(*((self,) + tuple(self._args)), **self._kwargs)
	  File "/home/drkthomp/protect3/src/protect/mutation_calling/mutect.py", line 123, in run_mutect_perchrom
	    input_files['dbsnp.vcf'] = gunzip(input_files['dbsnp.vcf.gz'])
	  File "/home/drkthomp/protect3/src/protect/common.py", line 172, in gunzip
	    assert is_gzipfile(input_gzip_file)
	AssertionError
	[2020-10-20T20:00:01-0700] [MainThread] [E] [toil.worker] Exiting the worker because of a failed job on host drkthomp-virtualbox
<=========
[2020-10-20T20:00:01-0700] [MainThread] [W] [toil.jobGraph] Due to failure we are reducing the remaining retry count of job 'run_mutect_perchrom' kind-run_mutect_perchrom/instance-wflniclq with ID kind-run_mutect_perchrom/instance-wflniclq to 1
[2020-10-20T20:00:01-0700] [MainThread] [I] [toil.leader] Issued job 'run_mutect_perchrom' kind-run_mutect_perchrom/instance-wflniclq with job batch system ID: 52 and cores: 1, disk: 23.0 G, and memory: 6.0 G
[2020-10-20T20:00:01-0700] [MainThread] [I] [toil.worker] Redirecting logging to /home/drkthomp/workDir/node-72996abd-6cf4-462a-aea1-4d483640105b-1e53f69f16d74e0b881e7db602b2d2c3/tmpn2awtt9m/worker_log.txt
[2020-10-20T20:00:01-0700] [Thread-1  ] [E] [toil.batchSystems.singleMachine] Got exit code 1 (indicating failure) from job _toil_worker run_mutect_perchrom file:/home/drkthomp/protect3/jobStore kind-run_mutect_perchrom/instance-3a6rn9f9.
[2020-10-20T20:00:01-0700] [MainThread] [W] [toil.leader] Job failed with exit value 1: 'run_mutect_perchrom' kind-run_mutect_perchrom/instance-3a6rn9f9
[2020-10-20T20:00:01-0700] [MainThread] [W] [toil.leader] The job seems to have left a log file, indicating failure: 'run_mutect_perchrom' kind-run_mutect_perchrom/instance-3a6rn9f9
[2020-10-20T20:00:01-0700] [MainThread] [W] [toil.leader] Log from job kind-run_mutect_perchrom/instance-3a6rn9f9 follows:
=========>
	[2020-10-20T20:00:01-0700] [MainThread] [I] [toil.worker] ---TOIL WORKER OUTPUT LOG---
	[2020-10-20T20:00:01-0700] [MainThread] [I] [toil] Running Toil version 4.2.0-3aa1da130141039cb357efe36d7df9b9f6ae9b5b on host drkthomp-virtualbox.
	Traceback (most recent call last):
	  File "/home/drkthomp/protect3/venv/lib/python3.8/site-packages/toil/worker.py", line 368, in workerScript
	    job._runner(jobGraph=jobGraph, jobStore=jobStore, fileStore=fileStore, defer=defer)
	  File "/home/drkthomp/protect3/venv/lib/python3.8/site-packages/toil/job.py", line 1424, in _runner
	    returnValues = self._run(jobGraph, fileStore)
	  File "/home/drkthomp/protect3/venv/lib/python3.8/site-packages/toil/job.py", line 1361, in _run
	    return self.run(fileStore)
	  File "/home/drkthomp/protect3/venv/lib/python3.8/site-packages/toil/job.py", line 1565, in run
	    rValue = userFunction(*((self,) + tuple(self._args)), **self._kwargs)
	  File "/home/drkthomp/protect3/src/protect/mutation_calling/mutect.py", line 123, in run_mutect_perchrom
	    input_files['dbsnp.vcf'] = gunzip(input_files['dbsnp.vcf.gz'])
	  File "/home/drkthomp/protect3/src/protect/common.py", line 172, in gunzip
	    assert is_gzipfile(input_gzip_file)
	AssertionError
	[2020-10-20T20:00:01-0700] [MainThread] [E] [toil.worker] Exiting the worker because of a failed job on host drkthomp-virtualbox
<=========
[2020-10-20T20:00:01-0700] [MainThread] [W] [toil.jobGraph] Due to failure we are reducing the remaining retry count of job 'run_mutect_perchrom' kind-run_mutect_perchrom/instance-3a6rn9f9 with ID kind-run_mutect_perchrom/instance-3a6rn9f9 to 1
[2020-10-20T20:00:01-0700] [MainThread] [I] [toil.leader] Issued job 'run_mutect_perchrom' kind-run_mutect_perchrom/instance-3a6rn9f9 with job batch system ID: 53 and cores: 1, disk: 23.0 G, and memory: 6.0 G
[2020-10-20T20:00:01-0700] [MainThread] [I] [toil.worker] Redirecting logging to /home/drkthomp/workDir/node-72996abd-6cf4-462a-aea1-4d483640105b-1e53f69f16d74e0b881e7db602b2d2c3/tmpjbei7ntc/worker_log.txt
[2020-10-20T20:00:02-0700] [Thread-1  ] [E] [toil.batchSystems.singleMachine] Got exit code 1 (indicating failure) from job _toil_worker run_mutect_perchrom file:/home/drkthomp/protect3/jobStore kind-run_mutect_perchrom/instance-h18ep_9e.
[2020-10-20T20:00:02-0700] [MainThread] [W] [toil.leader] Job failed with exit value 1: 'run_mutect_perchrom' kind-run_mutect_perchrom/instance-h18ep_9e
[2020-10-20T20:00:02-0700] [MainThread] [W] [toil.leader] The job seems to have left a log file, indicating failure: 'run_mutect_perchrom' kind-run_mutect_perchrom/instance-h18ep_9e
[2020-10-20T20:00:02-0700] [MainThread] [W] [toil.leader] Log from job kind-run_mutect_perchrom/instance-h18ep_9e follows:
=========>
	[2020-10-20T20:00:01-0700] [MainThread] [I] [toil.worker] ---TOIL WORKER OUTPUT LOG---
	[2020-10-20T20:00:01-0700] [MainThread] [I] [toil] Running Toil version 4.2.0-3aa1da130141039cb357efe36d7df9b9f6ae9b5b on host drkthomp-virtualbox.
	Traceback (most recent call last):
	  File "/home/drkthomp/protect3/venv/lib/python3.8/site-packages/toil/worker.py", line 368, in workerScript
	    job._runner(jobGraph=jobGraph, jobStore=jobStore, fileStore=fileStore, defer=defer)
	  File "/home/drkthomp/protect3/venv/lib/python3.8/site-packages/toil/job.py", line 1424, in _runner
	    returnValues = self._run(jobGraph, fileStore)
	  File "/home/drkthomp/protect3/venv/lib/python3.8/site-packages/toil/job.py", line 1361, in _run
	    return self.run(fileStore)
	  File "/home/drkthomp/protect3/venv/lib/python3.8/site-packages/toil/job.py", line 1565, in run
	    rValue = userFunction(*((self,) + tuple(self._args)), **self._kwargs)
	  File "/home/drkthomp/protect3/src/protect/mutation_calling/mutect.py", line 123, in run_mutect_perchrom
	    input_files['dbsnp.vcf'] = gunzip(input_files['dbsnp.vcf.gz'])
	  File "/home/drkthomp/protect3/src/protect/common.py", line 172, in gunzip
	    assert is_gzipfile(input_gzip_file)
	AssertionError
	[2020-10-20T20:00:01-0700] [MainThread] [E] [toil.worker] Exiting the worker because of a failed job on host drkthomp-virtualbox
<=========
[2020-10-20T20:00:02-0700] [MainThread] [W] [toil.jobGraph] Due to failure we are reducing the remaining retry count of job 'run_mutect_perchrom' kind-run_mutect_perchrom/instance-h18ep_9e with ID kind-run_mutect_perchrom/instance-h18ep_9e to 0
[2020-10-20T20:00:02-0700] [MainThread] [W] [toil.leader] Job 'run_mutect_perchrom' kind-run_mutect_perchrom/instance-h18ep_9e with ID kind-run_mutect_perchrom/instance-h18ep_9e is completely failed
[2020-10-20T20:00:02-0700] [MainThread] [I] [toil.worker] Redirecting logging to /home/drkthomp/workDir/node-72996abd-6cf4-462a-aea1-4d483640105b-1e53f69f16d74e0b881e7db602b2d2c3/tmp_1p3hy6k/worker_log.txt
[2020-10-20T20:00:02-0700] [Thread-1  ] [E] [toil.batchSystems.singleMachine] Got exit code 1 (indicating failure) from job _toil_worker run_mutect_perchrom file:/home/drkthomp/protect3/jobStore kind-run_mutect_perchrom/instance-bm4dpfik.
[2020-10-20T20:00:02-0700] [MainThread] [W] [toil.leader] Job failed with exit value 1: 'run_mutect_perchrom' kind-run_mutect_perchrom/instance-bm4dpfik
[2020-10-20T20:00:02-0700] [MainThread] [W] [toil.leader] The job seems to have left a log file, indicating failure: 'run_mutect_perchrom' kind-run_mutect_perchrom/instance-bm4dpfik
[2020-10-20T20:00:02-0700] [MainThread] [W] [toil.leader] Log from job kind-run_mutect_perchrom/instance-bm4dpfik follows:
=========>
	[2020-10-20T20:00:02-0700] [MainThread] [I] [toil.worker] ---TOIL WORKER OUTPUT LOG---
	[2020-10-20T20:00:02-0700] [MainThread] [I] [toil] Running Toil version 4.2.0-3aa1da130141039cb357efe36d7df9b9f6ae9b5b on host drkthomp-virtualbox.
	Traceback (most recent call last):
	  File "/home/drkthomp/protect3/venv/lib/python3.8/site-packages/toil/worker.py", line 368, in workerScript
	    job._runner(jobGraph=jobGraph, jobStore=jobStore, fileStore=fileStore, defer=defer)
	  File "/home/drkthomp/protect3/venv/lib/python3.8/site-packages/toil/job.py", line 1424, in _runner
	    returnValues = self._run(jobGraph, fileStore)
	  File "/home/drkthomp/protect3/venv/lib/python3.8/site-packages/toil/job.py", line 1361, in _run
	    return self.run(fileStore)
	  File "/home/drkthomp/protect3/venv/lib/python3.8/site-packages/toil/job.py", line 1565, in run
	    rValue = userFunction(*((self,) + tuple(self._args)), **self._kwargs)
	  File "/home/drkthomp/protect3/src/protect/mutation_calling/mutect.py", line 123, in run_mutect_perchrom
	    input_files['dbsnp.vcf'] = gunzip(input_files['dbsnp.vcf.gz'])
	  File "/home/drkthomp/protect3/src/protect/common.py", line 172, in gunzip
	    assert is_gzipfile(input_gzip_file)
	AssertionError
	[2020-10-20T20:00:02-0700] [MainThread] [E] [toil.worker] Exiting the worker because of a failed job on host drkthomp-virtualbox
<=========
[2020-10-20T20:00:02-0700] [MainThread] [W] [toil.jobGraph] Due to failure we are reducing the remaining retry count of job 'run_mutect_perchrom' kind-run_mutect_perchrom/instance-bm4dpfik with ID kind-run_mutect_perchrom/instance-bm4dpfik to 0
[2020-10-20T20:00:02-0700] [MainThread] [W] [toil.leader] Job 'run_mutect_perchrom' kind-run_mutect_perchrom/instance-bm4dpfik with ID kind-run_mutect_perchrom/instance-bm4dpfik is completely failed
[2020-10-20T20:00:02-0700] [MainThread] [I] [toil.worker] Redirecting logging to /home/drkthomp/workDir/node-72996abd-6cf4-462a-aea1-4d483640105b-1e53f69f16d74e0b881e7db602b2d2c3/tmpt0dk20jm/worker_log.txt
[2020-10-20T20:00:02-0700] [Thread-1  ] [E] [toil.batchSystems.singleMachine] Got exit code 1 (indicating failure) from job _toil_worker run_mutect_perchrom file:/home/drkthomp/protect3/jobStore kind-run_mutect_perchrom/instance-6clikwgf.
[2020-10-20T20:00:02-0700] [MainThread] [W] [toil.leader] Job failed with exit value 1: 'run_mutect_perchrom' kind-run_mutect_perchrom/instance-6clikwgf
[2020-10-20T20:00:02-0700] [MainThread] [W] [toil.leader] The job seems to have left a log file, indicating failure: 'run_mutect_perchrom' kind-run_mutect_perchrom/instance-6clikwgf
[2020-10-20T20:00:02-0700] [MainThread] [W] [toil.leader] Log from job kind-run_mutect_perchrom/instance-6clikwgf follows:
=========>
	[2020-10-20T20:00:02-0700] [MainThread] [I] [toil.worker] ---TOIL WORKER OUTPUT LOG---
	[2020-10-20T20:00:02-0700] [MainThread] [I] [toil] Running Toil version 4.2.0-3aa1da130141039cb357efe36d7df9b9f6ae9b5b on host drkthomp-virtualbox.
	Traceback (most recent call last):
	  File "/home/drkthomp/protect3/venv/lib/python3.8/site-packages/toil/worker.py", line 368, in workerScript
	    job._runner(jobGraph=jobGraph, jobStore=jobStore, fileStore=fileStore, defer=defer)
	  File "/home/drkthomp/protect3/venv/lib/python3.8/site-packages/toil/job.py", line 1424, in _runner
	    returnValues = self._run(jobGraph, fileStore)
	  File "/home/drkthomp/protect3/venv/lib/python3.8/site-packages/toil/job.py", line 1361, in _run
	    return self.run(fileStore)
	  File "/home/drkthomp/protect3/venv/lib/python3.8/site-packages/toil/job.py", line 1565, in run
	    rValue = userFunction(*((self,) + tuple(self._args)), **self._kwargs)
	  File "/home/drkthomp/protect3/src/protect/mutation_calling/mutect.py", line 123, in run_mutect_perchrom
	    input_files['dbsnp.vcf'] = gunzip(input_files['dbsnp.vcf.gz'])
	  File "/home/drkthomp/protect3/src/protect/common.py", line 172, in gunzip
	    assert is_gzipfile(input_gzip_file)
	AssertionError
	[2020-10-20T20:00:02-0700] [MainThread] [E] [toil.worker] Exiting the worker because of a failed job on host drkthomp-virtualbox
<=========
[2020-10-20T20:00:02-0700] [MainThread] [W] [toil.jobGraph] Due to failure we are reducing the remaining retry count of job 'run_mutect_perchrom' kind-run_mutect_perchrom/instance-6clikwgf with ID kind-run_mutect_perchrom/instance-6clikwgf to 0
[2020-10-20T20:00:02-0700] [MainThread] [W] [toil.leader] Job 'run_mutect_perchrom' kind-run_mutect_perchrom/instance-6clikwgf with ID kind-run_mutect_perchrom/instance-6clikwgf is completely failed
[2020-10-20T20:00:02-0700] [MainThread] [I] [toil.worker] Redirecting logging to /home/drkthomp/workDir/node-72996abd-6cf4-462a-aea1-4d483640105b-1e53f69f16d74e0b881e7db602b2d2c3/tmp06cwdrq5/worker_log.txt
[2020-10-20T20:00:02-0700] [Thread-1  ] [E] [toil.batchSystems.singleMachine] Got exit code 1 (indicating failure) from job _toil_worker run_mutect_perchrom file:/home/drkthomp/protect3/jobStore kind-run_mutect_perchrom/instance-daisoolw.
[2020-10-20T20:00:02-0700] [MainThread] [W] [toil.leader] Job failed with exit value 1: 'run_mutect_perchrom' kind-run_mutect_perchrom/instance-daisoolw
[2020-10-20T20:00:02-0700] [MainThread] [W] [toil.leader] The job seems to have left a log file, indicating failure: 'run_mutect_perchrom' kind-run_mutect_perchrom/instance-daisoolw
[2020-10-20T20:00:02-0700] [MainThread] [W] [toil.leader] Log from job kind-run_mutect_perchrom/instance-daisoolw follows:
=========>
	[2020-10-20T20:00:02-0700] [MainThread] [I] [toil.worker] ---TOIL WORKER OUTPUT LOG---
	[2020-10-20T20:00:02-0700] [MainThread] [I] [toil] Running Toil version 4.2.0-3aa1da130141039cb357efe36d7df9b9f6ae9b5b on host drkthomp-virtualbox.
	Traceback (most recent call last):
	  File "/home/drkthomp/protect3/venv/lib/python3.8/site-packages/toil/worker.py", line 368, in workerScript
	    job._runner(jobGraph=jobGraph, jobStore=jobStore, fileStore=fileStore, defer=defer)
	  File "/home/drkthomp/protect3/venv/lib/python3.8/site-packages/toil/job.py", line 1424, in _runner
	    returnValues = self._run(jobGraph, fileStore)
	  File "/home/drkthomp/protect3/venv/lib/python3.8/site-packages/toil/job.py", line 1361, in _run
	    return self.run(fileStore)
	  File "/home/drkthomp/protect3/venv/lib/python3.8/site-packages/toil/job.py", line 1565, in run
	    rValue = userFunction(*((self,) + tuple(self._args)), **self._kwargs)
	  File "/home/drkthomp/protect3/src/protect/mutation_calling/mutect.py", line 123, in run_mutect_perchrom
	    input_files['dbsnp.vcf'] = gunzip(input_files['dbsnp.vcf.gz'])
	  File "/home/drkthomp/protect3/src/protect/common.py", line 172, in gunzip
	    assert is_gzipfile(input_gzip_file)
	AssertionError
	[2020-10-20T20:00:02-0700] [MainThread] [E] [toil.worker] Exiting the worker because of a failed job on host drkthomp-virtualbox
<=========
[2020-10-20T20:00:02-0700] [MainThread] [W] [toil.jobGraph] Due to failure we are reducing the remaining retry count of job 'run_mutect_perchrom' kind-run_mutect_perchrom/instance-daisoolw with ID kind-run_mutect_perchrom/instance-daisoolw to 0
[2020-10-20T20:00:02-0700] [MainThread] [W] [toil.leader] Job 'run_mutect_perchrom' kind-run_mutect_perchrom/instance-daisoolw with ID kind-run_mutect_perchrom/instance-daisoolw is completely failed
[2020-10-20T20:00:02-0700] [MainThread] [I] [toil.worker] Redirecting logging to /home/drkthomp/workDir/node-72996abd-6cf4-462a-aea1-4d483640105b-1e53f69f16d74e0b881e7db602b2d2c3/tmplpdhisra/worker_log.txt
[2020-10-20T20:00:02-0700] [Thread-1  ] [E] [toil.batchSystems.singleMachine] Got exit code 1 (indicating failure) from job _toil_worker run_mutect_perchrom file:/home/drkthomp/protect3/jobStore kind-run_mutect_perchrom/instance-9hdk8gj3.
[2020-10-20T20:00:02-0700] [MainThread] [W] [toil.leader] Job failed with exit value 1: 'run_mutect_perchrom' kind-run_mutect_perchrom/instance-9hdk8gj3
[2020-10-20T20:00:02-0700] [MainThread] [W] [toil.leader] The job seems to have left a log file, indicating failure: 'run_mutect_perchrom' kind-run_mutect_perchrom/instance-9hdk8gj3
[2020-10-20T20:00:02-0700] [MainThread] [W] [toil.leader] Log from job kind-run_mutect_perchrom/instance-9hdk8gj3 follows:
=========>
	[2020-10-20T20:00:02-0700] [MainThread] [I] [toil.worker] ---TOIL WORKER OUTPUT LOG---
	[2020-10-20T20:00:02-0700] [MainThread] [I] [toil] Running Toil version 4.2.0-3aa1da130141039cb357efe36d7df9b9f6ae9b5b on host drkthomp-virtualbox.
	Traceback (most recent call last):
	  File "/home/drkthomp/protect3/venv/lib/python3.8/site-packages/toil/worker.py", line 368, in workerScript
	    job._runner(jobGraph=jobGraph, jobStore=jobStore, fileStore=fileStore, defer=defer)
	  File "/home/drkthomp/protect3/venv/lib/python3.8/site-packages/toil/job.py", line 1424, in _runner
	    returnValues = self._run(jobGraph, fileStore)
	  File "/home/drkthomp/protect3/venv/lib/python3.8/site-packages/toil/job.py", line 1361, in _run
	    return self.run(fileStore)
	  File "/home/drkthomp/protect3/venv/lib/python3.8/site-packages/toil/job.py", line 1565, in run
	    rValue = userFunction(*((self,) + tuple(self._args)), **self._kwargs)
	  File "/home/drkthomp/protect3/src/protect/mutation_calling/mutect.py", line 123, in run_mutect_perchrom
	    input_files['dbsnp.vcf'] = gunzip(input_files['dbsnp.vcf.gz'])
	  File "/home/drkthomp/protect3/src/protect/common.py", line 172, in gunzip
	    assert is_gzipfile(input_gzip_file)
	AssertionError
	[2020-10-20T20:00:02-0700] [MainThread] [E] [toil.worker] Exiting the worker because of a failed job on host drkthomp-virtualbox
<=========
[2020-10-20T20:00:02-0700] [MainThread] [W] [toil.jobGraph] Due to failure we are reducing the remaining retry count of job 'run_mutect_perchrom' kind-run_mutect_perchrom/instance-9hdk8gj3 with ID kind-run_mutect_perchrom/instance-9hdk8gj3 to 0
[2020-10-20T20:00:02-0700] [MainThread] [W] [toil.leader] Job 'run_mutect_perchrom' kind-run_mutect_perchrom/instance-9hdk8gj3 with ID kind-run_mutect_perchrom/instance-9hdk8gj3 is completely failed
[2020-10-20T20:00:02-0700] [MainThread] [I] [toil.worker] Redirecting logging to /home/drkthomp/workDir/node-72996abd-6cf4-462a-aea1-4d483640105b-1e53f69f16d74e0b881e7db602b2d2c3/tmp4c5y_3ez/worker_log.txt
[2020-10-20T20:00:02-0700] [Thread-1  ] [E] [toil.batchSystems.singleMachine] Got exit code 1 (indicating failure) from job _toil_worker run_mutect_perchrom file:/home/drkthomp/protect3/jobStore kind-run_mutect_perchrom/instance-3a6rn9f9.
[2020-10-20T20:00:02-0700] [MainThread] [W] [toil.leader] Job failed with exit value 1: 'run_mutect_perchrom' kind-run_mutect_perchrom/instance-3a6rn9f9
[2020-10-20T20:00:02-0700] [MainThread] [W] [toil.leader] The job seems to have left a log file, indicating failure: 'run_mutect_perchrom' kind-run_mutect_perchrom/instance-3a6rn9f9
[2020-10-20T20:00:02-0700] [MainThread] [W] [toil.leader] Log from job kind-run_mutect_perchrom/instance-3a6rn9f9 follows:
=========>
	[2020-10-20T20:00:02-0700] [MainThread] [I] [toil.worker] ---TOIL WORKER OUTPUT LOG---
	[2020-10-20T20:00:02-0700] [MainThread] [I] [toil] Running Toil version 4.2.0-3aa1da130141039cb357efe36d7df9b9f6ae9b5b on host drkthomp-virtualbox.
	Traceback (most recent call last):
	  File "/home/drkthomp/protect3/venv/lib/python3.8/site-packages/toil/worker.py", line 368, in workerScript
	    job._runner(jobGraph=jobGraph, jobStore=jobStore, fileStore=fileStore, defer=defer)
	  File "/home/drkthomp/protect3/venv/lib/python3.8/site-packages/toil/job.py", line 1424, in _runner
	    returnValues = self._run(jobGraph, fileStore)
	  File "/home/drkthomp/protect3/venv/lib/python3.8/site-packages/toil/job.py", line 1361, in _run
	    return self.run(fileStore)
	  File "/home/drkthomp/protect3/venv/lib/python3.8/site-packages/toil/job.py", line 1565, in run
	    rValue = userFunction(*((self,) + tuple(self._args)), **self._kwargs)
	  File "/home/drkthomp/protect3/src/protect/mutation_calling/mutect.py", line 123, in run_mutect_perchrom
	    input_files['dbsnp.vcf'] = gunzip(input_files['dbsnp.vcf.gz'])
	  File "/home/drkthomp/protect3/src/protect/common.py", line 172, in gunzip
	    assert is_gzipfile(input_gzip_file)
	AssertionError
	[2020-10-20T20:00:02-0700] [MainThread] [E] [toil.worker] Exiting the worker because of a failed job on host drkthomp-virtualbox
<=========
[2020-10-20T20:00:02-0700] [MainThread] [W] [toil.jobGraph] Due to failure we are reducing the remaining retry count of job 'run_mutect_perchrom' kind-run_mutect_perchrom/instance-3a6rn9f9 with ID kind-run_mutect_perchrom/instance-3a6rn9f9 to 0
[2020-10-20T20:00:02-0700] [MainThread] [W] [toil.leader] Job 'run_mutect_perchrom' kind-run_mutect_perchrom/instance-3a6rn9f9 with ID kind-run_mutect_perchrom/instance-3a6rn9f9 is completely failed
[2020-10-20T20:00:02-0700] [MainThread] [I] [toil.worker] Redirecting logging to /home/drkthomp/workDir/node-72996abd-6cf4-462a-aea1-4d483640105b-1e53f69f16d74e0b881e7db602b2d2c3/tmplzzq842k/worker_log.txt
[2020-10-20T20:00:03-0700] [Thread-1  ] [E] [toil.batchSystems.singleMachine] Got exit code 1 (indicating failure) from job _toil_worker run_mutect_perchrom file:/home/drkthomp/protect3/jobStore kind-run_mutect_perchrom/instance-92gnpm9m.
[2020-10-20T20:00:03-0700] [MainThread] [W] [toil.leader] Job failed with exit value 1: 'run_mutect_perchrom' kind-run_mutect_perchrom/instance-92gnpm9m
[2020-10-20T20:00:03-0700] [MainThread] [W] [toil.leader] The job seems to have left a log file, indicating failure: 'run_mutect_perchrom' kind-run_mutect_perchrom/instance-92gnpm9m
[2020-10-20T20:00:03-0700] [MainThread] [W] [toil.leader] Log from job kind-run_mutect_perchrom/instance-92gnpm9m follows:
=========>
	[2020-10-20T20:00:02-0700] [MainThread] [I] [toil.worker] ---TOIL WORKER OUTPUT LOG---
	[2020-10-20T20:00:02-0700] [MainThread] [I] [toil] Running Toil version 4.2.0-3aa1da130141039cb357efe36d7df9b9f6ae9b5b on host drkthomp-virtualbox.
	Traceback (most recent call last):
	  File "/home/drkthomp/protect3/venv/lib/python3.8/site-packages/toil/worker.py", line 368, in workerScript
	    job._runner(jobGraph=jobGraph, jobStore=jobStore, fileStore=fileStore, defer=defer)
	  File "/home/drkthomp/protect3/venv/lib/python3.8/site-packages/toil/job.py", line 1424, in _runner
	    returnValues = self._run(jobGraph, fileStore)
	  File "/home/drkthomp/protect3/venv/lib/python3.8/site-packages/toil/job.py", line 1361, in _run
	    return self.run(fileStore)
	  File "/home/drkthomp/protect3/venv/lib/python3.8/site-packages/toil/job.py", line 1565, in run
	    rValue = userFunction(*((self,) + tuple(self._args)), **self._kwargs)
	  File "/home/drkthomp/protect3/src/protect/mutation_calling/mutect.py", line 123, in run_mutect_perchrom
	    input_files['dbsnp.vcf'] = gunzip(input_files['dbsnp.vcf.gz'])
	  File "/home/drkthomp/protect3/src/protect/common.py", line 172, in gunzip
	    assert is_gzipfile(input_gzip_file)
	AssertionError
	[2020-10-20T20:00:02-0700] [MainThread] [E] [toil.worker] Exiting the worker because of a failed job on host drkthomp-virtualbox
<=========
[2020-10-20T20:00:03-0700] [MainThread] [W] [toil.jobGraph] Due to failure we are reducing the remaining retry count of job 'run_mutect_perchrom' kind-run_mutect_perchrom/instance-92gnpm9m with ID kind-run_mutect_perchrom/instance-92gnpm9m to 0
[2020-10-20T20:00:03-0700] [MainThread] [W] [toil.leader] Job 'run_mutect_perchrom' kind-run_mutect_perchrom/instance-92gnpm9m with ID kind-run_mutect_perchrom/instance-92gnpm9m is completely failed
[2020-10-20T20:00:03-0700] [MainThread] [I] [toil.worker] Redirecting logging to /home/drkthomp/workDir/node-72996abd-6cf4-462a-aea1-4d483640105b-1e53f69f16d74e0b881e7db602b2d2c3/tmp3gn2clpx/worker_log.txt
[2020-10-20T20:00:03-0700] [Thread-1  ] [E] [toil.batchSystems.singleMachine] Got exit code 1 (indicating failure) from job _toil_worker run_mutect_perchrom file:/home/drkthomp/protect3/jobStore kind-run_mutect_perchrom/instance-wflniclq.
[2020-10-20T20:00:03-0700] [MainThread] [W] [toil.leader] Job failed with exit value 1: 'run_mutect_perchrom' kind-run_mutect_perchrom/instance-wflniclq
[2020-10-20T20:00:03-0700] [MainThread] [W] [toil.leader] The job seems to have left a log file, indicating failure: 'run_mutect_perchrom' kind-run_mutect_perchrom/instance-wflniclq
[2020-10-20T20:00:03-0700] [MainThread] [W] [toil.leader] Log from job kind-run_mutect_perchrom/instance-wflniclq follows:
=========>
	[2020-10-20T20:00:03-0700] [MainThread] [I] [toil.worker] ---TOIL WORKER OUTPUT LOG---
	[2020-10-20T20:00:03-0700] [MainThread] [I] [toil] Running Toil version 4.2.0-3aa1da130141039cb357efe36d7df9b9f6ae9b5b on host drkthomp-virtualbox.
	Traceback (most recent call last):
	  File "/home/drkthomp/protect3/venv/lib/python3.8/site-packages/toil/worker.py", line 368, in workerScript
	    job._runner(jobGraph=jobGraph, jobStore=jobStore, fileStore=fileStore, defer=defer)
	  File "/home/drkthomp/protect3/venv/lib/python3.8/site-packages/toil/job.py", line 1424, in _runner
	    returnValues = self._run(jobGraph, fileStore)
	  File "/home/drkthomp/protect3/venv/lib/python3.8/site-packages/toil/job.py", line 1361, in _run
	    return self.run(fileStore)
	  File "/home/drkthomp/protect3/venv/lib/python3.8/site-packages/toil/job.py", line 1565, in run
	    rValue = userFunction(*((self,) + tuple(self._args)), **self._kwargs)
	  File "/home/drkthomp/protect3/src/protect/mutation_calling/mutect.py", line 123, in run_mutect_perchrom
	    input_files['dbsnp.vcf'] = gunzip(input_files['dbsnp.vcf.gz'])
	  File "/home/drkthomp/protect3/src/protect/common.py", line 172, in gunzip
	    assert is_gzipfile(input_gzip_file)
	AssertionError
	[2020-10-20T20:00:03-0700] [MainThread] [E] [toil.worker] Exiting the worker because of a failed job on host drkthomp-virtualbox
<=========
[2020-10-20T20:00:03-0700] [MainThread] [W] [toil.jobGraph] Due to failure we are reducing the remaining retry count of job 'run_mutect_perchrom' kind-run_mutect_perchrom/instance-wflniclq with ID kind-run_mutect_perchrom/instance-wflniclq to 0
[2020-10-20T20:00:03-0700] [MainThread] [W] [toil.leader] Job 'run_mutect_perchrom' kind-run_mutect_perchrom/instance-wflniclq with ID kind-run_mutect_perchrom/instance-wflniclq is completely failed
[2020-10-20T20:00:03-0700] [MainThread] [I] [toil.worker] Redirecting logging to /home/drkthomp/workDir/node-72996abd-6cf4-462a-aea1-4d483640105b-1e53f69f16d74e0b881e7db602b2d2c3/tmp4r82gt2j/worker_log.txt
[2020-10-20T20:00:03-0700] [Thread-1  ] [E] [toil.batchSystems.singleMachine] Got exit code 1 (indicating failure) from job _toil_worker run_mutect_perchrom file:/home/drkthomp/protect3/jobStore kind-run_mutect_perchrom/instance-yrvj0gxx.
[2020-10-20T20:00:03-0700] [MainThread] [W] [toil.leader] Job failed with exit value 1: 'run_mutect_perchrom' kind-run_mutect_perchrom/instance-yrvj0gxx
[2020-10-20T20:00:03-0700] [MainThread] [W] [toil.leader] The job seems to have left a log file, indicating failure: 'run_mutect_perchrom' kind-run_mutect_perchrom/instance-yrvj0gxx
[2020-10-20T20:00:03-0700] [MainThread] [W] [toil.leader] Log from job kind-run_mutect_perchrom/instance-yrvj0gxx follows:
=========>
	[2020-10-20T20:00:03-0700] [MainThread] [I] [toil.worker] ---TOIL WORKER OUTPUT LOG---
	[2020-10-20T20:00:03-0700] [MainThread] [I] [toil] Running Toil version 4.2.0-3aa1da130141039cb357efe36d7df9b9f6ae9b5b on host drkthomp-virtualbox.
	Traceback (most recent call last):
	  File "/home/drkthomp/protect3/venv/lib/python3.8/site-packages/toil/worker.py", line 368, in workerScript
	    job._runner(jobGraph=jobGraph, jobStore=jobStore, fileStore=fileStore, defer=defer)
	  File "/home/drkthomp/protect3/venv/lib/python3.8/site-packages/toil/job.py", line 1424, in _runner
	    returnValues = self._run(jobGraph, fileStore)
	  File "/home/drkthomp/protect3/venv/lib/python3.8/site-packages/toil/job.py", line 1361, in _run
	    return self.run(fileStore)
	  File "/home/drkthomp/protect3/venv/lib/python3.8/site-packages/toil/job.py", line 1565, in run
	    rValue = userFunction(*((self,) + tuple(self._args)), **self._kwargs)
	  File "/home/drkthomp/protect3/src/protect/mutation_calling/mutect.py", line 123, in run_mutect_perchrom
	    input_files['dbsnp.vcf'] = gunzip(input_files['dbsnp.vcf.gz'])
	  File "/home/drkthomp/protect3/src/protect/common.py", line 172, in gunzip
	    assert is_gzipfile(input_gzip_file)
	AssertionError
	[2020-10-20T20:00:03-0700] [MainThread] [E] [toil.worker] Exiting the worker because of a failed job on host drkthomp-virtualbox
<=========
[2020-10-20T20:00:03-0700] [MainThread] [W] [toil.jobGraph] Due to failure we are reducing the remaining retry count of job 'run_mutect_perchrom' kind-run_mutect_perchrom/instance-yrvj0gxx with ID kind-run_mutect_perchrom/instance-yrvj0gxx to 1
[2020-10-20T20:00:03-0700] [MainThread] [I] [toil.leader] Issued job 'run_mutect_perchrom' kind-run_mutect_perchrom/instance-yrvj0gxx with job batch system ID: 54 and cores: 1, disk: 23.0 G, and memory: 6.0 G
[2020-10-20T20:00:03-0700] [MainThread] [I] [toil.worker] Redirecting logging to /home/drkthomp/workDir/node-72996abd-6cf4-462a-aea1-4d483640105b-1e53f69f16d74e0b881e7db602b2d2c3/tmpa4inzpl6/worker_log.txt
[2020-10-20T20:00:03-0700] [Thread-1  ] [E] [toil.batchSystems.singleMachine] Got exit code 1 (indicating failure) from job _toil_worker run_mutect_perchrom file:/home/drkthomp/protect3/jobStore kind-run_mutect_perchrom/instance-tjkov9ea.
[2020-10-20T20:00:03-0700] [MainThread] [W] [toil.leader] Job failed with exit value 1: 'run_mutect_perchrom' kind-run_mutect_perchrom/instance-tjkov9ea
[2020-10-20T20:00:03-0700] [MainThread] [W] [toil.leader] The job seems to have left a log file, indicating failure: 'run_mutect_perchrom' kind-run_mutect_perchrom/instance-tjkov9ea
[2020-10-20T20:00:03-0700] [MainThread] [W] [toil.leader] Log from job kind-run_mutect_perchrom/instance-tjkov9ea follows:
=========>
	[2020-10-20T20:00:03-0700] [MainThread] [I] [toil.worker] ---TOIL WORKER OUTPUT LOG---
	[2020-10-20T20:00:03-0700] [MainThread] [I] [toil] Running Toil version 4.2.0-3aa1da130141039cb357efe36d7df9b9f6ae9b5b on host drkthomp-virtualbox.
	Traceback (most recent call last):
	  File "/home/drkthomp/protect3/venv/lib/python3.8/site-packages/toil/worker.py", line 368, in workerScript
	    job._runner(jobGraph=jobGraph, jobStore=jobStore, fileStore=fileStore, defer=defer)
	  File "/home/drkthomp/protect3/venv/lib/python3.8/site-packages/toil/job.py", line 1424, in _runner
	    returnValues = self._run(jobGraph, fileStore)
	  File "/home/drkthomp/protect3/venv/lib/python3.8/site-packages/toil/job.py", line 1361, in _run
	    return self.run(fileStore)
	  File "/home/drkthomp/protect3/venv/lib/python3.8/site-packages/toil/job.py", line 1565, in run
	    rValue = userFunction(*((self,) + tuple(self._args)), **self._kwargs)
	  File "/home/drkthomp/protect3/src/protect/mutation_calling/mutect.py", line 123, in run_mutect_perchrom
	    input_files['dbsnp.vcf'] = gunzip(input_files['dbsnp.vcf.gz'])
	  File "/home/drkthomp/protect3/src/protect/common.py", line 172, in gunzip
	    assert is_gzipfile(input_gzip_file)
	AssertionError
	[2020-10-20T20:00:03-0700] [MainThread] [E] [toil.worker] Exiting the worker because of a failed job on host drkthomp-virtualbox
<=========
[2020-10-20T20:00:03-0700] [MainThread] [W] [toil.jobGraph] Due to failure we are reducing the remaining retry count of job 'run_mutect_perchrom' kind-run_mutect_perchrom/instance-tjkov9ea with ID kind-run_mutect_perchrom/instance-tjkov9ea to 0
[2020-10-20T20:00:03-0700] [MainThread] [W] [toil.leader] Job 'run_mutect_perchrom' kind-run_mutect_perchrom/instance-tjkov9ea with ID kind-run_mutect_perchrom/instance-tjkov9ea is completely failed
[2020-10-20T20:00:03-0700] [MainThread] [I] [toil.worker] Redirecting logging to /home/drkthomp/workDir/node-72996abd-6cf4-462a-aea1-4d483640105b-1e53f69f16d74e0b881e7db602b2d2c3/tmpi5gyj9pp/worker_log.txt
[2020-10-20T20:00:03-0700] [Thread-1  ] [E] [toil.batchSystems.singleMachine] Got exit code 1 (indicating failure) from job _toil_worker run_mutect_perchrom file:/home/drkthomp/protect3/jobStore kind-run_mutect_perchrom/instance-40bfs1db.
[2020-10-20T20:00:03-0700] [MainThread] [W] [toil.leader] Job failed with exit value 1: 'run_mutect_perchrom' kind-run_mutect_perchrom/instance-40bfs1db
[2020-10-20T20:00:03-0700] [MainThread] [W] [toil.leader] The job seems to have left a log file, indicating failure: 'run_mutect_perchrom' kind-run_mutect_perchrom/instance-40bfs1db
[2020-10-20T20:00:03-0700] [MainThread] [W] [toil.leader] Log from job kind-run_mutect_perchrom/instance-40bfs1db follows:
=========>
	[2020-10-20T20:00:03-0700] [MainThread] [I] [toil.worker] ---TOIL WORKER OUTPUT LOG---
	[2020-10-20T20:00:03-0700] [MainThread] [I] [toil] Running Toil version 4.2.0-3aa1da130141039cb357efe36d7df9b9f6ae9b5b on host drkthomp-virtualbox.
	Traceback (most recent call last):
	  File "/home/drkthomp/protect3/venv/lib/python3.8/site-packages/toil/worker.py", line 368, in workerScript
	    job._runner(jobGraph=jobGraph, jobStore=jobStore, fileStore=fileStore, defer=defer)
	  File "/home/drkthomp/protect3/venv/lib/python3.8/site-packages/toil/job.py", line 1424, in _runner
	    returnValues = self._run(jobGraph, fileStore)
	  File "/home/drkthomp/protect3/venv/lib/python3.8/site-packages/toil/job.py", line 1361, in _run
	    return self.run(fileStore)
	  File "/home/drkthomp/protect3/venv/lib/python3.8/site-packages/toil/job.py", line 1565, in run
	    rValue = userFunction(*((self,) + tuple(self._args)), **self._kwargs)
	  File "/home/drkthomp/protect3/src/protect/mutation_calling/mutect.py", line 123, in run_mutect_perchrom
	    input_files['dbsnp.vcf'] = gunzip(input_files['dbsnp.vcf.gz'])
	  File "/home/drkthomp/protect3/src/protect/common.py", line 172, in gunzip
	    assert is_gzipfile(input_gzip_file)
	AssertionError
	[2020-10-20T20:00:03-0700] [MainThread] [E] [toil.worker] Exiting the worker because of a failed job on host drkthomp-virtualbox
<=========
[2020-10-20T20:00:03-0700] [MainThread] [W] [toil.jobGraph] Due to failure we are reducing the remaining retry count of job 'run_mutect_perchrom' kind-run_mutect_perchrom/instance-40bfs1db with ID kind-run_mutect_perchrom/instance-40bfs1db to 0
[2020-10-20T20:00:03-0700] [MainThread] [W] [toil.leader] Job 'run_mutect_perchrom' kind-run_mutect_perchrom/instance-40bfs1db with ID kind-run_mutect_perchrom/instance-40bfs1db is completely failed
[2020-10-20T20:00:03-0700] [MainThread] [I] [toil.worker] Redirecting logging to /home/drkthomp/workDir/node-72996abd-6cf4-462a-aea1-4d483640105b-1e53f69f16d74e0b881e7db602b2d2c3/tmpmqx7un80/worker_log.txt
[2020-10-20T20:00:03-0700] [Thread-1  ] [E] [toil.batchSystems.singleMachine] Got exit code 1 (indicating failure) from job _toil_worker run_mutect_perchrom file:/home/drkthomp/protect3/jobStore kind-run_mutect_perchrom/instance-c65720sq.
[2020-10-20T20:00:03-0700] [MainThread] [W] [toil.leader] Job failed with exit value 1: 'run_mutect_perchrom' kind-run_mutect_perchrom/instance-c65720sq
[2020-10-20T20:00:03-0700] [MainThread] [W] [toil.leader] The job seems to have left a log file, indicating failure: 'run_mutect_perchrom' kind-run_mutect_perchrom/instance-c65720sq
[2020-10-20T20:00:03-0700] [MainThread] [W] [toil.leader] Log from job kind-run_mutect_perchrom/instance-c65720sq follows:
=========>
	[2020-10-20T20:00:03-0700] [MainThread] [I] [toil.worker] ---TOIL WORKER OUTPUT LOG---
	[2020-10-20T20:00:03-0700] [MainThread] [I] [toil] Running Toil version 4.2.0-3aa1da130141039cb357efe36d7df9b9f6ae9b5b on host drkthomp-virtualbox.
	Traceback (most recent call last):
	  File "/home/drkthomp/protect3/venv/lib/python3.8/site-packages/toil/worker.py", line 368, in workerScript
	    job._runner(jobGraph=jobGraph, jobStore=jobStore, fileStore=fileStore, defer=defer)
	  File "/home/drkthomp/protect3/venv/lib/python3.8/site-packages/toil/job.py", line 1424, in _runner
	    returnValues = self._run(jobGraph, fileStore)
	  File "/home/drkthomp/protect3/venv/lib/python3.8/site-packages/toil/job.py", line 1361, in _run
	    return self.run(fileStore)
	  File "/home/drkthomp/protect3/venv/lib/python3.8/site-packages/toil/job.py", line 1565, in run
	    rValue = userFunction(*((self,) + tuple(self._args)), **self._kwargs)
	  File "/home/drkthomp/protect3/src/protect/mutation_calling/mutect.py", line 123, in run_mutect_perchrom
	    input_files['dbsnp.vcf'] = gunzip(input_files['dbsnp.vcf.gz'])
	  File "/home/drkthomp/protect3/src/protect/common.py", line 172, in gunzip
	    assert is_gzipfile(input_gzip_file)
	AssertionError
	[2020-10-20T20:00:03-0700] [MainThread] [E] [toil.worker] Exiting the worker because of a failed job on host drkthomp-virtualbox
<=========
[2020-10-20T20:00:03-0700] [MainThread] [W] [toil.jobGraph] Due to failure we are reducing the remaining retry count of job 'run_mutect_perchrom' kind-run_mutect_perchrom/instance-c65720sq with ID kind-run_mutect_perchrom/instance-c65720sq to 0
[2020-10-20T20:00:03-0700] [MainThread] [W] [toil.leader] Job 'run_mutect_perchrom' kind-run_mutect_perchrom/instance-c65720sq with ID kind-run_mutect_perchrom/instance-c65720sq is completely failed
[2020-10-20T20:00:03-0700] [MainThread] [I] [toil.worker] Redirecting logging to /home/drkthomp/workDir/node-72996abd-6cf4-462a-aea1-4d483640105b-1e53f69f16d74e0b881e7db602b2d2c3/tmp6ngmji95/worker_log.txt
[2020-10-20T20:00:04-0700] [Thread-1  ] [E] [toil.batchSystems.singleMachine] Got exit code 1 (indicating failure) from job _toil_worker run_mutect_perchrom file:/home/drkthomp/protect3/jobStore kind-run_mutect_perchrom/instance-fu63ea_u.
[2020-10-20T20:00:04-0700] [MainThread] [W] [toil.leader] Job failed with exit value 1: 'run_mutect_perchrom' kind-run_mutect_perchrom/instance-fu63ea_u
[2020-10-20T20:00:04-0700] [MainThread] [W] [toil.leader] The job seems to have left a log file, indicating failure: 'run_mutect_perchrom' kind-run_mutect_perchrom/instance-fu63ea_u
[2020-10-20T20:00:04-0700] [MainThread] [W] [toil.leader] Log from job kind-run_mutect_perchrom/instance-fu63ea_u follows:
=========>
	[2020-10-20T20:00:03-0700] [MainThread] [I] [toil.worker] ---TOIL WORKER OUTPUT LOG---
	[2020-10-20T20:00:03-0700] [MainThread] [I] [toil] Running Toil version 4.2.0-3aa1da130141039cb357efe36d7df9b9f6ae9b5b on host drkthomp-virtualbox.
	Traceback (most recent call last):
	  File "/home/drkthomp/protect3/venv/lib/python3.8/site-packages/toil/worker.py", line 368, in workerScript
	    job._runner(jobGraph=jobGraph, jobStore=jobStore, fileStore=fileStore, defer=defer)
	  File "/home/drkthomp/protect3/venv/lib/python3.8/site-packages/toil/job.py", line 1424, in _runner
	    returnValues = self._run(jobGraph, fileStore)
	  File "/home/drkthomp/protect3/venv/lib/python3.8/site-packages/toil/job.py", line 1361, in _run
	    return self.run(fileStore)
	  File "/home/drkthomp/protect3/venv/lib/python3.8/site-packages/toil/job.py", line 1565, in run
	    rValue = userFunction(*((self,) + tuple(self._args)), **self._kwargs)
	  File "/home/drkthomp/protect3/src/protect/mutation_calling/mutect.py", line 123, in run_mutect_perchrom
	    input_files['dbsnp.vcf'] = gunzip(input_files['dbsnp.vcf.gz'])
	  File "/home/drkthomp/protect3/src/protect/common.py", line 172, in gunzip
	    assert is_gzipfile(input_gzip_file)
	AssertionError
	[2020-10-20T20:00:04-0700] [MainThread] [E] [toil.worker] Exiting the worker because of a failed job on host drkthomp-virtualbox
<=========
[2020-10-20T20:00:04-0700] [MainThread] [W] [toil.jobGraph] Due to failure we are reducing the remaining retry count of job 'run_mutect_perchrom' kind-run_mutect_perchrom/instance-fu63ea_u with ID kind-run_mutect_perchrom/instance-fu63ea_u to 0
[2020-10-20T20:00:04-0700] [MainThread] [W] [toil.leader] Job 'run_mutect_perchrom' kind-run_mutect_perchrom/instance-fu63ea_u with ID kind-run_mutect_perchrom/instance-fu63ea_u is completely failed
[2020-10-20T20:00:04-0700] [MainThread] [I] [toil.worker] Redirecting logging to /home/drkthomp/workDir/node-72996abd-6cf4-462a-aea1-4d483640105b-1e53f69f16d74e0b881e7db602b2d2c3/tmp3a4po_6d/worker_log.txt
[2020-10-20T20:00:04-0700] [Thread-1  ] [E] [toil.batchSystems.singleMachine] Got exit code 1 (indicating failure) from job _toil_worker run_mutect_perchrom file:/home/drkthomp/protect3/jobStore kind-run_mutect_perchrom/instance-cije5tr0.
[2020-10-20T20:00:04-0700] [MainThread] [W] [toil.leader] Job failed with exit value 1: 'run_mutect_perchrom' kind-run_mutect_perchrom/instance-cije5tr0
[2020-10-20T20:00:04-0700] [MainThread] [W] [toil.leader] The job seems to have left a log file, indicating failure: 'run_mutect_perchrom' kind-run_mutect_perchrom/instance-cije5tr0
[2020-10-20T20:00:04-0700] [MainThread] [W] [toil.leader] Log from job kind-run_mutect_perchrom/instance-cije5tr0 follows:
=========>
	[2020-10-20T20:00:04-0700] [MainThread] [I] [toil.worker] ---TOIL WORKER OUTPUT LOG---
	[2020-10-20T20:00:04-0700] [MainThread] [I] [toil] Running Toil version 4.2.0-3aa1da130141039cb357efe36d7df9b9f6ae9b5b on host drkthomp-virtualbox.
	Traceback (most recent call last):
	  File "/home/drkthomp/protect3/venv/lib/python3.8/site-packages/toil/worker.py", line 368, in workerScript
	    job._runner(jobGraph=jobGraph, jobStore=jobStore, fileStore=fileStore, defer=defer)
	  File "/home/drkthomp/protect3/venv/lib/python3.8/site-packages/toil/job.py", line 1424, in _runner
	    returnValues = self._run(jobGraph, fileStore)
	  File "/home/drkthomp/protect3/venv/lib/python3.8/site-packages/toil/job.py", line 1361, in _run
	    return self.run(fileStore)
	  File "/home/drkthomp/protect3/venv/lib/python3.8/site-packages/toil/job.py", line 1565, in run
	    rValue = userFunction(*((self,) + tuple(self._args)), **self._kwargs)
	  File "/home/drkthomp/protect3/src/protect/mutation_calling/mutect.py", line 123, in run_mutect_perchrom
	    input_files['dbsnp.vcf'] = gunzip(input_files['dbsnp.vcf.gz'])
	  File "/home/drkthomp/protect3/src/protect/common.py", line 172, in gunzip
	    assert is_gzipfile(input_gzip_file)
	AssertionError
	[2020-10-20T20:00:04-0700] [MainThread] [E] [toil.worker] Exiting the worker because of a failed job on host drkthomp-virtualbox
<=========
[2020-10-20T20:00:04-0700] [MainThread] [W] [toil.jobGraph] Due to failure we are reducing the remaining retry count of job 'run_mutect_perchrom' kind-run_mutect_perchrom/instance-cije5tr0 with ID kind-run_mutect_perchrom/instance-cije5tr0 to 0
[2020-10-20T20:00:04-0700] [MainThread] [W] [toil.leader] Job 'run_mutect_perchrom' kind-run_mutect_perchrom/instance-cije5tr0 with ID kind-run_mutect_perchrom/instance-cije5tr0 is completely failed
[2020-10-20T20:00:04-0700] [MainThread] [I] [toil.worker] Redirecting logging to /home/drkthomp/workDir/node-72996abd-6cf4-462a-aea1-4d483640105b-1e53f69f16d74e0b881e7db602b2d2c3/tmpvfn2mc8k/worker_log.txt
[2020-10-20T20:00:04-0700] [Thread-1  ] [E] [toil.batchSystems.singleMachine] Got exit code 1 (indicating failure) from job _toil_worker run_mutect_perchrom file:/home/drkthomp/protect3/jobStore kind-run_mutect_perchrom/instance-yrvj0gxx.
[2020-10-20T20:00:04-0700] [MainThread] [W] [toil.leader] Job failed with exit value 1: 'run_mutect_perchrom' kind-run_mutect_perchrom/instance-yrvj0gxx
[2020-10-20T20:00:04-0700] [MainThread] [W] [toil.leader] The job seems to have left a log file, indicating failure: 'run_mutect_perchrom' kind-run_mutect_perchrom/instance-yrvj0gxx
[2020-10-20T20:00:04-0700] [MainThread] [W] [toil.leader] Log from job kind-run_mutect_perchrom/instance-yrvj0gxx follows:
=========>
	[2020-10-20T20:00:04-0700] [MainThread] [I] [toil.worker] ---TOIL WORKER OUTPUT LOG---
	[2020-10-20T20:00:04-0700] [MainThread] [I] [toil] Running Toil version 4.2.0-3aa1da130141039cb357efe36d7df9b9f6ae9b5b on host drkthomp-virtualbox.
	Traceback (most recent call last):
	  File "/home/drkthomp/protect3/venv/lib/python3.8/site-packages/toil/worker.py", line 368, in workerScript
	    job._runner(jobGraph=jobGraph, jobStore=jobStore, fileStore=fileStore, defer=defer)
	  File "/home/drkthomp/protect3/venv/lib/python3.8/site-packages/toil/job.py", line 1424, in _runner
	    returnValues = self._run(jobGraph, fileStore)
	  File "/home/drkthomp/protect3/venv/lib/python3.8/site-packages/toil/job.py", line 1361, in _run
	    return self.run(fileStore)
	  File "/home/drkthomp/protect3/venv/lib/python3.8/site-packages/toil/job.py", line 1565, in run
	    rValue = userFunction(*((self,) + tuple(self._args)), **self._kwargs)
	  File "/home/drkthomp/protect3/src/protect/mutation_calling/mutect.py", line 123, in run_mutect_perchrom
	    input_files['dbsnp.vcf'] = gunzip(input_files['dbsnp.vcf.gz'])
	  File "/home/drkthomp/protect3/src/protect/common.py", line 172, in gunzip
	    assert is_gzipfile(input_gzip_file)
	AssertionError
	[2020-10-20T20:00:04-0700] [MainThread] [E] [toil.worker] Exiting the worker because of a failed job on host drkthomp-virtualbox
<=========
[2020-10-20T20:00:04-0700] [MainThread] [W] [toil.jobGraph] Due to failure we are reducing the remaining retry count of job 'run_mutect_perchrom' kind-run_mutect_perchrom/instance-yrvj0gxx with ID kind-run_mutect_perchrom/instance-yrvj0gxx to 0
[2020-10-20T20:00:04-0700] [MainThread] [W] [toil.leader] Job 'run_mutect_perchrom' kind-run_mutect_perchrom/instance-yrvj0gxx with ID kind-run_mutect_perchrom/instance-yrvj0gxx is completely failed
[2020-10-20T20:00:04-0700] [MainThread] [I] [toil.worker] Redirecting logging to /home/drkthomp/workDir/node-72996abd-6cf4-462a-aea1-4d483640105b-1e53f69f16d74e0b881e7db602b2d2c3/tmp1vgmc0qo/worker_log.txt
