[2020-10-19T14:57:49-0700] [MainThread] [C] [toil.jobStores.abstractJobStore] Repairing job: kind-run_phlat/instance-foexdy0m
[2020-10-19T14:57:49-0700] [MainThread] [I] [toil] Running Toil version 4.2.0-3aa1da130141039cb357efe36d7df9b9f6ae9b5b on host drkthomp-virtualbox.
[2020-10-19T14:57:49-0700] [MainThread] [I] [toil.leader] Issued job 'run_phlat' kind-run_phlat/instance-foexdy0m with job batch system ID: 0 and cores: 4, disk: 7.8 G, and memory: 2.0 G
[2020-10-19T14:57:49-0700] [MainThread] [I] [toil.leader] Issued job 'run_bwa' kind-run_bwa/instance-n45358fz with job batch system ID: 1 and cores: 4, disk: 9.6 G, and memory: 12.0 G
[2020-10-19T14:57:49-0700] [MainThread] [I] [toil.leader] Issued job 'run_phlat' kind-run_phlat/instance-xpy0rfpy with job batch system ID: 2 and cores: 4, disk: 7.7 G, and memory: 2.0 G
[2020-10-19T14:57:49-0700] [MainThread] [I] [toil.leader] Issued job 'run_bwa' kind-run_bwa/instance-75n4628j with job batch system ID: 3 and cores: 4, disk: 9.4 G, and memory: 12.0 G
[2020-10-19T14:57:49-0700] [MainThread] [I] [toil.leader] Issued job 'run_phlat' kind-run_phlat/instance-2oiyd0li with job batch system ID: 4 and cores: 4, disk: 7.7 G, and memory: 2.0 G
[2020-10-19T14:57:49-0700] [MainThread] [I] [toil.leader] Issued job 'run_star' kind-run_star/instance-rpbnfzyy with job batch system ID: 5 and cores: 4, disk: 52.8 G, and memory: 48.6 G
[2020-10-19T14:57:49-0700] [MainThread] [I] [toil.worker] Redirecting logging to /home/drkthomp/workDir/node-77a2b3ac-69eb-4325-9205-afc132e2b6e3-1e53f69f16d74e0b881e7db602b2d2c3/tmpj8pqddja/worker_log.txt
[2020-10-19T14:57:51-0700] [MainThread] [I] [toil.leader] 1 jobs are running, 5 jobs are issued and waiting to run
[2020-10-19T15:00:33-0700] [Thread-1  ] [E] [toil.batchSystems.singleMachine] Got exit code 1 (indicating failure) from job _toil_worker run_phlat file:/home/drkthomp/protect3/jobStore kind-run_phlat/instance-foexdy0m.
[2020-10-19T15:00:33-0700] [MainThread] [W] [toil.leader] Job failed with exit value 1: 'run_phlat' kind-run_phlat/instance-foexdy0m
[2020-10-19T15:00:33-0700] [MainThread] [W] [toil.leader] The job seems to have left a log file, indicating failure: 'run_phlat' kind-run_phlat/instance-foexdy0m
[2020-10-19T15:00:33-0700] [MainThread] [W] [toil.leader] Log from job kind-run_phlat/instance-foexdy0m follows:
=========>
	[2020-10-19T14:57:49-0700] [MainThread] [I] [toil.worker] ---TOIL WORKER OUTPUT LOG---
	[2020-10-19T14:57:49-0700] [MainThread] [I] [toil] Running Toil version 4.2.0-3aa1da130141039cb357efe36d7df9b9f6ae9b5b on host drkthomp-virtualbox.
	567573 reads; of these:
	  567573 (100.00%) were paired; of these:
	    3570 (0.63%) aligned concordantly 0 times
	    514680 (90.68%) aligned concordantly exactly 1 time
	    49323 (8.69%) aligned concordantly >1 times
	99.37% overall alignment rate
	.....Process Bowtie 2 mapping on tumor_dna.......
	
	.....Prepare files of tumor_dna for PHLAT.......
	
	..... Running PHLAT .......
	Traceback (most recent call last):
	  File "/home/phlat-1.0/dist/PHLAT.py", line 64, in <module>
	    go(tag,outdir,phlatdir)
	  File "/home/yubai/programs/phlat-1.0/dist/utilities.py", line 79, in go
	  File "/home/yubai/programs/phlat-1.0/dist/extensions.py", line 617, in __init__
	  File "/home/yubai/programs/phlat-1.0/dist/extensions.py", line 645, in setMaster
	IndexError: list index out of range
	Traceback (most recent call last):
	  File "/home/drkthomp/protect3/src/protect/common.py", line 136, in docker_call
	    subprocess.check_call(call, stdout=outfile)
	  File "/usr/lib/python3.8/subprocess.py", line 364, in check_call
	    raise CalledProcessError(retcode, cmd)
	subprocess.CalledProcessError: Command '['docker', 'run', '--rm=true', '-v', '/home/drkthomp/workDir/node-77a2b3ac-69eb-4325-9205-afc132e2b6e3-1e53f69f16d74e0b881e7db602b2d2c3/tmpj8pqddja/a0ac95e2-e630-4058-8af8-896d4f133203:/data', '--log-driver=none', 'aarjunrao/phlat:1.0', '-1', '/data/input_1.fastq', '-2', '/data/input_2.fastq', '-index', '/data/index4phlat', '-b2url', '/usr/local/bin/bowtie2', '-tag', 'tumor_dna', '-e', '/home/phlat-1.0', '-o', '/data', '-p', '4']' returned non-zero exit status 1.
	
	During handling of the above exception, another exception occurred:
	
	Traceback (most recent call last):
	  File "/home/drkthomp/protect3/venv/lib/python3.8/site-packages/toil/worker.py", line 368, in workerScript
	    job._runner(jobGraph=jobGraph, jobStore=jobStore, fileStore=fileStore, defer=defer)
	  File "/home/drkthomp/protect3/venv/lib/python3.8/site-packages/toil/job.py", line 1424, in _runner
	    returnValues = self._run(jobGraph, fileStore)
	  File "/home/drkthomp/protect3/venv/lib/python3.8/site-packages/toil/job.py", line 1361, in _run
	    return self.run(fileStore)
	  File "/home/drkthomp/protect3/venv/lib/python3.8/site-packages/toil/job.py", line 1565, in run
	    rValue = userFunction(*((self,) + tuple(self._args)), **self._kwargs)
	  File "/home/drkthomp/protect3/src/protect/haplotyping/phlat.py", line 73, in run_phlat
	    docker_call(tool='phlat', tool_parameters=parameters, work_dir=work_dir,
	  File "/home/drkthomp/protect3/src/protect/common.py", line 138, in docker_call
	    raise RuntimeError('docker command returned a non-zero exit status (%s)' % err.returncode +
	RuntimeError: docker command returned a non-zero exit status (1)for command "docker run --rm=true -v /home/drkthomp/workDir/node-77a2b3ac-69eb-4325-9205-afc132e2b6e3-1e53f69f16d74e0b881e7db602b2d2c3/tmpj8pqddja/a0ac95e2-e630-4058-8af8-896d4f133203:/data --log-driver=none aarjunrao/phlat:1.0 -1 /data/input_1.fastq -2 /data/input_2.fastq -index /data/index4phlat -b2url /usr/local/bin/bowtie2 -tag tumor_dna -e /home/phlat-1.0 -o /data -p 4"
	[2020-10-19T15:00:33-0700] [MainThread] [E] [toil.worker] Exiting the worker because of a failed job on host drkthomp-virtualbox
	{'input_1.fastq': '/home/drkthomp/workDir/node-77a2b3ac-69eb-4325-9205-afc132e2b6e3-1e53f69f16d74e0b881e7db602b2d2c3/tmpj8pqddja/a0ac95e2-e630-4058-8af8-896d4f133203/input_1.fastq', 'input_2.fastq': '/home/drkthomp/workDir/node-77a2b3ac-69eb-4325-9205-afc132e2b6e3-1e53f69f16d74e0b881e7db602b2d2c3/tmpj8pqddja/a0ac95e2-e630-4058-8af8-896d4f133203/input_2.fastq', 'phlat_index.tar.gz': '/home/drkthomp/workDir/node-77a2b3ac-69eb-4325-9205-afc132e2b6e3-1e53f69f16d74e0b881e7db602b2d2c3/tmpj8pqddja/a0ac95e2-e630-4058-8af8-896d4f133203/phlat_index.tar.gz'}
<=========
[2020-10-19T15:00:33-0700] [MainThread] [W] [toil.jobGraph] Due to failure we are reducing the remaining retry count of job 'run_phlat' kind-run_phlat/instance-foexdy0m with ID kind-run_phlat/instance-foexdy0m to 1
[2020-10-19T15:00:33-0700] [MainThread] [I] [toil.leader] Issued job 'run_phlat' kind-run_phlat/instance-foexdy0m with job batch system ID: 6 and cores: 4, disk: 7.8 G, and memory: 2.0 G
[2020-10-19T15:00:35-0700] [MainThread] [I] [toil.worker] Redirecting logging to /home/drkthomp/workDir/node-77a2b3ac-69eb-4325-9205-afc132e2b6e3-1e53f69f16d74e0b881e7db602b2d2c3/tmpuh28jgni/worker_log.txt
[2020-10-19T15:03:06-0700] [Thread-1  ] [E] [toil.batchSystems.singleMachine] Got exit code 1 (indicating failure) from job _toil_worker run_phlat file:/home/drkthomp/protect3/jobStore kind-run_phlat/instance-xpy0rfpy.
[2020-10-19T15:03:06-0700] [MainThread] [W] [toil.leader] Job failed with exit value 1: 'run_phlat' kind-run_phlat/instance-xpy0rfpy
[2020-10-19T15:03:06-0700] [MainThread] [W] [toil.leader] The job seems to have left a log file, indicating failure: 'run_phlat' kind-run_phlat/instance-xpy0rfpy
[2020-10-19T15:03:06-0700] [MainThread] [W] [toil.leader] Log from job kind-run_phlat/instance-xpy0rfpy follows:
=========>
	[2020-10-19T15:00:35-0700] [MainThread] [I] [toil.worker] ---TOIL WORKER OUTPUT LOG---
	[2020-10-19T15:00:35-0700] [MainThread] [I] [toil] Running Toil version 4.2.0-3aa1da130141039cb357efe36d7df9b9f6ae9b5b on host drkthomp-virtualbox.
	491247 reads; of these:
	  491247 (100.00%) were paired; of these:
	    3488 (0.71%) aligned concordantly 0 times
	    442898 (90.16%) aligned concordantly exactly 1 time
	    44861 (9.13%) aligned concordantly >1 times
	99.29% overall alignment rate
	.....Process Bowtie 2 mapping on normal_dna.......
	
	.....Prepare files of normal_dna for PHLAT.......
	
	..... Running PHLAT .......
	Traceback (most recent call last):
	  File "/home/phlat-1.0/dist/PHLAT.py", line 64, in <module>
	    go(tag,outdir,phlatdir)
	  File "/home/yubai/programs/phlat-1.0/dist/utilities.py", line 79, in go
	  File "/home/yubai/programs/phlat-1.0/dist/extensions.py", line 617, in __init__
	  File "/home/yubai/programs/phlat-1.0/dist/extensions.py", line 645, in setMaster
	IndexError: list index out of range
	Traceback (most recent call last):
	  File "/home/drkthomp/protect3/src/protect/common.py", line 136, in docker_call
	    subprocess.check_call(call, stdout=outfile)
	  File "/usr/lib/python3.8/subprocess.py", line 364, in check_call
	    raise CalledProcessError(retcode, cmd)
	subprocess.CalledProcessError: Command '['docker', 'run', '--rm=true', '-v', '/home/drkthomp/workDir/node-77a2b3ac-69eb-4325-9205-afc132e2b6e3-1e53f69f16d74e0b881e7db602b2d2c3/tmpuh28jgni/5320bc4c-c2cd-451c-b94e-490c3ec13e8f:/data', '--log-driver=none', 'aarjunrao/phlat:1.0', '-1', '/data/input_1.fastq', '-2', '/data/input_2.fastq', '-index', '/data/index4phlat', '-b2url', '/usr/local/bin/bowtie2', '-tag', 'normal_dna', '-e', '/home/phlat-1.0', '-o', '/data', '-p', '4']' returned non-zero exit status 1.
	
	During handling of the above exception, another exception occurred:
	
	Traceback (most recent call last):
	  File "/home/drkthomp/protect3/venv/lib/python3.8/site-packages/toil/worker.py", line 368, in workerScript
	    job._runner(jobGraph=jobGraph, jobStore=jobStore, fileStore=fileStore, defer=defer)
	  File "/home/drkthomp/protect3/venv/lib/python3.8/site-packages/toil/job.py", line 1424, in _runner
	    returnValues = self._run(jobGraph, fileStore)
	  File "/home/drkthomp/protect3/venv/lib/python3.8/site-packages/toil/job.py", line 1361, in _run
	    return self.run(fileStore)
	  File "/home/drkthomp/protect3/venv/lib/python3.8/site-packages/toil/job.py", line 1565, in run
	    rValue = userFunction(*((self,) + tuple(self._args)), **self._kwargs)
	  File "/home/drkthomp/protect3/src/protect/haplotyping/phlat.py", line 73, in run_phlat
	    docker_call(tool='phlat', tool_parameters=parameters, work_dir=work_dir,
	  File "/home/drkthomp/protect3/src/protect/common.py", line 138, in docker_call
	    raise RuntimeError('docker command returned a non-zero exit status (%s)' % err.returncode +
	RuntimeError: docker command returned a non-zero exit status (1)for command "docker run --rm=true -v /home/drkthomp/workDir/node-77a2b3ac-69eb-4325-9205-afc132e2b6e3-1e53f69f16d74e0b881e7db602b2d2c3/tmpuh28jgni/5320bc4c-c2cd-451c-b94e-490c3ec13e8f:/data --log-driver=none aarjunrao/phlat:1.0 -1 /data/input_1.fastq -2 /data/input_2.fastq -index /data/index4phlat -b2url /usr/local/bin/bowtie2 -tag normal_dna -e /home/phlat-1.0 -o /data -p 4"
	[2020-10-19T15:03:06-0700] [MainThread] [E] [toil.worker] Exiting the worker because of a failed job on host drkthomp-virtualbox
	{'input_1.fastq': '/home/drkthomp/workDir/node-77a2b3ac-69eb-4325-9205-afc132e2b6e3-1e53f69f16d74e0b881e7db602b2d2c3/tmpuh28jgni/5320bc4c-c2cd-451c-b94e-490c3ec13e8f/input_1.fastq', 'input_2.fastq': '/home/drkthomp/workDir/node-77a2b3ac-69eb-4325-9205-afc132e2b6e3-1e53f69f16d74e0b881e7db602b2d2c3/tmpuh28jgni/5320bc4c-c2cd-451c-b94e-490c3ec13e8f/input_2.fastq', 'phlat_index.tar.gz': '/home/drkthomp/workDir/node-77a2b3ac-69eb-4325-9205-afc132e2b6e3-1e53f69f16d74e0b881e7db602b2d2c3/tmpuh28jgni/5320bc4c-c2cd-451c-b94e-490c3ec13e8f/phlat_index.tar.gz'}
<=========
[2020-10-19T15:03:06-0700] [MainThread] [W] [toil.jobGraph] Due to failure we are reducing the remaining retry count of job 'run_phlat' kind-run_phlat/instance-xpy0rfpy with ID kind-run_phlat/instance-xpy0rfpy to 1
[2020-10-19T15:03:06-0700] [MainThread] [I] [toil.leader] Issued job 'run_phlat' kind-run_phlat/instance-xpy0rfpy with job batch system ID: 7 and cores: 4, disk: 7.7 G, and memory: 2.0 G
[2020-10-19T15:03:07-0700] [MainThread] [I] [toil.worker] Redirecting logging to /home/drkthomp/workDir/node-77a2b3ac-69eb-4325-9205-afc132e2b6e3-1e53f69f16d74e0b881e7db602b2d2c3/tmps5g5jnhi/worker_log.txt
[2020-10-19T15:04:32-0700] [Thread-1  ] [E] [toil.batchSystems.singleMachine] Got exit code 1 (indicating failure) from job _toil_worker run_bwa file:/home/drkthomp/protect3/jobStore kind-run_bwa/instance-n45358fz.
[2020-10-19T15:04:32-0700] [MainThread] [W] [toil.leader] Job failed with exit value 1: 'run_bwa' kind-run_bwa/instance-n45358fz
[2020-10-19T15:04:32-0700] [MainThread] [W] [toil.leader] The job seems to have left a log file, indicating failure: 'run_bwa' kind-run_bwa/instance-n45358fz
[2020-10-19T15:04:32-0700] [MainThread] [W] [toil.leader] Log from job kind-run_bwa/instance-n45358fz follows:
=========>
	[2020-10-19T15:03:07-0700] [MainThread] [I] [toil.worker] ---TOIL WORKER OUTPUT LOG---
	[2020-10-19T15:03:07-0700] [MainThread] [I] [toil] Running Toil version 4.2.0-3aa1da130141039cb357efe36d7df9b9f6ae9b5b on host drkthomp-virtualbox.
	Traceback (most recent call last):
	  File "/home/drkthomp/protect3/venv/lib/python3.8/site-packages/toil/worker.py", line 368, in workerScript
	    job._runner(jobGraph=jobGraph, jobStore=jobStore, fileStore=fileStore, defer=defer)
	  File "/home/drkthomp/protect3/venv/lib/python3.8/site-packages/toil/job.py", line 1424, in _runner
	    returnValues = self._run(jobGraph, fileStore)
	  File "/home/drkthomp/protect3/venv/lib/python3.8/site-packages/toil/job.py", line 1361, in _run
	    return self.run(fileStore)
	  File "/home/drkthomp/protect3/venv/lib/python3.8/site-packages/toil/job.py", line 1565, in run
	    rValue = userFunction(*((self,) + tuple(self._args)), **self._kwargs)
	  File "/home/drkthomp/protect3/src/protect/alignment/dna.py", line 140, in run_bwa
	    docker_call(tool='bwa', tool_parameters=parameters, work_dir=work_dir,
	  File "/home/drkthomp/protect3/src/protect/common.py", line 101, in docker_call
	    assert isinstance(outfile, file), 'outfile was not passsed a file'
	NameError: name 'file' is not defined
	[2020-10-19T15:04:31-0700] [MainThread] [E] [toil.worker] Exiting the worker because of a failed job on host drkthomp-virtualbox
<=========
[2020-10-19T15:04:32-0700] [MainThread] [W] [toil.jobGraph] Due to failure we are reducing the remaining retry count of job 'run_bwa' kind-run_bwa/instance-n45358fz with ID kind-run_bwa/instance-n45358fz to 1
[2020-10-19T15:04:32-0700] [MainThread] [I] [toil.leader] Issued job 'run_bwa' kind-run_bwa/instance-n45358fz with job batch system ID: 8 and cores: 4, disk: 9.6 G, and memory: 12.0 G
[2020-10-19T15:04:32-0700] [MainThread] [I] [toil.worker] Redirecting logging to /home/drkthomp/workDir/node-77a2b3ac-69eb-4325-9205-afc132e2b6e3-1e53f69f16d74e0b881e7db602b2d2c3/tmpx9ev25qk/worker_log.txt
[2020-10-19T15:07:09-0700] [Thread-1  ] [E] [toil.batchSystems.singleMachine] Got exit code 1 (indicating failure) from job _toil_worker run_phlat file:/home/drkthomp/protect3/jobStore kind-run_phlat/instance-xpy0rfpy.
[2020-10-19T15:07:09-0700] [MainThread] [W] [toil.leader] Job failed with exit value 1: 'run_phlat' kind-run_phlat/instance-xpy0rfpy
[2020-10-19T15:07:09-0700] [MainThread] [W] [toil.leader] The job seems to have left a log file, indicating failure: 'run_phlat' kind-run_phlat/instance-xpy0rfpy
[2020-10-19T15:07:09-0700] [MainThread] [W] [toil.leader] Log from job kind-run_phlat/instance-xpy0rfpy follows:
=========>
	[2020-10-19T15:04:32-0700] [MainThread] [I] [toil.worker] ---TOIL WORKER OUTPUT LOG---
	[2020-10-19T15:04:32-0700] [MainThread] [I] [toil] Running Toil version 4.2.0-3aa1da130141039cb357efe36d7df9b9f6ae9b5b on host drkthomp-virtualbox.
	491247 reads; of these:
	  491247 (100.00%) were paired; of these:
	    3488 (0.71%) aligned concordantly 0 times
	    442898 (90.16%) aligned concordantly exactly 1 time
	    44861 (9.13%) aligned concordantly >1 times
	99.29% overall alignment rate
	.....Process Bowtie 2 mapping on normal_dna.......
	
	.....Prepare files of normal_dna for PHLAT.......
	
	Traceback (most recent call last):
	  File "/home/phlat-1.0/dist/PHLAT.py", line 64, in <module>
	..... Running PHLAT .......
	    go(tag,outdir,phlatdir)
	  File "/home/yubai/programs/phlat-1.0/dist/utilities.py", line 79, in go
	  File "/home/yubai/programs/phlat-1.0/dist/extensions.py", line 617, in __init__
	  File "/home/yubai/programs/phlat-1.0/dist/extensions.py", line 645, in setMaster
	IndexError: list index out of range
	Traceback (most recent call last):
	  File "/home/drkthomp/protect3/src/protect/common.py", line 136, in docker_call
	    subprocess.check_call(call, stdout=outfile)
	  File "/usr/lib/python3.8/subprocess.py", line 364, in check_call
	    raise CalledProcessError(retcode, cmd)
	subprocess.CalledProcessError: Command '['docker', 'run', '--rm=true', '-v', '/home/drkthomp/workDir/node-77a2b3ac-69eb-4325-9205-afc132e2b6e3-1e53f69f16d74e0b881e7db602b2d2c3/tmpx9ev25qk/f858a60a-81a6-4c08-9472-6a0085cc69ea:/data', '--log-driver=none', 'aarjunrao/phlat:1.0', '-1', '/data/input_1.fastq', '-2', '/data/input_2.fastq', '-index', '/data/index4phlat', '-b2url', '/usr/local/bin/bowtie2', '-tag', 'normal_dna', '-e', '/home/phlat-1.0', '-o', '/data', '-p', '4']' returned non-zero exit status 1.
	
	During handling of the above exception, another exception occurred:
	
	Traceback (most recent call last):
	  File "/home/drkthomp/protect3/venv/lib/python3.8/site-packages/toil/worker.py", line 368, in workerScript
	    job._runner(jobGraph=jobGraph, jobStore=jobStore, fileStore=fileStore, defer=defer)
	  File "/home/drkthomp/protect3/venv/lib/python3.8/site-packages/toil/job.py", line 1424, in _runner
	    returnValues = self._run(jobGraph, fileStore)
	  File "/home/drkthomp/protect3/venv/lib/python3.8/site-packages/toil/job.py", line 1361, in _run
	    return self.run(fileStore)
	  File "/home/drkthomp/protect3/venv/lib/python3.8/site-packages/toil/job.py", line 1565, in run
	    rValue = userFunction(*((self,) + tuple(self._args)), **self._kwargs)
	  File "/home/drkthomp/protect3/src/protect/haplotyping/phlat.py", line 73, in run_phlat
	    docker_call(tool='phlat', tool_parameters=parameters, work_dir=work_dir,
	  File "/home/drkthomp/protect3/src/protect/common.py", line 138, in docker_call
	    raise RuntimeError('docker command returned a non-zero exit status (%s)' % err.returncode +
	RuntimeError: docker command returned a non-zero exit status (1)for command "docker run --rm=true -v /home/drkthomp/workDir/node-77a2b3ac-69eb-4325-9205-afc132e2b6e3-1e53f69f16d74e0b881e7db602b2d2c3/tmpx9ev25qk/f858a60a-81a6-4c08-9472-6a0085cc69ea:/data --log-driver=none aarjunrao/phlat:1.0 -1 /data/input_1.fastq -2 /data/input_2.fastq -index /data/index4phlat -b2url /usr/local/bin/bowtie2 -tag normal_dna -e /home/phlat-1.0 -o /data -p 4"
	[2020-10-19T15:07:09-0700] [MainThread] [E] [toil.worker] Exiting the worker because of a failed job on host drkthomp-virtualbox
	{'input_1.fastq': '/home/drkthomp/workDir/node-77a2b3ac-69eb-4325-9205-afc132e2b6e3-1e53f69f16d74e0b881e7db602b2d2c3/tmpx9ev25qk/f858a60a-81a6-4c08-9472-6a0085cc69ea/input_1.fastq', 'input_2.fastq': '/home/drkthomp/workDir/node-77a2b3ac-69eb-4325-9205-afc132e2b6e3-1e53f69f16d74e0b881e7db602b2d2c3/tmpx9ev25qk/f858a60a-81a6-4c08-9472-6a0085cc69ea/input_2.fastq', 'phlat_index.tar.gz': '/home/drkthomp/workDir/node-77a2b3ac-69eb-4325-9205-afc132e2b6e3-1e53f69f16d74e0b881e7db602b2d2c3/tmpx9ev25qk/f858a60a-81a6-4c08-9472-6a0085cc69ea/phlat_index.tar.gz'}
<=========
[2020-10-19T15:07:09-0700] [MainThread] [W] [toil.jobGraph] Due to failure we are reducing the remaining retry count of job 'run_phlat' kind-run_phlat/instance-xpy0rfpy with ID kind-run_phlat/instance-xpy0rfpy to 0
[2020-10-19T15:07:09-0700] [MainThread] [W] [toil.leader] Job 'run_phlat' kind-run_phlat/instance-xpy0rfpy with ID kind-run_phlat/instance-xpy0rfpy is completely failed
[2020-10-19T15:07:10-0700] [MainThread] [I] [toil.worker] Redirecting logging to /home/drkthomp/workDir/node-77a2b3ac-69eb-4325-9205-afc132e2b6e3-1e53f69f16d74e0b881e7db602b2d2c3/tmpg3b7n5f7/worker_log.txt
[2020-10-19T15:08:06-0700] [Thread-1  ] [E] [toil.batchSystems.singleMachine] Got exit code 1 (indicating failure) from job _toil_worker run_bwa file:/home/drkthomp/protect3/jobStore kind-run_bwa/instance-n45358fz.
[2020-10-19T15:08:06-0700] [MainThread] [W] [toil.leader] Job failed with exit value 1: 'run_bwa' kind-run_bwa/instance-n45358fz
[2020-10-19T15:08:06-0700] [MainThread] [W] [toil.leader] The job seems to have left a log file, indicating failure: 'run_bwa' kind-run_bwa/instance-n45358fz
[2020-10-19T15:08:06-0700] [MainThread] [W] [toil.leader] Log from job kind-run_bwa/instance-n45358fz follows:
=========>
	[2020-10-19T15:07:10-0700] [MainThread] [I] [toil.worker] ---TOIL WORKER OUTPUT LOG---
	[2020-10-19T15:07:10-0700] [MainThread] [I] [toil] Running Toil version 4.2.0-3aa1da130141039cb357efe36d7df9b9f6ae9b5b on host drkthomp-virtualbox.
	Traceback (most recent call last):
	  File "/home/drkthomp/protect3/venv/lib/python3.8/site-packages/toil/worker.py", line 368, in workerScript
	    job._runner(jobGraph=jobGraph, jobStore=jobStore, fileStore=fileStore, defer=defer)
	  File "/home/drkthomp/protect3/venv/lib/python3.8/site-packages/toil/job.py", line 1424, in _runner
	    returnValues = self._run(jobGraph, fileStore)
	  File "/home/drkthomp/protect3/venv/lib/python3.8/site-packages/toil/job.py", line 1361, in _run
	    return self.run(fileStore)
	  File "/home/drkthomp/protect3/venv/lib/python3.8/site-packages/toil/job.py", line 1565, in run
	    rValue = userFunction(*((self,) + tuple(self._args)), **self._kwargs)
	  File "/home/drkthomp/protect3/src/protect/alignment/dna.py", line 140, in run_bwa
	    docker_call(tool='bwa', tool_parameters=parameters, work_dir=work_dir,
	  File "/home/drkthomp/protect3/src/protect/common.py", line 101, in docker_call
	    assert isinstance(outfile, file), 'outfile was not passsed a file'
	NameError: name 'file' is not defined
	[2020-10-19T15:08:04-0700] [MainThread] [E] [toil.worker] Exiting the worker because of a failed job on host drkthomp-virtualbox
<=========
[2020-10-19T15:08:06-0700] [MainThread] [W] [toil.jobGraph] Due to failure we are reducing the remaining retry count of job 'run_bwa' kind-run_bwa/instance-n45358fz with ID kind-run_bwa/instance-n45358fz to 0
[2020-10-19T15:08:06-0700] [MainThread] [W] [toil.leader] Job 'run_bwa' kind-run_bwa/instance-n45358fz with ID kind-run_bwa/instance-n45358fz is completely failed
[2020-10-19T15:08:06-0700] [MainThread] [I] [toil.worker] Redirecting logging to /home/drkthomp/workDir/node-77a2b3ac-69eb-4325-9205-afc132e2b6e3-1e53f69f16d74e0b881e7db602b2d2c3/tmp67xxzuvv/worker_log.txt
[2020-10-19T15:11:07-0700] [Thread-1  ] [E] [toil.batchSystems.singleMachine] Got exit code 1 (indicating failure) from job _toil_worker run_phlat file:/home/drkthomp/protect3/jobStore kind-run_phlat/instance-foexdy0m.
[2020-10-19T15:11:07-0700] [MainThread] [W] [toil.leader] Job failed with exit value 1: 'run_phlat' kind-run_phlat/instance-foexdy0m
[2020-10-19T15:11:07-0700] [MainThread] [W] [toil.leader] The job seems to have left a log file, indicating failure: 'run_phlat' kind-run_phlat/instance-foexdy0m
[2020-10-19T15:11:07-0700] [MainThread] [W] [toil.leader] Log from job kind-run_phlat/instance-foexdy0m follows:
=========>
	[2020-10-19T15:08:06-0700] [MainThread] [I] [toil.worker] ---TOIL WORKER OUTPUT LOG---
	[2020-10-19T15:08:06-0700] [MainThread] [I] [toil] Running Toil version 4.2.0-3aa1da130141039cb357efe36d7df9b9f6ae9b5b on host drkthomp-virtualbox.
	567573 reads; of these:
	  567573 (100.00%) were paired; of these:
	    3570 (0.63%) aligned concordantly 0 times
	    514680 (90.68%) aligned concordantly exactly 1 time
	    49323 (8.69%) aligned concordantly >1 times
	99.37% overall alignment rate
	.....Process Bowtie 2 mapping on tumor_dna.......
	
	.....Prepare files of tumor_dna for PHLAT.......
	
	..... Running PHLAT .......
	Traceback (most recent call last):
	  File "/home/phlat-1.0/dist/PHLAT.py", line 64, in <module>
	    go(tag,outdir,phlatdir)
	  File "/home/yubai/programs/phlat-1.0/dist/utilities.py", line 79, in go
	  File "/home/yubai/programs/phlat-1.0/dist/extensions.py", line 617, in __init__
	  File "/home/yubai/programs/phlat-1.0/dist/extensions.py", line 645, in setMaster
	IndexError: list index out of range
	Traceback (most recent call last):
	  File "/home/drkthomp/protect3/src/protect/common.py", line 136, in docker_call
	    subprocess.check_call(call, stdout=outfile)
	  File "/usr/lib/python3.8/subprocess.py", line 364, in check_call
	    raise CalledProcessError(retcode, cmd)
	subprocess.CalledProcessError: Command '['docker', 'run', '--rm=true', '-v', '/home/drkthomp/workDir/node-77a2b3ac-69eb-4325-9205-afc132e2b6e3-1e53f69f16d74e0b881e7db602b2d2c3/tmp67xxzuvv/78e94666-8f7d-4d01-b17f-0e201d55b8bb:/data', '--log-driver=none', 'aarjunrao/phlat:1.0', '-1', '/data/input_1.fastq', '-2', '/data/input_2.fastq', '-index', '/data/index4phlat', '-b2url', '/usr/local/bin/bowtie2', '-tag', 'tumor_dna', '-e', '/home/phlat-1.0', '-o', '/data', '-p', '4']' returned non-zero exit status 1.
	
	During handling of the above exception, another exception occurred:
	
	Traceback (most recent call last):
	  File "/home/drkthomp/protect3/venv/lib/python3.8/site-packages/toil/worker.py", line 368, in workerScript
	    job._runner(jobGraph=jobGraph, jobStore=jobStore, fileStore=fileStore, defer=defer)
	  File "/home/drkthomp/protect3/venv/lib/python3.8/site-packages/toil/job.py", line 1424, in _runner
	    returnValues = self._run(jobGraph, fileStore)
	  File "/home/drkthomp/protect3/venv/lib/python3.8/site-packages/toil/job.py", line 1361, in _run
	    return self.run(fileStore)
	  File "/home/drkthomp/protect3/venv/lib/python3.8/site-packages/toil/job.py", line 1565, in run
	    rValue = userFunction(*((self,) + tuple(self._args)), **self._kwargs)
	  File "/home/drkthomp/protect3/src/protect/haplotyping/phlat.py", line 73, in run_phlat
	    docker_call(tool='phlat', tool_parameters=parameters, work_dir=work_dir,
	  File "/home/drkthomp/protect3/src/protect/common.py", line 138, in docker_call
	    raise RuntimeError('docker command returned a non-zero exit status (%s)' % err.returncode +
	RuntimeError: docker command returned a non-zero exit status (1)for command "docker run --rm=true -v /home/drkthomp/workDir/node-77a2b3ac-69eb-4325-9205-afc132e2b6e3-1e53f69f16d74e0b881e7db602b2d2c3/tmp67xxzuvv/78e94666-8f7d-4d01-b17f-0e201d55b8bb:/data --log-driver=none aarjunrao/phlat:1.0 -1 /data/input_1.fastq -2 /data/input_2.fastq -index /data/index4phlat -b2url /usr/local/bin/bowtie2 -tag tumor_dna -e /home/phlat-1.0 -o /data -p 4"
	[2020-10-19T15:11:07-0700] [MainThread] [E] [toil.worker] Exiting the worker because of a failed job on host drkthomp-virtualbox
	{'input_1.fastq': '/home/drkthomp/workDir/node-77a2b3ac-69eb-4325-9205-afc132e2b6e3-1e53f69f16d74e0b881e7db602b2d2c3/tmp67xxzuvv/78e94666-8f7d-4d01-b17f-0e201d55b8bb/input_1.fastq', 'input_2.fastq': '/home/drkthomp/workDir/node-77a2b3ac-69eb-4325-9205-afc132e2b6e3-1e53f69f16d74e0b881e7db602b2d2c3/tmp67xxzuvv/78e94666-8f7d-4d01-b17f-0e201d55b8bb/input_2.fastq', 'phlat_index.tar.gz': '/home/drkthomp/workDir/node-77a2b3ac-69eb-4325-9205-afc132e2b6e3-1e53f69f16d74e0b881e7db602b2d2c3/tmp67xxzuvv/78e94666-8f7d-4d01-b17f-0e201d55b8bb/phlat_index.tar.gz'}
<=========
[2020-10-19T15:11:07-0700] [MainThread] [W] [toil.jobGraph] Due to failure we are reducing the remaining retry count of job 'run_phlat' kind-run_phlat/instance-foexdy0m with ID kind-run_phlat/instance-foexdy0m to 0
[2020-10-19T15:11:07-0700] [MainThread] [W] [toil.leader] Job 'run_phlat' kind-run_phlat/instance-foexdy0m with ID kind-run_phlat/instance-foexdy0m is completely failed
[2020-10-19T15:11:08-0700] [MainThread] [I] [toil.worker] Redirecting logging to /home/drkthomp/workDir/node-77a2b3ac-69eb-4325-9205-afc132e2b6e3-1e53f69f16d74e0b881e7db602b2d2c3/tmph10zw7zc/worker_log.txt
[2020-10-19T15:12:03-0700] [Thread-1  ] [E] [toil.batchSystems.singleMachine] Got exit code 1 (indicating failure) from job _toil_worker run_bwa file:/home/drkthomp/protect3/jobStore kind-run_bwa/instance-75n4628j.
[2020-10-19T15:12:03-0700] [MainThread] [W] [toil.leader] Job failed with exit value 1: 'run_bwa' kind-run_bwa/instance-75n4628j
[2020-10-19T15:12:03-0700] [MainThread] [W] [toil.leader] The job seems to have left a log file, indicating failure: 'run_bwa' kind-run_bwa/instance-75n4628j
[2020-10-19T15:12:03-0700] [MainThread] [W] [toil.leader] Log from job kind-run_bwa/instance-75n4628j follows:
=========>
	[2020-10-19T15:11:08-0700] [MainThread] [I] [toil.worker] ---TOIL WORKER OUTPUT LOG---
	[2020-10-19T15:11:08-0700] [MainThread] [I] [toil] Running Toil version 4.2.0-3aa1da130141039cb357efe36d7df9b9f6ae9b5b on host drkthomp-virtualbox.
	Traceback (most recent call last):
	  File "/home/drkthomp/protect3/venv/lib/python3.8/site-packages/toil/worker.py", line 368, in workerScript
	    job._runner(jobGraph=jobGraph, jobStore=jobStore, fileStore=fileStore, defer=defer)
	  File "/home/drkthomp/protect3/venv/lib/python3.8/site-packages/toil/job.py", line 1424, in _runner
	    returnValues = self._run(jobGraph, fileStore)
	  File "/home/drkthomp/protect3/venv/lib/python3.8/site-packages/toil/job.py", line 1361, in _run
	    return self.run(fileStore)
	  File "/home/drkthomp/protect3/venv/lib/python3.8/site-packages/toil/job.py", line 1565, in run
	    rValue = userFunction(*((self,) + tuple(self._args)), **self._kwargs)
	  File "/home/drkthomp/protect3/src/protect/alignment/dna.py", line 140, in run_bwa
	    docker_call(tool='bwa', tool_parameters=parameters, work_dir=work_dir,
	  File "/home/drkthomp/protect3/src/protect/common.py", line 101, in docker_call
	    assert isinstance(outfile, file), 'outfile was not passsed a file'
	NameError: name 'file' is not defined
	[2020-10-19T15:12:01-0700] [MainThread] [E] [toil.worker] Exiting the worker because of a failed job on host drkthomp-virtualbox
<=========
[2020-10-19T15:12:03-0700] [MainThread] [W] [toil.jobGraph] Due to failure we are reducing the remaining retry count of job 'run_bwa' kind-run_bwa/instance-75n4628j with ID kind-run_bwa/instance-75n4628j to 1
[2020-10-19T15:12:03-0700] [MainThread] [I] [toil.leader] Issued job 'run_bwa' kind-run_bwa/instance-75n4628j with job batch system ID: 9 and cores: 4, disk: 9.4 G, and memory: 12.0 G
[2020-10-19T15:12:03-0700] [MainThread] [I] [toil.worker] Redirecting logging to /home/drkthomp/workDir/node-77a2b3ac-69eb-4325-9205-afc132e2b6e3-1e53f69f16d74e0b881e7db602b2d2c3/tmpl2u2480c/worker_log.txt
[2020-10-19T15:14:18-0700] [Thread-1  ] [E] [toil.batchSystems.singleMachine] Got exit code 1 (indicating failure) from job _toil_worker run_phlat file:/home/drkthomp/protect3/jobStore kind-run_phlat/instance-2oiyd0li.
[2020-10-19T15:14:18-0700] [MainThread] [W] [toil.leader] Job failed with exit value 1: 'run_phlat' kind-run_phlat/instance-2oiyd0li
[2020-10-19T15:14:18-0700] [MainThread] [W] [toil.leader] The job seems to have left a log file, indicating failure: 'run_phlat' kind-run_phlat/instance-2oiyd0li
[2020-10-19T15:14:18-0700] [MainThread] [W] [toil.leader] Log from job kind-run_phlat/instance-2oiyd0li follows:
=========>
	[2020-10-19T15:12:03-0700] [MainThread] [I] [toil.worker] ---TOIL WORKER OUTPUT LOG---
	[2020-10-19T15:12:03-0700] [MainThread] [I] [toil] Running Toil version 4.2.0-3aa1da130141039cb357efe36d7df9b9f6ae9b5b on host drkthomp-virtualbox.
	462668 reads; of these:
	  462668 (100.00%) were paired; of these:
	    75207 (16.26%) aligned concordantly 0 times
	    235430 (50.89%) aligned concordantly exactly 1 time
	    152031 (32.86%) aligned concordantly >1 times
	83.74% overall alignment rate
	.....Process Bowtie 2 mapping on tumor_rna.......
	
	.....Prepare files of tumor_rna for PHLAT.......
	
	..... Running PHLAT .......
	Traceback (most recent call last):
	  File "/home/phlat-1.0/dist/PHLAT.py", line 64, in <module>
	    go(tag,outdir,phlatdir)
	  File "/home/yubai/programs/phlat-1.0/dist/utilities.py", line 79, in go
	  File "/home/yubai/programs/phlat-1.0/dist/extensions.py", line 617, in __init__
	  File "/home/yubai/programs/phlat-1.0/dist/extensions.py", line 645, in setMaster
	IndexError: list index out of range
	Traceback (most recent call last):
	  File "/home/drkthomp/protect3/src/protect/common.py", line 136, in docker_call
	    subprocess.check_call(call, stdout=outfile)
	  File "/usr/lib/python3.8/subprocess.py", line 364, in check_call
	    raise CalledProcessError(retcode, cmd)
	subprocess.CalledProcessError: Command '['docker', 'run', '--rm=true', '-v', '/home/drkthomp/workDir/node-77a2b3ac-69eb-4325-9205-afc132e2b6e3-1e53f69f16d74e0b881e7db602b2d2c3/tmpl2u2480c/3f892483-6778-4874-af82-231b605ff625:/data', '--log-driver=none', 'aarjunrao/phlat:1.0', '-1', '/data/input_1.fastq', '-2', '/data/input_2.fastq', '-index', '/data/index4phlat', '-b2url', '/usr/local/bin/bowtie2', '-tag', 'tumor_rna', '-e', '/home/phlat-1.0', '-o', '/data', '-p', '4']' returned non-zero exit status 1.
	
	During handling of the above exception, another exception occurred:
	
	Traceback (most recent call last):
	  File "/home/drkthomp/protect3/venv/lib/python3.8/site-packages/toil/worker.py", line 368, in workerScript
	    job._runner(jobGraph=jobGraph, jobStore=jobStore, fileStore=fileStore, defer=defer)
	  File "/home/drkthomp/protect3/venv/lib/python3.8/site-packages/toil/job.py", line 1424, in _runner
	    returnValues = self._run(jobGraph, fileStore)
	  File "/home/drkthomp/protect3/venv/lib/python3.8/site-packages/toil/job.py", line 1361, in _run
	    return self.run(fileStore)
	  File "/home/drkthomp/protect3/venv/lib/python3.8/site-packages/toil/job.py", line 1565, in run
	    rValue = userFunction(*((self,) + tuple(self._args)), **self._kwargs)
	  File "/home/drkthomp/protect3/src/protect/haplotyping/phlat.py", line 73, in run_phlat
	    docker_call(tool='phlat', tool_parameters=parameters, work_dir=work_dir,
	  File "/home/drkthomp/protect3/src/protect/common.py", line 138, in docker_call
	    raise RuntimeError('docker command returned a non-zero exit status (%s)' % err.returncode +
	RuntimeError: docker command returned a non-zero exit status (1)for command "docker run --rm=true -v /home/drkthomp/workDir/node-77a2b3ac-69eb-4325-9205-afc132e2b6e3-1e53f69f16d74e0b881e7db602b2d2c3/tmpl2u2480c/3f892483-6778-4874-af82-231b605ff625:/data --log-driver=none aarjunrao/phlat:1.0 -1 /data/input_1.fastq -2 /data/input_2.fastq -index /data/index4phlat -b2url /usr/local/bin/bowtie2 -tag tumor_rna -e /home/phlat-1.0 -o /data -p 4"
	[2020-10-19T15:14:18-0700] [MainThread] [E] [toil.worker] Exiting the worker because of a failed job on host drkthomp-virtualbox
	{'input_1.fastq': '/home/drkthomp/workDir/node-77a2b3ac-69eb-4325-9205-afc132e2b6e3-1e53f69f16d74e0b881e7db602b2d2c3/tmpl2u2480c/3f892483-6778-4874-af82-231b605ff625/input_1.fastq', 'input_2.fastq': '/home/drkthomp/workDir/node-77a2b3ac-69eb-4325-9205-afc132e2b6e3-1e53f69f16d74e0b881e7db602b2d2c3/tmpl2u2480c/3f892483-6778-4874-af82-231b605ff625/input_2.fastq', 'phlat_index.tar.gz': '/home/drkthomp/workDir/node-77a2b3ac-69eb-4325-9205-afc132e2b6e3-1e53f69f16d74e0b881e7db602b2d2c3/tmpl2u2480c/3f892483-6778-4874-af82-231b605ff625/phlat_index.tar.gz'}
<=========
[2020-10-19T15:14:18-0700] [MainThread] [W] [toil.jobGraph] Due to failure we are reducing the remaining retry count of job 'run_phlat' kind-run_phlat/instance-2oiyd0li with ID kind-run_phlat/instance-2oiyd0li to 1
[2020-10-19T15:14:18-0700] [MainThread] [I] [toil.leader] Issued job 'run_phlat' kind-run_phlat/instance-2oiyd0li with job batch system ID: 10 and cores: 4, disk: 7.7 G, and memory: 2.0 G
[2020-10-19T15:14:19-0700] [MainThread] [I] [toil.worker] Redirecting logging to /home/drkthomp/workDir/node-77a2b3ac-69eb-4325-9205-afc132e2b6e3-1e53f69f16d74e0b881e7db602b2d2c3/tmpydrl0r5w/worker_log.txt
[2020-10-19T15:15:17-0700] [Thread-1  ] [E] [toil.batchSystems.singleMachine] Got exit code 1 (indicating failure) from job _toil_worker run_bwa file:/home/drkthomp/protect3/jobStore kind-run_bwa/instance-75n4628j.
[2020-10-19T15:15:17-0700] [MainThread] [W] [toil.leader] Job failed with exit value 1: 'run_bwa' kind-run_bwa/instance-75n4628j
[2020-10-19T15:15:17-0700] [MainThread] [W] [toil.leader] The job seems to have left a log file, indicating failure: 'run_bwa' kind-run_bwa/instance-75n4628j
[2020-10-19T15:15:17-0700] [MainThread] [W] [toil.leader] Log from job kind-run_bwa/instance-75n4628j follows:
=========>
	[2020-10-19T15:14:19-0700] [MainThread] [I] [toil.worker] ---TOIL WORKER OUTPUT LOG---
	[2020-10-19T15:14:19-0700] [MainThread] [I] [toil] Running Toil version 4.2.0-3aa1da130141039cb357efe36d7df9b9f6ae9b5b on host drkthomp-virtualbox.
	Traceback (most recent call last):
	  File "/home/drkthomp/protect3/venv/lib/python3.8/site-packages/toil/worker.py", line 368, in workerScript
	    job._runner(jobGraph=jobGraph, jobStore=jobStore, fileStore=fileStore, defer=defer)
	  File "/home/drkthomp/protect3/venv/lib/python3.8/site-packages/toil/job.py", line 1424, in _runner
	    returnValues = self._run(jobGraph, fileStore)
	  File "/home/drkthomp/protect3/venv/lib/python3.8/site-packages/toil/job.py", line 1361, in _run
	    return self.run(fileStore)
	  File "/home/drkthomp/protect3/venv/lib/python3.8/site-packages/toil/job.py", line 1565, in run
	    rValue = userFunction(*((self,) + tuple(self._args)), **self._kwargs)
	  File "/home/drkthomp/protect3/src/protect/alignment/dna.py", line 140, in run_bwa
	    docker_call(tool='bwa', tool_parameters=parameters, work_dir=work_dir,
	  File "/home/drkthomp/protect3/src/protect/common.py", line 101, in docker_call
	    assert isinstance(outfile, file), 'outfile was not passsed a file'
	NameError: name 'file' is not defined
	[2020-10-19T15:15:16-0700] [MainThread] [E] [toil.worker] Exiting the worker because of a failed job on host drkthomp-virtualbox
<=========
[2020-10-19T15:15:17-0700] [MainThread] [W] [toil.jobGraph] Due to failure we are reducing the remaining retry count of job 'run_bwa' kind-run_bwa/instance-75n4628j with ID kind-run_bwa/instance-75n4628j to 0
[2020-10-19T15:15:17-0700] [MainThread] [W] [toil.leader] Job 'run_bwa' kind-run_bwa/instance-75n4628j with ID kind-run_bwa/instance-75n4628j is completely failed
[2020-10-19T15:15:18-0700] [MainThread] [I] [toil.worker] Redirecting logging to /home/drkthomp/workDir/node-77a2b3ac-69eb-4325-9205-afc132e2b6e3-1e53f69f16d74e0b881e7db602b2d2c3/tmpyqubeh1w/worker_log.txt
[2020-10-19T15:17:37-0700] [Thread-1  ] [E] [toil.batchSystems.singleMachine] Got exit code 1 (indicating failure) from job _toil_worker run_phlat file:/home/drkthomp/protect3/jobStore kind-run_phlat/instance-2oiyd0li.
[2020-10-19T15:17:37-0700] [MainThread] [W] [toil.leader] Job failed with exit value 1: 'run_phlat' kind-run_phlat/instance-2oiyd0li
[2020-10-19T15:17:37-0700] [MainThread] [W] [toil.leader] The job seems to have left a log file, indicating failure: 'run_phlat' kind-run_phlat/instance-2oiyd0li
[2020-10-19T15:17:37-0700] [MainThread] [W] [toil.leader] Log from job kind-run_phlat/instance-2oiyd0li follows:
=========>
	[2020-10-19T15:15:18-0700] [MainThread] [I] [toil.worker] ---TOIL WORKER OUTPUT LOG---
	[2020-10-19T15:15:18-0700] [MainThread] [I] [toil] Running Toil version 4.2.0-3aa1da130141039cb357efe36d7df9b9f6ae9b5b on host drkthomp-virtualbox.
	462668 reads; of these:
	  462668 (100.00%) were paired; of these:
	    75207 (16.26%) aligned concordantly 0 times
	    235430 (50.89%) aligned concordantly exactly 1 time
	    152031 (32.86%) aligned concordantly >1 times
	83.74% overall alignment rate
	.....Process Bowtie 2 mapping on tumor_rna.......
	
	.....Prepare files of tumor_rna for PHLAT.......
	
	..... Running PHLAT .......
	Traceback (most recent call last):
	  File "/home/phlat-1.0/dist/PHLAT.py", line 64, in <module>
	    go(tag,outdir,phlatdir)
	  File "/home/yubai/programs/phlat-1.0/dist/utilities.py", line 79, in go
	  File "/home/yubai/programs/phlat-1.0/dist/extensions.py", line 617, in __init__
	  File "/home/yubai/programs/phlat-1.0/dist/extensions.py", line 645, in setMaster
	IndexError: list index out of range
	Traceback (most recent call last):
	  File "/home/drkthomp/protect3/src/protect/common.py", line 136, in docker_call
	    subprocess.check_call(call, stdout=outfile)
	  File "/usr/lib/python3.8/subprocess.py", line 364, in check_call
	    raise CalledProcessError(retcode, cmd)
	subprocess.CalledProcessError: Command '['docker', 'run', '--rm=true', '-v', '/home/drkthomp/workDir/node-77a2b3ac-69eb-4325-9205-afc132e2b6e3-1e53f69f16d74e0b881e7db602b2d2c3/tmpyqubeh1w/b2b182ee-f0fa-4d4e-9fc7-ba1a0a3a14e9:/data', '--log-driver=none', 'aarjunrao/phlat:1.0', '-1', '/data/input_1.fastq', '-2', '/data/input_2.fastq', '-index', '/data/index4phlat', '-b2url', '/usr/local/bin/bowtie2', '-tag', 'tumor_rna', '-e', '/home/phlat-1.0', '-o', '/data', '-p', '4']' returned non-zero exit status 1.
	
	During handling of the above exception, another exception occurred:
	
	Traceback (most recent call last):
	  File "/home/drkthomp/protect3/venv/lib/python3.8/site-packages/toil/worker.py", line 368, in workerScript
	    job._runner(jobGraph=jobGraph, jobStore=jobStore, fileStore=fileStore, defer=defer)
	  File "/home/drkthomp/protect3/venv/lib/python3.8/site-packages/toil/job.py", line 1424, in _runner
	    returnValues = self._run(jobGraph, fileStore)
	  File "/home/drkthomp/protect3/venv/lib/python3.8/site-packages/toil/job.py", line 1361, in _run
	    return self.run(fileStore)
	  File "/home/drkthomp/protect3/venv/lib/python3.8/site-packages/toil/job.py", line 1565, in run
	    rValue = userFunction(*((self,) + tuple(self._args)), **self._kwargs)
	  File "/home/drkthomp/protect3/src/protect/haplotyping/phlat.py", line 73, in run_phlat
	    docker_call(tool='phlat', tool_parameters=parameters, work_dir=work_dir,
	  File "/home/drkthomp/protect3/src/protect/common.py", line 138, in docker_call
	    raise RuntimeError('docker command returned a non-zero exit status (%s)' % err.returncode +
	RuntimeError: docker command returned a non-zero exit status (1)for command "docker run --rm=true -v /home/drkthomp/workDir/node-77a2b3ac-69eb-4325-9205-afc132e2b6e3-1e53f69f16d74e0b881e7db602b2d2c3/tmpyqubeh1w/b2b182ee-f0fa-4d4e-9fc7-ba1a0a3a14e9:/data --log-driver=none aarjunrao/phlat:1.0 -1 /data/input_1.fastq -2 /data/input_2.fastq -index /data/index4phlat -b2url /usr/local/bin/bowtie2 -tag tumor_rna -e /home/phlat-1.0 -o /data -p 4"
	[2020-10-19T15:17:36-0700] [MainThread] [E] [toil.worker] Exiting the worker because of a failed job on host drkthomp-virtualbox
	{'input_1.fastq': '/home/drkthomp/workDir/node-77a2b3ac-69eb-4325-9205-afc132e2b6e3-1e53f69f16d74e0b881e7db602b2d2c3/tmpyqubeh1w/b2b182ee-f0fa-4d4e-9fc7-ba1a0a3a14e9/input_1.fastq', 'input_2.fastq': '/home/drkthomp/workDir/node-77a2b3ac-69eb-4325-9205-afc132e2b6e3-1e53f69f16d74e0b881e7db602b2d2c3/tmpyqubeh1w/b2b182ee-f0fa-4d4e-9fc7-ba1a0a3a14e9/input_2.fastq', 'phlat_index.tar.gz': '/home/drkthomp/workDir/node-77a2b3ac-69eb-4325-9205-afc132e2b6e3-1e53f69f16d74e0b881e7db602b2d2c3/tmpyqubeh1w/b2b182ee-f0fa-4d4e-9fc7-ba1a0a3a14e9/phlat_index.tar.gz'}
<=========
[2020-10-19T15:17:37-0700] [MainThread] [W] [toil.jobGraph] Due to failure we are reducing the remaining retry count of job 'run_phlat' kind-run_phlat/instance-2oiyd0li with ID kind-run_phlat/instance-2oiyd0li to 0
[2020-10-19T15:17:37-0700] [MainThread] [W] [toil.leader] Job 'run_phlat' kind-run_phlat/instance-2oiyd0li with ID kind-run_phlat/instance-2oiyd0li is completely failed
[2020-10-19T15:57:52-0700] [MainThread] [I] [toil.leader] 0 jobs are running, 1 jobs are issued and waiting to run
