[2020-11-17T10:01:55-0800] [MainThread] [C] [toil.jobStores.abstractJobStore] Repairing job: kind-run_cutadapt/instance-zdc0z58x
[2020-11-17T10:01:55-0800] [MainThread] [C] [toil.jobStores.abstractJobStore] Repairing job: kind-run_bwa/instance-fvcm11nr
[2020-11-17T10:01:55-0800] [MainThread] [C] [toil.jobStores.abstractJobStore] Repairing job: kind-parse_config_file/instance-ml5szru_
[2020-11-17T10:01:55-0800] [MainThread] [C] [toil.jobStores.abstractJobStore] Repairing job: kind-run_phlat/instance-3chuyae2
[2020-11-17T10:01:55-0800] [MainThread] [C] [toil.jobStores.abstractJobStore] Repairing job: kind-run_phlat/instance-rssn99a0
[2020-11-17T10:01:55-0800] [MainThread] [C] [toil.jobStores.abstractJobStore] Repairing job: kind-run_phlat/instance-z35qoqn5
[2020-11-17T10:01:55-0800] [MainThread] [C] [toil.jobStores.abstractJobStore] Repairing job: kind-run_bwa/instance-bou2djh0
[2020-11-17T10:01:55-0800] [MainThread] [I] [toil] Running Toil version 4.2.0-3aa1da130141039cb357efe36d7df9b9f6ae9b5b on host mustard.
[2020-11-17T10:01:56-0800] [MainThread] [I] [toil.leader] Issued job 'run_phlat' kind-run_phlat/instance-3chuyae2 with job batch system ID: 0 and cores: 80, disk: 8.4 G, and memory: 2.0 G
[2020-11-17T10:01:56-0800] [MainThread] [I] [toil.leader] Issued job 'run_bwa' kind-run_bwa/instance-bou2djh0 with job batch system ID: 1 and cores: 80, disk: 13.4 G, and memory: 12.0 G
[2020-11-17T10:01:56-0800] [MainThread] [I] [toil.leader] Issued job 'run_phlat' kind-run_phlat/instance-z35qoqn5 with job batch system ID: 2 and cores: 80, disk: 8.3 G, and memory: 2.0 G
[2020-11-17T10:01:56-0800] [MainThread] [I] [toil.leader] Issued job 'run_bwa' kind-run_bwa/instance-fvcm11nr with job batch system ID: 3 and cores: 80, disk: 12.8 G, and memory: 12.0 G
[2020-11-17T10:01:56-0800] [MainThread] [I] [toil.leader] Issued job 'run_phlat' kind-run_phlat/instance-rssn99a0 with job batch system ID: 4 and cores: 80, disk: 8.2 G, and memory: 2.0 G
[2020-11-17T10:01:56-0800] [MainThread] [I] [toil.leader] Issued job 'run_cutadapt' kind-run_cutadapt/instance-zdc0z58x with job batch system ID: 5 and cores: 1, disk: 2.0 G, and memory: 2.0 G
[2020-11-17T10:01:56-0800] [MainThread] [I] [toil.worker] Redirecting logging to /private/home/drkthomp/protect3/workDir/node-60141861-48d9-4a88-81d8-ba092a076b7d-e8611b53-bdab-4598-acae-87977f99831e/tmplcmx1t4b/worker_log.txt
[2020-11-17T10:01:56-0800] [MainThread] [I] [toil.worker] Redirecting logging to /private/home/drkthomp/protect3/workDir/node-60141861-48d9-4a88-81d8-ba092a076b7d-e8611b53-bdab-4598-acae-87977f99831e/tmpny6uf6cr/worker_log.txt
[2020-11-17T10:01:58-0800] [MainThread] [I] [toil.leader] 2 jobs are running, 4 jobs are issued and waiting to run
[2020-11-17T10:18:23-0800] [Thread-1  ] [E] [toil.batchSystems.singleMachine] Got exit code 1 (indicating failure) from job _toil_worker run_phlat file:/scratch/drkthomp/jobStore kind-run_phlat/instance-3chuyae2.
[2020-11-17T10:18:23-0800] [MainThread] [W] [toil.leader] Job failed with exit value 1: 'run_phlat' kind-run_phlat/instance-3chuyae2
[2020-11-17T10:18:23-0800] [MainThread] [W] [toil.leader] The job seems to have left a log file, indicating failure: 'run_phlat' kind-run_phlat/instance-3chuyae2
[2020-11-17T10:18:23-0800] [MainThread] [W] [toil.leader] Log from job kind-run_phlat/instance-3chuyae2 follows:
=========>
	[2020-11-17T10:01:56-0800] [MainThread] [I] [toil.worker] ---TOIL WORKER OUTPUT LOG---
	[2020-11-17T10:01:56-0800] [MainThread] [I] [toil] Running Toil version 4.2.0-3aa1da130141039cb357efe36d7df9b9f6ae9b5b on host mustard.
	Traceback (most recent call last):
	  File "/private/home/drkthomp/protect3/venv/lib/python3.6/site-packages/toil/worker.py", line 368, in workerScript
	    job._runner(jobGraph=jobGraph, jobStore=jobStore, fileStore=fileStore, defer=defer)
	  File "/private/home/drkthomp/protect3/venv/lib/python3.6/site-packages/toil/job.py", line 1424, in _runner
	    returnValues = self._run(jobGraph, fileStore)
	  File "/private/home/drkthomp/protect3/venv/lib/python3.6/site-packages/toil/job.py", line 1361, in _run
	    return self.run(fileStore)
	  File "/private/home/drkthomp/protect3/venv/lib/python3.6/site-packages/toil/job.py", line 1565, in run
	    rValue = userFunction(*((self,) + tuple(self._args)), **self._kwargs)
	  File "/private/home/drkthomp/protect3/src/protect/haplotyping/phlat.py", line 62, in run_phlat
	    input_files['phlat_index'] = untargz(input_files['phlat_index.tar.gz'], work_dir)
	  File "/private/home/drkthomp/protect3/src/protect/common.py", line 158, in untargz
	    tarball.extractall(path=untar_to_dir)
	  File "/private/home/drkthomp/protect3/venv/lib64/python3.6/tarfile.py", line 2008, in extractall
	    numeric_owner=numeric_owner)
	  File "/private/home/drkthomp/protect3/venv/lib64/python3.6/tarfile.py", line 2050, in extract
	    numeric_owner=numeric_owner)
	  File "/private/home/drkthomp/protect3/venv/lib64/python3.6/tarfile.py", line 2120, in _extract_member
	    self.makefile(tarinfo, targetpath)
	  File "/private/home/drkthomp/protect3/venv/lib64/python3.6/tarfile.py", line 2169, in makefile
	    copyfileobj(source, target, tarinfo.size, ReadError, bufsize)
	OSError: [Errno 122] Disk quota exceeded
	[2020-11-17T10:18:19-0800] [MainThread] [E] [toil.worker] Exiting the worker because of a failed job on host mustard
	{'input_1.fastq': '/private/home/drkthomp/protect3/workDir/node-60141861-48d9-4a88-81d8-ba092a076b7d-e8611b53-bdab-4598-acae-87977f99831e/tmplcmx1t4b/0a69aeb0-5ac3-420c-a5fd-5f1f1af93eec/input_1.fastq', 'input_2.fastq': '/private/home/drkthomp/protect3/workDir/node-60141861-48d9-4a88-81d8-ba092a076b7d-e8611b53-bdab-4598-acae-87977f99831e/tmplcmx1t4b/0a69aeb0-5ac3-420c-a5fd-5f1f1af93eec/input_2.fastq', 'phlat_index.tar.gz': '/private/home/drkthomp/protect3/workDir/node-60141861-48d9-4a88-81d8-ba092a076b7d-e8611b53-bdab-4598-acae-87977f99831e/tmplcmx1t4b/0a69aeb0-5ac3-420c-a5fd-5f1f1af93eec/phlat_index.tar.gz'}
<=========
[2020-11-17T10:18:23-0800] [MainThread] [W] [toil.jobGraph] Due to failure we are reducing the remaining retry count of job 'run_phlat' kind-run_phlat/instance-3chuyae2 with ID kind-run_phlat/instance-3chuyae2 to 1
[2020-11-17T10:18:23-0800] [MainThread] [I] [toil.leader] Issued job 'run_phlat' kind-run_phlat/instance-3chuyae2 with job batch system ID: 6 and cores: 80, disk: 8.4 G, and memory: 2.0 G
[2020-11-17T10:18:24-0800] [MainThread] [I] [toil.worker] Redirecting logging to /private/home/drkthomp/protect3/workDir/node-60141861-48d9-4a88-81d8-ba092a076b7d-e8611b53-bdab-4598-acae-87977f99831e/tmpa94_fc_n/worker_log.txt
[2020-11-17T10:23:38-0800] [Thread-1  ] [E] [toil.batchSystems.singleMachine] Got exit code 1 (indicating failure) from job _toil_worker run_bwa file:/scratch/drkthomp/jobStore kind-run_bwa/instance-bou2djh0.
[2020-11-17T10:23:38-0800] [MainThread] [W] [toil.leader] Job failed with exit value 1: 'run_bwa' kind-run_bwa/instance-bou2djh0
[2020-11-17T10:23:38-0800] [MainThread] [W] [toil.leader] The job seems to have left a log file, indicating failure: 'run_bwa' kind-run_bwa/instance-bou2djh0
[2020-11-17T10:23:38-0800] [MainThread] [W] [toil.leader] Log from job kind-run_bwa/instance-bou2djh0 follows:
=========>
	[2020-11-17T10:01:56-0800] [MainThread] [I] [toil.worker] ---TOIL WORKER OUTPUT LOG---
	[2020-11-17T10:01:56-0800] [MainThread] [I] [toil] Running Toil version 4.2.0-3aa1da130141039cb357efe36d7df9b9f6ae9b5b on host mustard.
	0.7.9a: Pulling from aarjunrao/bwa
	943c334059c7: Pulling fs layer
	a1acf99303d2: Pulling fs layer
	27616aacb7b3: Pulling fs layer
	35d12cd1c9fc: Pulling fs layer
	a3ed95caeb02: Pulling fs layer
	35d12cd1c9fc: Waiting
	a3ed95caeb02: Waiting
	a27d4604b3b3: Pulling fs layer
	b23184322fd8: Pulling fs layer
	a27d4604b3b3: Waiting
	45490e2c3ebf: Pulling fs layer
	b23184322fd8: Waiting
	07bc45a5d3f9: Pulling fs layer
	2211351c9e85: Pulling fs layer
	45490e2c3ebf: Waiting
	db8e7509afc0: Pulling fs layer
	2211351c9e85: Waiting
	27616aacb7b3: Download complete
	a1acf99303d2: Download complete
	a3ed95caeb02: Verifying Checksum
	35d12cd1c9fc: Download complete
	943c334059c7: Verifying Checksum
	943c334059c7: Download complete
	b23184322fd8: Verifying Checksum
	b23184322fd8: Download complete
	45490e2c3ebf: Download complete
	07bc45a5d3f9: Verifying Checksum
	07bc45a5d3f9: Download complete
	2211351c9e85: Verifying Checksum
	2211351c9e85: Download complete
	db8e7509afc0: Verifying Checksum
	db8e7509afc0: Download complete
	943c334059c7: Pull complete
	a1acf99303d2: Pull complete
	27616aacb7b3: Pull complete
	35d12cd1c9fc: Pull complete
	a3ed95caeb02: Pull complete
	a27d4604b3b3: Verifying Checksum
	a27d4604b3b3: Download complete
	a27d4604b3b3: Pull complete
	b23184322fd8: Pull complete
	45490e2c3ebf: Pull complete
	07bc45a5d3f9: Pull complete
	2211351c9e85: Pull complete
	db8e7509afc0: Pull complete
	Digest: sha256:dbd3bf232ec8e2371bb10bc108393bdb5c7ee184bdae783a53d165f36639245f
	Status: Downloaded newer image for aarjunrao/bwa:0.7.9a
	[M::mem_pestat] analyzing insert size distribution for orientation FF...
	[M::mem_pestat] (25, 50, 75) percentile: (744, 1518, 3419)
	[M::mem_pestat] low and high boundaries for computing mean and std.dev: (1, 8769)
	[M::mem_pestat] mean and std.dev: (2133.63, 1924.92)
	[M::mem_pestat] low and high boundaries for proper pairs: (1, 11444)
	[M::mem_pestat] analyzing insert size distribution for orientation FR...
	[M::mem_pestat] (25, 50, 75) percentile: (233, 257, 275)
	[M::mem_pestat] low and high boundaries for computing mean and std.dev: (149, 359)
	[M::mem_pestat] mean and std.dev: (254.01, 30.06)
	[M::mem_pestat] low and high boundaries for proper pairs: (107, 401)
	[M::mem_pestat] analyzing insert size distribution for orientation RF...
	[M::mem_pestat] (25, 50, 75) percentile: (111, 125, 146)
	[M::mem_pestat] low and high boundaries for computing mean and std.dev: (41, 216)
	[M::mem_pestat] mean and std.dev: (127.10, 25.26)
	[M::mem_pestat] low and high boundaries for proper pairs: (6, 251)
	[M::mem_pestat] analyzing insert size distribution for orientation RR...
	[M::mem_pestat] (25, 50, 75) percentile: (865, 1736, 3570)
	[M::mem_pestat] low and high boundaries for computing mean and std.dev: (1, 8980)
	[M::mem_pestat] mean and std.dev: (2498.64, 2101.67)
	[M::mem_pestat] low and high boundaries for proper pairs: (1, 11685)
	[M::mem_pestat] skip orientation FF
	[M::mem_pestat] skip orientation RF
	[M::mem_pestat] skip orientation RR
	[main] Version: 0.7.9a-r786
	[main] CMD: /usr/local/bin/bwa mem -t 80.0 -v 1 /data/bwa_indexes/hg38 /data/dna_1.fastq /data/dna_2.fastq
	[main] Real time: 110.481 sec; CPU: 2127.537 sec
	chown: changing ownership of '/data/.jobState': Operation not permitted
	chown: changing ownership of '/data/dna_1.fastq': Operation not permitted
	chown: changing ownership of '/data/dna_2.fastq': Operation not permitted
	chown: changing ownership of '/data/bwa_index.tar.gz': Operation not permitted
	chown: changing ownership of '/data/bwa_indexes/hg38.amb': Operation not permitted
	chown: changing ownership of '/data/bwa_indexes/hg38.sa': Operation not permitted
	chown: changing ownership of '/data/bwa_indexes/hg38.bwt': Operation not permitted
	chown: changing ownership of '/data/bwa_indexes/hg38.pac': Operation not permitted
	chown: changing ownership of '/data/bwa_indexes/hg38.ann': Operation not permitted
	chown: changing ownership of '/data/bwa_indexes': Operation not permitted
	chown: changing ownership of '/data/tumor_dna.sam': Operation not permitted
	chown: changing ownership of '/data': Operation not permitted
	Traceback (most recent call last):
	  File "/private/home/drkthomp/protect3/src/protect/common.py", line 136, in docker_call
	    subprocess.check_call(call, stdout=outfile)
	  File "/usr/lib64/python3.6/subprocess.py", line 291, in check_call
	    raise CalledProcessError(retcode, cmd)
	subprocess.CalledProcessError: Command '['docker', 'run', '--rm=true', '-v', '/private/home/drkthomp/protect3/workDir/node-60141861-48d9-4a88-81d8-ba092a076b7d-e8611b53-bdab-4598-acae-87977f99831e/tmpny6uf6cr/59673ac1-349e-46f0-9a45-69a2d56c4e51:/data', '--log-driver=none', 'aarjunrao/bwa:0.7.9a', 'mem', '-t', '80.0', '-v', '1', '/data/bwa_indexes/hg38', '/data/dna_1.fastq', '/data/dna_2.fastq']' returned non-zero exit status 1.
	
	During handling of the above exception, another exception occurred:
	
	Traceback (most recent call last):
	  File "/private/home/drkthomp/protect3/venv/lib/python3.6/site-packages/toil/worker.py", line 368, in workerScript
	    job._runner(jobGraph=jobGraph, jobStore=jobStore, fileStore=fileStore, defer=defer)
	  File "/private/home/drkthomp/protect3/venv/lib/python3.6/site-packages/toil/job.py", line 1424, in _runner
	    returnValues = self._run(jobGraph, fileStore)
	  File "/private/home/drkthomp/protect3/venv/lib/python3.6/site-packages/toil/job.py", line 1361, in _run
	    return self.run(fileStore)
	  File "/private/home/drkthomp/protect3/venv/lib/python3.6/site-packages/toil/job.py", line 1565, in run
	    rValue = userFunction(*((self,) + tuple(self._args)), **self._kwargs)
	  File "/private/home/drkthomp/protect3/src/protect/alignment/dna.py", line 142, in run_bwa
	    tool_version=bwa_options['version'])
	  File "/private/home/drkthomp/protect3/src/protect/common.py", line 139, in docker_call
	    'for command \"%s\"' % ' '.join(call),)
	RuntimeError: docker command returned a non-zero exit status (1)for command "docker run --rm=true -v /private/home/drkthomp/protect3/workDir/node-60141861-48d9-4a88-81d8-ba092a076b7d-e8611b53-bdab-4598-acae-87977f99831e/tmpny6uf6cr/59673ac1-349e-46f0-9a45-69a2d56c4e51:/data --log-driver=none aarjunrao/bwa:0.7.9a mem -t 80.0 -v 1 /data/bwa_indexes/hg38 /data/dna_1.fastq /data/dna_2.fastq"
	[2020-11-17T10:23:35-0800] [MainThread] [E] [toil.worker] Exiting the worker because of a failed job on host mustard
<=========
[2020-11-17T10:23:38-0800] [MainThread] [W] [toil.jobGraph] Due to failure we are reducing the remaining retry count of job 'run_bwa' kind-run_bwa/instance-bou2djh0 with ID kind-run_bwa/instance-bou2djh0 to 1
[2020-11-17T10:23:38-0800] [MainThread] [I] [toil.leader] Issued job 'run_bwa' kind-run_bwa/instance-bou2djh0 with job batch system ID: 7 and cores: 80, disk: 13.4 G, and memory: 12.0 G
[2020-11-17T10:23:39-0800] [MainThread] [I] [toil.worker] Redirecting logging to /private/home/drkthomp/protect3/workDir/node-60141861-48d9-4a88-81d8-ba092a076b7d-e8611b53-bdab-4598-acae-87977f99831e/tmp_d21ezs7/worker_log.txt
[2020-11-17T10:32:06-0800] [Thread-1  ] [E] [toil.batchSystems.singleMachine] Got exit code 1 (indicating failure) from job _toil_worker run_phlat file:/scratch/drkthomp/jobStore kind-run_phlat/instance-z35qoqn5.
[2020-11-17T10:32:06-0800] [MainThread] [W] [toil.leader] Job failed with exit value 1: 'run_phlat' kind-run_phlat/instance-z35qoqn5
[2020-11-17T10:32:06-0800] [MainThread] [W] [toil.leader] The job seems to have left a log file, indicating failure: 'run_phlat' kind-run_phlat/instance-z35qoqn5
[2020-11-17T10:32:06-0800] [MainThread] [W] [toil.leader] Log from job kind-run_phlat/instance-z35qoqn5 follows:
=========>
	[2020-11-17T10:18:24-0800] [MainThread] [I] [toil.worker] ---TOIL WORKER OUTPUT LOG---
	[2020-11-17T10:18:24-0800] [MainThread] [I] [toil] Running Toil version 4.2.0-3aa1da130141039cb357efe36d7df9b9f6ae9b5b on host mustard.
	1.0: Pulling from aarjunrao/phlat
	943c334059c7: Already exists
	a1acf99303d2: Already exists
	27616aacb7b3: Already exists
	35d12cd1c9fc: Already exists
	a3ed95caeb02: Already exists
	a3ed95caeb02: Already exists
	a3ed95caeb02: Already exists
	a27d4604b3b3: Already exists
	b23184322fd8: Already exists
	45490e2c3ebf: Already exists
	a3ed95caeb02: Already exists
	07bc45a5d3f9: Already exists
	a3ed95caeb02: Already exists
	4e8282f9b0b2: Pulling fs layer
	d8467ea2e124: Pulling fs layer
	b53fc7d0498f: Pulling fs layer
	30ab0013e0b7: Pulling fs layer
	949d3b3c935b: Pulling fs layer
	a98c227726f6: Pulling fs layer
	4347594c2d1a: Pulling fs layer
	f13886bcc594: Pulling fs layer
	30ab0013e0b7: Waiting
	4347594c2d1a: Waiting
	a3ed95caeb02: Pulling fs layer
	949d3b3c935b: Waiting
	f13886bcc594: Waiting
	a3ed95caeb02: Waiting
	4e8282f9b0b2: Verifying Checksum
	4e8282f9b0b2: Download complete
	b53fc7d0498f: Download complete
	4e8282f9b0b2: Pull complete
	d8467ea2e124: Verifying Checksum
	d8467ea2e124: Download complete
	d8467ea2e124: Pull complete
	a98c227726f6: Download complete
	b53fc7d0498f: Pull complete
	30ab0013e0b7: Verifying Checksum
	30ab0013e0b7: Download complete
	30ab0013e0b7: Pull complete
	f13886bcc594: Download complete
	949d3b3c935b: Verifying Checksum
	949d3b3c935b: Download complete
	4347594c2d1a: Verifying Checksum
	4347594c2d1a: Download complete
	a3ed95caeb02: Download complete
	949d3b3c935b: Pull complete
	a98c227726f6: Pull complete
	4347594c2d1a: Pull complete
	f13886bcc594: Pull complete
	a3ed95caeb02: Pull complete
	Digest: sha256:a11b92ed62d9e189ae36823abeb405c8bca9f41f47fd0d956397c539f8534b5f
	Status: Downloaded newer image for aarjunrao/phlat:1.0
	Traceback (most recent call last):
	  File "/home/phlat-1.0/dist/PHLAT.py", line 59, in <module>
	    nthreads=int(val)
	ValueError: invalid literal for int() with base 10: '80.0'
	chown: changing ownership of '/data/.jobState': Operation not permitted
	chown: changing ownership of '/data/input_1.fastq': Operation not permitted
	chown: changing ownership of '/data/input_2.fastq': Operation not permitted
	chown: changing ownership of '/data/phlat_index.tar.gz': Operation not permitted
	chown: changing ownership of '/data/index4phlat/ucsc.artHLA.rev.2.bt2': Operation not permitted
	chown: changing ownership of '/data/index4phlat/ucsc.artHLA.4.bt2': Operation not permitted
	chown: changing ownership of '/data/index4phlat/ucsc.artHLA.3.bt2': Operation not permitted
	chown: changing ownership of '/data/index4phlat/ucsc.artHLA.rev.1.bt2': Operation not permitted
	chown: changing ownership of '/data/index4phlat/ucsc.artHLA.2.bt2': Operation not permitted
	chown: changing ownership of '/data/index4phlat/ucsc.artHLA.1.bt2': Operation not permitted
	chown: changing ownership of '/data/index4phlat': Operation not permitted
	chown: changing ownership of '/data': Operation not permitted
	Traceback (most recent call last):
	  File "/private/home/drkthomp/protect3/src/protect/common.py", line 136, in docker_call
	    subprocess.check_call(call, stdout=outfile)
	  File "/usr/lib64/python3.6/subprocess.py", line 291, in check_call
	    raise CalledProcessError(retcode, cmd)
	subprocess.CalledProcessError: Command '['docker', 'run', '--rm=true', '-v', '/private/home/drkthomp/protect3/workDir/node-60141861-48d9-4a88-81d8-ba092a076b7d-e8611b53-bdab-4598-acae-87977f99831e/tmpa94_fc_n/931d52d0-cfb2-41ae-a58a-17ac7019b925:/data', '--log-driver=none', 'aarjunrao/phlat:1.0', '-1', '/data/input_1.fastq', '-2', '/data/input_2.fastq', '-index', '/data/index4phlat', '-b2url', '/usr/local/bin/bowtie2', '-tag', 'normal_dna', '-e', '/home/phlat-1.0', '-o', '/data', '-p', '80.0']' returned non-zero exit status 1.
	
	During handling of the above exception, another exception occurred:
	
	Traceback (most recent call last):
	  File "/private/home/drkthomp/protect3/venv/lib/python3.6/site-packages/toil/worker.py", line 368, in workerScript
	    job._runner(jobGraph=jobGraph, jobStore=jobStore, fileStore=fileStore, defer=defer)
	  File "/private/home/drkthomp/protect3/venv/lib/python3.6/site-packages/toil/job.py", line 1424, in _runner
	    returnValues = self._run(jobGraph, fileStore)
	  File "/private/home/drkthomp/protect3/venv/lib/python3.6/site-packages/toil/job.py", line 1361, in _run
	    return self.run(fileStore)
	  File "/private/home/drkthomp/protect3/venv/lib/python3.6/site-packages/toil/job.py", line 1565, in run
	    rValue = userFunction(*((self,) + tuple(self._args)), **self._kwargs)
	  File "/private/home/drkthomp/protect3/src/protect/haplotyping/phlat.py", line 74, in run_phlat
	    dockerhub=univ_options['dockerhub'], tool_version=phlat_options['version'])
	  File "/private/home/drkthomp/protect3/src/protect/common.py", line 139, in docker_call
	    'for command \"%s\"' % ' '.join(call),)
	RuntimeError: docker command returned a non-zero exit status (1)for command "docker run --rm=true -v /private/home/drkthomp/protect3/workDir/node-60141861-48d9-4a88-81d8-ba092a076b7d-e8611b53-bdab-4598-acae-87977f99831e/tmpa94_fc_n/931d52d0-cfb2-41ae-a58a-17ac7019b925:/data --log-driver=none aarjunrao/phlat:1.0 -1 /data/input_1.fastq -2 /data/input_2.fastq -index /data/index4phlat -b2url /usr/local/bin/bowtie2 -tag normal_dna -e /home/phlat-1.0 -o /data -p 80.0"
	[2020-11-17T10:32:02-0800] [MainThread] [E] [toil.worker] Exiting the worker because of a failed job on host mustard
	{'input_1.fastq': '/private/home/drkthomp/protect3/workDir/node-60141861-48d9-4a88-81d8-ba092a076b7d-e8611b53-bdab-4598-acae-87977f99831e/tmpa94_fc_n/931d52d0-cfb2-41ae-a58a-17ac7019b925/input_1.fastq', 'input_2.fastq': '/private/home/drkthomp/protect3/workDir/node-60141861-48d9-4a88-81d8-ba092a076b7d-e8611b53-bdab-4598-acae-87977f99831e/tmpa94_fc_n/931d52d0-cfb2-41ae-a58a-17ac7019b925/input_2.fastq', 'phlat_index.tar.gz': '/private/home/drkthomp/protect3/workDir/node-60141861-48d9-4a88-81d8-ba092a076b7d-e8611b53-bdab-4598-acae-87977f99831e/tmpa94_fc_n/931d52d0-cfb2-41ae-a58a-17ac7019b925/phlat_index.tar.gz'}
<=========
[2020-11-17T10:32:06-0800] [MainThread] [W] [toil.jobGraph] Due to failure we are reducing the remaining retry count of job 'run_phlat' kind-run_phlat/instance-z35qoqn5 with ID kind-run_phlat/instance-z35qoqn5 to 1
[2020-11-17T10:32:06-0800] [MainThread] [I] [toil.leader] Issued job 'run_phlat' kind-run_phlat/instance-z35qoqn5 with job batch system ID: 8 and cores: 80, disk: 8.3 G, and memory: 2.0 G
[2020-11-17T10:32:48-0800] [MainThread] [I] [toil.worker] Redirecting logging to /private/home/drkthomp/protect3/workDir/node-60141861-48d9-4a88-81d8-ba092a076b7d-e8611b53-bdab-4598-acae-87977f99831e/tmp8_w41v8t/worker_log.txt
[2020-11-17T10:35:15-0800] [Thread-1  ] [E] [toil.batchSystems.singleMachine] Got exit code 1 (indicating failure) from job _toil_worker run_phlat file:/scratch/drkthomp/jobStore kind-run_phlat/instance-rssn99a0.
[2020-11-17T10:35:15-0800] [MainThread] [W] [toil.leader] Job failed with exit value 1: 'run_phlat' kind-run_phlat/instance-rssn99a0
[2020-11-17T10:35:15-0800] [MainThread] [W] [toil.leader] The job seems to have left a log file, indicating failure: 'run_phlat' kind-run_phlat/instance-rssn99a0
[2020-11-17T10:35:15-0800] [MainThread] [W] [toil.leader] Log from job kind-run_phlat/instance-rssn99a0 follows:
=========>
	[2020-11-17T10:23:39-0800] [MainThread] [I] [toil.worker] ---TOIL WORKER OUTPUT LOG---
	[2020-11-17T10:23:39-0800] [MainThread] [I] [toil] Running Toil version 4.2.0-3aa1da130141039cb357efe36d7df9b9f6ae9b5b on host mustard.
	Traceback (most recent call last):
	  File "/home/phlat-1.0/dist/PHLAT.py", line 59, in <module>
	    nthreads=int(val)
	ValueError: invalid literal for int() with base 10: '80.0'
	chown: changing ownership of '/data/.jobState': Operation not permitted
	chown: changing ownership of '/data/input_1.fastq': Operation not permitted
	chown: changing ownership of '/data/input_2.fastq': Operation not permitted
	chown: changing ownership of '/data/phlat_index.tar.gz': Operation not permitted
	chown: changing ownership of '/data/index4phlat/ucsc.artHLA.rev.2.bt2': Operation not permitted
	chown: changing ownership of '/data/index4phlat/ucsc.artHLA.4.bt2': Operation not permitted
	chown: changing ownership of '/data/index4phlat/ucsc.artHLA.3.bt2': Operation not permitted
	chown: changing ownership of '/data/index4phlat/ucsc.artHLA.rev.1.bt2': Operation not permitted
	chown: changing ownership of '/data/index4phlat/ucsc.artHLA.2.bt2': Operation not permitted
	chown: changing ownership of '/data/index4phlat/ucsc.artHLA.1.bt2': Operation not permitted
	chown: changing ownership of '/data/index4phlat': Operation not permitted
	chown: changing ownership of '/data': Operation not permitted
	Traceback (most recent call last):
	  File "/private/home/drkthomp/protect3/src/protect/common.py", line 136, in docker_call
	    subprocess.check_call(call, stdout=outfile)
	  File "/usr/lib64/python3.6/subprocess.py", line 291, in check_call
	    raise CalledProcessError(retcode, cmd)
	subprocess.CalledProcessError: Command '['docker', 'run', '--rm=true', '-v', '/private/home/drkthomp/protect3/workDir/node-60141861-48d9-4a88-81d8-ba092a076b7d-e8611b53-bdab-4598-acae-87977f99831e/tmp_d21ezs7/ff0f1f0e-a853-4357-9246-fb5aa3feb95c:/data', '--log-driver=none', 'aarjunrao/phlat:1.0', '-1', '/data/input_1.fastq', '-2', '/data/input_2.fastq', '-index', '/data/index4phlat', '-b2url', '/usr/local/bin/bowtie2', '-tag', 'tumor_rna', '-e', '/home/phlat-1.0', '-o', '/data', '-p', '80.0']' returned non-zero exit status 1.
	
	During handling of the above exception, another exception occurred:
	
	Traceback (most recent call last):
	  File "/private/home/drkthomp/protect3/venv/lib/python3.6/site-packages/toil/worker.py", line 368, in workerScript
	    job._runner(jobGraph=jobGraph, jobStore=jobStore, fileStore=fileStore, defer=defer)
	  File "/private/home/drkthomp/protect3/venv/lib/python3.6/site-packages/toil/job.py", line 1424, in _runner
	    returnValues = self._run(jobGraph, fileStore)
	  File "/private/home/drkthomp/protect3/venv/lib/python3.6/site-packages/toil/job.py", line 1361, in _run
	    return self.run(fileStore)
	  File "/private/home/drkthomp/protect3/venv/lib/python3.6/site-packages/toil/job.py", line 1565, in run
	    rValue = userFunction(*((self,) + tuple(self._args)), **self._kwargs)
	  File "/private/home/drkthomp/protect3/src/protect/haplotyping/phlat.py", line 74, in run_phlat
	    dockerhub=univ_options['dockerhub'], tool_version=phlat_options['version'])
	  File "/private/home/drkthomp/protect3/src/protect/common.py", line 139, in docker_call
	    'for command \"%s\"' % ' '.join(call),)
	RuntimeError: docker command returned a non-zero exit status (1)for command "docker run --rm=true -v /private/home/drkthomp/protect3/workDir/node-60141861-48d9-4a88-81d8-ba092a076b7d-e8611b53-bdab-4598-acae-87977f99831e/tmp_d21ezs7/ff0f1f0e-a853-4357-9246-fb5aa3feb95c:/data --log-driver=none aarjunrao/phlat:1.0 -1 /data/input_1.fastq -2 /data/input_2.fastq -index /data/index4phlat -b2url /usr/local/bin/bowtie2 -tag tumor_rna -e /home/phlat-1.0 -o /data -p 80.0"
	[2020-11-17T10:35:10-0800] [MainThread] [E] [toil.worker] Exiting the worker because of a failed job on host mustard
	{'input_1.fastq': '/private/home/drkthomp/protect3/workDir/node-60141861-48d9-4a88-81d8-ba092a076b7d-e8611b53-bdab-4598-acae-87977f99831e/tmp_d21ezs7/ff0f1f0e-a853-4357-9246-fb5aa3feb95c/input_1.fastq', 'input_2.fastq': '/private/home/drkthomp/protect3/workDir/node-60141861-48d9-4a88-81d8-ba092a076b7d-e8611b53-bdab-4598-acae-87977f99831e/tmp_d21ezs7/ff0f1f0e-a853-4357-9246-fb5aa3feb95c/input_2.fastq', 'phlat_index.tar.gz': '/private/home/drkthomp/protect3/workDir/node-60141861-48d9-4a88-81d8-ba092a076b7d-e8611b53-bdab-4598-acae-87977f99831e/tmp_d21ezs7/ff0f1f0e-a853-4357-9246-fb5aa3feb95c/phlat_index.tar.gz'}
<=========
[2020-11-17T10:35:15-0800] [MainThread] [W] [toil.jobGraph] Due to failure we are reducing the remaining retry count of job 'run_phlat' kind-run_phlat/instance-rssn99a0 with ID kind-run_phlat/instance-rssn99a0 to 1
[2020-11-17T10:35:15-0800] [MainThread] [I] [toil.leader] Issued job 'run_phlat' kind-run_phlat/instance-rssn99a0 with job batch system ID: 9 and cores: 80, disk: 8.2 G, and memory: 2.0 G
[2020-11-17T10:35:16-0800] [MainThread] [I] [toil.worker] Redirecting logging to /private/home/drkthomp/protect3/workDir/node-60141861-48d9-4a88-81d8-ba092a076b7d-e8611b53-bdab-4598-acae-87977f99831e/tmpn_evxpvz/worker_log.txt
[2020-11-17T10:35:16-0800] [Thread-1  ] [E] [toil.batchSystems.singleMachine] Got exit code 1 (indicating failure) from job _toil_worker run_cutadapt file:/scratch/drkthomp/jobStore kind-run_cutadapt/instance-zdc0z58x.
[2020-11-17T10:35:16-0800] [MainThread] [W] [toil.leader] Job failed with exit value 1: 'run_cutadapt' kind-run_cutadapt/instance-zdc0z58x
[2020-11-17T10:35:16-0800] [MainThread] [W] [toil.leader] The job seems to have left a log file, indicating failure: 'run_cutadapt' kind-run_cutadapt/instance-zdc0z58x
[2020-11-17T10:35:16-0800] [MainThread] [W] [toil.leader] Log from job kind-run_cutadapt/instance-zdc0z58x follows:
=========>
	[2020-11-17T10:32:48-0800] [MainThread] [I] [toil.worker] ---TOIL WORKER OUTPUT LOG---
	[2020-11-17T10:32:48-0800] [MainThread] [I] [toil] Running Toil version 4.2.0-3aa1da130141039cb357efe36d7df9b9f6ae9b5b on host mustard.
	1.9.1: Pulling from aarjunrao/cutadapt
	943c334059c7: Already exists
	a1acf99303d2: Already exists
	27616aacb7b3: Already exists
	35d12cd1c9fc: Already exists
	a3ed95caeb02: Already exists
	a3ed95caeb02: Already exists
	a3ed95caeb02: Already exists
	a27d4604b3b3: Already exists
	b23184322fd8: Already exists
	45490e2c3ebf: Already exists
	a3ed95caeb02: Already exists
	07bc45a5d3f9: Already exists
	a3ed95caeb02: Already exists
	e99a83101e51: Pulling fs layer
	c948cbf08432: Pulling fs layer
	6554961e8521: Pulling fs layer
	a3ed95caeb02: Pulling fs layer
	a3ed95caeb02: Waiting
	6554961e8521: Verifying Checksum
	6554961e8521: Download complete
	a3ed95caeb02: Download complete
	c948cbf08432: Verifying Checksum
	c948cbf08432: Download complete
	e99a83101e51: Verifying Checksum
	e99a83101e51: Download complete
	e99a83101e51: Pull complete
	c948cbf08432: Pull complete
	6554961e8521: Pull complete
	a3ed95caeb02: Pull complete
	Digest: sha256:0bb80f77facdceb34bb619c871760b2035391a0c17ef35873898f03a18eb49e2
	Status: Downloaded newer image for aarjunrao/cutadapt:1.9.1
	This is cutadapt 1.9.1 with Python 2.7.6
	Command line parameters: -a AGATCGGAAGAG -A AGATCGGAAGAG -m 35 -o /data/rna_cutadapt_1.fastq.gz -p /data/rna_cutadapt_2.fastq.gz /data/rna_1.fastq /data/rna_2.fastq
	Trimming 2 adapters with at most 10.0% errors in paired-end mode ...
	Finished in 45.30 s (29 us/read; 2.07 M reads/minute).
	
	=== Summary ===
	
	Total read pairs processed:          1,562,357
	  Read 1 with adapter:                  46,459 (3.0%)
	  Read 2 with adapter:                  45,067 (2.9%)
	Pairs that were too short:               2,154 (0.1%)
	Pairs written (passing filters):     1,560,203 (99.9%)
	
	Total basepairs processed:   312,471,400 bp
	  Read 1:   156,235,700 bp
	  Read 2:   156,235,700 bp
	Total written (filtered):    311,600,470 bp (99.7%)
	  Read 1:   155,800,190 bp
	  Read 2:   155,800,280 bp
	
	=== First read: Adapter 1 ===
	
	Sequence: AGATCGGAAGAG; Type: regular 3'; Length: 12; Trimmed: 46459 times.
	
	No. of allowed errors:
	0-9 bp: 0; 10-12 bp: 1
	
	Bases preceding removed adapters:
	  A: 32.1%
	  C: 27.2%
	  G: 23.0%
	  T: 13.9%
	  none/other: 3.8%
	
	Overview of removed sequences
	length	count	expect	max.err	error counts
	3	31191	24411.8	0	31191
	4	6994	6103.0	0	6994
	5	1726	1525.7	0	1726
	6	408	381.4	0	408
	7	294	95.4	0	294
	8	224	23.8	0	224
	9	244	6.0	0	220 24
	10	235	1.5	1	196 39
	11	263	0.4	1	223 40
	12	169	0.1	1	161 8
	13	177	0.1	1	170 7
	14	160	0.1	1	153 7
	15	148	0.1	1	144 4
	16	154	0.1	1	146 8
	17	127	0.1	1	118 9
	18	109	0.1	1	101 8
	19	108	0.1	1	101 7
	20	99	0.1	1	92 7
	21	107	0.1	1	98 9
	22	84	0.1	1	78 6
	23	87	0.1	1	81 6
	24	74	0.1	1	66 8
	25	74	0.1	1	66 8
	26	70	0.1	1	65 5
	27	68	0.1	1	62 6
	28	75	0.1	1	68 7
	29	60	0.1	1	56 4
	30	52	0.1	1	44 8
	31	53	0.1	1	50 3
	32	47	0.1	1	39 8
	33	69	0.1	1	63 6
	34	53	0.1	1	48 5
	35	67	0.1	1	62 5
	36	46	0.1	1	39 7
	37	29	0.1	1	26 3
	38	46	0.1	1	41 5
	39	31	0.1	1	29 2
	40	31	0.1	1	24 7
	41	37	0.1	1	31 6
	42	36	0.1	1	28 8
	43	23	0.1	1	18 5
	44	26	0.1	1	18 8
	45	31	0.1	1	23 8
	46	24	0.1	1	14 10
	47	25	0.1	1	21 4
	48	17	0.1	1	14 3
	49	23	0.1	1	18 5
	50	15	0.1	1	12 3
	51	23	0.1	1	19 4
	52	12	0.1	1	9 3
	53	17	0.1	1	12 5
	54	17	0.1	1	11 6
	55	11	0.1	1	9 2
	56	12	0.1	1	5 7
	57	10	0.1	1	6 4
	58	8	0.1	1	3 5
	59	11	0.1	1	7 4
	60	8	0.1	1	2 6
	61	9	0.1	1	6 3
	62	6	0.1	1	3 3
	63	9	0.1	1	4 5
	64	12	0.1	1	6 6
	65	11	0.1	1	5 6
	66	9	0.1	1	3 6
	67	7	0.1	1	0 7
	68	9	0.1	1	2 7
	69	7	0.1	1	3 4
	70	10	0.1	1	3 7
	71	6	0.1	1	0 6
	72	7	0.1	1	1 6
	73	5	0.1	1	0 5
	74	7	0.1	1	2 5
	75	6	0.1	1	1 5
	76	2	0.1	1	0 2
	77	5	0.1	1	0 5
	78	7	0.1	1	4 3
	79	5	0.1	1	0 5
	80	8	0.1	1	2 6
	81	1	0.1	1	1
	82	4	0.1	1	1 3
	83	6	0.1	1	1 5
	84	4	0.1	1	1 3
	85	4	0.1	1	1 3
	86	6	0.1	1	2 4
	87	2	0.1	1	0 2
	88	6	0.1	1	0 6
	89	9	0.1	1	1 8
	90	6	0.1	1	1 5
	91	5	0.1	1	0 5
	92	6	0.1	1	2 4
	93	5	0.1	1	0 5
	94	4	0.1	1	0 4
	95	7	0.1	1	0 7
	96	4	0.1	1	0 4
	97	4	0.1	1	0 4
	98	2	0.1	1	0 2
	99	5	0.1	1	0 5
	100	1783	0.1	1	0 1783
	
	=== Second read: Adapter 2 ===
	
	Sequence: AGATCGGAAGAG; Type: regular 3'; Length: 12; Trimmed: 45067 times.
	
	No. of allowed errors:
	0-9 bp: 0; 10-12 bp: 1
	
	Bases preceding removed adapters:
	  A: 32.9%
	  C: 27.6%
	  G: 23.8%
	  T: 14.4%
	  none/other: 1.4%
	
	Overview of removed sequences
	length	count	expect	max.err	error counts
	3	31015	24411.8	0	31015
	4	6968	6103.0	0	6968
	5	1707	1525.7	0	1707
	6	392	381.4	0	392
	7	290	95.4	0	290
	8	223	23.8	0	223
	9	236	6.0	0	211 25
	10	220	1.5	1	195 25
	11	250	0.4	1	215 35
	12	176	0.1	1	155 21
	13	176	0.1	1	168 8
	14	157	0.1	1	148 9
	15	155	0.1	1	143 12
	16	155	0.1	1	145 10
	17	129	0.1	1	116 13
	18	109	0.1	1	98 11
	19	109	0.1	1	98 11
	20	99	0.1	1	87 12
	21	109	0.1	1	101 8
	22	82	0.1	1	74 8
	23	88	0.1	1	76 12
	24	71	0.1	1	60 11
	25	75	0.1	1	65 10
	26	71	0.1	1	63 8
	27	63	0.1	1	58 5
	28	74	0.1	1	70 4
	29	58	0.1	1	52 6
	30	51	0.1	1	45 6
	31	58	0.1	1	49 9
	32	44	0.1	1	37 7
	33	71	0.1	1	61 10
	34	54	0.1	1	45 9
	35	69	0.1	1	64 5
	36	45	0.1	1	39 6
	37	29	0.1	1	24 5
	38	47	0.1	1	36 11
	39	35	0.1	1	26 9
	40	34	0.1	1	25 9
	41	39	0.1	1	32 7
	42	33	0.1	1	28 5
	43	26	0.1	1	18 8
	44	29	0.1	1	16 13
	45	28	0.1	1	22 6
	46	16	0.1	1	13 3
	47	23	0.1	1	19 4
	48	20	0.1	1	12 8
	49	27	0.1	1	19 8
	50	21	0.1	1	14 7
	51	30	0.1	1	20 10
	52	12	0.1	1	8 4
	53	15	0.1	1	10 5
	54	16	0.1	1	11 5
	55	11	0.1	1	10 1
	56	13	0.1	1	6 7
	57	13	0.1	1	6 7
	58	12	0.1	1	4 8
	59	12	0.1	1	6 6
	60	6	0.1	1	1 5
	61	8	0.1	1	4 4
	62	6	0.1	1	2 4
	63	10	0.1	1	5 5
	64	9	0.1	1	5 4
	65	13	0.1	1	5 8
	66	13	0.1	1	2 11
	67	6	0.1	1	2 4
	68	5	0.1	1	2 3
	69	6	0.1	1	3 3
	70	6	0.1	1	3 3
	71	3	0.1	1	0 3
	72	6	0.1	1	2 4
	73	11	0.1	1	2 9
	74	15	0.1	1	2 13
	75	7	0.1	1	0 7
	76	7	0.1	1	0 7
	77	5	0.1	1	0 5
	78	9	0.1	1	5 4
	79	7	0.1	1	2 5
	80	6	0.1	1	2 4
	81	5	0.1	1	1 4
	82	6	0.1	1	2 4
	83	7	0.1	1	1 6
	84	4	0.1	1	0 4
	85	1	0.1	1	1
	86	5	0.1	1	1 4
	87	12	0.1	1	1 11
	88	3	0.1	1	0 3
	89	5	0.1	1	2 3
	90	3	0.1	1	1 2
	91	8	0.1	1	1 7
	92	6	0.1	1	1 5
	93	2	0.1	1	0 2
	94	4	0.1	1	0 4
	95	3	0.1	1	0 3
	96	3	0.1	1	0 3
	97	1	0.1	1	0 1
	98	4	0.1	1	0 4
	99	6	0.1	1	0 6
	100	625	0.1	1	0 625
	
	chown: changing ownership of '/data/.jobState': Operation not permitted
	chown: changing ownership of '/data/rna_1.fastq': Operation not permitted
	chown: changing ownership of '/data/rna_2.fastq': Operation not permitted
	chown: changing ownership of '/data/rna_cutadapt_1.fastq.gz': Operation not permitted
	chown: changing ownership of '/data/rna_cutadapt_2.fastq.gz': Operation not permitted
	chown: changing ownership of '/data': Operation not permitted
	Traceback (most recent call last):
	  File "/private/home/drkthomp/protect3/src/protect/common.py", line 136, in docker_call
	    subprocess.check_call(call, stdout=outfile)
	  File "/usr/lib64/python3.6/subprocess.py", line 291, in check_call
	    raise CalledProcessError(retcode, cmd)
	subprocess.CalledProcessError: Command '['docker', 'run', '--rm=true', '-v', '/private/home/drkthomp/protect3/workDir/node-60141861-48d9-4a88-81d8-ba092a076b7d-e8611b53-bdab-4598-acae-87977f99831e/tmp8_w41v8t/fed56e00-bdad-4d5b-b416-0e7a320a3433:/data', '--log-driver=none', 'aarjunrao/cutadapt:1.9.1', '-a', 'AGATCGGAAGAG', '-A', 'AGATCGGAAGAG', '-m', '35', '-o', '/data/rna_cutadapt_1.fastq.gz', '-p', '/data/rna_cutadapt_2.fastq.gz', '/data/rna_1.fastq', '/data/rna_2.fastq']' returned non-zero exit status 1.
	
	During handling of the above exception, another exception occurred:
	
	Traceback (most recent call last):
	  File "/private/home/drkthomp/protect3/venv/lib/python3.6/site-packages/toil/worker.py", line 368, in workerScript
	    job._runner(jobGraph=jobGraph, jobStore=jobStore, fileStore=fileStore, defer=defer)
	  File "/private/home/drkthomp/protect3/venv/lib/python3.6/site-packages/toil/job.py", line 1424, in _runner
	    returnValues = self._run(jobGraph, fileStore)
	  File "/private/home/drkthomp/protect3/venv/lib/python3.6/site-packages/toil/job.py", line 1361, in _run
	    return self.run(fileStore)
	  File "/private/home/drkthomp/protect3/venv/lib/python3.6/site-packages/toil/job.py", line 1565, in run
	    rValue = userFunction(*((self,) + tuple(self._args)), **self._kwargs)
	  File "/private/home/drkthomp/protect3/src/protect/qc/rna.py", line 59, in run_cutadapt
	    dockerhub=univ_options['dockerhub'], tool_version=cutadapt_options['version'])
	  File "/private/home/drkthomp/protect3/src/protect/common.py", line 139, in docker_call
	    'for command \"%s\"' % ' '.join(call),)
	RuntimeError: docker command returned a non-zero exit status (1)for command "docker run --rm=true -v /private/home/drkthomp/protect3/workDir/node-60141861-48d9-4a88-81d8-ba092a076b7d-e8611b53-bdab-4598-acae-87977f99831e/tmp8_w41v8t/fed56e00-bdad-4d5b-b416-0e7a320a3433:/data --log-driver=none aarjunrao/cutadapt:1.9.1 -a AGATCGGAAGAG -A AGATCGGAAGAG -m 35 -o /data/rna_cutadapt_1.fastq.gz -p /data/rna_cutadapt_2.fastq.gz /data/rna_1.fastq /data/rna_2.fastq"
	[2020-11-17T10:35:16-0800] [MainThread] [E] [toil.worker] Exiting the worker because of a failed job on host mustard
<=========
[2020-11-17T10:35:16-0800] [MainThread] [W] [toil.jobGraph] Due to failure we are reducing the remaining retry count of job 'run_cutadapt' kind-run_cutadapt/instance-zdc0z58x with ID kind-run_cutadapt/instance-zdc0z58x to 1
[2020-11-17T10:35:16-0800] [MainThread] [I] [toil.leader] Issued job 'run_cutadapt' kind-run_cutadapt/instance-zdc0z58x with job batch system ID: 10 and cores: 1, disk: 2.0 G, and memory: 2.0 G
[2020-11-17T10:35:32-0800] [MainThread] [I] [toil.worker] Redirecting logging to /private/home/drkthomp/protect3/workDir/node-60141861-48d9-4a88-81d8-ba092a076b7d-e8611b53-bdab-4598-acae-87977f99831e/tmpvxfdc39j/worker_log.txt
[2020-11-17T10:49:11-0800] [Thread-1  ] [E] [toil.batchSystems.singleMachine] Got exit code 1 (indicating failure) from job _toil_worker run_bwa file:/scratch/drkthomp/jobStore kind-run_bwa/instance-fvcm11nr.
[2020-11-17T10:49:11-0800] [MainThread] [W] [toil.leader] Job failed with exit value 1: 'run_bwa' kind-run_bwa/instance-fvcm11nr
[2020-11-17T10:49:11-0800] [MainThread] [W] [toil.leader] The job seems to have left a log file, indicating failure: 'run_bwa' kind-run_bwa/instance-fvcm11nr
[2020-11-17T10:49:11-0800] [MainThread] [W] [toil.leader] Log from job kind-run_bwa/instance-fvcm11nr follows:
=========>
	[2020-11-17T10:35:16-0800] [MainThread] [I] [toil.worker] ---TOIL WORKER OUTPUT LOG---
	[2020-11-17T10:35:16-0800] [MainThread] [I] [toil] Running Toil version 4.2.0-3aa1da130141039cb357efe36d7df9b9f6ae9b5b on host mustard.
	Traceback (most recent call last):
	  File "/private/home/drkthomp/protect3/venv/lib/python3.6/site-packages/toil/worker.py", line 368, in workerScript
	    job._runner(jobGraph=jobGraph, jobStore=jobStore, fileStore=fileStore, defer=defer)
	  File "/private/home/drkthomp/protect3/venv/lib/python3.6/site-packages/toil/job.py", line 1424, in _runner
	    returnValues = self._run(jobGraph, fileStore)
	  File "/private/home/drkthomp/protect3/venv/lib/python3.6/site-packages/toil/job.py", line 1361, in _run
	    return self.run(fileStore)
	  File "/private/home/drkthomp/protect3/venv/lib/python3.6/site-packages/toil/job.py", line 1565, in run
	    rValue = userFunction(*((self,) + tuple(self._args)), **self._kwargs)
	  File "/private/home/drkthomp/protect3/src/protect/alignment/dna.py", line 130, in run_bwa
	    input_files['bwa_index'] = untargz(input_files['bwa_index.tar.gz'], work_dir)
	  File "/private/home/drkthomp/protect3/src/protect/common.py", line 158, in untargz
	    tarball.extractall(path=untar_to_dir)
	  File "/private/home/drkthomp/protect3/venv/lib64/python3.6/tarfile.py", line 2008, in extractall
	    numeric_owner=numeric_owner)
	  File "/private/home/drkthomp/protect3/venv/lib64/python3.6/tarfile.py", line 2050, in extract
	    numeric_owner=numeric_owner)
	  File "/private/home/drkthomp/protect3/venv/lib64/python3.6/tarfile.py", line 2120, in _extract_member
	    self.makefile(tarinfo, targetpath)
	  File "/private/home/drkthomp/protect3/venv/lib64/python3.6/tarfile.py", line 2161, in makefile
	    with bltn_open(targetpath, "wb") as target:
	OSError: [Errno 122] Disk quota exceeded: '/private/home/drkthomp/protect3/workDir/node-60141861-48d9-4a88-81d8-ba092a076b7d-e8611b53-bdab-4598-acae-87977f99831e/tmpn_evxpvz/f8e26626-c5d8-4a3d-b307-d390674cd8c3/bwa_indexes/hg38.ann'
	[2020-11-17T10:49:07-0800] [MainThread] [E] [toil.worker] Exiting the worker because of a failed job on host mustard
<=========
[2020-11-17T10:49:11-0800] [MainThread] [W] [toil.jobGraph] Due to failure we are reducing the remaining retry count of job 'run_bwa' kind-run_bwa/instance-fvcm11nr with ID kind-run_bwa/instance-fvcm11nr to 1
[2020-11-17T10:49:11-0800] [MainThread] [I] [toil.leader] Issued job 'run_bwa' kind-run_bwa/instance-fvcm11nr with job batch system ID: 11 and cores: 80, disk: 12.8 G, and memory: 12.0 G
[2020-11-17T10:49:12-0800] [MainThread] [I] [toil.worker] Redirecting logging to /private/home/drkthomp/protect3/workDir/node-60141861-48d9-4a88-81d8-ba092a076b7d-e8611b53-bdab-4598-acae-87977f99831e/tmpqui9rmov/worker_log.txt
[2020-11-17T10:49:31-0800] [Thread-1  ] [E] [toil.batchSystems.singleMachine] Got exit code 1 (indicating failure) from job _toil_worker run_phlat file:/scratch/drkthomp/jobStore kind-run_phlat/instance-rssn99a0.
[2020-11-17T10:49:31-0800] [MainThread] [W] [toil.leader] Job failed with exit value 1: 'run_phlat' kind-run_phlat/instance-rssn99a0
[2020-11-17T10:49:31-0800] [MainThread] [W] [toil.leader] The job seems to have left a log file, indicating failure: 'run_phlat' kind-run_phlat/instance-rssn99a0
[2020-11-17T10:49:31-0800] [MainThread] [W] [toil.leader] Log from job kind-run_phlat/instance-rssn99a0 follows:
=========>
	[2020-11-17T10:35:32-0800] [MainThread] [I] [toil.worker] ---TOIL WORKER OUTPUT LOG---
	[2020-11-17T10:35:32-0800] [MainThread] [I] [toil] Running Toil version 4.2.0-3aa1da130141039cb357efe36d7df9b9f6ae9b5b on host mustard.
	Traceback (most recent call last):
	  File "/private/home/drkthomp/protect3/venv/lib/python3.6/site-packages/toil/worker.py", line 368, in workerScript
	    job._runner(jobGraph=jobGraph, jobStore=jobStore, fileStore=fileStore, defer=defer)
	  File "/private/home/drkthomp/protect3/venv/lib/python3.6/site-packages/toil/job.py", line 1424, in _runner
	    returnValues = self._run(jobGraph, fileStore)
	  File "/private/home/drkthomp/protect3/venv/lib/python3.6/site-packages/toil/job.py", line 1361, in _run
	    return self.run(fileStore)
	  File "/private/home/drkthomp/protect3/venv/lib/python3.6/site-packages/toil/job.py", line 1565, in run
	    rValue = userFunction(*((self,) + tuple(self._args)), **self._kwargs)
	  File "/private/home/drkthomp/protect3/src/protect/haplotyping/phlat.py", line 62, in run_phlat
	    input_files['phlat_index'] = untargz(input_files['phlat_index.tar.gz'], work_dir)
	  File "/private/home/drkthomp/protect3/src/protect/common.py", line 158, in untargz
	    tarball.extractall(path=untar_to_dir)
	  File "/private/home/drkthomp/protect3/venv/lib64/python3.6/tarfile.py", line 2008, in extractall
	    numeric_owner=numeric_owner)
	  File "/private/home/drkthomp/protect3/venv/lib64/python3.6/tarfile.py", line 2050, in extract
	    numeric_owner=numeric_owner)
	  File "/private/home/drkthomp/protect3/venv/lib64/python3.6/tarfile.py", line 2120, in _extract_member
	    self.makefile(tarinfo, targetpath)
	  File "/private/home/drkthomp/protect3/venv/lib64/python3.6/tarfile.py", line 2169, in makefile
	    copyfileobj(source, target, tarinfo.size, ReadError, bufsize)
	OSError: [Errno 122] Disk quota exceeded
	[2020-11-17T10:49:10-0800] [MainThread] [E] [toil.worker] Exiting the worker because of a failed job on host mustard
	{'input_1.fastq': '/private/home/drkthomp/protect3/workDir/node-60141861-48d9-4a88-81d8-ba092a076b7d-e8611b53-bdab-4598-acae-87977f99831e/tmpvxfdc39j/040194b9-67ca-4865-b990-915887dbbaea/input_1.fastq', 'input_2.fastq': '/private/home/drkthomp/protect3/workDir/node-60141861-48d9-4a88-81d8-ba092a076b7d-e8611b53-bdab-4598-acae-87977f99831e/tmpvxfdc39j/040194b9-67ca-4865-b990-915887dbbaea/input_2.fastq', 'phlat_index.tar.gz': '/private/home/drkthomp/protect3/workDir/node-60141861-48d9-4a88-81d8-ba092a076b7d-e8611b53-bdab-4598-acae-87977f99831e/tmpvxfdc39j/040194b9-67ca-4865-b990-915887dbbaea/phlat_index.tar.gz'}
<=========
[2020-11-17T10:49:31-0800] [MainThread] [W] [toil.jobGraph] Due to failure we are reducing the remaining retry count of job 'run_phlat' kind-run_phlat/instance-rssn99a0 with ID kind-run_phlat/instance-rssn99a0 to 0
[2020-11-17T10:49:31-0800] [MainThread] [W] [toil.leader] Job 'run_phlat' kind-run_phlat/instance-rssn99a0 with ID kind-run_phlat/instance-rssn99a0 is completely failed
[2020-11-17T10:49:32-0800] [MainThread] [I] [toil.worker] Redirecting logging to /private/home/drkthomp/protect3/workDir/node-60141861-48d9-4a88-81d8-ba092a076b7d-e8611b53-bdab-4598-acae-87977f99831e/tmpkw799set/worker_log.txt
[2020-11-17T11:01:59-0800] [MainThread] [I] [toil.leader] 2 jobs are running, 3 jobs are issued and waiting to run
[2020-11-17T11:05:00-0800] [Thread-1  ] [E] [toil.batchSystems.singleMachine] Got exit code 1 (indicating failure) from job _toil_worker run_phlat file:/scratch/drkthomp/jobStore kind-run_phlat/instance-z35qoqn5.
[2020-11-17T11:05:00-0800] [MainThread] [W] [toil.leader] Job failed with exit value 1: 'run_phlat' kind-run_phlat/instance-z35qoqn5
[2020-11-17T11:05:00-0800] [MainThread] [W] [toil.leader] The job seems to have left a log file, indicating failure: 'run_phlat' kind-run_phlat/instance-z35qoqn5
[2020-11-17T11:05:00-0800] [MainThread] [W] [toil.leader] Log from job kind-run_phlat/instance-z35qoqn5 follows:
=========>
	[2020-11-17T10:49:12-0800] [MainThread] [I] [toil.worker] ---TOIL WORKER OUTPUT LOG---
	[2020-11-17T10:49:12-0800] [MainThread] [I] [toil] Running Toil version 4.2.0-3aa1da130141039cb357efe36d7df9b9f6ae9b5b on host mustard.
	Traceback (most recent call last):
	  File "/home/phlat-1.0/dist/PHLAT.py", line 59, in <module>
	    nthreads=int(val)
	ValueError: invalid literal for int() with base 10: '80.0'
	chown: changing ownership of '/data/.jobState': Operation not permitted
	chown: changing ownership of '/data/input_1.fastq': Operation not permitted
	chown: changing ownership of '/data/input_2.fastq': Operation not permitted
	chown: changing ownership of '/data/phlat_index.tar.gz': Operation not permitted
	chown: changing ownership of '/data/index4phlat/ucsc.artHLA.rev.2.bt2': Operation not permitted
	chown: changing ownership of '/data/index4phlat/ucsc.artHLA.4.bt2': Operation not permitted
	chown: changing ownership of '/data/index4phlat/ucsc.artHLA.3.bt2': Operation not permitted
	chown: changing ownership of '/data/index4phlat/ucsc.artHLA.rev.1.bt2': Operation not permitted
	chown: changing ownership of '/data/index4phlat/ucsc.artHLA.2.bt2': Operation not permitted
	chown: changing ownership of '/data/index4phlat/ucsc.artHLA.1.bt2': Operation not permitted
	chown: changing ownership of '/data/index4phlat': Operation not permitted
	chown: changing ownership of '/data': Operation not permitted
	Traceback (most recent call last):
	  File "/private/home/drkthomp/protect3/src/protect/common.py", line 136, in docker_call
	    subprocess.check_call(call, stdout=outfile)
	  File "/usr/lib64/python3.6/subprocess.py", line 291, in check_call
	    raise CalledProcessError(retcode, cmd)
	subprocess.CalledProcessError: Command '['docker', 'run', '--rm=true', '-v', '/private/home/drkthomp/protect3/workDir/node-60141861-48d9-4a88-81d8-ba092a076b7d-e8611b53-bdab-4598-acae-87977f99831e/tmpqui9rmov/2cab0a37-e05e-4fc3-804c-a5e699d961ee:/data', '--log-driver=none', 'aarjunrao/phlat:1.0', '-1', '/data/input_1.fastq', '-2', '/data/input_2.fastq', '-index', '/data/index4phlat', '-b2url', '/usr/local/bin/bowtie2', '-tag', 'normal_dna', '-e', '/home/phlat-1.0', '-o', '/data', '-p', '80.0']' returned non-zero exit status 1.
	
	During handling of the above exception, another exception occurred:
	
	Traceback (most recent call last):
	  File "/private/home/drkthomp/protect3/venv/lib/python3.6/site-packages/toil/worker.py", line 368, in workerScript
	    job._runner(jobGraph=jobGraph, jobStore=jobStore, fileStore=fileStore, defer=defer)
	  File "/private/home/drkthomp/protect3/venv/lib/python3.6/site-packages/toil/job.py", line 1424, in _runner
	    returnValues = self._run(jobGraph, fileStore)
	  File "/private/home/drkthomp/protect3/venv/lib/python3.6/site-packages/toil/job.py", line 1361, in _run
	    return self.run(fileStore)
	  File "/private/home/drkthomp/protect3/venv/lib/python3.6/site-packages/toil/job.py", line 1565, in run
	    rValue = userFunction(*((self,) + tuple(self._args)), **self._kwargs)
	  File "/private/home/drkthomp/protect3/src/protect/haplotyping/phlat.py", line 74, in run_phlat
	    dockerhub=univ_options['dockerhub'], tool_version=phlat_options['version'])
	  File "/private/home/drkthomp/protect3/src/protect/common.py", line 139, in docker_call
	    'for command \"%s\"' % ' '.join(call),)
	RuntimeError: docker command returned a non-zero exit status (1)for command "docker run --rm=true -v /private/home/drkthomp/protect3/workDir/node-60141861-48d9-4a88-81d8-ba092a076b7d-e8611b53-bdab-4598-acae-87977f99831e/tmpqui9rmov/2cab0a37-e05e-4fc3-804c-a5e699d961ee:/data --log-driver=none aarjunrao/phlat:1.0 -1 /data/input_1.fastq -2 /data/input_2.fastq -index /data/index4phlat -b2url /usr/local/bin/bowtie2 -tag normal_dna -e /home/phlat-1.0 -o /data -p 80.0"
	[2020-11-17T11:04:57-0800] [MainThread] [E] [toil.worker] Exiting the worker because of a failed job on host mustard
	{'input_1.fastq': '/private/home/drkthomp/protect3/workDir/node-60141861-48d9-4a88-81d8-ba092a076b7d-e8611b53-bdab-4598-acae-87977f99831e/tmpqui9rmov/2cab0a37-e05e-4fc3-804c-a5e699d961ee/input_1.fastq', 'input_2.fastq': '/private/home/drkthomp/protect3/workDir/node-60141861-48d9-4a88-81d8-ba092a076b7d-e8611b53-bdab-4598-acae-87977f99831e/tmpqui9rmov/2cab0a37-e05e-4fc3-804c-a5e699d961ee/input_2.fastq', 'phlat_index.tar.gz': '/private/home/drkthomp/protect3/workDir/node-60141861-48d9-4a88-81d8-ba092a076b7d-e8611b53-bdab-4598-acae-87977f99831e/tmpqui9rmov/2cab0a37-e05e-4fc3-804c-a5e699d961ee/phlat_index.tar.gz'}
<=========
[2020-11-17T11:05:00-0800] [MainThread] [W] [toil.jobGraph] Due to failure we are reducing the remaining retry count of job 'run_phlat' kind-run_phlat/instance-z35qoqn5 with ID kind-run_phlat/instance-z35qoqn5 to 0
[2020-11-17T11:05:00-0800] [MainThread] [W] [toil.leader] Job 'run_phlat' kind-run_phlat/instance-z35qoqn5 with ID kind-run_phlat/instance-z35qoqn5 is completely failed
[2020-11-17T11:05:01-0800] [MainThread] [I] [toil.worker] Redirecting logging to /private/home/drkthomp/protect3/workDir/node-60141861-48d9-4a88-81d8-ba092a076b7d-e8611b53-bdab-4598-acae-87977f99831e/tmpjt457_86/worker_log.txt
[2020-11-17T11:05:17-0800] [Thread-1  ] [E] [toil.batchSystems.singleMachine] Got exit code 1 (indicating failure) from job _toil_worker run_phlat file:/scratch/drkthomp/jobStore kind-run_phlat/instance-3chuyae2.
[2020-11-17T11:05:17-0800] [MainThread] [W] [toil.leader] Job failed with exit value 1: 'run_phlat' kind-run_phlat/instance-3chuyae2
[2020-11-17T11:05:17-0800] [MainThread] [W] [toil.leader] The job seems to have left a log file, indicating failure: 'run_phlat' kind-run_phlat/instance-3chuyae2
[2020-11-17T11:05:17-0800] [MainThread] [W] [toil.leader] Log from job kind-run_phlat/instance-3chuyae2 follows:
=========>
	[2020-11-17T10:49:32-0800] [MainThread] [I] [toil.worker] ---TOIL WORKER OUTPUT LOG---
	[2020-11-17T10:49:32-0800] [MainThread] [I] [toil] Running Toil version 4.2.0-3aa1da130141039cb357efe36d7df9b9f6ae9b5b on host mustard.
	Traceback (most recent call last):
	  File "/private/home/drkthomp/protect3/venv/lib/python3.6/site-packages/toil/worker.py", line 368, in workerScript
	    job._runner(jobGraph=jobGraph, jobStore=jobStore, fileStore=fileStore, defer=defer)
	  File "/private/home/drkthomp/protect3/venv/lib/python3.6/site-packages/toil/job.py", line 1424, in _runner
	    returnValues = self._run(jobGraph, fileStore)
	  File "/private/home/drkthomp/protect3/venv/lib/python3.6/site-packages/toil/job.py", line 1361, in _run
	    return self.run(fileStore)
	  File "/private/home/drkthomp/protect3/venv/lib/python3.6/site-packages/toil/job.py", line 1565, in run
	    rValue = userFunction(*((self,) + tuple(self._args)), **self._kwargs)
	  File "/private/home/drkthomp/protect3/src/protect/haplotyping/phlat.py", line 62, in run_phlat
	    input_files['phlat_index'] = untargz(input_files['phlat_index.tar.gz'], work_dir)
	  File "/private/home/drkthomp/protect3/src/protect/common.py", line 158, in untargz
	    tarball.extractall(path=untar_to_dir)
	  File "/private/home/drkthomp/protect3/venv/lib64/python3.6/tarfile.py", line 2008, in extractall
	    numeric_owner=numeric_owner)
	  File "/private/home/drkthomp/protect3/venv/lib64/python3.6/tarfile.py", line 2050, in extract
	    numeric_owner=numeric_owner)
	  File "/private/home/drkthomp/protect3/venv/lib64/python3.6/tarfile.py", line 2120, in _extract_member
	    self.makefile(tarinfo, targetpath)
	  File "/private/home/drkthomp/protect3/venv/lib64/python3.6/tarfile.py", line 2169, in makefile
	    copyfileobj(source, target, tarinfo.size, ReadError, bufsize)
	OSError: [Errno 122] Disk quota exceeded
	[2020-11-17T11:05:00-0800] [MainThread] [E] [toil.worker] Exiting the worker because of a failed job on host mustard
	{'input_1.fastq': '/private/home/drkthomp/protect3/workDir/node-60141861-48d9-4a88-81d8-ba092a076b7d-e8611b53-bdab-4598-acae-87977f99831e/tmpkw799set/3decbccd-c3c7-428b-90a8-f6bb79745ba2/input_1.fastq', 'input_2.fastq': '/private/home/drkthomp/protect3/workDir/node-60141861-48d9-4a88-81d8-ba092a076b7d-e8611b53-bdab-4598-acae-87977f99831e/tmpkw799set/3decbccd-c3c7-428b-90a8-f6bb79745ba2/input_2.fastq', 'phlat_index.tar.gz': '/private/home/drkthomp/protect3/workDir/node-60141861-48d9-4a88-81d8-ba092a076b7d-e8611b53-bdab-4598-acae-87977f99831e/tmpkw799set/3decbccd-c3c7-428b-90a8-f6bb79745ba2/phlat_index.tar.gz'}
<=========
[2020-11-17T11:05:17-0800] [MainThread] [W] [toil.jobGraph] Due to failure we are reducing the remaining retry count of job 'run_phlat' kind-run_phlat/instance-3chuyae2 with ID kind-run_phlat/instance-3chuyae2 to 0
[2020-11-17T11:05:17-0800] [MainThread] [W] [toil.leader] Job 'run_phlat' kind-run_phlat/instance-3chuyae2 with ID kind-run_phlat/instance-3chuyae2 is completely failed
[2020-11-17T11:05:18-0800] [MainThread] [I] [toil.worker] Redirecting logging to /private/home/drkthomp/protect3/workDir/node-60141861-48d9-4a88-81d8-ba092a076b7d-e8611b53-bdab-4598-acae-87977f99831e/tmp5gyyr1e8/worker_log.txt
