7331b3-1e53f69f16d74e0b881e7db602b2d2c3/tmpbf77rqv6/57fad350-313b-40b4-b8b7-103f860efde4:/data --log-driver=none aarjunrao/phlat:1.0 -1 /data/input_1.fastq -2 /data/input_2.fastq -index /data/index4phlat -b2url /usr/local/bin/bowtie2 -tag normal_dna -e /home/phlat-1.0 -o /data -p 4
Could not locate a Bowtie index corresponding to basename "/data/index4phlat/ucsc.artHLA"
Error: Encountered internal Bowtie 2 exception (#1)
Command: /usr/local/bin/bowtie2-align-s --wrapper basic-0 --maxins 450 --no-mixed --no-discordant -p 4 -D 20 -R 3 -N 0 -L 20 -i S,1,0.50 -x /data/index4phlat/ucsc.artHLA --passthrough -1 /data/input_1.fastq -2 /data/input_2.fastq 
(ERR): bowtie2-align exited with value 1
.....Process Bowtie 2 mapping on normal_dna.......

.....Prepare files of normal_dna for PHLAT.......

..... Running PHLAT .......
Traceback (most recent call last):
  File "/home/phlat-1.0/dist/PHLAT.py", line 64, in <module>
    go(tag,outdir,phlatdir)
  File "/home/yubai/programs/phlat-1.0/dist/utilities.py", line 79, in go
  File "/home/yubai/programs/phlat-1.0/dist/extensions.py", line 617, in __init__
  File "/home/yubai/programs/phlat-1.0/dist/extensions.py", line 645, in setMaster
IndexError: list index out of range

