[2020-11-15T00:28:10-0800] [MainThread] [I] [toil] Running Toil version 4.2.0-3aa1da130141039cb357efe36d7df9b9f6ae9b5b on host mustard.
[2020-11-15T00:28:11-0800] [MainThread] [I] [toil.leader] Issued job 'parse_config_file' kind-parse_config_file/instance-ml5szru_ with job batch system ID: 0 and cores: 1, disk: 2.0 G, and memory: 2.0 G
[2020-11-15T00:28:11-0800] [MainThread] [I] [toil.worker] Redirecting logging to /private/home/drkthomp/protect3/workDir/node-60141861-48d9-4a88-81d8-ba092a076b7d-e8611b53-bdab-4598-acae-87977f99831e/tmppxo7wk8d/worker_log.txt
[2020-11-15T00:28:12-0800] [MainThread] [I] [toil.leader] Job ended: 'parse_config_file' kind-parse_config_file/instance-ml5szru_
[2020-11-15T00:28:12-0800] [MainThread] [I] [toil.leader] 0 jobs are running, 0 jobs are issued and waiting to run
[2020-11-15T00:28:12-0800] [MainThread] [I] [toil.leader] Issued job 'get_pipeline_inputs' kind-get_pipeline_inputs/instance-xlca_kav with job batch system ID: 1 and cores: 1, disk: 2.0 G, and memory: 2.0 G
[2020-11-15T00:28:12-0800] [MainThread] [I] [toil.leader] Issued job 'get_pipeline_inputs' kind-get_pipeline_inputs/instance-w0r0fgkl with job batch system ID: 2 and cores: 1, disk: 2.0 G, and memory: 2.0 G
[2020-11-15T00:28:12-0800] [MainThread] [I] [toil.leader] Issued job 'get_pipeline_inputs' kind-get_pipeline_inputs/instance-4449i24l with job batch system ID: 3 and cores: 1, disk: 2.0 G, and memory: 2.0 G
[2020-11-15T00:28:12-0800] [MainThread] [I] [toil.leader] Issued job 'get_pipeline_inputs' kind-get_pipeline_inputs/instance-lwawpwto with job batch system ID: 4 and cores: 1, disk: 2.0 G, and memory: 2.0 G
[2020-11-15T00:28:12-0800] [MainThread] [I] [toil.leader] Issued job 'get_pipeline_inputs' kind-get_pipeline_inputs/instance-moo53zz6 with job batch system ID: 5 and cores: 1, disk: 2.0 G, and memory: 2.0 G
[2020-11-15T00:28:12-0800] [MainThread] [I] [toil.leader] Issued job 'get_pipeline_inputs' kind-get_pipeline_inputs/instance-s36dw4ty with job batch system ID: 6 and cores: 1, disk: 2.0 G, and memory: 2.0 G
[2020-11-15T00:28:12-0800] [MainThread] [I] [toil.leader] Issued job 'get_pipeline_inputs' kind-get_pipeline_inputs/instance-_5sx0yzj with job batch system ID: 7 and cores: 1, disk: 2.0 G, and memory: 2.0 G
[2020-11-15T00:28:12-0800] [MainThread] [I] [toil.leader] Issued job 'get_pipeline_inputs' kind-get_pipeline_inputs/instance-_91ux51r with job batch system ID: 8 and cores: 1, disk: 2.0 G, and memory: 2.0 G
[2020-11-15T00:28:12-0800] [MainThread] [I] [toil.leader] Issued job 'get_pipeline_inputs' kind-get_pipeline_inputs/instance-e60iam16 with job batch system ID: 9 and cores: 1, disk: 2.0 G, and memory: 2.0 G
[2020-11-15T00:28:12-0800] [MainThread] [I] [toil.leader] Issued job 'get_pipeline_inputs' kind-get_pipeline_inputs/instance-kruxi_g4 with job batch system ID: 10 and cores: 1, disk: 2.0 G, and memory: 2.0 G
[2020-11-15T00:28:12-0800] [MainThread] [I] [toil.leader] Issued job 'get_pipeline_inputs' kind-get_pipeline_inputs/instance-1y_velvd with job batch system ID: 11 and cores: 1, disk: 2.0 G, and memory: 2.0 G
[2020-11-15T00:28:12-0800] [MainThread] [I] [toil.leader] Issued job 'get_pipeline_inputs' kind-get_pipeline_inputs/instance-9yk9icyt with job batch system ID: 12 and cores: 1, disk: 2.0 G, and memory: 2.0 G
[2020-11-15T00:28:12-0800] [MainThread] [I] [toil.leader] Issued job 'get_pipeline_inputs' kind-get_pipeline_inputs/instance-nb2ttglx with job batch system ID: 13 and cores: 1, disk: 2.0 G, and memory: 2.0 G
[2020-11-15T00:28:12-0800] [MainThread] [I] [toil.leader] Issued job 'get_pipeline_inputs' kind-get_pipeline_inputs/instance-k53dxsrv with job batch system ID: 14 and cores: 1, disk: 2.0 G, and memory: 2.0 G
[2020-11-15T00:28:12-0800] [MainThread] [I] [toil.leader] Issued job 'get_pipeline_inputs' kind-get_pipeline_inputs/instance-1jy08oj3 with job batch system ID: 15 and cores: 1, disk: 2.0 G, and memory: 2.0 G
[2020-11-15T00:28:12-0800] [MainThread] [I] [toil.leader] Issued job 'get_pipeline_inputs' kind-get_pipeline_inputs/instance-fp_69yov with job batch system ID: 16 and cores: 1, disk: 2.0 G, and memory: 2.0 G
[2020-11-15T00:28:12-0800] [MainThread] [I] [toil.leader] Issued job 'get_pipeline_inputs' kind-get_pipeline_inputs/instance-1iu44e5t with job batch system ID: 17 and cores: 1, disk: 2.0 G, and memory: 2.0 G
[2020-11-15T00:28:12-0800] [MainThread] [I] [toil.leader] Issued job 'get_pipeline_inputs' kind-get_pipeline_inputs/instance-q7rykuf9 with job batch system ID: 18 and cores: 1, disk: 2.0 G, and memory: 2.0 G
[2020-11-15T00:28:12-0800] [MainThread] [I] [toil.leader] Issued job 'get_pipeline_inputs' kind-get_pipeline_inputs/instance-28832prp with job batch system ID: 19 and cores: 1, disk: 2.0 G, and memory: 2.0 G
[2020-11-15T00:28:12-0800] [MainThread] [I] [toil.leader] Issued job 'get_pipeline_inputs' kind-get_pipeline_inputs/instance-v9w5g4zj with job batch system ID: 20 and cores: 1, disk: 2.0 G, and memory: 2.0 G
[2020-11-15T00:28:12-0800] [MainThread] [I] [toil.leader] Issued job 'get_pipeline_inputs' kind-get_pipeline_inputs/instance-g34bgkh6 with job batch system ID: 21 and cores: 1, disk: 2.0 G, and memory: 2.0 G
[2020-11-15T00:28:12-0800] [MainThread] [I] [toil.leader] Issued job 'get_pipeline_inputs' kind-get_pipeline_inputs/instance-4okw3zyq with job batch system ID: 22 and cores: 1, disk: 2.0 G, and memory: 2.0 G
[2020-11-15T00:28:12-0800] [MainThread] [I] [toil.leader] Issued job 'get_pipeline_inputs' kind-get_pipeline_inputs/instance-igauxjaw with job batch system ID: 23 and cores: 1, disk: 2.0 G, and memory: 2.0 G
[2020-11-15T00:28:12-0800] [MainThread] [I] [toil.leader] Issued job 'get_pipeline_inputs' kind-get_pipeline_inputs/instance-mjjj9pl3 with job batch system ID: 24 and cores: 1, disk: 2.0 G, and memory: 2.0 G
[2020-11-15T00:28:12-0800] [MainThread] [I] [toil.leader] Issued job 'get_pipeline_inputs' kind-get_pipeline_inputs/instance-fdqruxwl with job batch system ID: 25 and cores: 1, disk: 2.0 G, and memory: 2.0 G
[2020-11-15T00:28:12-0800] [MainThread] [I] [toil.leader] Issued job 'get_pipeline_inputs' kind-get_pipeline_inputs/instance-gquoa6eo with job batch system ID: 26 and cores: 1, disk: 2.0 G, and memory: 2.0 G
[2020-11-15T00:28:12-0800] [MainThread] [I] [toil.leader] Issued job 'get_pipeline_inputs' kind-get_pipeline_inputs/instance-b07a33j5 with job batch system ID: 27 and cores: 1, disk: 2.0 G, and memory: 2.0 G
[2020-11-15T00:28:12-0800] [MainThread] [I] [toil.leader] Issued job 'get_pipeline_inputs' kind-get_pipeline_inputs/instance-4wagfh4p with job batch system ID: 28 and cores: 1, disk: 2.0 G, and memory: 2.0 G
[2020-11-15T00:28:12-0800] [MainThread] [I] [toil.leader] Issued job 'get_pipeline_inputs' kind-get_pipeline_inputs/instance-1i_zjhkv with job batch system ID: 29 and cores: 1, disk: 2.0 G, and memory: 2.0 G
[2020-11-15T00:28:13-0800] [Thread-3  ] [I] [toil.statsAndLogging] Got message from job at time 11-15-2020 00:28:13: Parsing config file
[2020-11-15T00:28:13-0800] [Thread-3  ] [I] [toil.statsAndLogging] Got message from job at time 11-15-2020 00:28:13: Obtaining tool inputs
[2020-11-15T00:28:13-0800] [Thread-3  ] [I] [toil.statsAndLogging] Got message from job at time 11-15-2020 00:28:13: Obtained tool inputs
[2020-11-15T00:28:14-0800] [MainThread] [I] [toil.worker] Redirecting logging to /private/home/drkthomp/protect3/workDir/node-60141861-48d9-4a88-81d8-ba092a076b7d-e8611b53-bdab-4598-acae-87977f99831e/tmpvncllpoc/worker_log.txt
[2020-11-15T00:28:14-0800] [MainThread] [I] [toil.worker] Redirecting logging to /private/home/drkthomp/protect3/workDir/node-60141861-48d9-4a88-81d8-ba092a076b7d-e8611b53-bdab-4598-acae-87977f99831e/tmpm8ckh0gz/worker_log.txt
[2020-11-15T00:28:14-0800] [MainThread] [I] [toil.worker] Redirecting logging to /private/home/drkthomp/protect3/workDir/node-60141861-48d9-4a88-81d8-ba092a076b7d-e8611b53-bdab-4598-acae-87977f99831e/tmp3g54ebyq/worker_log.txt
[2020-11-15T00:28:14-0800] [MainThread] [I] [toil.worker] Redirecting logging to /private/home/drkthomp/protect3/workDir/node-60141861-48d9-4a88-81d8-ba092a076b7d-e8611b53-bdab-4598-acae-87977f99831e/tmp873znnf0/worker_log.txt
[2020-11-15T00:28:14-0800] [MainThread] [I] [toil.worker] Redirecting logging to /private/home/drkthomp/protect3/workDir/node-60141861-48d9-4a88-81d8-ba092a076b7d-e8611b53-bdab-4598-acae-87977f99831e/tmpv414u8qc/worker_log.txt
[2020-11-15T00:28:14-0800] [MainThread] [I] [toil.worker] Redirecting logging to /private/home/drkthomp/protect3/workDir/node-60141861-48d9-4a88-81d8-ba092a076b7d-e8611b53-bdab-4598-acae-87977f99831e/tmppwo8qx_x/worker_log.txt
[2020-11-15T00:28:14-0800] [MainThread] [I] [toil.worker] Redirecting logging to /private/home/drkthomp/protect3/workDir/node-60141861-48d9-4a88-81d8-ba092a076b7d-e8611b53-bdab-4598-acae-87977f99831e/tmpt4x6mc8d/worker_log.txt
[2020-11-15T00:28:14-0800] [MainThread] [I] [toil.worker] Redirecting logging to /private/home/drkthomp/protect3/workDir/node-60141861-48d9-4a88-81d8-ba092a076b7d-e8611b53-bdab-4598-acae-87977f99831e/tmp26d70kcl/worker_log.txt
[2020-11-15T00:28:14-0800] [MainThread] [I] [toil.worker] Redirecting logging to /private/home/drkthomp/protect3/workDir/node-60141861-48d9-4a88-81d8-ba092a076b7d-e8611b53-bdab-4598-acae-87977f99831e/tmpwrp008xn/worker_log.txt
[2020-11-15T00:28:14-0800] [MainThread] [I] [toil.worker] Redirecting logging to /private/home/drkthomp/protect3/workDir/node-60141861-48d9-4a88-81d8-ba092a076b7d-e8611b53-bdab-4598-acae-87977f99831e/tmpqkw2t5jc/worker_log.txt
[2020-11-15T00:28:14-0800] [MainThread] [I] [toil.worker] Redirecting logging to /private/home/drkthomp/protect3/workDir/node-60141861-48d9-4a88-81d8-ba092a076b7d-e8611b53-bdab-4598-acae-87977f99831e/tmp4o3681u6/worker_log.txt
[2020-11-15T00:28:14-0800] [MainThread] [I] [toil.worker] Redirecting logging to /private/home/drkthomp/protect3/workDir/node-60141861-48d9-4a88-81d8-ba092a076b7d-e8611b53-bdab-4598-acae-87977f99831e/tmp_jplrlq7/worker_log.txt
[2020-11-15T00:28:14-0800] [MainThread] [I] [toil.worker] Redirecting logging to /private/home/drkthomp/protect3/workDir/node-60141861-48d9-4a88-81d8-ba092a076b7d-e8611b53-bdab-4598-acae-87977f99831e/tmpje66eddv/worker_log.txt
[2020-11-15T00:28:14-0800] [MainThread] [I] [toil.worker] Redirecting logging to /private/home/drkthomp/protect3/workDir/node-60141861-48d9-4a88-81d8-ba092a076b7d-e8611b53-bdab-4598-acae-87977f99831e/tmp4p00aryl/worker_log.txt
[2020-11-15T00:28:14-0800] [MainThread] [I] [toil.worker] Redirecting logging to /private/home/drkthomp/protect3/workDir/node-60141861-48d9-4a88-81d8-ba092a076b7d-e8611b53-bdab-4598-acae-87977f99831e/tmp4m_504_n/worker_log.txt
[2020-11-15T00:28:14-0800] [MainThread] [I] [toil.worker] Redirecting logging to /private/home/drkthomp/protect3/workDir/node-60141861-48d9-4a88-81d8-ba092a076b7d-e8611b53-bdab-4598-acae-87977f99831e/tmp3u5y9dn7/worker_log.txt
[2020-11-15T00:28:14-0800] [MainThread] [I] [toil.worker] Redirecting logging to /private/home/drkthomp/protect3/workDir/node-60141861-48d9-4a88-81d8-ba092a076b7d-e8611b53-bdab-4598-acae-87977f99831e/tmp3yqbr8f1/worker_log.txt
[2020-11-15T00:28:14-0800] [MainThread] [I] [toil.worker] Redirecting logging to /private/home/drkthomp/protect3/workDir/node-60141861-48d9-4a88-81d8-ba092a076b7d-e8611b53-bdab-4598-acae-87977f99831e/tmpcf10i63i/worker_log.txt
[2020-11-15T00:28:14-0800] [MainThread] [I] [toil.worker] Redirecting logging to /private/home/drkthomp/protect3/workDir/node-60141861-48d9-4a88-81d8-ba092a076b7d-e8611b53-bdab-4598-acae-87977f99831e/tmpnsnvn10s/worker_log.txt
[2020-11-15T00:28:14-0800] [MainThread] [I] [toil.worker] Redirecting logging to /private/home/drkthomp/protect3/workDir/node-60141861-48d9-4a88-81d8-ba092a076b7d-e8611b53-bdab-4598-acae-87977f99831e/tmp39kl6szq/worker_log.txt
[2020-11-15T00:28:14-0800] [MainThread] [I] [toil.worker] Redirecting logging to /private/home/drkthomp/protect3/workDir/node-60141861-48d9-4a88-81d8-ba092a076b7d-e8611b53-bdab-4598-acae-87977f99831e/tmpolc0_9s3/worker_log.txt
[2020-11-15T00:28:14-0800] [MainThread] [I] [toil.worker] Redirecting logging to /private/home/drkthomp/protect3/workDir/node-60141861-48d9-4a88-81d8-ba092a076b7d-e8611b53-bdab-4598-acae-87977f99831e/tmp1342g8o9/worker_log.txt
[2020-11-15T00:28:14-0800] [MainThread] [I] [toil.worker] Redirecting logging to /private/home/drkthomp/protect3/workDir/node-60141861-48d9-4a88-81d8-ba092a076b7d-e8611b53-bdab-4598-acae-87977f99831e/tmpnjhlz_m_/worker_log.txt
[2020-11-15T00:28:14-0800] [MainThread] [I] [toil.worker] Redirecting logging to /private/home/drkthomp/protect3/workDir/node-60141861-48d9-4a88-81d8-ba092a076b7d-e8611b53-bdab-4598-acae-87977f99831e/tmp5o4zjpxi/worker_log.txt
[2020-11-15T00:28:14-0800] [MainThread] [I] [toil.worker] Redirecting logging to /private/home/drkthomp/protect3/workDir/node-60141861-48d9-4a88-81d8-ba092a076b7d-e8611b53-bdab-4598-acae-87977f99831e/tmpemqjsf_7/worker_log.txt
[2020-11-15T00:28:14-0800] [MainThread] [I] [toil.worker] Redirecting logging to /private/home/drkthomp/protect3/workDir/node-60141861-48d9-4a88-81d8-ba092a076b7d-e8611b53-bdab-4598-acae-87977f99831e/tmp56aktw6z/worker_log.txt
[2020-11-15T00:28:14-0800] [MainThread] [I] [toil.worker] Redirecting logging to /private/home/drkthomp/protect3/workDir/node-60141861-48d9-4a88-81d8-ba092a076b7d-e8611b53-bdab-4598-acae-87977f99831e/tmps71f55cu/worker_log.txt
[2020-11-15T00:28:14-0800] [MainThread] [I] [toil.worker] Redirecting logging to /private/home/drkthomp/protect3/workDir/node-60141861-48d9-4a88-81d8-ba092a076b7d-e8611b53-bdab-4598-acae-87977f99831e/tmp9v0ir0_w/worker_log.txt
[2020-11-15T00:28:14-0800] [MainThread] [I] [toil.worker] Redirecting logging to /private/home/drkthomp/protect3/workDir/node-60141861-48d9-4a88-81d8-ba092a076b7d-e8611b53-bdab-4598-acae-87977f99831e/tmpwybr_mle/worker_log.txt
[2020-11-15T00:28:15-0800] [MainThread] [I] [toil.leader] Job ended: 'get_pipeline_inputs' kind-get_pipeline_inputs/instance-s36dw4ty
[2020-11-15T00:28:16-0800] [Thread-3  ] [I] [toil.statsAndLogging] Got message from job at time 11-15-2020 00:28:16: Obtaining file (indexes:genome_dict) to the file job store
[2020-11-15T00:28:16-0800] [Thread-3  ] [I] [toil.statsAndLogging] Got message from job at time 11-15-2020 00:28:16: Obtaining file (indexes:genome_fai) to the file job store
[2020-11-15T00:28:16-0800] [MainThread] [I] [toil.leader] Job ended: 'get_pipeline_inputs' kind-get_pipeline_inputs/instance-moo53zz6
[2020-11-15T00:28:16-0800] [Thread-3  ] [I] [toil.statsAndLogging] Got message from job at time 11-15-2020 00:28:16: Obtaining file (radia:retrogene_beds) to the file job store
[2020-11-15T00:28:16-0800] [Thread-3  ] [I] [toil.statsAndLogging] Got message from job at time 11-15-2020 00:28:16: Obtaining file (radia:pseudogene_beds) to the file job store
[2020-11-15T00:28:17-0800] [Thread-3  ] [I] [toil.statsAndLogging] Got message from job at time 11-15-2020 00:28:17: Obtaining file (indexes:cosmic_idx) to the file job store
[2020-11-15T00:28:17-0800] [Thread-3  ] [I] [toil.statsAndLogging] Got message from job at time 11-15-2020 00:28:17: Obtaining file (reports:immune_resistance_pathways_file) to the file job store
[2020-11-15T00:28:17-0800] [Thread-3  ] [I] [toil.statsAndLogging] Got message from job at time 11-15-2020 00:28:17: Obtaining file (indexes:dbsnp_tbi) to the file job store
[2020-11-15T00:28:17-0800] [Thread-3  ] [I] [toil.statsAndLogging] Got message from job at time 11-15-2020 00:28:17: Obtaining file (reports:itx_resistance_file) to the file job store
[2020-11-15T00:28:17-0800] [Thread-3  ] [I] [toil.statsAndLogging] Got message from job at time 11-15-2020 00:28:17: Obtaining file (reports:mhc_pathways_file) to the file job store
[2020-11-15T00:28:17-0800] [Thread-3  ] [I] [toil.statsAndLogging] Got message from job at time 11-15-2020 00:28:17: Obtaining file (strelka:config_file) to the file job store
[2020-11-15T00:28:17-0800] [Thread-3  ] [I] [toil.statsAndLogging] Got message from job at time 11-15-2020 00:28:17: Obtaining file (radia:gencode_beds) to the file job store
[2020-11-15T00:28:17-0800] [Thread-3  ] [I] [toil.statsAndLogging] Got message from job at time 11-15-2020 00:28:17: Obtaining file (indexes:dbsnp_idx) to the file job store
[2020-11-15T00:28:17-0800] [MainThread] [I] [toil.leader] Job ended: 'get_pipeline_inputs' kind-get_pipeline_inputs/instance-1jy08oj3
[2020-11-15T00:28:18-0800] [MainThread] [I] [toil.leader] Job ended: 'get_pipeline_inputs' kind-get_pipeline_inputs/instance-k53dxsrv
[2020-11-15T00:28:18-0800] [Thread-3  ] [I] [toil.statsAndLogging] Got message from job at time 11-15-2020 00:28:18: Obtaining file (mhci:method_file) to the file job store
[2020-11-15T00:28:18-0800] [Thread-3  ] [I] [toil.statsAndLogging] Got message from job at time 11-15-2020 00:28:18: Obtaining file (mhcii:method_file) to the file job store
[2020-11-15T00:28:18-0800] [Thread-3  ] [I] [toil.statsAndLogging] Got message from job at time 11-15-2020 00:28:18: Obtaining file (radia:cosmic_beds) to the file job store
[2020-11-15T00:28:18-0800] [Thread-3  ] [I] [toil.statsAndLogging] Got message from job at time 11-15-2020 00:28:18: Obtaining file (reports:car_t_targets_file) to the file job store
[2020-11-15T00:28:18-0800] [MainThread] [I] [toil.leader] Job ended: 'get_pipeline_inputs' kind-get_pipeline_inputs/instance-_91ux51r
[2020-11-15T00:28:18-0800] [MainThread] [I] [toil.leader] Job ended: 'get_pipeline_inputs' kind-get_pipeline_inputs/instance-4wagfh4p
[2020-11-15T00:28:18-0800] [MainThread] [I] [toil.leader] Job ended: 'get_pipeline_inputs' kind-get_pipeline_inputs/instance-1y_velvd
[2020-11-15T00:28:18-0800] [MainThread] [I] [toil.leader] Job ended: 'get_pipeline_inputs' kind-get_pipeline_inputs/instance-b07a33j5
[2020-11-15T00:28:18-0800] [MainThread] [I] [toil.leader] Job ended: 'get_pipeline_inputs' kind-get_pipeline_inputs/instance-gquoa6eo
[2020-11-15T00:28:18-0800] [MainThread] [I] [toil.leader] Job ended: 'get_pipeline_inputs' kind-get_pipeline_inputs/instance-kruxi_g4
[2020-11-15T00:28:18-0800] [MainThread] [I] [toil.leader] Job ended: 'get_pipeline_inputs' kind-get_pipeline_inputs/instance-fp_69yov
[2020-11-15T00:28:18-0800] [MainThread] [I] [toil.leader] Job ended: 'get_pipeline_inputs' kind-get_pipeline_inputs/instance-1iu44e5t
[2020-11-15T00:28:18-0800] [MainThread] [I] [toil.leader] Job ended: 'get_pipeline_inputs' kind-get_pipeline_inputs/instance-mjjj9pl3
[2020-11-15T00:28:18-0800] [MainThread] [I] [toil.leader] Job ended: 'get_pipeline_inputs' kind-get_pipeline_inputs/instance-9yk9icyt
[2020-11-15T00:28:18-0800] [MainThread] [I] [toil.leader] Job ended: 'get_pipeline_inputs' kind-get_pipeline_inputs/instance-fdqruxwl
[2020-11-15T00:28:18-0800] [MainThread] [I] [toil.leader] Job ended: 'get_pipeline_inputs' kind-get_pipeline_inputs/instance-1i_zjhkv
[2020-11-15T00:28:18-0800] [MainThread] [I] [toil.leader] Job ended: 'get_pipeline_inputs' kind-get_pipeline_inputs/instance-_5sx0yzj
[2020-11-15T00:28:18-0800] [Thread-3  ] [I] [toil.statsAndLogging] Got message from job at time 11-15-2020 00:28:18: Obtaining file (indexes:cosmic_vcf) to the file job store
[2020-11-15T00:28:18-0800] [Thread-3  ] [I] [toil.statsAndLogging] Got message from job at time 11-15-2020 00:28:18: Obtaining file (transgene:gencode_peptide_fasta) to the file job store
[2020-11-15T00:28:18-0800] [MainThread] [I] [toil.leader] Job ended: 'get_pipeline_inputs' kind-get_pipeline_inputs/instance-28832prp
[2020-11-15T00:28:19-0800] [MainThread] [I] [toil.leader] Job ended: 'get_pipeline_inputs' kind-get_pipeline_inputs/instance-v9w5g4zj
[2020-11-15T00:28:19-0800] [Thread-3  ] [I] [toil.statsAndLogging] Got message from job at time 11-15-2020 00:28:19: Obtaining file (transgene:gencode_transcript_fasta) to the file job store
[2020-11-15T00:28:20-0800] [MainThread] [I] [toil.leader] Job ended: 'get_pipeline_inputs' kind-get_pipeline_inputs/instance-g34bgkh6
[2020-11-15T00:28:20-0800] [Thread-3  ] [I] [toil.statsAndLogging] Got message from job at time 11-15-2020 00:28:20: Obtaining file (transgene:gencode_annotation_gtf) to the file job store
[2020-11-15T00:28:42-0800] [MainThread] [I] [toil.leader] Job ended: 'get_pipeline_inputs' kind-get_pipeline_inputs/instance-lwawpwto
[2020-11-15T00:28:43-0800] [MainThread] [I] [toil.leader] Job ended: 'get_pipeline_inputs' kind-get_pipeline_inputs/instance-4okw3zyq
[2020-11-15T00:28:43-0800] [Thread-3  ] [I] [toil.statsAndLogging] Got message from job at time 11-15-2020 00:28:43: Obtaining file (indexes:genome_fasta) to the file job store
[2020-11-15T00:28:43-0800] [Thread-3  ] [I] [toil.statsAndLogging] Got message from job at time 11-15-2020 00:28:43: Obtaining file (transgene:genome_fasta) to the file job store
[2020-11-15T00:28:44-0800] [MainThread] [I] [toil.leader] Job ended: 'get_pipeline_inputs' kind-get_pipeline_inputs/instance-nb2ttglx
[2020-11-15T00:28:44-0800] [Thread-3  ] [I] [toil.statsAndLogging] Got message from job at time 11-15-2020 00:28:44: Obtaining file (radia:dbsnp_beds) to the file job store
[2020-11-15T00:29:04-0800] [Thread-3  ] [I] [toil.statsAndLogging] Got message from job at time 11-15-2020 00:29:04: Obtaining file (snpeff:index) to the file job store
[2020-11-15T00:29:04-0800] [Thread-3  ] [I] [toil.statsAndLogging] Got message from job at time 11-15-2020 00:29:04: Obtaining file (rsem:index) to the file job store
[2020-11-15T00:29:04-0800] [MainThread] [I] [toil.leader] Job ended: 'get_pipeline_inputs' kind-get_pipeline_inputs/instance-q7rykuf9
[2020-11-15T00:29:04-0800] [MainThread] [I] [toil.leader] Job ended: 'get_pipeline_inputs' kind-get_pipeline_inputs/instance-4449i24l
[2020-11-15T00:29:26-0800] [Thread-3  ] [I] [toil.statsAndLogging] Got message from job at time 11-15-2020 00:29:26: Obtaining file (indexes:dbsnp_vcf) to the file job store
[2020-11-15T00:29:26-0800] [MainThread] [I] [toil.leader] Job ended: 'get_pipeline_inputs' kind-get_pipeline_inputs/instance-e60iam16
[2020-11-15T00:30:07-0800] [MainThread] [I] [toil.leader] Job ended: 'get_pipeline_inputs' kind-get_pipeline_inputs/instance-w0r0fgkl
[2020-11-15T00:30:07-0800] [Thread-3  ] [I] [toil.statsAndLogging] Got message from job at time 11-15-2020 00:30:07: Obtaining file (bwa:index) to the file job store
[2020-11-15T00:30:15-0800] [MainThread] [I] [toil.leader] Job ended: 'get_pipeline_inputs' kind-get_pipeline_inputs/instance-igauxjaw
[2020-11-15T00:30:15-0800] [Thread-3  ] [I] [toil.statsAndLogging] Got message from job at time 11-15-2020 00:30:15: Obtaining file (phlat:index) to the file job store
[2020-11-15T00:32:10-0800] [MainThread] [I] [toil.leader] Job ended: 'get_pipeline_inputs' kind-get_pipeline_inputs/instance-xlca_kav
[2020-11-15T00:32:10-0800] [MainThread] [I] [toil.leader] Issued job 'launch_protect' kind-launch_protect/instance-9wa2ilmx with job batch system ID: 30 and cores: 1, disk: 2.0 G, and memory: 2.0 G
[2020-11-15T00:32:11-0800] [Thread-3  ] [I] [toil.statsAndLogging] Got message from job at time 11-15-2020 00:32:11: Obtaining file (star:index) to the file job store
[2020-11-15T00:32:11-0800] [MainThread] [I] [toil.worker] Redirecting logging to /private/home/drkthomp/protect3/workDir/node-60141861-48d9-4a88-81d8-ba092a076b7d-e8611b53-bdab-4598-acae-87977f99831e/tmp55ch8a3g/worker_log.txt
[2020-11-15T00:32:13-0800] [MainThread] [I] [toil.leader] Job ended: 'launch_protect' kind-launch_protect/instance-9wa2ilmx
[2020-11-15T00:32:13-0800] [MainThread] [I] [toil.leader] Issued job 'prepare_samples' kind-prepare_samples/instance-melw0o77 with job batch system ID: 31 and cores: 1, disk: 40.0 G, and memory: 2.0 G
[2020-11-15T00:32:13-0800] [MainThread] [I] [toil.worker] Redirecting logging to /private/home/drkthomp/protect3/workDir/node-60141861-48d9-4a88-81d8-ba092a076b7d-e8611b53-bdab-4598-acae-87977f99831e/tmpbbm40ixo/worker_log.txt
[2020-11-15T00:32:18-0800] [MainThread] [I] [toil.leader] Job ended: 'prepare_samples' kind-prepare_samples/instance-melw0o77
[2020-11-15T00:32:18-0800] [MainThread] [I] [toil.leader] Issued job 'get_patient_fastqs' kind-get_patient_fastqs/instance-z2akd685 with job batch system ID: 32 and cores: 1, disk: 10.0 M, and memory: 2.0 G
[2020-11-15T00:32:18-0800] [MainThread] [I] [toil.leader] Issued job 'get_patient_fastqs' kind-get_patient_fastqs/instance-3b6z2ec2 with job batch system ID: 33 and cores: 1, disk: 10.0 M, and memory: 2.0 G
[2020-11-15T00:32:18-0800] [MainThread] [I] [toil.leader] Issued job 'get_patient_fastqs' kind-get_patient_fastqs/instance-g31njymf with job batch system ID: 34 and cores: 1, disk: 10.0 M, and memory: 2.0 G
[2020-11-15T00:32:18-0800] [Thread-3  ] [I] [toil.statsAndLogging] Got message from job at time 11-15-2020 00:32:18: Downloading Inputs for TEST
[2020-11-15T00:32:18-0800] [Thread-3  ] [I] [toil.statsAndLogging] Got message from job at time 11-15-2020 00:32:18: Obtaining file (TEST:normal_dna_fastq_2) to the file job store
[2020-11-15T00:32:18-0800] [Thread-3  ] [I] [toil.statsAndLogging] Got message from job at time 11-15-2020 00:32:18: Obtaining file (TEST:tumor_rna_fastq_1) to the file job store
[2020-11-15T00:32:18-0800] [Thread-3  ] [I] [toil.statsAndLogging] Got message from job at time 11-15-2020 00:32:18: Obtaining file (TEST:normal_dna_fastq_1) to the file job store
[2020-11-15T00:32:18-0800] [Thread-3  ] [I] [toil.statsAndLogging] Got message from job at time 11-15-2020 00:32:18: Obtaining file (TEST:tumor_rna_fastq_2) to the file job store
[2020-11-15T00:32:18-0800] [Thread-3  ] [I] [toil.statsAndLogging] Got message from job at time 11-15-2020 00:32:18: Obtaining file (TEST:tumor_dna_fastq_2) to the file job store
[2020-11-15T00:32:18-0800] [Thread-3  ] [I] [toil.statsAndLogging] Got message from job at time 11-15-2020 00:32:18: Obtaining file (TEST:tumor_dna_fastq_1) to the file job store
[2020-11-15T00:32:19-0800] [MainThread] [I] [toil.worker] Redirecting logging to /private/home/drkthomp/protect3/workDir/node-60141861-48d9-4a88-81d8-ba092a076b7d-e8611b53-bdab-4598-acae-87977f99831e/tmpbfdfb38q/worker_log.txt
[2020-11-15T00:32:19-0800] [MainThread] [I] [toil.worker] Redirecting logging to /private/home/drkthomp/protect3/workDir/node-60141861-48d9-4a88-81d8-ba092a076b7d-e8611b53-bdab-4598-acae-87977f99831e/tmp0wkkhiwy/worker_log.txt
[2020-11-15T00:32:19-0800] [MainThread] [I] [toil.worker] Redirecting logging to /private/home/drkthomp/protect3/workDir/node-60141861-48d9-4a88-81d8-ba092a076b7d-e8611b53-bdab-4598-acae-87977f99831e/tmpwqv62_9x/worker_log.txt
[2020-11-15T00:32:20-0800] [MainThread] [I] [toil.leader] Job ended: 'get_patient_fastqs' kind-get_patient_fastqs/instance-z2akd685
[2020-11-15T00:32:20-0800] [MainThread] [I] [toil.leader] Issued job 'EncapsulatedJob' kind-EncapsulatedJob/instance-6r5wxjaz with job batch system ID: 35 and cores: 0, disk: 1.0 M, and memory: 32.0 M
[2020-11-15T00:32:20-0800] [MainThread] [I] [toil.leader] Issued job 'EncapsulatedJob' kind-EncapsulatedJob/instance-w4x4xjcb with job batch system ID: 36 and cores: 1, disk: 100.0 M, and memory: 2.0 G
[2020-11-15T00:32:20-0800] [MainThread] [I] [toil.leader] Job ended: 'get_patient_fastqs' kind-get_patient_fastqs/instance-g31njymf
[2020-11-15T00:32:20-0800] [MainThread] [I] [toil.leader] Issued job 'EncapsulatedJob' kind-EncapsulatedJob/instance-0l8ktz2m with job batch system ID: 37 and cores: 0, disk: 1.0 M, and memory: 32.0 M
[2020-11-15T00:32:20-0800] [MainThread] [I] [toil.leader] Issued job 'EncapsulatedJob' kind-EncapsulatedJob/instance-9fqlkbpn with job batch system ID: 38 and cores: 0, disk: 1.0 M, and memory: 32.0 M
[2020-11-15T00:32:20-0800] [MainThread] [I] [toil.leader] Job ended: 'get_patient_fastqs' kind-get_patient_fastqs/instance-3b6z2ec2
[2020-11-15T00:32:20-0800] [MainThread] [I] [toil.leader] Issued job 'EncapsulatedJob' kind-EncapsulatedJob/instance-gxsdjbsw with job batch system ID: 39 and cores: 0, disk: 1.0 M, and memory: 32.0 M
[2020-11-15T00:32:20-0800] [MainThread] [I] [toil.leader] Issued job 'EncapsulatedJob' kind-EncapsulatedJob/instance-fg9lg8z2 with job batch system ID: 40 and cores: 1, disk: 100.0 M, and memory: 2.0 G
[2020-11-15T00:32:20-0800] [MainThread] [I] [toil.worker] Redirecting logging to /private/home/drkthomp/protect3/workDir/node-60141861-48d9-4a88-81d8-ba092a076b7d-e8611b53-bdab-4598-acae-87977f99831e/tmpnxt8xcij/worker_log.txt
[2020-11-15T00:32:20-0800] [MainThread] [I] [toil.worker] Redirecting logging to /private/home/drkthomp/protect3/workDir/node-60141861-48d9-4a88-81d8-ba092a076b7d-e8611b53-bdab-4598-acae-87977f99831e/tmpihta2mkm/worker_log.txt
[2020-11-15T00:32:21-0800] [MainThread] [I] [toil.worker] Redirecting logging to /private/home/drkthomp/protect3/workDir/node-60141861-48d9-4a88-81d8-ba092a076b7d-e8611b53-bdab-4598-acae-87977f99831e/tmp548sakwu/worker_log.txt
[2020-11-15T00:32:21-0800] [MainThread] [I] [toil.worker] Redirecting logging to /private/home/drkthomp/protect3/workDir/node-60141861-48d9-4a88-81d8-ba092a076b7d-e8611b53-bdab-4598-acae-87977f99831e/tmp5nsvjnk7/worker_log.txt
[2020-11-15T00:32:21-0800] [MainThread] [I] [toil.worker] Redirecting logging to /private/home/drkthomp/protect3/workDir/node-60141861-48d9-4a88-81d8-ba092a076b7d-e8611b53-bdab-4598-acae-87977f99831e/tmpag4u9ej2/worker_log.txt
[2020-11-15T00:32:21-0800] [MainThread] [I] [toil.worker] Redirecting logging to /private/home/drkthomp/protect3/workDir/node-60141861-48d9-4a88-81d8-ba092a076b7d-e8611b53-bdab-4598-acae-87977f99831e/tmpve4br74u/worker_log.txt
[2020-11-15T00:32:21-0800] [MainThread] [I] [toil.leader] Job ended: 'EncapsulatedJob' kind-EncapsulatedJob/instance-6r5wxjaz
[2020-11-15T00:32:21-0800] [MainThread] [I] [toil.leader] Issued job 'run_phlat' kind-run_phlat/instance-3chuyae2 with job batch system ID: 41 and cores: 80, disk: 8.4 G, and memory: 2.0 G
[2020-11-15T00:32:22-0800] [MainThread] [I] [toil.leader] Job ended: 'EncapsulatedJob' kind-EncapsulatedJob/instance-0l8ktz2m
[2020-11-15T00:32:22-0800] [MainThread] [I] [toil.leader] Issued job 'run_phlat' kind-run_phlat/instance-rssn99a0 with job batch system ID: 42 and cores: 80, disk: 8.2 G, and memory: 2.0 G
[2020-11-15T00:32:22-0800] [MainThread] [I] [toil.leader] Job ended: 'EncapsulatedJob' kind-EncapsulatedJob/instance-gxsdjbsw
[2020-11-15T00:32:22-0800] [MainThread] [I] [toil.leader] Issued job 'run_phlat' kind-run_phlat/instance-z35qoqn5 with job batch system ID: 43 and cores: 80, disk: 8.3 G, and memory: 2.0 G
[2020-11-15T00:32:22-0800] [MainThread] [I] [toil.leader] Job ended: 'EncapsulatedJob' kind-EncapsulatedJob/instance-w4x4xjcb
[2020-11-15T00:32:22-0800] [MainThread] [I] [toil.leader] Issued job 'run_bwa' kind-run_bwa/instance-bou2djh0 with job batch system ID: 44 and cores: 80, disk: 13.4 G, and memory: 12.0 G
[2020-11-15T00:32:22-0800] [MainThread] [I] [toil.leader] Job ended: 'EncapsulatedJob' kind-EncapsulatedJob/instance-9fqlkbpn
[2020-11-15T00:32:22-0800] [MainThread] [I] [toil.leader] Issued job 'run_cutadapt' kind-run_cutadapt/instance-zdc0z58x with job batch system ID: 45 and cores: 1, disk: 1.8 G, and memory: 2.0 G
[2020-11-15T00:32:22-0800] [MainThread] [I] [toil.worker] Redirecting logging to /private/home/drkthomp/protect3/workDir/node-60141861-48d9-4a88-81d8-ba092a076b7d-e8611b53-bdab-4598-acae-87977f99831e/tmphy_rjfhn/worker_log.txt
[2020-11-15T00:32:22-0800] [MainThread] [I] [toil.leader] Job ended: 'EncapsulatedJob' kind-EncapsulatedJob/instance-fg9lg8z2
[2020-11-15T00:32:22-0800] [MainThread] [I] [toil.leader] Issued job 'run_bwa' kind-run_bwa/instance-fvcm11nr with job batch system ID: 46 and cores: 80, disk: 12.8 G, and memory: 12.0 G
[2020-11-15T00:32:22-0800] [MainThread] [I] [toil.worker] Redirecting logging to /private/home/drkthomp/protect3/workDir/node-60141861-48d9-4a88-81d8-ba092a076b7d-e8611b53-bdab-4598-acae-87977f99831e/tmp4_ttlnyx/worker_log.txt
[2020-11-15T00:33:53-0800] [Thread-1  ] [E] [toil.batchSystems.singleMachine] Got exit code 1 (indicating failure) from job _toil_worker run_cutadapt file:/scratch/drkthomp/jobStore kind-run_cutadapt/instance-zdc0z58x.
[2020-11-15T00:33:53-0800] [MainThread] [W] [toil.leader] Job failed with exit value 1: 'run_cutadapt' kind-run_cutadapt/instance-zdc0z58x
[2020-11-15T00:33:53-0800] [MainThread] [W] [toil.leader] The job seems to have left a log file, indicating failure: 'run_cutadapt' kind-run_cutadapt/instance-zdc0z58x
[2020-11-15T00:33:53-0800] [MainThread] [W] [toil.leader] Log from job kind-run_cutadapt/instance-zdc0z58x follows:
=========>
	[2020-11-15T00:32:22-0800] [MainThread] [I] [toil.worker] ---TOIL WORKER OUTPUT LOG---
	[2020-11-15T00:32:22-0800] [MainThread] [I] [toil] Running Toil version 4.2.0-3aa1da130141039cb357efe36d7df9b9f6ae9b5b on host mustard.
	Got permission denied while trying to connect to the Docker daemon socket at unix:///var/run/docker.sock: Get http://%2Fvar%2Frun%2Fdocker.sock/v1.37/images/json: dial unix /var/run/docker.sock: connect: permission denied
	Traceback (most recent call last):
	  File "/private/home/drkthomp/protect3/venv/lib/python3.6/site-packages/toil/worker.py", line 368, in workerScript
	    job._runner(jobGraph=jobGraph, jobStore=jobStore, fileStore=fileStore, defer=defer)
	  File "/private/home/drkthomp/protect3/venv/lib/python3.6/site-packages/toil/job.py", line 1424, in _runner
	    returnValues = self._run(jobGraph, fileStore)
	  File "/private/home/drkthomp/protect3/venv/lib/python3.6/site-packages/toil/job.py", line 1361, in _run
	    return self.run(fileStore)
	  File "/private/home/drkthomp/protect3/venv/lib/python3.6/site-packages/toil/job.py", line 1565, in run
	    rValue = userFunction(*((self,) + tuple(self._args)), **self._kwargs)
	  File "/private/home/drkthomp/protect3/src/protect/qc/rna.py", line 59, in run_cutadapt
	    dockerhub=univ_options['dockerhub'], tool_version=cutadapt_options['version'])
	  File "/private/home/drkthomp/protect3/src/protect/common.py", line 113, in docker_call
	    dimg_rv = subprocess.check_output(call).decode('utf-8')
	  File "/usr/lib64/python3.6/subprocess.py", line 336, in check_output
	    **kwargs).stdout
	  File "/usr/lib64/python3.6/subprocess.py", line 418, in run
	    output=stdout, stderr=stderr)
	subprocess.CalledProcessError: Command '['docker', 'images']' returned non-zero exit status 1.
	[2020-11-15T00:33:53-0800] [MainThread] [E] [toil.worker] Exiting the worker because of a failed job on host mustard
<=========
[2020-11-15T00:33:53-0800] [MainThread] [W] [toil.jobGraph] Due to failure we are reducing the remaining retry count of job 'run_cutadapt' kind-run_cutadapt/instance-zdc0z58x with ID kind-run_cutadapt/instance-zdc0z58x to 1
[2020-11-15T00:33:53-0800] [MainThread] [W] [toil.jobGraph] We have increased the disk of the failed job 'run_cutadapt' kind-run_cutadapt/instance-zdc0z58x to the default of 2147483648 bytes
[2020-11-15T00:33:53-0800] [MainThread] [I] [toil.leader] Issued job 'run_cutadapt' kind-run_cutadapt/instance-zdc0z58x with job batch system ID: 47 and cores: 1, disk: 2.0 G, and memory: 2.0 G
[2020-11-15T00:34:02-0800] [MainThread] [I] [toil.worker] Redirecting logging to /private/home/drkthomp/protect3/workDir/node-60141861-48d9-4a88-81d8-ba092a076b7d-e8611b53-bdab-4598-acae-87977f99831e/tmpzl1rm73q/worker_log.txt
[2020-11-15T00:47:35-0800] [Thread-1  ] [E] [toil.batchSystems.singleMachine] Got exit code 1 (indicating failure) from job _toil_worker run_phlat file:/scratch/drkthomp/jobStore kind-run_phlat/instance-3chuyae2.
[2020-11-15T00:47:35-0800] [MainThread] [W] [toil.leader] Job failed with exit value 1: 'run_phlat' kind-run_phlat/instance-3chuyae2
[2020-11-15T00:47:35-0800] [MainThread] [W] [toil.leader] The job seems to have left a log file, indicating failure: 'run_phlat' kind-run_phlat/instance-3chuyae2
[2020-11-15T00:47:35-0800] [MainThread] [W] [toil.leader] Log from job kind-run_phlat/instance-3chuyae2 follows:
=========>
	[2020-11-15T00:32:22-0800] [MainThread] [I] [toil.worker] ---TOIL WORKER OUTPUT LOG---
	[2020-11-15T00:32:22-0800] [MainThread] [I] [toil] Running Toil version 4.2.0-3aa1da130141039cb357efe36d7df9b9f6ae9b5b on host mustard.
	Got permission denied while trying to connect to the Docker daemon socket at unix:///var/run/docker.sock: Get http://%2Fvar%2Frun%2Fdocker.sock/v1.37/images/json: dial unix /var/run/docker.sock: connect: permission denied
	Traceback (most recent call last):
	  File "/private/home/drkthomp/protect3/venv/lib/python3.6/site-packages/toil/worker.py", line 368, in workerScript
	    job._runner(jobGraph=jobGraph, jobStore=jobStore, fileStore=fileStore, defer=defer)
	  File "/private/home/drkthomp/protect3/venv/lib/python3.6/site-packages/toil/job.py", line 1424, in _runner
	    returnValues = self._run(jobGraph, fileStore)
	  File "/private/home/drkthomp/protect3/venv/lib/python3.6/site-packages/toil/job.py", line 1361, in _run
	    return self.run(fileStore)
	  File "/private/home/drkthomp/protect3/venv/lib/python3.6/site-packages/toil/job.py", line 1565, in run
	    rValue = userFunction(*((self,) + tuple(self._args)), **self._kwargs)
	  File "/private/home/drkthomp/protect3/src/protect/haplotyping/phlat.py", line 74, in run_phlat
	    dockerhub=univ_options['dockerhub'], tool_version=phlat_options['version'])
	  File "/private/home/drkthomp/protect3/src/protect/common.py", line 113, in docker_call
	    dimg_rv = subprocess.check_output(call).decode('utf-8')
	  File "/usr/lib64/python3.6/subprocess.py", line 336, in check_output
	    **kwargs).stdout
	  File "/usr/lib64/python3.6/subprocess.py", line 418, in run
	    output=stdout, stderr=stderr)
	subprocess.CalledProcessError: Command '['docker', 'images']' returned non-zero exit status 1.
	[2020-11-15T00:47:31-0800] [MainThread] [E] [toil.worker] Exiting the worker because of a failed job on host mustard
	{'input_1.fastq': '/private/home/drkthomp/protect3/workDir/node-60141861-48d9-4a88-81d8-ba092a076b7d-e8611b53-bdab-4598-acae-87977f99831e/tmphy_rjfhn/446e9b13-3d2b-49c2-b442-7bb98ea88f41/input_1.fastq', 'input_2.fastq': '/private/home/drkthomp/protect3/workDir/node-60141861-48d9-4a88-81d8-ba092a076b7d-e8611b53-bdab-4598-acae-87977f99831e/tmphy_rjfhn/446e9b13-3d2b-49c2-b442-7bb98ea88f41/input_2.fastq', 'phlat_index.tar.gz': '/private/home/drkthomp/protect3/workDir/node-60141861-48d9-4a88-81d8-ba092a076b7d-e8611b53-bdab-4598-acae-87977f99831e/tmphy_rjfhn/446e9b13-3d2b-49c2-b442-7bb98ea88f41/phlat_index.tar.gz'}
<=========
[2020-11-15T00:47:35-0800] [MainThread] [W] [toil.jobGraph] Due to failure we are reducing the remaining retry count of job 'run_phlat' kind-run_phlat/instance-3chuyae2 with ID kind-run_phlat/instance-3chuyae2 to 1
[2020-11-15T00:47:35-0800] [MainThread] [I] [toil.leader] Issued job 'run_phlat' kind-run_phlat/instance-3chuyae2 with job batch system ID: 48 and cores: 80, disk: 8.4 G, and memory: 2.0 G
[2020-11-15T00:47:35-0800] [MainThread] [I] [toil.worker] Redirecting logging to /private/home/drkthomp/protect3/workDir/node-60141861-48d9-4a88-81d8-ba092a076b7d-e8611b53-bdab-4598-acae-87977f99831e/tmpe462tvp3/worker_log.txt
[2020-11-15T00:49:41-0800] [Thread-1  ] [E] [toil.batchSystems.singleMachine] Got exit code 1 (indicating failure) from job _toil_worker run_bwa file:/scratch/drkthomp/jobStore kind-run_bwa/instance-fvcm11nr.
[2020-11-15T00:49:41-0800] [MainThread] [W] [toil.leader] Job failed with exit value 1: 'run_bwa' kind-run_bwa/instance-fvcm11nr
[2020-11-15T00:49:41-0800] [MainThread] [W] [toil.leader] The job seems to have left a log file, indicating failure: 'run_bwa' kind-run_bwa/instance-fvcm11nr
[2020-11-15T00:49:41-0800] [MainThread] [W] [toil.leader] Log from job kind-run_bwa/instance-fvcm11nr follows:
=========>
	[2020-11-15T00:36:49-0800] [MainThread] [I] [toil.worker] ---TOIL WORKER OUTPUT LOG---
	[2020-11-15T00:36:49-0800] [MainThread] [I] [toil] Running Toil version 4.2.0-3aa1da130141039cb357efe36d7df9b9f6ae9b5b on host mustard.
	Got permission denied while trying to connect to the Docker daemon socket at unix:///var/run/docker.sock: Get http://%2Fvar%2Frun%2Fdocker.sock/v1.37/images/json: dial unix /var/run/docker.sock: connect: permission denied
	Traceback (most recent call last):
	  File "/private/home/drkthomp/protect3/venv/lib/python3.6/site-packages/toil/worker.py", line 368, in workerScript
	    job._runner(jobGraph=jobGraph, jobStore=jobStore, fileStore=fileStore, defer=defer)
	  File "/private/home/drkthomp/protect3/venv/lib/python3.6/site-packages/toil/job.py", line 1424, in _runner
	    returnValues = self._run(jobGraph, fileStore)
	  File "/private/home/drkthomp/protect3/venv/lib/python3.6/site-packages/toil/job.py", line 1361, in _run
	    return self.run(fileStore)
	  File "/private/home/drkthomp/protect3/venv/lib/python3.6/site-packages/toil/job.py", line 1565, in run
	    rValue = userFunction(*((self,) + tuple(self._args)), **self._kwargs)
	  File "/private/home/drkthomp/protect3/src/protect/alignment/dna.py", line 142, in run_bwa
	    tool_version=bwa_options['version'])
	  File "/private/home/drkthomp/protect3/src/protect/common.py", line 113, in docker_call
	    dimg_rv = subprocess.check_output(call).decode('utf-8')
	  File "/usr/lib64/python3.6/subprocess.py", line 336, in check_output
	    **kwargs).stdout
	  File "/usr/lib64/python3.6/subprocess.py", line 418, in run
	    output=stdout, stderr=stderr)
	subprocess.CalledProcessError: Command '['docker', 'images']' returned non-zero exit status 1.
	[2020-11-15T00:49:36-0800] [MainThread] [E] [toil.worker] Exiting the worker because of a failed job on host mustard
<=========
[2020-11-15T00:49:41-0800] [MainThread] [W] [toil.jobGraph] Due to failure we are reducing the remaining retry count of job 'run_bwa' kind-run_bwa/instance-fvcm11nr with ID kind-run_bwa/instance-fvcm11nr to 1
[2020-11-15T00:49:41-0800] [MainThread] [I] [toil.leader] Issued job 'run_bwa' kind-run_bwa/instance-fvcm11nr with job batch system ID: 49 and cores: 80, disk: 12.8 G, and memory: 12.0 G
[2020-11-15T00:49:41-0800] [MainThread] [I] [toil.worker] Redirecting logging to /private/home/drkthomp/protect3/workDir/node-60141861-48d9-4a88-81d8-ba092a076b7d-e8611b53-bdab-4598-acae-87977f99831e/tmpkc9r42n6/worker_log.txt
[2020-11-15T01:05:00-0800] [Thread-1  ] [E] [toil.batchSystems.singleMachine] Got exit code 1 (indicating failure) from job _toil_worker run_phlat file:/scratch/drkthomp/jobStore kind-run_phlat/instance-z35qoqn5.
[2020-11-15T01:05:00-0800] [MainThread] [W] [toil.leader] Job failed with exit value 1: 'run_phlat' kind-run_phlat/instance-z35qoqn5
[2020-11-15T01:05:00-0800] [MainThread] [W] [toil.leader] The job seems to have left a log file, indicating failure: 'run_phlat' kind-run_phlat/instance-z35qoqn5
[2020-11-15T01:05:00-0800] [MainThread] [W] [toil.leader] Log from job kind-run_phlat/instance-z35qoqn5 follows:
=========>
	[2020-11-15T00:49:41-0800] [MainThread] [I] [toil.worker] ---TOIL WORKER OUTPUT LOG---
	[2020-11-15T00:49:41-0800] [MainThread] [I] [toil] Running Toil version 4.2.0-3aa1da130141039cb357efe36d7df9b9f6ae9b5b on host mustard.
	Got permission denied while trying to connect to the Docker daemon socket at unix:///var/run/docker.sock: Get http://%2Fvar%2Frun%2Fdocker.sock/v1.37/images/json: dial unix /var/run/docker.sock: connect: permission denied
	[2020-11-15T01:04:56-0800] [MainThread] [W] [toil.fileStores.abstractFileStore] LOG-TO-MASTER: Job used more disk than requested. Consider modifying the user script to avoid the chance of failure due to incorrectly requested resources. Job files/for-job/kind-EncapsulatedJob/instance-gxsdjbsw/cleanup/file-m5btl4fd/stream used 100.26% (8.3 GB [8937328640B] used, 8.3 GB [8914445280B] requested) at the end of its run.
	Traceback (most recent call last):
	  File "/private/home/drkthomp/protect3/venv/lib/python3.6/site-packages/toil/worker.py", line 368, in workerScript
	    job._runner(jobGraph=jobGraph, jobStore=jobStore, fileStore=fileStore, defer=defer)
	  File "/private/home/drkthomp/protect3/venv/lib/python3.6/site-packages/toil/job.py", line 1424, in _runner
	    returnValues = self._run(jobGraph, fileStore)
	  File "/private/home/drkthomp/protect3/venv/lib/python3.6/site-packages/toil/job.py", line 1361, in _run
	    return self.run(fileStore)
	  File "/private/home/drkthomp/protect3/venv/lib/python3.6/site-packages/toil/job.py", line 1565, in run
	    rValue = userFunction(*((self,) + tuple(self._args)), **self._kwargs)
	  File "/private/home/drkthomp/protect3/src/protect/haplotyping/phlat.py", line 74, in run_phlat
	    dockerhub=univ_options['dockerhub'], tool_version=phlat_options['version'])
	  File "/private/home/drkthomp/protect3/src/protect/common.py", line 113, in docker_call
	    dimg_rv = subprocess.check_output(call).decode('utf-8')
	  File "/usr/lib64/python3.6/subprocess.py", line 336, in check_output
	    **kwargs).stdout
	  File "/usr/lib64/python3.6/subprocess.py", line 418, in run
	    output=stdout, stderr=stderr)
	subprocess.CalledProcessError: Command '['docker', 'images']' returned non-zero exit status 1.
	[2020-11-15T01:04:56-0800] [MainThread] [E] [toil.worker] Exiting the worker because of a failed job on host mustard
	{'input_1.fastq': '/private/home/drkthomp/protect3/workDir/node-60141861-48d9-4a88-81d8-ba092a076b7d-e8611b53-bdab-4598-acae-87977f99831e/tmpkc9r42n6/dd78e603-aed3-4dff-93b0-12359cb8a8df/input_1.fastq', 'input_2.fastq': '/private/home/drkthomp/protect3/workDir/node-60141861-48d9-4a88-81d8-ba092a076b7d-e8611b53-bdab-4598-acae-87977f99831e/tmpkc9r42n6/dd78e603-aed3-4dff-93b0-12359cb8a8df/input_2.fastq', 'phlat_index.tar.gz': '/private/home/drkthomp/protect3/workDir/node-60141861-48d9-4a88-81d8-ba092a076b7d-e8611b53-bdab-4598-acae-87977f99831e/tmpkc9r42n6/dd78e603-aed3-4dff-93b0-12359cb8a8df/phlat_index.tar.gz'}
<=========
[2020-11-15T01:05:00-0800] [MainThread] [W] [toil.jobGraph] Due to failure we are reducing the remaining retry count of job 'run_phlat' kind-run_phlat/instance-z35qoqn5 with ID kind-run_phlat/instance-z35qoqn5 to 1
[2020-11-15T01:05:00-0800] [MainThread] [I] [toil.leader] Issued job 'run_phlat' kind-run_phlat/instance-z35qoqn5 with job batch system ID: 50 and cores: 80, disk: 8.3 G, and memory: 2.0 G
[2020-11-15T01:05:40-0800] [MainThread] [I] [toil.worker] Redirecting logging to /private/home/drkthomp/protect3/workDir/node-60141861-48d9-4a88-81d8-ba092a076b7d-e8611b53-bdab-4598-acae-87977f99831e/tmp_0lelddo/worker_log.txt
[2020-11-15T01:06:37-0800] [Thread-1  ] [E] [toil.batchSystems.singleMachine] Got exit code 1 (indicating failure) from job _toil_worker run_phlat file:/scratch/drkthomp/jobStore kind-run_phlat/instance-rssn99a0.
[2020-11-15T01:06:37-0800] [MainThread] [W] [toil.leader] Job failed with exit value 1: 'run_phlat' kind-run_phlat/instance-rssn99a0
[2020-11-15T01:06:37-0800] [MainThread] [W] [toil.leader] The job seems to have left a log file, indicating failure: 'run_phlat' kind-run_phlat/instance-rssn99a0
[2020-11-15T01:06:37-0800] [MainThread] [W] [toil.leader] Log from job kind-run_phlat/instance-rssn99a0 follows:
=========>
	[2020-11-15T00:47:35-0800] [MainThread] [I] [toil.worker] ---TOIL WORKER OUTPUT LOG---
	[2020-11-15T00:47:35-0800] [MainThread] [I] [toil] Running Toil version 4.2.0-3aa1da130141039cb357efe36d7df9b9f6ae9b5b on host mustard.
	Got permission denied while trying to connect to the Docker daemon socket at unix:///var/run/docker.sock: Get http://%2Fvar%2Frun%2Fdocker.sock/v1.37/images/json: dial unix /var/run/docker.sock: connect: permission denied
	Traceback (most recent call last):
	  File "/private/home/drkthomp/protect3/venv/lib/python3.6/site-packages/toil/worker.py", line 368, in workerScript
	    job._runner(jobGraph=jobGraph, jobStore=jobStore, fileStore=fileStore, defer=defer)
	  File "/private/home/drkthomp/protect3/venv/lib/python3.6/site-packages/toil/job.py", line 1424, in _runner
	    returnValues = self._run(jobGraph, fileStore)
	  File "/private/home/drkthomp/protect3/venv/lib/python3.6/site-packages/toil/job.py", line 1361, in _run
	    return self.run(fileStore)
	  File "/private/home/drkthomp/protect3/venv/lib/python3.6/site-packages/toil/job.py", line 1565, in run
	    rValue = userFunction(*((self,) + tuple(self._args)), **self._kwargs)
	  File "/private/home/drkthomp/protect3/src/protect/haplotyping/phlat.py", line 74, in run_phlat
	    dockerhub=univ_options['dockerhub'], tool_version=phlat_options['version'])
	  File "/private/home/drkthomp/protect3/src/protect/common.py", line 113, in docker_call
	    dimg_rv = subprocess.check_output(call).decode('utf-8')
	  File "/usr/lib64/python3.6/subprocess.py", line 336, in check_output
	    **kwargs).stdout
	  File "/usr/lib64/python3.6/subprocess.py", line 418, in run
	    output=stdout, stderr=stderr)
	subprocess.CalledProcessError: Command '['docker', 'images']' returned non-zero exit status 1.
	[2020-11-15T01:06:10-0800] [MainThread] [E] [toil.worker] Exiting the worker because of a failed job on host mustard
	{'input_1.fastq': '/private/home/drkthomp/protect3/workDir/node-60141861-48d9-4a88-81d8-ba092a076b7d-e8611b53-bdab-4598-acae-87977f99831e/tmpe462tvp3/6525744e-5cc8-4261-93e3-ea8705ff5bea/input_1.fastq', 'input_2.fastq': '/private/home/drkthomp/protect3/workDir/node-60141861-48d9-4a88-81d8-ba092a076b7d-e8611b53-bdab-4598-acae-87977f99831e/tmpe462tvp3/6525744e-5cc8-4261-93e3-ea8705ff5bea/input_2.fastq', 'phlat_index.tar.gz': '/private/home/drkthomp/protect3/workDir/node-60141861-48d9-4a88-81d8-ba092a076b7d-e8611b53-bdab-4598-acae-87977f99831e/tmpe462tvp3/6525744e-5cc8-4261-93e3-ea8705ff5bea/phlat_index.tar.gz'}
<=========
[2020-11-15T01:06:37-0800] [MainThread] [W] [toil.jobGraph] Due to failure we are reducing the remaining retry count of job 'run_phlat' kind-run_phlat/instance-rssn99a0 with ID kind-run_phlat/instance-rssn99a0 to 1
[2020-11-15T01:06:37-0800] [MainThread] [I] [toil.leader] Issued job 'run_phlat' kind-run_phlat/instance-rssn99a0 with job batch system ID: 51 and cores: 80, disk: 8.2 G, and memory: 2.0 G
[2020-11-15T01:06:38-0800] [MainThread] [I] [toil.worker] Redirecting logging to /private/home/drkthomp/protect3/workDir/node-60141861-48d9-4a88-81d8-ba092a076b7d-e8611b53-bdab-4598-acae-87977f99831e/tmp_06vhw95/worker_log.txt
[2020-11-15T01:19:35-0800] [Thread-1  ] [E] [toil.batchSystems.singleMachine] Got exit code 1 (indicating failure) from job _toil_worker run_phlat file:/scratch/drkthomp/jobStore kind-run_phlat/instance-3chuyae2.
[2020-11-15T01:19:35-0800] [MainThread] [W] [toil.leader] Job failed with exit value 1: 'run_phlat' kind-run_phlat/instance-3chuyae2
[2020-11-15T01:19:35-0800] [MainThread] [W] [toil.leader] The job seems to have left a log file, indicating failure: 'run_phlat' kind-run_phlat/instance-3chuyae2
[2020-11-15T01:19:35-0800] [MainThread] [W] [toil.leader] Log from job kind-run_phlat/instance-3chuyae2 follows:
=========>
	[2020-11-15T01:05:40-0800] [MainThread] [I] [toil.worker] ---TOIL WORKER OUTPUT LOG---
	[2020-11-15T01:05:40-0800] [MainThread] [I] [toil] Running Toil version 4.2.0-3aa1da130141039cb357efe36d7df9b9f6ae9b5b on host mustard.
	Got permission denied while trying to connect to the Docker daemon socket at unix:///var/run/docker.sock: Get http://%2Fvar%2Frun%2Fdocker.sock/v1.37/images/json: dial unix /var/run/docker.sock: connect: permission denied
	Traceback (most recent call last):
	  File "/private/home/drkthomp/protect3/venv/lib/python3.6/site-packages/toil/worker.py", line 368, in workerScript
	    job._runner(jobGraph=jobGraph, jobStore=jobStore, fileStore=fileStore, defer=defer)
	  File "/private/home/drkthomp/protect3/venv/lib/python3.6/site-packages/toil/job.py", line 1424, in _runner
	    returnValues = self._run(jobGraph, fileStore)
	  File "/private/home/drkthomp/protect3/venv/lib/python3.6/site-packages/toil/job.py", line 1361, in _run
	    return self.run(fileStore)
	  File "/private/home/drkthomp/protect3/venv/lib/python3.6/site-packages/toil/job.py", line 1565, in run
	    rValue = userFunction(*((self,) + tuple(self._args)), **self._kwargs)
	  File "/private/home/drkthomp/protect3/src/protect/haplotyping/phlat.py", line 74, in run_phlat
	    dockerhub=univ_options['dockerhub'], tool_version=phlat_options['version'])
	  File "/private/home/drkthomp/protect3/src/protect/common.py", line 113, in docker_call
	    dimg_rv = subprocess.check_output(call).decode('utf-8')
	  File "/usr/lib64/python3.6/subprocess.py", line 336, in check_output
	    **kwargs).stdout
	  File "/usr/lib64/python3.6/subprocess.py", line 418, in run
	    output=stdout, stderr=stderr)
	subprocess.CalledProcessError: Command '['docker', 'images']' returned non-zero exit status 1.
	[2020-11-15T01:19:31-0800] [MainThread] [E] [toil.worker] Exiting the worker because of a failed job on host mustard
	{'input_1.fastq': '/private/home/drkthomp/protect3/workDir/node-60141861-48d9-4a88-81d8-ba092a076b7d-e8611b53-bdab-4598-acae-87977f99831e/tmp_0lelddo/56082201-c209-4966-aac9-416a6c9f8418/input_1.fastq', 'input_2.fastq': '/private/home/drkthomp/protect3/workDir/node-60141861-48d9-4a88-81d8-ba092a076b7d-e8611b53-bdab-4598-acae-87977f99831e/tmp_0lelddo/56082201-c209-4966-aac9-416a6c9f8418/input_2.fastq', 'phlat_index.tar.gz': '/private/home/drkthomp/protect3/workDir/node-60141861-48d9-4a88-81d8-ba092a076b7d-e8611b53-bdab-4598-acae-87977f99831e/tmp_0lelddo/56082201-c209-4966-aac9-416a6c9f8418/phlat_index.tar.gz'}
<=========
[2020-11-15T01:19:35-0800] [MainThread] [W] [toil.jobGraph] Due to failure we are reducing the remaining retry count of job 'run_phlat' kind-run_phlat/instance-3chuyae2 with ID kind-run_phlat/instance-3chuyae2 to 0
[2020-11-15T01:19:35-0800] [MainThread] [W] [toil.leader] Job 'run_phlat' kind-run_phlat/instance-3chuyae2 with ID kind-run_phlat/instance-3chuyae2 is completely failed
[2020-11-15T01:19:36-0800] [MainThread] [I] [toil.worker] Redirecting logging to /private/home/drkthomp/protect3/workDir/node-60141861-48d9-4a88-81d8-ba092a076b7d-e8611b53-bdab-4598-acae-87977f99831e/tmpy_dkrea9/worker_log.txt
[2020-11-15T01:20:52-0800] [Thread-1  ] [E] [toil.batchSystems.singleMachine] Got exit code 1 (indicating failure) from job _toil_worker run_bwa file:/scratch/drkthomp/jobStore kind-run_bwa/instance-fvcm11nr.
[2020-11-15T01:20:52-0800] [MainThread] [W] [toil.leader] Job failed with exit value 1: 'run_bwa' kind-run_bwa/instance-fvcm11nr
[2020-11-15T01:20:52-0800] [MainThread] [W] [toil.leader] The job seems to have left a log file, indicating failure: 'run_bwa' kind-run_bwa/instance-fvcm11nr
[2020-11-15T01:20:52-0800] [MainThread] [W] [toil.leader] Log from job kind-run_bwa/instance-fvcm11nr follows:
=========>
	[2020-11-15T01:06:38-0800] [MainThread] [I] [toil.worker] ---TOIL WORKER OUTPUT LOG---
	[2020-11-15T01:06:38-0800] [MainThread] [I] [toil] Running Toil version 4.2.0-3aa1da130141039cb357efe36d7df9b9f6ae9b5b on host mustard.
	Got permission denied while trying to connect to the Docker daemon socket at unix:///var/run/docker.sock: Get http://%2Fvar%2Frun%2Fdocker.sock/v1.37/images/json: dial unix /var/run/docker.sock: connect: permission denied
	Traceback (most recent call last):
	  File "/private/home/drkthomp/protect3/venv/lib/python3.6/site-packages/toil/worker.py", line 368, in workerScript
	    job._runner(jobGraph=jobGraph, jobStore=jobStore, fileStore=fileStore, defer=defer)
	  File "/private/home/drkthomp/protect3/venv/lib/python3.6/site-packages/toil/job.py", line 1424, in _runner
	    returnValues = self._run(jobGraph, fileStore)
	  File "/private/home/drkthomp/protect3/venv/lib/python3.6/site-packages/toil/job.py", line 1361, in _run
	    return self.run(fileStore)
	  File "/private/home/drkthomp/protect3/venv/lib/python3.6/site-packages/toil/job.py", line 1565, in run
	    rValue = userFunction(*((self,) + tuple(self._args)), **self._kwargs)
	  File "/private/home/drkthomp/protect3/src/protect/alignment/dna.py", line 142, in run_bwa
	    tool_version=bwa_options['version'])
	  File "/private/home/drkthomp/protect3/src/protect/common.py", line 113, in docker_call
	    dimg_rv = subprocess.check_output(call).decode('utf-8')
	  File "/usr/lib64/python3.6/subprocess.py", line 336, in check_output
	    **kwargs).stdout
	  File "/usr/lib64/python3.6/subprocess.py", line 418, in run
	    output=stdout, stderr=stderr)
	subprocess.CalledProcessError: Command '['docker', 'images']' returned non-zero exit status 1.
	[2020-11-15T01:20:32-0800] [MainThread] [E] [toil.worker] Exiting the worker because of a failed job on host mustard
<=========
[2020-11-15T01:20:52-0800] [MainThread] [W] [toil.jobGraph] Due to failure we are reducing the remaining retry count of job 'run_bwa' kind-run_bwa/instance-fvcm11nr with ID kind-run_bwa/instance-fvcm11nr to 0
[2020-11-15T01:20:52-0800] [MainThread] [W] [toil.leader] Job 'run_bwa' kind-run_bwa/instance-fvcm11nr with ID kind-run_bwa/instance-fvcm11nr is completely failed
[2020-11-15T01:20:53-0800] [MainThread] [I] [toil.worker] Redirecting logging to /private/home/drkthomp/protect3/workDir/node-60141861-48d9-4a88-81d8-ba092a076b7d-e8611b53-bdab-4598-acae-87977f99831e/tmpuu1i8kep/worker_log.txt
[2020-11-15T01:28:14-0800] [MainThread] [I] [toil.leader] 2 jobs are running, 2 jobs are issued and waiting to run
[2020-11-15T01:35:01-0800] [Thread-1  ] [E] [toil.batchSystems.singleMachine] Got exit code 1 (indicating failure) from job _toil_worker run_phlat file:/scratch/drkthomp/jobStore kind-run_phlat/instance-rssn99a0.
[2020-11-15T01:35:01-0800] [MainThread] [W] [toil.leader] Job failed with exit value 1: 'run_phlat' kind-run_phlat/instance-rssn99a0
[2020-11-15T01:35:01-0800] [MainThread] [W] [toil.leader] The job seems to have left a log file, indicating failure: 'run_phlat' kind-run_phlat/instance-rssn99a0
[2020-11-15T01:35:01-0800] [MainThread] [W] [toil.leader] Log from job kind-run_phlat/instance-rssn99a0 follows:
=========>
	[2020-11-15T01:19:36-0800] [MainThread] [I] [toil.worker] ---TOIL WORKER OUTPUT LOG---
	[2020-11-15T01:19:36-0800] [MainThread] [I] [toil] Running Toil version 4.2.0-3aa1da130141039cb357efe36d7df9b9f6ae9b5b on host mustard.
	Got permission denied while trying to connect to the Docker daemon socket at unix:///var/run/docker.sock: Get http://%2Fvar%2Frun%2Fdocker.sock/v1.37/images/json: dial unix /var/run/docker.sock: connect: permission denied
	Traceback (most recent call last):
	  File "/private/home/drkthomp/protect3/venv/lib/python3.6/site-packages/toil/worker.py", line 368, in workerScript
	    job._runner(jobGraph=jobGraph, jobStore=jobStore, fileStore=fileStore, defer=defer)
	  File "/private/home/drkthomp/protect3/venv/lib/python3.6/site-packages/toil/job.py", line 1424, in _runner
	    returnValues = self._run(jobGraph, fileStore)
	  File "/private/home/drkthomp/protect3/venv/lib/python3.6/site-packages/toil/job.py", line 1361, in _run
	    return self.run(fileStore)
	  File "/private/home/drkthomp/protect3/venv/lib/python3.6/site-packages/toil/job.py", line 1565, in run
	    rValue = userFunction(*((self,) + tuple(self._args)), **self._kwargs)
	  File "/private/home/drkthomp/protect3/src/protect/haplotyping/phlat.py", line 74, in run_phlat
	    dockerhub=univ_options['dockerhub'], tool_version=phlat_options['version'])
	  File "/private/home/drkthomp/protect3/src/protect/common.py", line 113, in docker_call
	    dimg_rv = subprocess.check_output(call).decode('utf-8')
	  File "/usr/lib64/python3.6/subprocess.py", line 336, in check_output
	    **kwargs).stdout
	  File "/usr/lib64/python3.6/subprocess.py", line 418, in run
	    output=stdout, stderr=stderr)
	subprocess.CalledProcessError: Command '['docker', 'images']' returned non-zero exit status 1.
	[2020-11-15T01:34:56-0800] [MainThread] [E] [toil.worker] Exiting the worker because of a failed job on host mustard
	{'input_1.fastq': '/private/home/drkthomp/protect3/workDir/node-60141861-48d9-4a88-81d8-ba092a076b7d-e8611b53-bdab-4598-acae-87977f99831e/tmpy_dkrea9/78036fa8-a915-466e-aaef-c8d1f08c7bd7/input_1.fastq', 'input_2.fastq': '/private/home/drkthomp/protect3/workDir/node-60141861-48d9-4a88-81d8-ba092a076b7d-e8611b53-bdab-4598-acae-87977f99831e/tmpy_dkrea9/78036fa8-a915-466e-aaef-c8d1f08c7bd7/input_2.fastq', 'phlat_index.tar.gz': '/private/home/drkthomp/protect3/workDir/node-60141861-48d9-4a88-81d8-ba092a076b7d-e8611b53-bdab-4598-acae-87977f99831e/tmpy_dkrea9/78036fa8-a915-466e-aaef-c8d1f08c7bd7/phlat_index.tar.gz'}
<=========
[2020-11-15T01:35:01-0800] [MainThread] [W] [toil.jobGraph] Due to failure we are reducing the remaining retry count of job 'run_phlat' kind-run_phlat/instance-rssn99a0 with ID kind-run_phlat/instance-rssn99a0 to 0
[2020-11-15T01:35:01-0800] [MainThread] [W] [toil.leader] Job 'run_phlat' kind-run_phlat/instance-rssn99a0 with ID kind-run_phlat/instance-rssn99a0 is completely failed
[2020-11-15T01:35:02-0800] [MainThread] [I] [toil.worker] Redirecting logging to /private/home/drkthomp/protect3/workDir/node-60141861-48d9-4a88-81d8-ba092a076b7d-e8611b53-bdab-4598-acae-87977f99831e/tmpf8x9yyk2/worker_log.txt
[2020-11-15T01:36:31-0800] [Thread-1  ] [E] [toil.batchSystems.singleMachine] Got exit code 1 (indicating failure) from job _toil_worker run_bwa file:/scratch/drkthomp/jobStore kind-run_bwa/instance-bou2djh0.
[2020-11-15T01:36:31-0800] [MainThread] [W] [toil.leader] Job failed with exit value 1: 'run_bwa' kind-run_bwa/instance-bou2djh0
[2020-11-15T01:36:31-0800] [MainThread] [W] [toil.leader] The job seems to have left a log file, indicating failure: 'run_bwa' kind-run_bwa/instance-bou2djh0
[2020-11-15T01:36:31-0800] [MainThread] [W] [toil.leader] Log from job kind-run_bwa/instance-bou2djh0 follows:
=========>
	[2020-11-15T01:20:53-0800] [MainThread] [I] [toil.worker] ---TOIL WORKER OUTPUT LOG---
	[2020-11-15T01:20:53-0800] [MainThread] [I] [toil] Running Toil version 4.2.0-3aa1da130141039cb357efe36d7df9b9f6ae9b5b on host mustard.
	Got permission denied while trying to connect to the Docker daemon socket at unix:///var/run/docker.sock: Get http://%2Fvar%2Frun%2Fdocker.sock/v1.37/images/json: dial unix /var/run/docker.sock: connect: permission denied
	Traceback (most recent call last):
	  File "/private/home/drkthomp/protect3/venv/lib/python3.6/site-packages/toil/worker.py", line 368, in workerScript
	    job._runner(jobGraph=jobGraph, jobStore=jobStore, fileStore=fileStore, defer=defer)
	  File "/private/home/drkthomp/protect3/venv/lib/python3.6/site-packages/toil/job.py", line 1424, in _runner
	    returnValues = self._run(jobGraph, fileStore)
	  File "/private/home/drkthomp/protect3/venv/lib/python3.6/site-packages/toil/job.py", line 1361, in _run
	    return self.run(fileStore)
	  File "/private/home/drkthomp/protect3/venv/lib/python3.6/site-packages/toil/job.py", line 1565, in run
	    rValue = userFunction(*((self,) + tuple(self._args)), **self._kwargs)
	  File "/private/home/drkthomp/protect3/src/protect/alignment/dna.py", line 142, in run_bwa
	    tool_version=bwa_options['version'])
	  File "/private/home/drkthomp/protect3/src/protect/common.py", line 113, in docker_call
	    dimg_rv = subprocess.check_output(call).decode('utf-8')
	  File "/usr/lib64/python3.6/subprocess.py", line 336, in check_output
	    **kwargs).stdout
	  File "/usr/lib64/python3.6/subprocess.py", line 418, in run
	    output=stdout, stderr=stderr)
	subprocess.CalledProcessError: Command '['docker', 'images']' returned non-zero exit status 1.
	[2020-11-15T01:36:10-0800] [MainThread] [E] [toil.worker] Exiting the worker because of a failed job on host mustard
<=========
[2020-11-15T01:36:31-0800] [MainThread] [W] [toil.jobGraph] Due to failure we are reducing the remaining retry count of job 'run_bwa' kind-run_bwa/instance-bou2djh0 with ID kind-run_bwa/instance-bou2djh0 to 1
[2020-11-15T01:36:31-0800] [MainThread] [I] [toil.leader] Issued job 'run_bwa' kind-run_bwa/instance-bou2djh0 with job batch system ID: 52 and cores: 80, disk: 13.4 G, and memory: 12.0 G
[2020-11-15T01:36:32-0800] [MainThread] [I] [toil.worker] Redirecting logging to /private/home/drkthomp/protect3/workDir/node-60141861-48d9-4a88-81d8-ba092a076b7d-e8611b53-bdab-4598-acae-87977f99831e/tmpoq63s6mq/worker_log.txt
[2020-11-15T01:40:10-0800] [Thread-1  ] [E] [toil.batchSystems.singleMachine] Got exit code 1 (indicating failure) from job _toil_worker run_cutadapt file:/scratch/drkthomp/jobStore kind-run_cutadapt/instance-zdc0z58x.
[2020-11-15T01:40:10-0800] [MainThread] [W] [toil.leader] Job failed with exit value 1: 'run_cutadapt' kind-run_cutadapt/instance-zdc0z58x
[2020-11-15T01:40:10-0800] [MainThread] [W] [toil.leader] The job seems to have left a log file, indicating failure: 'run_cutadapt' kind-run_cutadapt/instance-zdc0z58x
[2020-11-15T01:40:10-0800] [MainThread] [W] [toil.leader] Log from job kind-run_cutadapt/instance-zdc0z58x follows:
=========>
	[2020-11-15T01:36:32-0800] [MainThread] [I] [toil.worker] ---TOIL WORKER OUTPUT LOG---
	[2020-11-15T01:36:32-0800] [MainThread] [I] [toil] Running Toil version 4.2.0-3aa1da130141039cb357efe36d7df9b9f6ae9b5b on host mustard.
	Got permission denied while trying to connect to the Docker daemon socket at unix:///var/run/docker.sock: Get http://%2Fvar%2Frun%2Fdocker.sock/v1.37/images/json: dial unix /var/run/docker.sock: connect: permission denied
	Traceback (most recent call last):
	  File "/private/home/drkthomp/protect3/venv/lib/python3.6/site-packages/toil/worker.py", line 368, in workerScript
	    job._runner(jobGraph=jobGraph, jobStore=jobStore, fileStore=fileStore, defer=defer)
	  File "/private/home/drkthomp/protect3/venv/lib/python3.6/site-packages/toil/job.py", line 1424, in _runner
	    returnValues = self._run(jobGraph, fileStore)
	  File "/private/home/drkthomp/protect3/venv/lib/python3.6/site-packages/toil/job.py", line 1361, in _run
	    return self.run(fileStore)
	  File "/private/home/drkthomp/protect3/venv/lib/python3.6/site-packages/toil/job.py", line 1565, in run
	    rValue = userFunction(*((self,) + tuple(self._args)), **self._kwargs)
	  File "/private/home/drkthomp/protect3/src/protect/qc/rna.py", line 59, in run_cutadapt
	    dockerhub=univ_options['dockerhub'], tool_version=cutadapt_options['version'])
	  File "/private/home/drkthomp/protect3/src/protect/common.py", line 113, in docker_call
	    dimg_rv = subprocess.check_output(call).decode('utf-8')
	  File "/usr/lib64/python3.6/subprocess.py", line 336, in check_output
	    **kwargs).stdout
	  File "/usr/lib64/python3.6/subprocess.py", line 418, in run
	    output=stdout, stderr=stderr)
	subprocess.CalledProcessError: Command '['docker', 'images']' returned non-zero exit status 1.
	[2020-11-15T01:40:09-0800] [MainThread] [E] [toil.worker] Exiting the worker because of a failed job on host mustard
<=========
[2020-11-15T01:40:10-0800] [MainThread] [W] [toil.jobGraph] Due to failure we are reducing the remaining retry count of job 'run_cutadapt' kind-run_cutadapt/instance-zdc0z58x with ID kind-run_cutadapt/instance-zdc0z58x to 0
[2020-11-15T01:40:10-0800] [MainThread] [W] [toil.leader] Job 'run_cutadapt' kind-run_cutadapt/instance-zdc0z58x with ID kind-run_cutadapt/instance-zdc0z58x is completely failed
[2020-11-15T01:40:11-0800] [MainThread] [I] [toil.worker] Redirecting logging to /private/home/drkthomp/protect3/workDir/node-60141861-48d9-4a88-81d8-ba092a076b7d-e8611b53-bdab-4598-acae-87977f99831e/tmpd87eiccp/worker_log.txt
[2020-11-15T01:50:51-0800] [Thread-1  ] [E] [toil.batchSystems.singleMachine] Got exit code 1 (indicating failure) from job _toil_worker run_phlat file:/scratch/drkthomp/jobStore kind-run_phlat/instance-z35qoqn5.
[2020-11-15T01:50:51-0800] [MainThread] [W] [toil.leader] Job failed with exit value 1: 'run_phlat' kind-run_phlat/instance-z35qoqn5
[2020-11-15T01:50:51-0800] [MainThread] [W] [toil.leader] The job seems to have left a log file, indicating failure: 'run_phlat' kind-run_phlat/instance-z35qoqn5
[2020-11-15T01:50:51-0800] [MainThread] [W] [toil.leader] Log from job kind-run_phlat/instance-z35qoqn5 follows:
=========>
	[2020-11-15T01:35:02-0800] [MainThread] [I] [toil.worker] ---TOIL WORKER OUTPUT LOG---
	[2020-11-15T01:35:02-0800] [MainThread] [I] [toil] Running Toil version 4.2.0-3aa1da130141039cb357efe36d7df9b9f6ae9b5b on host mustard.
	Got permission denied while trying to connect to the Docker daemon socket at unix:///var/run/docker.sock: Get http://%2Fvar%2Frun%2Fdocker.sock/v1.37/images/json: dial unix /var/run/docker.sock: connect: permission denied
	Traceback (most recent call last):
	  File "/private/home/drkthomp/protect3/venv/lib/python3.6/site-packages/toil/worker.py", line 368, in workerScript
	    job._runner(jobGraph=jobGraph, jobStore=jobStore, fileStore=fileStore, defer=defer)
	  File "/private/home/drkthomp/protect3/venv/lib/python3.6/site-packages/toil/job.py", line 1424, in _runner
	    returnValues = self._run(jobGraph, fileStore)
	  File "/private/home/drkthomp/protect3/venv/lib/python3.6/site-packages/toil/job.py", line 1361, in _run
	    return self.run(fileStore)
	  File "/private/home/drkthomp/protect3/venv/lib/python3.6/site-packages/toil/job.py", line 1565, in run
	    rValue = userFunction(*((self,) + tuple(self._args)), **self._kwargs)
	  File "/private/home/drkthomp/protect3/src/protect/haplotyping/phlat.py", line 74, in run_phlat
	    dockerhub=univ_options['dockerhub'], tool_version=phlat_options['version'])
	  File "/private/home/drkthomp/protect3/src/protect/common.py", line 113, in docker_call
	    dimg_rv = subprocess.check_output(call).decode('utf-8')
	  File "/usr/lib64/python3.6/subprocess.py", line 336, in check_output
	    **kwargs).stdout
	  File "/usr/lib64/python3.6/subprocess.py", line 418, in run
	    output=stdout, stderr=stderr)
	subprocess.CalledProcessError: Command '['docker', 'images']' returned non-zero exit status 1.
	[2020-11-15T01:50:47-0800] [MainThread] [E] [toil.worker] Exiting the worker because of a failed job on host mustard
	{'input_1.fastq': '/private/home/drkthomp/protect3/workDir/node-60141861-48d9-4a88-81d8-ba092a076b7d-e8611b53-bdab-4598-acae-87977f99831e/tmpf8x9yyk2/1454df9f-4b67-4586-b6d7-e59750b2b923/input_1.fastq', 'input_2.fastq': '/private/home/drkthomp/protect3/workDir/node-60141861-48d9-4a88-81d8-ba092a076b7d-e8611b53-bdab-4598-acae-87977f99831e/tmpf8x9yyk2/1454df9f-4b67-4586-b6d7-e59750b2b923/input_2.fastq', 'phlat_index.tar.gz': '/private/home/drkthomp/protect3/workDir/node-60141861-48d9-4a88-81d8-ba092a076b7d-e8611b53-bdab-4598-acae-87977f99831e/tmpf8x9yyk2/1454df9f-4b67-4586-b6d7-e59750b2b923/phlat_index.tar.gz'}
<=========
[2020-11-15T01:50:51-0800] [MainThread] [W] [toil.jobGraph] Due to failure we are reducing the remaining retry count of job 'run_phlat' kind-run_phlat/instance-z35qoqn5 with ID kind-run_phlat/instance-z35qoqn5 to 0
[2020-11-15T01:50:51-0800] [MainThread] [W] [toil.leader] Job 'run_phlat' kind-run_phlat/instance-z35qoqn5 with ID kind-run_phlat/instance-z35qoqn5 is completely failed
[2020-11-15T01:51:36-0800] [Thread-1  ] [E] [toil.batchSystems.singleMachine] Got exit code 1 (indicating failure) from job _toil_worker run_bwa file:/scratch/drkthomp/jobStore kind-run_bwa/instance-bou2djh0.
[2020-11-15T01:51:36-0800] [MainThread] [W] [toil.leader] Job failed with exit value 1: 'run_bwa' kind-run_bwa/instance-bou2djh0
[2020-11-15T01:51:36-0800] [MainThread] [W] [toil.leader] The job seems to have left a log file, indicating failure: 'run_bwa' kind-run_bwa/instance-bou2djh0
[2020-11-15T01:51:36-0800] [MainThread] [W] [toil.leader] Log from job kind-run_bwa/instance-bou2djh0 follows:
=========>
	[2020-11-15T01:40:11-0800] [MainThread] [I] [toil.worker] ---TOIL WORKER OUTPUT LOG---
	[2020-11-15T01:40:11-0800] [MainThread] [I] [toil] Running Toil version 4.2.0-3aa1da130141039cb357efe36d7df9b9f6ae9b5b on host mustard.
	Got permission denied while trying to connect to the Docker daemon socket at unix:///var/run/docker.sock: Get http://%2Fvar%2Frun%2Fdocker.sock/v1.37/images/json: dial unix /var/run/docker.sock: connect: permission denied
	Traceback (most recent call last):
	  File "/private/home/drkthomp/protect3/venv/lib/python3.6/site-packages/toil/worker.py", line 368, in workerScript
	    job._runner(jobGraph=jobGraph, jobStore=jobStore, fileStore=fileStore, defer=defer)
	  File "/private/home/drkthomp/protect3/venv/lib/python3.6/site-packages/toil/job.py", line 1424, in _runner
	    returnValues = self._run(jobGraph, fileStore)
	  File "/private/home/drkthomp/protect3/venv/lib/python3.6/site-packages/toil/job.py", line 1361, in _run
	    return self.run(fileStore)
	  File "/private/home/drkthomp/protect3/venv/lib/python3.6/site-packages/toil/job.py", line 1565, in run
	    rValue = userFunction(*((self,) + tuple(self._args)), **self._kwargs)
	  File "/private/home/drkthomp/protect3/src/protect/alignment/dna.py", line 142, in run_bwa
	    tool_version=bwa_options['version'])
	  File "/private/home/drkthomp/protect3/src/protect/common.py", line 113, in docker_call
	    dimg_rv = subprocess.check_output(call).decode('utf-8')
	  File "/usr/lib64/python3.6/subprocess.py", line 336, in check_output
	    **kwargs).stdout
	  File "/usr/lib64/python3.6/subprocess.py", line 418, in run
	    output=stdout, stderr=stderr)
	subprocess.CalledProcessError: Command '['docker', 'images']' returned non-zero exit status 1.
	[2020-11-15T01:51:31-0800] [MainThread] [E] [toil.worker] Exiting the worker because of a failed job on host mustard
<=========
[2020-11-15T01:51:36-0800] [MainThread] [W] [toil.jobGraph] Due to failure we are reducing the remaining retry count of job 'run_bwa' kind-run_bwa/instance-bou2djh0 with ID kind-run_bwa/instance-bou2djh0 to 0
[2020-11-15T01:51:36-0800] [MainThread] [W] [toil.leader] Job 'run_bwa' kind-run_bwa/instance-bou2djh0 with ID kind-run_bwa/instance-bou2djh0 is completely failed
[2020-11-15T01:51:50-0800] [MainThread] [I] [toil.leader] Finished toil run with 18 failed jobs.
[2020-11-15T01:51:50-0800] [MainThread] [I] [toil.leader] Failed jobs at end of the run: 'get_all_tool_inputs' kind-parse_config_file/instance-ml5szru_ 'run_bwa' kind-EncapsulatedJob/instance-fg9lg8z2 'get_patient_fastqs' kind-get_patient_fastqs/instance-g31njymf 'run_bwa' kind-EncapsulatedJob/instance-w4x4xjcb 'run_phlat' kind-run_phlat/instance-3chuyae2 'run_phlat' kind-EncapsulatedJob/instance-gxsdjbsw 'run_bwa' kind-run_bwa/instance-bou2djh0 'run_phlat' kind-run_phlat/instance-rssn99a0 'get_patient_fastqs' kind-get_patient_fastqs/instance-z2akd685 'prepare_samples' kind-prepare_samples/instance-melw0o77 'launch_protect' kind-launch_protect/instance-9wa2ilmx 'run_phlat' kind-EncapsulatedJob/instance-6r5wxjaz 'run_bwa' kind-run_bwa/instance-fvcm11nr 'run_phlat' kind-EncapsulatedJob/instance-0l8ktz2m 'run_phlat' kind-run_phlat/instance-z35qoqn5 'run_cutadapt' kind-run_cutadapt/instance-zdc0z58x 'get_patient_fastqs' kind-get_patient_fastqs/instance-3b6z2ec2 'run_cutadapt' kind-EncapsulatedJob/instance-9fqlkbpn
Traceback (most recent call last):
  File "/private/home/drkthomp/protect3/venv/bin/ProTECT", line 11, in <module>
    load_entry_point('protect', 'console_scripts', 'ProTECT')()
  File "/private/home/drkthomp/protect3/src/protect/pipeline/ProTECT.py", line 1025, in main
    Job.Runner.startToil(start, params)
  File "/private/home/drkthomp/protect3/venv/lib/python3.6/site-packages/toil/job.py", line 796, in startToil
    return toil.start(job)
  File "/private/home/drkthomp/protect3/venv/lib/python3.6/site-packages/toil/common.py", line 846, in start
    return self._runMainLoop(rootJobGraph)
  File "/private/home/drkthomp/protect3/venv/lib/python3.6/site-packages/toil/common.py", line 1138, in _runMainLoop
    jobCache=self._jobCache).run()
  File "/private/home/drkthomp/protect3/venv/lib/python3.6/site-packages/toil/leader.py", line 269, in run
    raise FailedJobsException(self.config.jobStore, self.toilState.totalFailedJobs, self.jobStore)
toil.leader.FailedJobsException: The job store 'file:/scratch/drkthomp/jobStore' contains 18 failed jobs: 'get_all_tool_inputs' kind-parse_config_file/instance-ml5szru_, 'run_bwa' kind-EncapsulatedJob/instance-fg9lg8z2, 'get_patient_fastqs' kind-get_patient_fastqs/instance-g31njymf, 'run_bwa' kind-EncapsulatedJob/instance-w4x4xjcb, 'run_phlat' kind-run_phlat/instance-3chuyae2, 'run_phlat' kind-EncapsulatedJob/instance-gxsdjbsw, 'run_bwa' kind-run_bwa/instance-bou2djh0, 'run_phlat' kind-run_phlat/instance-rssn99a0, 'get_patient_fastqs' kind-get_patient_fastqs/instance-z2akd685, 'prepare_samples' kind-prepare_samples/instance-melw0o77, 'launch_protect' kind-launch_protect/instance-9wa2ilmx, 'run_phlat' kind-EncapsulatedJob/instance-6r5wxjaz, 'run_bwa' kind-run_bwa/instance-fvcm11nr, 'run_phlat' kind-EncapsulatedJob/instance-0l8ktz2m, 'run_phlat' kind-run_phlat/instance-z35qoqn5, 'run_cutadapt' kind-run_cutadapt/instance-zdc0z58x, 'get_patient_fastqs' kind-get_patient_fastqs/instance-3b6z2ec2, 'run_cutadapt' kind-EncapsulatedJob/instance-9fqlkbpn
Log from job 'run_phlat' kind-run_phlat/instance-3chuyae2 follows:
=========>
	[2020-11-15T01:05:40-0800] [MainThread] [I] [toil.worker] ---TOIL WORKER OUTPUT LOG---
	[2020-11-15T01:05:40-0800] [MainThread] [I] [toil] Running Toil version 4.2.0-3aa1da130141039cb357efe36d7df9b9f6ae9b5b on host mustard.
	Got permission denied while trying to connect to the Docker daemon socket at unix:///var/run/docker.sock: Get http://%2Fvar%2Frun%2Fdocker.sock/v1.37/images/json: dial unix /var/run/docker.sock: connect: permission denied
	Traceback (most recent call last):
	  File "/private/home/drkthomp/protect3/venv/lib/python3.6/site-packages/toil/worker.py", line 368, in workerScript
	    job._runner(jobGraph=jobGraph, jobStore=jobStore, fileStore=fileStore, defer=defer)
	  File "/private/home/drkthomp/protect3/venv/lib/python3.6/site-packages/toil/job.py", line 1424, in _runner
	    returnValues = self._run(jobGraph, fileStore)
	  File "/private/home/drkthomp/protect3/venv/lib/python3.6/site-packages/toil/job.py", line 1361, in _run
	    return self.run(fileStore)
	  File "/private/home/drkthomp/protect3/venv/lib/python3.6/site-packages/toil/job.py", line 1565, in run
	    rValue = userFunction(*((self,) + tuple(self._args)), **self._kwargs)
	  File "/private/home/drkthomp/protect3/src/protect/haplotyping/phlat.py", line 74, in run_phlat
	    dockerhub=univ_options['dockerhub'], tool_version=phlat_options['version'])
	  File "/private/home/drkthomp/protect3/src/protect/common.py", line 113, in docker_call
	    dimg_rv = subprocess.check_output(call).decode('utf-8')
	  File "/usr/lib64/python3.6/subprocess.py", line 336, in check_output
	    **kwargs).stdout
	  File "/usr/lib64/python3.6/subprocess.py", line 418, in run
	    output=stdout, stderr=stderr)
	subprocess.CalledProcessError: Command '['docker', 'images']' returned non-zero exit status 1.
	[2020-11-15T01:19:31-0800] [MainThread] [E] [toil.worker] Exiting the worker because of a failed job on host mustard
	{'input_1.fastq': '/private/home/drkthomp/protect3/workDir/node-60141861-48d9-4a88-81d8-ba092a076b7d-e8611b53-bdab-4598-acae-87977f99831e/tmp_0lelddo/56082201-c209-4966-aac9-416a6c9f8418/input_1.fastq', 'input_2.fastq': '/private/home/drkthomp/protect3/workDir/node-60141861-48d9-4a88-81d8-ba092a076b7d-e8611b53-bdab-4598-acae-87977f99831e/tmp_0lelddo/56082201-c209-4966-aac9-416a6c9f8418/input_2.fastq', 'phlat_index.tar.gz': '/private/home/drkthomp/protect3/workDir/node-60141861-48d9-4a88-81d8-ba092a076b7d-e8611b53-bdab-4598-acae-87977f99831e/tmp_0lelddo/56082201-c209-4966-aac9-416a6c9f8418/phlat_index.tar.gz'}
<=========
Log from job 'run_bwa' kind-run_bwa/instance-bou2djh0 follows:
=========>
	[2020-11-15T01:40:11-0800] [MainThread] [I] [toil.worker] ---TOIL WORKER OUTPUT LOG---
	[2020-11-15T01:40:11-0800] [MainThread] [I] [toil] Running Toil version 4.2.0-3aa1da130141039cb357efe36d7df9b9f6ae9b5b on host mustard.
	Got permission denied while trying to connect to the Docker daemon socket at unix:///var/run/docker.sock: Get http://%2Fvar%2Frun%2Fdocker.sock/v1.37/images/json: dial unix /var/run/docker.sock: connect: permission denied
	Traceback (most recent call last):
	  File "/private/home/drkthomp/protect3/venv/lib/python3.6/site-packages/toil/worker.py", line 368, in workerScript
	    job._runner(jobGraph=jobGraph, jobStore=jobStore, fileStore=fileStore, defer=defer)
	  File "/private/home/drkthomp/protect3/venv/lib/python3.6/site-packages/toil/job.py", line 1424, in _runner
	    returnValues = self._run(jobGraph, fileStore)
	  File "/private/home/drkthomp/protect3/venv/lib/python3.6/site-packages/toil/job.py", line 1361, in _run
	    return self.run(fileStore)
	  File "/private/home/drkthomp/protect3/venv/lib/python3.6/site-packages/toil/job.py", line 1565, in run
	    rValue = userFunction(*((self,) + tuple(self._args)), **self._kwargs)
	  File "/private/home/drkthomp/protect3/src/protect/alignment/dna.py", line 142, in run_bwa
	    tool_version=bwa_options['version'])
	  File "/private/home/drkthomp/protect3/src/protect/common.py", line 113, in docker_call
	    dimg_rv = subprocess.check_output(call).decode('utf-8')
	  File "/usr/lib64/python3.6/subprocess.py", line 336, in check_output
	    **kwargs).stdout
	  File "/usr/lib64/python3.6/subprocess.py", line 418, in run
	    output=stdout, stderr=stderr)
	subprocess.CalledProcessError: Command '['docker', 'images']' returned non-zero exit status 1.
	[2020-11-15T01:51:31-0800] [MainThread] [E] [toil.worker] Exiting the worker because of a failed job on host mustard
<=========
Log from job 'run_phlat' kind-run_phlat/instance-rssn99a0 follows:
=========>
	[2020-11-15T01:19:36-0800] [MainThread] [I] [toil.worker] ---TOIL WORKER OUTPUT LOG---
	[2020-11-15T01:19:36-0800] [MainThread] [I] [toil] Running Toil version 4.2.0-3aa1da130141039cb357efe36d7df9b9f6ae9b5b on host mustard.
	Got permission denied while trying to connect to the Docker daemon socket at unix:///var/run/docker.sock: Get http://%2Fvar%2Frun%2Fdocker.sock/v1.37/images/json: dial unix /var/run/docker.sock: connect: permission denied
	Traceback (most recent call last):
	  File "/private/home/drkthomp/protect3/venv/lib/python3.6/site-packages/toil/worker.py", line 368, in workerScript
	    job._runner(jobGraph=jobGraph, jobStore=jobStore, fileStore=fileStore, defer=defer)
	  File "/private/home/drkthomp/protect3/venv/lib/python3.6/site-packages/toil/job.py", line 1424, in _runner
	    returnValues = self._run(jobGraph, fileStore)
	  File "/private/home/drkthomp/protect3/venv/lib/python3.6/site-packages/toil/job.py", line 1361, in _run
	    return self.run(fileStore)
	  File "/private/home/drkthomp/protect3/venv/lib/python3.6/site-packages/toil/job.py", line 1565, in run
	    rValue = userFunction(*((self,) + tuple(self._args)), **self._kwargs)
	  File "/private/home/drkthomp/protect3/src/protect/haplotyping/phlat.py", line 74, in run_phlat
	    dockerhub=univ_options['dockerhub'], tool_version=phlat_options['version'])
	  File "/private/home/drkthomp/protect3/src/protect/common.py", line 113, in docker_call
	    dimg_rv = subprocess.check_output(call).decode('utf-8')
	  File "/usr/lib64/python3.6/subprocess.py", line 336, in check_output
	    **kwargs).stdout
	  File "/usr/lib64/python3.6/subprocess.py", line 418, in run
	    output=stdout, stderr=stderr)
	subprocess.CalledProcessError: Command '['docker', 'images']' returned non-zero exit status 1.
	[2020-11-15T01:34:56-0800] [MainThread] [E] [toil.worker] Exiting the worker because of a failed job on host mustard
	{'input_1.fastq': '/private/home/drkthomp/protect3/workDir/node-60141861-48d9-4a88-81d8-ba092a076b7d-e8611b53-bdab-4598-acae-87977f99831e/tmpy_dkrea9/78036fa8-a915-466e-aaef-c8d1f08c7bd7/input_1.fastq', 'input_2.fastq': '/private/home/drkthomp/protect3/workDir/node-60141861-48d9-4a88-81d8-ba092a076b7d-e8611b53-bdab-4598-acae-87977f99831e/tmpy_dkrea9/78036fa8-a915-466e-aaef-c8d1f08c7bd7/input_2.fastq', 'phlat_index.tar.gz': '/private/home/drkthomp/protect3/workDir/node-60141861-48d9-4a88-81d8-ba092a076b7d-e8611b53-bdab-4598-acae-87977f99831e/tmpy_dkrea9/78036fa8-a915-466e-aaef-c8d1f08c7bd7/phlat_index.tar.gz'}
<=========
Log from job 'run_bwa' kind-run_bwa/instance-fvcm11nr follows:
=========>
	[2020-11-15T01:06:38-0800] [MainThread] [I] [toil.worker] ---TOIL WORKER OUTPUT LOG---
	[2020-11-15T01:06:38-0800] [MainThread] [I] [toil] Running Toil version 4.2.0-3aa1da130141039cb357efe36d7df9b9f6ae9b5b on host mustard.
	Got permission denied while trying to connect to the Docker daemon socket at unix:///var/run/docker.sock: Get http://%2Fvar%2Frun%2Fdocker.sock/v1.37/images/json: dial unix /var/run/docker.sock: connect: permission denied
	Traceback (most recent call last):
	  File "/private/home/drkthomp/protect3/venv/lib/python3.6/site-packages/toil/worker.py", line 368, in workerScript
	    job._runner(jobGraph=jobGraph, jobStore=jobStore, fileStore=fileStore, defer=defer)
	  File "/private/home/drkthomp/protect3/venv/lib/python3.6/site-packages/toil/job.py", line 1424, in _runner
	    returnValues = self._run(jobGraph, fileStore)
	  File "/private/home/drkthomp/protect3/venv/lib/python3.6/site-packages/toil/job.py", line 1361, in _run
	    return self.run(fileStore)
	  File "/private/home/drkthomp/protect3/venv/lib/python3.6/site-packages/toil/job.py", line 1565, in run
	    rValue = userFunction(*((self,) + tuple(self._args)), **self._kwargs)
	  File "/private/home/drkthomp/protect3/src/protect/alignment/dna.py", line 142, in run_bwa
	    tool_version=bwa_options['version'])
	  File "/private/home/drkthomp/protect3/src/protect/common.py", line 113, in docker_call
	    dimg_rv = subprocess.check_output(call).decode('utf-8')
	  File "/usr/lib64/python3.6/subprocess.py", line 336, in check_output
	    **kwargs).stdout
	  File "/usr/lib64/python3.6/subprocess.py", line 418, in run
	    output=stdout, stderr=stderr)
	subprocess.CalledProcessError: Command '['docker', 'images']' returned non-zero exit status 1.
	[2020-11-15T01:20:32-0800] [MainThread] [E] [toil.worker] Exiting the worker because of a failed job on host mustard
<=========
Log from job 'run_phlat' kind-run_phlat/instance-z35qoqn5 follows:
=========>
	[2020-11-15T01:35:02-0800] [MainThread] [I] [toil.worker] ---TOIL WORKER OUTPUT LOG---
	[2020-11-15T01:35:02-0800] [MainThread] [I] [toil] Running Toil version 4.2.0-3aa1da130141039cb357efe36d7df9b9f6ae9b5b on host mustard.
	Got permission denied while trying to connect to the Docker daemon socket at unix:///var/run/docker.sock: Get http://%2Fvar%2Frun%2Fdocker.sock/v1.37/images/json: dial unix /var/run/docker.sock: connect: permission denied
	Traceback (most recent call last):
	  File "/private/home/drkthomp/protect3/venv/lib/python3.6/site-packages/toil/worker.py", line 368, in workerScript
	    job._runner(jobGraph=jobGraph, jobStore=jobStore, fileStore=fileStore, defer=defer)
	  File "/private/home/drkthomp/protect3/venv/lib/python3.6/site-packages/toil/job.py", line 1424, in _runner
	    returnValues = self._run(jobGraph, fileStore)
	  File "/private/home/drkthomp/protect3/venv/lib/python3.6/site-packages/toil/job.py", line 1361, in _run
	    return self.run(fileStore)
	  File "/private/home/drkthomp/protect3/venv/lib/python3.6/site-packages/toil/job.py", line 1565, in run
	    rValue = userFunction(*((self,) + tuple(self._args)), **self._kwargs)
	  File "/private/home/drkthomp/protect3/src/protect/haplotyping/phlat.py", line 74, in run_phlat
	    dockerhub=univ_options['dockerhub'], tool_version=phlat_options['version'])
	  File "/private/home/drkthomp/protect3/src/protect/common.py", line 113, in docker_call
	    dimg_rv = subprocess.check_output(call).decode('utf-8')
	  File "/usr/lib64/python3.6/subprocess.py", line 336, in check_output
	    **kwargs).stdout
	  File "/usr/lib64/python3.6/subprocess.py", line 418, in run
	    output=stdout, stderr=stderr)
	subprocess.CalledProcessError: Command '['docker', 'images']' returned non-zero exit status 1.
	[2020-11-15T01:50:47-0800] [MainThread] [E] [toil.worker] Exiting the worker because of a failed job on host mustard
	{'input_1.fastq': '/private/home/drkthomp/protect3/workDir/node-60141861-48d9-4a88-81d8-ba092a076b7d-e8611b53-bdab-4598-acae-87977f99831e/tmpf8x9yyk2/1454df9f-4b67-4586-b6d7-e59750b2b923/input_1.fastq', 'input_2.fastq': '/private/home/drkthomp/protect3/workDir/node-60141861-48d9-4a88-81d8-ba092a076b7d-e8611b53-bdab-4598-acae-87977f99831e/tmpf8x9yyk2/1454df9f-4b67-4586-b6d7-e59750b2b923/input_2.fastq', 'phlat_index.tar.gz': '/private/home/drkthomp/protect3/workDir/node-60141861-48d9-4a88-81d8-ba092a076b7d-e8611b53-bdab-4598-acae-87977f99831e/tmpf8x9yyk2/1454df9f-4b67-4586-b6d7-e59750b2b923/phlat_index.tar.gz'}
<=========
Log from job 'run_cutadapt' kind-run_cutadapt/instance-zdc0z58x follows:
=========>
	[2020-11-15T01:36:32-0800] [MainThread] [I] [toil.worker] ---TOIL WORKER OUTPUT LOG---
	[2020-11-15T01:36:32-0800] [MainThread] [I] [toil] Running Toil version 4.2.0-3aa1da130141039cb357efe36d7df9b9f6ae9b5b on host mustard.
	Got permission denied while trying to connect to the Docker daemon socket at unix:///var/run/docker.sock: Get http://%2Fvar%2Frun%2Fdocker.sock/v1.37/images/json: dial unix /var/run/docker.sock: connect: permission denied
	Traceback (most recent call last):
	  File "/private/home/drkthomp/protect3/venv/lib/python3.6/site-packages/toil/worker.py", line 368, in workerScript
	    job._runner(jobGraph=jobGraph, jobStore=jobStore, fileStore=fileStore, defer=defer)
	  File "/private/home/drkthomp/protect3/venv/lib/python3.6/site-packages/toil/job.py", line 1424, in _runner
	    returnValues = self._run(jobGraph, fileStore)
	  File "/private/home/drkthomp/protect3/venv/lib/python3.6/site-packages/toil/job.py", line 1361, in _run
	    return self.run(fileStore)
	  File "/private/home/drkthomp/protect3/venv/lib/python3.6/site-packages/toil/job.py", line 1565, in run
	    rValue = userFunction(*((self,) + tuple(self._args)), **self._kwargs)
	  File "/private/home/drkthomp/protect3/src/protect/qc/rna.py", line 59, in run_cutadapt
	    dockerhub=univ_options['dockerhub'], tool_version=cutadapt_options['version'])
	  File "/private/home/drkthomp/protect3/src/protect/common.py", line 113, in docker_call
	    dimg_rv = subprocess.check_output(call).decode('utf-8')
	  File "/usr/lib64/python3.6/subprocess.py", line 336, in check_output
	    **kwargs).stdout
	  File "/usr/lib64/python3.6/subprocess.py", line 418, in run
	    output=stdout, stderr=stderr)
	subprocess.CalledProcessError: Command '['docker', 'images']' returned non-zero exit status 1.
	[2020-11-15T01:40:09-0800] [MainThread] [E] [toil.worker] Exiting the worker because of a failed job on host mustard
<=========
